Workbook

Sheet Parameters
A1: EFIR — Staffing Model Parameters
A3: School Information
A4: School Name | B4: EFIR
A5: Academic Year | B5: AY 2026-2027 | D5: Projection year
A6: Curriculum | B6: French National (Éducation Nationale) | D6: AEFE homologated
A7: Tracks Offered | B7: Voie Générale only
A8: Weeks per Year | B8: 36 | D8: Standard French school year
A10: Class Size Parameters
A11: Level | B11: Max Class Size | C11: Input Override | D11: Notes
A12: PS (Maternelle) | B12: 24 | D12: Standard French maternelle
A13: MS (Maternelle) | B13: 24
A14: GS (Maternelle) | B14: 24
A15: CP | B15: 26 | D15: Élémentaire standard
A16: CE1 | B16: 26
A17: CE2 | B17: 26
A18: CM1 | B18: 26
A19: CM2 | B19: 26
A20: 6ème | B20: 26 | D20: Collège standard
A21: 5ème | B21: 26
A22: 4ème | B22: 26
A23: 3ème | B23: 26
A24: 2nde | B24: 28 | D24: Lycée — voie générale
A25: 1ère | B25: 28
A26: Terminale | B26: 28
A28: Teacher Service Obligations (h/week)
A29: Staff Category | B29: Weekly Hours | D29: Notes
A30: Professeur des Écoles (Maternelle/Élémentaire) | B30: 24 | D30: 26h in front of students, 108h annual other duties
A31: Certifié (Collège/Lycée) | B31: 18 | D31: Standard secondary teaching obligation
A32: Agrégé (Collège/Lycée) | B32: 15 | D32: If applicable
A33: Professeur d'EPS | B33: 20 | D33: Physical education
A34: Documentaliste | B34: 30 | D34: CDI — different nature of service
A35: Arabic/Islamic Studies Teacher | B35: 24 | D35: Estimated — adjust per EFIR contract
A36: ASEM / Teaching Assistant (Maternelle) | B36: 35 | D36: Full-time assistant
A38: HSA Optimization Parameters
A39: Parameter | B39: Value | C39: Range | D39: Notes
A40: HSA per Certifié (avg) | B40: 1.5 | C40: 0 – 2 | D40: Décret 2019-309: max 2 HSA imposable; AEFE avg ≈ 1.7
A41: HSA per Agrégé (avg) | B41: 1.5 | C41: 0 – 2 | D41: Same decree applies; ORS = 15h so effective = 15 + HSA
A42: HSA per EPS teacher (avg) | B42: 1 | C42: 0 – 2 | D42: ORS = 20h; typically less HSA capacity
A43: Effective ORS — Certifié | B43: =B31+B40 -> 19.5 | C43: h/wk | D43: ORS (18) + HSA assumption -> used for FTE calc
A44: Effective ORS — Agrégé | B44: =B32+B41 -> 16.5 | C44: h/wk | D44: ORS (15) + HSA assumption
...

Sheet Enrollment
A1: EFIR — Enrollment & Capacity Planning
A3: Grade | B3: Band | C3: AY2 Enrollment | D3: Max Class Size | E3: Sections Needed | F3: Plancher (70%) | G3: Cible (85%) | H3: Plafond (100%) | I3: Utilization % | J3: Alert
A4: PS | B4: Maternelle | C4: 65 | D4: 24 | E4: =ROUNDUP(C4/D4,0) -> 3 | F4: =ROUND(E4*D4*0.7,0) -> 50 | G4: =ROUND(E4*D4*0.85,0) -> 61 | H4: =E4*D4 -> 72 | I4: =C4/(E4*D4) -> 0.90277778 | J4: =IF(I4>0.95,"⚠ Near Cap",IF(I4<0.7,"⚠ Low","OK")) -> OK
A5: MS | B5: Maternelle | C5: 77 | D5: 24 | E5: =ROUNDUP(C5/D5,0) -> 4 | F5: =ROUND(E5*D5*0.7,0) -> 67 | G5: =ROUND(E5*D5*0.85,0) -> 82 | H5: =E5*D5 -> 96 | I5: =C5/(E5*D5) -> 0.80208333 | J5: =IF(I5>0.95,"⚠ Near Cap",IF(I5<0.7,"⚠ Low","OK")) -> OK
A6: GS | B6: Maternelle | C6: 124 | D6: 24 | E6: =ROUNDUP(C6/D6,0) -> 6 | F6: =ROUND(E6*D6*0.7,0) -> 101 | G6: =ROUND(E6*D6*0.85,0) -> 122 | H6: =E6*D6 -> 144 | I6: =C6/(E6*D6) -> 0.86111111 | J6: =IF(I6>0.95,"⚠ Near Cap",IF(I6<0.7,"⚠ Low","OK")) -> OK
A7: CP | B7: Élémentaire | C7: 126 | D7: 26 | E7: =ROUNDUP(C7/D7,0) -> 5 | F7: =ROUND(E7*D7*0.7,0) -> 91 | G7: =ROUND(E7*D7*0.85,0) -> 111 | H7: =E7*D7 -> 130 | I7: =C7/(E7*D7) -> 0.96923077 | J7: =IF(I7>0.95,"⚠ Near Cap",IF(I7<0.7,"⚠ Low","OK")) -> ⚠ Near Cap
A8: CE1 | B8: Élémentaire | C8: 118 | D8: 26 | E8: =ROUNDUP(C8/D8,0) -> 5 | F8: =ROUND(E8*D8*0.7,0) -> 91 | G8: =ROUND(E8*D8*0.85,0) -> 111 | H8: =E8*D8 -> 130 | I8: =C8/(E8*D8) -> 0.90769231 | J8: =IF(I8>0.95,"⚠ Near Cap",IF(I8<0.7,"⚠ Low","OK")) -> OK
A9: CE2 | B9: Élémentaire | C9: 132 | D9: 26 | E9: =ROUNDUP(C9/D9,0) -> 6 | F9: =ROUND(E9*D9*0.7,0) -> 109 | G9: =ROUND(E9*D9*0.85,0) -> 133 | H9: =E9*D9 -> 156 | I9: =C9/(E9*D9) -> 0.84615385 | J9: =IF(I9>0.95,"⚠ Near Cap",IF(I9<0.7,"⚠ Low","OK")) -> OK
A10: CM1 | B10: Élémentaire | C10: 121 | D10: 26 | E10: =ROUNDUP(C10/D10,0) -> 5 | F10: =ROUND(E10*D10*0.7,0) -> 91 | G10: =ROUND(E10*D10*0.85,0) -> 111 | H10: =E10*D10 -> 130 | I10: =C10/(E10*D10) -> 0.93076923 | J10: =IF(I10>0.95,"⚠ Near Cap",IF(I10<0.7,"⚠ Low","OK")) -> OK
A11: CM2 | B11: Élémentaire | C11: 121 | D11: 26 | E11: =ROUNDUP(C11/D11,0) -> 5 | F11: =ROUND(E11*D11*0.7,0) -> 91 | G11: =ROUND(E11*D11*0.85,0) -> 111 | H11: =E11*D11 -> 130 | I11: =C11/(E11*D11) -> 0.93076923 | J11: =IF(I11>0.95,"⚠ Near Cap",IF(I11<0.7,"⚠ Low","OK")) -> OK
A12: 6ème | B12: Collège | C12: 151 | D12: 26 | E12: =ROUNDUP(C12/D12,0) -> 6 | F12: =ROUND(E12*D12*0.7,0) -> 109 | G12: =ROUND(E12*D12*0.85,0) -> 133 | H12: =E12*D12 -> 156 | I12: =C12/(E12*D12) -> 0.96794872 | J12: =IF(I12>0.95,"⚠ Near Cap",IF(I12<0.7,"⚠ Low","OK")) -> ⚠ Near Cap
A13: 5ème | B13: Collège | C13: 139 | D13: 26 | E13: =ROUNDUP(C13/D13,0) -> 6 | F13: =ROUND(E13*D13*0.7,0) -> 109 | G13: =ROUND(E13*D13*0.85,0) -> 133 | H13: =E13*D13 -> 156 | I13: =C13/(E13*D13) -> 0.89102564 | J13: =IF(I13>0.95,"⚠ Near Cap",IF(I13<0.7,"⚠ Low","OK")) -> OK
A14: 4ème | B14: Collège | C14: 120 | D14: 26 | E14: =ROUNDUP(C14/D14,0) -> 5 | F14: =ROUND(E14*D14*0.7,0) -> 91 | G14: =ROUND(E14*D14*0.85,0) -> 111 | H14: =E14*D14 -> 130 | I14: =C14/(E14*D14) -> 0.92307692 | J14: =IF(I14>0.95,"⚠ Near Cap",IF(I14<0.7,"⚠ Low","OK")) -> OK
A15: 3ème | B15: Collège | C15: 103 | D15: 26 | E15: =ROUNDUP(C15/D15,0) -> 4 | F15: =ROUND(E15*D15*0.7,0) -> 73 | G15: =ROUND(E15*D15*0.85,0) -> 88 | H15: =E15*D15 -> 104 | I15: =C15/(E15*D15) -> 0.99038462 | J15: =IF(I15>0.95,"⚠ Near Cap",IF(I15<0.7,"⚠ Low","OK")) -> ⚠ Near Cap
... A18: Terminale | B18: Lycée | C18: 111 | D18: 28 | E18: =ROUNDUP(C18/D18,0) -> 4 | F18: =ROUND(E18*D18*0.7,0) -> 78 | G18: =ROUND(E18*D18*0.85,0) -> 95 | H18: =E18*D18 -> 112 | I18: =C18/(E18*D18) -> 0.99107143 | J18: =IF(I18>0.95,"⚠ Near Cap",IF(I18<0.7,"⚠ Low","OK")) -> ⚠ Near Cap
A20: TOTAL SCHOOL | C20: =SUM(C4:C18) -> 1753 | E20: =SUM(E4:E18) -> 74

Sheet Grille_Maternelle
A1: EFIR — Maternelle Teaching Hours (PS / MS / GS)
A2: Framework: Not DHG — French Maternelle uses 24h/week student time + 1 teacher per class + 1 ASEM
A4: Domain / Activity | B4: PS (h/wk) | C4: MS (h/wk) | D4: GS (h/wk) | E4: Notes
A5: Mobiliser le langage (oral & écrit) | B5: 8 | C5: 8 | D5: 9 | E5: Core language development
A6: Agir, s'exprimer à travers l'activité physique | B6: 3 | C6: 3 | D6: 3 | E6: Physical activity
A7: Agir, s'exprimer à travers les activités artistiques | B7: 3 | C7: 3 | D7: 2.5 | E7: Arts & creativity
A8: Construire les premiers outils (maths) | B8: 2 | C8: 3 | D8: 3.5 | E8: Early numeracy
A9: Explorer le monde | B9: 2.5 | C9: 2.5 | D9: 2.5 | E9: Discovery of the world
A10: Récréations | B10: 2.5 | C10: 2.5 | D10: 2.5 | E10: Breaks
A11: Accueil / Rituels | B11: 3 | C11: 2 | D11: 1 | E11: Welcome & routines
A12: Total Student Hours / Week | B12: =SUM(B5:B11) -> 24 | C12: =SUM(C5:C11) -> 24 | D12: =SUM(D5:D11) -> 24
A14: Host-Country Additions
A15: Subject | B15: PS (h/wk) | C15: MS (h/wk) | D15: GS (h/wk) | E15: Notes
A16: Arabic Language | B16: 2 | C16: 3 | D16: 3 | E16: KSA standard for French schools
A17: Islamic Studies | B17: 1 | C17: 1 | D17: 1 | E17: KSA standard for French schools
A18: Total Host-Country Hours / Week | B18: =SUM(B16:B17) -> 3 | C18: =SUM(C16:C17) -> 4 | D18: =SUM(D16:D17) -> 4
A20: Staffing Calculation — Maternelle
A21: Metric | B21: PS | C21: MS | D21: GS | E21: Notes
A22: Sections (from Enrollment) | B22: =Enrollment!E4 -> 3 | C22: =Enrollment!E5 -> 4 | D22: =Enrollment!E6 -> 6 | E22: Auto-linked from Enrollment sheet
A23: French Curriculum Teachers (PE) | B23: =B22 -> 3 | C23: =C22 -> 4 | D23: =D22 -> 6 | E23: 1 PE per section
A24: ASEM Assistants | B24: =B22 -> 3 | C24: =C22 -> 4 | D24: =D22 -> 6 | E24: 1 ASEM per section
A25: Arabic Teacher Hours Needed | B25: =B16*B22 -> 6 | C25: =C16*C22 -> 12 | D25: =D16*D22 -> 18 | E25: Hours = h/wk per section × sections
A26: Islamic Studies Hours Needed | B26: =B17*B22 -> 3 | C26: =C17*C22 -> 4 | D26: =D17*D22 -> 6

Sheet Grille_Elementaire
A1: EFIR — Élémentaire Teaching Hours (CP to CM2)
A2: Framework: French Élémentaire — 24h/week student hours, 1 PE per class
A4: Discipline | B4: CP (h/wk) | C4: CE1 (h/wk) | D4: CE2 (h/wk) | E4: CM1 (h/wk) | F4: CM2 (h/wk) | G4: Notes
A5: Français | B5: 10 | C5: 8 | D5: 8 | E5: 8 | F5: 8 | G5: Lecture, écriture, grammaire, vocabulaire
A6: Mathématiques | B6: 5 | C6: 5 | D6: 5 | E6: 5 | F6: 5 | G6: Nombres, calcul, géométrie, mesures
A7: Langue Vivante (Anglais) | B7: 1.5 | C7: 1.5 | D7: 1.5 | E7: 1.5 | F7: 1.5 | G7: LVA — English
A8: EPS | B8: 3 | C8: 3 | D8: 3 | E8: 3 | F8: 3 | G8: Éducation physique et sportive
A9: Sciences et Technologie | B9: 1 | C9: 1.5 | D9: 1.5 | E9: 2 | F9: 2 | G9: Questionner le monde / Sciences
A10: Histoire-Géographie-EMC | B10: 1 | C10: 1.5 | D10: 1.5 | E10: 2 | F10: 2 | G10: Questionner le monde / HG-EMC
A11: Arts Plastiques | B11: 1 | C11: 1 | D11: 1 | E11: 1 | F11: 1
A12: Éducation Musicale | B12: 1 | C12: 1 | D12: 1 | E12: 1 | F12: 1
A13: Récréations | B13: 0.5 | C13: 0.5 | D13: 0.5 | E13: 0.5 | F13: 0.5 | G13: Included in 24h framework
A14: Total Student Hours / Week | B14: =SUM(B5:B13) -> 24 | C14: =SUM(C5:C13) -> 23 | D14: =SUM(D5:D13) -> 23 | E14: =SUM(E5:E13) -> 24 | F14: =SUM(F5:F13) -> 24
A16: Host-Country Additions
A17: Subject | B17: CP (h/wk) | C17: CE1 (h/wk) | D17: CE2 (h/wk) | E17: CM1 (h/wk) | F17: CM2 (h/wk) | G17: Notes
A18: Arabic Language | B18: 4 | C18: 4 | D18: 4 | E18: 3 | F18: 3 | G18: KSA standard estimate
A19: Islamic Studies | B19: 2 | C19: 2 | D19: 2 | E19: 1 | F19: 1 | G19: KSA standard estimate
A20: Total Host-Country Hours / Week | B20: =SUM(B18:B19) -> 6 | C20: =SUM(C18:C19) -> 6 | D20: =SUM(D18:D19) -> 6 | E20: =SUM(E18:E19) -> 4 | F20: =SUM(F18:F19) -> 4
A22: Staffing Calculation — Élémentaire
A23: Metric | B23: CP | C23: CE1 | D23: CE2 | E23: CM1 | F23: CM2 | G23: Notes
A24: Sections (from Enrollment) | B24: =Enrollment!E7 -> 5 | C24: =Enrollment!E8 -> 5 | D24: =Enrollment!E9 -> 6 | E24: =Enrollment!E10 -> 5 | F24: =Enrollment!E11 -> 5 | G24: Auto-linked
A25: French Curriculum Teachers (PE) | B25: =B24 -> 5 | C25: =C24 -> 5 | D25: =D24 -> 6 | E25: =E24 -> 5 | F25: =F24 -> 5 | G25: 1 PE per section
A26: Arabic Teacher Hours Needed | B26: =B18*B24 -> 20 | C26: =C18*C24 -> 20 | D26: =D18*D24 -> 24 | E26: =E18*E24 -> 15 | F26: =F18*F24 -> 15 | G26: h/wk × sections
A27: Islamic Studies Hours Needed | B27: =B19*B24 -> 10 | C27: =C19*C24 -> 10 | D27: =D19*D24 -> 12 | E27: =E19*E24 -> 5 | F27: =F19*F24 -> 5

Sheet DHG_College
A1: EFIR — DHG Collège (6ème to 3ème)
A2: French National Grille Horaire — Arrêté du 19 mai 2015 (modified 2024/2025)
A4: Discipline | B4: 6ème (h/wk) | C4: 5ème (h/wk) | D4: 4ème (h/wk) | E4: 3ème (h/wk) | F4: 6ème Total | G4: 5ème Total | H4: 4ème Total | I4: 3ème Total | J4: Notes
A5: SECTIONS (from Enrollment) | B5: =Enrollment!E12 -> 6 | C5: =Enrollment!E13 -> 6 | D5: =Enrollment!E14 -> 5 | E5: =Enrollment!E15 -> 4
A6: Français | B6: 4.5 | C6: 4.5 | D6: 4.5 | E6: 4 | F6: =B6*B5 -> 27 | G6: =C6*C5 -> 27 | H6: =D6*D5 -> 22.5 | I6: =E6*E5 -> 16
A7: Mathématiques | B7: 4.5 | C7: 3.5 | D7: 3.5 | E7: 3.5 | F7: =B7*B5 -> 27 | G7: =C7*C5 -> 21 | H7: =D7*D5 -> 17.5 | I7: =E7*E5 -> 14
A8: Histoire-Géographie-EMC | B8: 3 | C8: 3 | D8: 3 | E8: 3.5 | F8: =B8*B5 -> 18 | G8: =C8*C5 -> 18 | H8: =D8*D5 -> 15 | I8: =E8*E5 -> 14 | J8: dont 30min EMC
A9: LVA — Anglais | B9: 4 | C9: 3 | D9: 3 | E9: 3 | F9: =B9*B5 -> 24 | G9: =C9*C5 -> 18 | H9: =D9*D5 -> 15 | I9: =E9*E5 -> 12
A10: LVB — Espagnol | B10: 0 | C10: 2.5 | D10: 2.5 | E10: 2.5 | F10: =B10*B5 -> 0 | G10: =C10*C5 -> 15 | H10: =D10*D5 -> 12.5 | I10: =E10*E5 -> 10 | J10: Starts in 5ème
A11: Sciences de la Vie et de la Terre | B11: 1.5 | C11: 1.5 | D11: 1.5 | E11: 1.5 | F11: =B11*B5 -> 9 | G11: =C11*C5 -> 9 | H11: =D11*D5 -> 7.5 | I11: =E11*E5 -> 6
A12: Physique-Chimie | B12: 1 | C12: 1.5 | D12: 1.5 | E12: 1.5 | F12: =B12*B5 -> 6 | G12: =C12*C5 -> 9 | H12: =D12*D5 -> 7.5 | I12: =E12*E5 -> 6
A13: Technologie | B13: 1.5 | C13: 1.5 | D13: 1.5 | E13: 1.5 | F13: =B13*B5 -> 9 | G13: =C13*C5 -> 9 | H13: =D13*D5 -> 7.5 | I13: =E13*E5 -> 6
A14: Arts Plastiques | B14: 1 | C14: 1 | D14: 1 | E14: 1 | F14: =B14*B5 -> 6 | G14: =C14*C5 -> 6 | H14: =D14*D5 -> 5 | I14: =E14*E5 -> 4
A15: Éducation Musicale | B15: 1 | C15: 1 | D15: 1 | E15: 1 | F15: =B15*B5 -> 6 | G15: =C15*C5 -> 6 | H15: =D15*D5 -> 5 | I15: =E15*E5 -> 4
A16: EPS | B16: 4 | C16: 3 | D16: 3 | E16: 3 | F16: =B16*B5 -> 24 | G16: =C16*C5 -> 18 | H16: =D16*D5 -> 15 | I16: =E16*E5 -> 12
A17: Marge d'autonomie (3h/division) | B17: 3 | C17: 3 | D17: 3 | E17: 3 | F17: =B17*B5 -> 18 | G17: =C17*C5 -> 18 | H17: =D17*D5 -> 15 | I17: =E17*E5 -> 12 | J17: AP, EPI, dédoublements, options
A18: TOTAL STRUCTURAL DHG (Collège) | B18: =SUM(B6:B17) -> 29 | C18: =SUM(C6:C17) -> 29 | D18: =SUM(D6:D17) -> 29 | E18: =SUM(E6:E17) -> 29 | F18: =SUM(F6:F17) -> 174 | G18: =SUM(G6:G17) -> 174 | H18: =SUM(H6:H17) -> 145 | I18: =SUM(I6:I17) -> 116
A20: Host-Country Additions — Collège
A21: Subject | B21: 6ème (h/wk) | C21: 5ème (h/wk) | D21: 4ème (h/wk) | E21: 3ème (h/wk) | F21: 6ème Total | G21: 5ème Total | H21: 4ème Total | I21: 3ème Total | J21: Notes
A22: Arabic Language | B22: 3 | C22: 3 | D22: 3 | E22: 3 | F22: =B22*B5 -> 18 | G22: =C22*C5 -> 18 | H22: =D22*D5 -> 15 | I22: =E22*E5 -> 12 | J22: KSA estimate for collège
A23: Islamic Studies | B23: 1 | C23: 1 | D23: 1 | E23: 1 | F23: =B23*B5 -> 6 | G23: =C23*C5 -> 6 | H23: =D23*D5 -> 5 | I23: =E23*E5 -> 4 | J23: KSA estimate for collège
A25: Complementary Dotations
A26: Item | B26: Hours/week | F26: Total h/wk | J26: Notes
A27: UNSS (3h per EPS teacher post) | B27: 3 | J27: Per EPS post — estimate 2 posts
A28: Vie de classe (10h annuelles/division) | B28: 0.28 | J28: 10h/36 weeks ≈ 0.28h/wk per division
A29: LV3 option (if offered) | B29: 3 | J29: Per LV3 group — estimate

Sheet DHG_Lycee
A1: EFIR — DHG Lycée Général (2nde / 1ère / Terminale)
A2: Voie Générale — Réforme Blanquer (Arrêté 16 juillet 2018, modified)
A4: SECONDE GÉNÉRALE ET TECHNOLOGIQUE
A5: Discipline | B5: h/wk per student | C5: Sections | D5: Total h/wk needed | H5: Notes
A6: Sections 2nde | C6: =Enrollment!E16 -> 5
A7: Français | B7: 4 | D7: =B7*C6 -> 20
A8: Histoire-Géographie | B8: 3 | D8: =B8*C6 -> 15
A9: LVA — Anglais | B9: 3 | D9: =B9*C6 -> 15
A10: LVB — Espagnol | B10: 2.5 | D10: =B10*C6 -> 12.5
A11: Sciences Économiques et Sociales | B11: 1.5 | D11: =B11*C6 -> 7.5
A12: Mathématiques | B12: 4 | D12: =B12*C6 -> 20
A13: Physique-Chimie | B13: 3 | D13: =B13*C6 -> 15
A14: Sciences de la Vie et de la Terre | B14: 1.5 | D14: =B14*C6 -> 7.5
A15: EPS | B15: 2 | D15: =B15*C6 -> 10
A16: Enseignement Moral et Civique | B16: 0.5 | D16: =B16*C6 -> 2.5
A17: Sciences Numériques et Technologie | B17: 1.5 | D17: =B17*C6 -> 7.5
A18: Heures d'autonomie (12h/division) | B18: 12 | D18: =B18*C6 -> 60 | H18: AP, groupes réduits, options
A19: TOTAL 2NDE DHG | D19: =SUM(D7:D18) -> 192.5
A21: PREMIÈRE GÉNÉRALE — Tronc Commun
A22: Discipline | B22: h/wk per student | C22: Sections | D22: Total h/wk needed | H22: Notes
A23: Sections 1ère | C23: =Enrollment!E17 -> 5
A24: Français | B24: 4 | D24: =B24*C23 -> 20
A25: Histoire-Géographie | B25: 3 | D25: =B25*C23 -> 15
A26: LVA — Anglais | B26: 2.5 | D26: =B26*C23 -> 12.5
A27: LVB — Espagnol | B27: 2 | D27: =B27*C23 -> 10
A28: Enseignement Scientifique | B28: 2 | D28: =B28*C23 -> 10
A29: EPS | B29: 2 | D29: =B29*C23 -> 10
A30: Enseignement Moral et Civique | B30: 0.5 | D30: =B30*C23 -> 2.5
A32: PREMIÈRE — Spécialités (3 × 4h)
A33: Spécialité | B33: h/wk | C33: Groups Est. | D33: Total h/wk | H33: Notes
A34: Mathématiques | B34: 4 | C34: 3 | D34: =B34*C34 -> 12 | H34: Estimate 3 groups
A35: Physique-Chimie | B35: 4 | C35: 2 | D35: =B35*C35 -> 8 | H35: Estimate 2 groups
A36: SVT | B36: 4 | C36: 2 | D36: =B36*C36 -> 8 | H36: Estimate 2 groups
A37: SES | B37: 4 | C37: 2 | D37: =B37*C37 -> 8 | H37: Estimate 2 groups
A38: HGGSP | B38: 4 | C38: 2 | D38: =B38*C38 -> 8 | H38: Estimate 2 groups
A39: NSI | B39: 4 | C39: 1 | D39: =B39*C39 -> 4 | H39: Estimate 1 group
A40: Heures d'autonomie (8h/division) | B40: 8 | D40: =B40*C23 -> 40
A41: Maths Tronc Commun (non-spé, 1.5h) | B41: 1.5 | C41: 2 | D41: =B41*C41 -> 3 | H41: Groups of students not taking Maths spé
A42: TOTAL 1ÈRE DHG | D42: =SUM(D24:D30)+SUM(D34:D39)+D40+D41 -> 171
A44: TERMINALE GÉNÉRALE — Tronc Commun
...

Sheet DHG_Optimization
A1: EFIR - DHG Optimization & HSA Scenario Analysis
A2: Flexible model: adjust HSA assumptions in Parameters to see impact on FTE needs
A4: SECTION A: Raw DHG Hours Summary
A5: Level | B5: Structural DHG (h/wk) | C5: Host-Country Arabic (h/wk) | D5: Host-Country Islamic (h/wk) | E5: Complementary (h/wk) | F5: Total DHG (h/wk) | G5: Notes
A6: 6eme | B6: =DHG_College!F18 -> 174 | C6: =DHG_College!F22 -> 18 | D6: =DHG_College!F23 -> 6 | E6: =DHG_College!B28*Enrollment!E12 -> 1.68 | F6: =B6+C6+D6+E6 -> 199.68 | G6: Structural + marge autonomie
A7: 5eme | B7: =DHG_College!G18 -> 174 | C7: =DHG_College!G22 -> 18 | D7: =DHG_College!G23 -> 6 | E7: =DHG_College!B28*Enrollment!E13 -> 1.68 | F7: =B7+C7+D7+E7 -> 199.68
A8: 4eme | B8: =DHG_College!H18 -> 145 | C8: =DHG_College!H22 -> 15 | D8: =DHG_College!H23 -> 5 | E8: =DHG_College!B28*Enrollment!E14 -> 1.4 | F8: =B8+C8+D8+E8 -> 166.4
A9: 3eme | B9: =DHG_College!I18 -> 116 | C9: =DHG_College!I22 -> 12 | D9: =DHG_College!I23 -> 4 | E9: =DHG_College!B28*Enrollment!E15 -> 1.12 | F9: =B9+C9+D9+E9 -> 133.12
A10: 2nde | B10: =DHG_Lycee!D19 -> 192.5 | C10: =DHG_Lycee!E68 -> 10 | D10: =DHG_Lycee!E69 -> 5 | E10: 0 | F10: =B10+C10+D10+E10 -> 207.5 | G10: Incl. 12h autonomie/div
A11: 1ere | B11: =DHG_Lycee!D42 -> 171 | C11: =DHG_Lycee!F68 -> 10 | D11: =DHG_Lycee!F69 -> 5 | E11: 0 | F11: =B11+C11+D11+E11 -> 186 | G11: Tronc commun + specialites
A12: Terminale | B12: =DHG_Lycee!D64 -> 154 | C12: =DHG_Lycee!G68 -> 8 | D12: =DHG_Lycee!G69 -> 4 | E12: 0 | F12: =B12+C12+D12+E12 -> 166 | G12: Tronc commun + specialites
A13: TOTAL SECONDARY | B13: =SUM(B6:B12) -> 1126.5 | C13: =SUM(C6:C12) -> 91 | D13: =SUM(D6:D12) -> 35 | E13: =SUM(E6:E12) -> 5.88 | F13: =SUM(F6:F12) -> 1258.38
A15: SECTION B: FTE Scenario Comparison (Certifie basis)
A16: Metric | B16: No HSA (ORS=18) | C16: Conservative (1 HSA) | D16: Your Scenario | E16: Full HSA (2 HSA) | F16: Savings vs No HSA | G16: H/E Benchmark | H16: Notes
A17: Effective ORS (h/wk) | B17: 18 | C17: 19 | D17: =Parameters!B43 -> 19.5 | E17: 20 | H17: Linked to Parameters!B43
A18: Total DHG Hours (h/wk) | B18: =F13 -> 1258.38 | C18: =F13 -> 1258.38 | D18: =F13 -> 1258.38 | E18: =F13 -> 1258.38
A19: FTE Needed (raw decimal) | B19: =B18/B17 -> 69.91 | C19: =C18/C17 -> 66.230526 | D19: =D18/D17 -> 64.532308 | E19: =E18/E17 -> 62.919 | H19: Total DHG / Effective ORS
A20: FTE Rounded Up (positions) | B20: =ROUNDUP(B19,0) -> 70 | C20: =ROUNDUP(C19,0) -> 67 | D20: =ROUNDUP(D19,0) -> 65 | E20: =ROUNDUP(E19,0) -> 63 | H20: Rounded from total; differs from level sum due to rounding
A21: Positions Saved vs No HSA | B21: 0 | C21: =B20-C20 -> 3 | D21: =B20-D20 -> 5 | E21: =B20-E20 -> 7 | F21: =D21 -> 5 | H21: Change HSA in Parameters to see impact
A22: Total HSA Hours Generated | B22: =B20*0 -> 0 | C22: =C20*1 -> 67 | D22: =D20*Parameters!B40 -> 97.5 | E22: =E20*2 -> 126
A24: SECTION C: FTE by Level (Your Scenario - linked to Parameters)
A25: Level | B25: Total DHG (h/wk) | C25: Effective ORS | D25: FTE (raw) | E25: FTE (rounded) | F25: FTE without HSA | G25: Delta | H25: Notes
A26: 6eme | B26: =F6 -> 199.68 | C26: =Parameters!B43 -> 19.5 | D26: =B26/C26 -> 10.24 | E26: =ROUNDUP(D26,0) -> 11 | F26: =ROUNDUP(B26/18,0) -> 12 | G26: =F26-E26 -> 1 | H26: College
A27: 5eme | B27: =F7 -> 199.68 | C27: =Parameters!B43 -> 19.5 | D27: =B27/C27 -> 10.24 | E27: =ROUNDUP(D27,0) -> 11 | F27: =ROUNDUP(B27/18,0) -> 12 | G27: =F27-E27 -> 1 | H27: College
A28: 4eme | B28: =F8 -> 166.4 | C28: =Parameters!B43 -> 19.5 | D28: =B28/C28 -> 8.5333333 | E28: =ROUNDUP(D28,0) -> 9 | F28: =ROUNDUP(B28/18,0) -> 10 | G28: =F28-E28 -> 1 | H28: College
A29: 3eme | B29: =F9 -> 133.12 | C29: =Parameters!B43 -> 19.5 | D29: =B29/C29 -> 6.8266667 | E29: =ROUNDUP(D29,0) -> 7 | F29: =ROUNDUP(B29/18,0) -> 8 | G29: =F29-E29 -> 1 | H29: College
A30: 2nde | B30: =F10 -> 207.5 | C30: =Parameters!B43 -> 19.5 | D30: =B30/C30 -> 10.641026 | E30: =ROUNDUP(D30,0) -> 11 | F30: =ROUNDUP(B30/18,0) -> 12 | G30: =F30-E30 -> 1 | H30: Lycee
A31: 1ere | B31: =F11 -> 186 | C31: =Parameters!B43 -> 19.5 | D31: =B31/C31 -> 9.5384615 | E31: =ROUNDUP(D31,0) -> 10 | F31: =ROUNDUP(B31/18,0) -> 11 | G31: =F31-E31 -> 1 | H31: Lycee
A32: Terminale | B32: =F12 -> 166 | C32: =Parameters!B43 -> 19.5 | D32: =B32/C32 -> 8.5128205 | E32: =ROUNDUP(D32,0) -> 9 | F32: =ROUNDUP(B32/18,0) -> 10 | G32: =F32-E32 -> 1 | H32: Lycee
A33: TOTAL SECONDARY | B33: =SUM(B26:B32) -> 1258.38 | D33: =SUM(D26:D32) -> 64.532308 | E33: =SUM(E26:E32) -> 68 | F33: =SUM(F26:F32) -> 75 | G33: =SUM(G26:G32) -> 7 | H33: Positions saved with HSA
A35: SECTION D: AEFE H/E Benchmark Cross-Reference
A36: Level | B36: Students | C36: Sections | D36: Avg Students/Div | E36: H/E (AEFE Mean) | F36: AEFE FTE Estimate | G36: EFIR Model FTE | H36: Variance
A37: 6eme | B37: =Enrollment!C12 -> 151 | C37: =Enrollment!E12 -> 6 | D37: =IFERROR(B37/C37,0) -> 25.166667 | E37: =MAX(0.87, -0.0536*D37+2.798) -> 1.4490667 | F37: =E37*B37/18 -> 12.156059 | G37: =D26 -> 10.24 | H37: =G37-F37 -> -1.9160593
A38: 5eme | B38: =Enrollment!C13 -> 139 | C38: =Enrollment!E13 -> 6 | D38: =IFERROR(B38/C38,0) -> 23.166667 | E38: =MAX(0.87, -0.0536*D38+2.798) -> 1.5562667 | F38: =E38*B38/18 -> 12.017837 | G38: =D27 -> 10.24 | H38: =G38-F38 -> -1.777837
A39: 4eme | B39: =Enrollment!C14 -> 120 | C39: =Enrollment!E14 -> 5 | D39: =IFERROR(B39/C39,0) -> 24 | E39: =MAX(0.87, -0.0536*D39+2.798) -> 1.5116 | F39: =E39*B39/18 -> 10.077333 | G39: =D28 -> 8.5333333 | H39: =G39-F39 -> -1.544
A40: 3eme | B40: =Enrollment!C15 -> 103 | C40: =Enrollment!E15 -> 4 | D40: =IFERROR(B40/C40,0) -> 25.75 | E40: =MAX(0.87, -0.0536*D40+2.798) -> 1.4178 | F40: =E40*B40/18 -> 8.1129667 | G40: =D29 -> 6.8266667 | H40: =G40-F40 -> -1.2863
A41: 2nde | B41: =Enrollment!C16 -> 125 | C41: =Enrollment!E16 -> 5 | D41: =IFERROR(B41/C41,0) -> 25 | E41: =MAX(0.98, -0.0809*D41+3.805) -> 1.7825 | F41: =E41*B41/18 -> 12.378472 | G41: =D30 -> 10.641026 | H41: =G41-F41 -> -1.7374466
A42: 1ere | B42: =Enrollment!C17 -> 120 | C42: =Enrollment!E17 -> 5 | D42: =IFERROR(B42/C42,0) -> 24 | E42: =MAX(0.98, -0.0809*D42+3.805) -> 1.8634 | F42: =E42*B42/18 -> 12.422667 | G42: =D31 -> 9.5384615 | H42: =G42-F42 -> -2.8842051
A43: Terminale | B43: =Enrollment!C18 -> 111 | C43: =Enrollment!E18 -> 4 | D43: =IFERROR(B43/C43,0) -> 27.75 | E43: =MAX(0.98, -0.0809*D43+3.805) -> 1.560025 | F43: =E43*B43/18 -> 9.6201542 | G43: =D32 -> 8.5128205 | H43: =G43-F43 -> -1.1073337
A44: TOTAL SECONDARY | B44: =SUM(B37:B43) -> 869 | F44: =SUM(F37:F43) -> 76.785489 | G44: =SUM(G37:G43) -> 64.532308 | H44: =G44-F44 -> -12.253182

Sheet Staff_Summary
A1: EFIR — Teaching Staff Force Summary
A2: Consolidated view across all levels — PS to Terminale
A4: SECTION A: Staff Count by Level
A5: Level / Band | B5: Sections | C5: FR Teachers | D5: ASEM/Assist. | E5: Arabic Hrs | F5: Islamic Hrs | G5: Total Staff* | H5: Notes
A6: PS | B6: =Enrollment!E4 -> 3 | C6: =Enrollment!E4 -> 3 | D6: =Enrollment!E4 -> 3 | E6: =Grille_Maternelle!B25 -> 6 | F6: =Grille_Maternelle!B26 -> 3 | H6: Maternelle
A7: MS | B7: =Enrollment!E5 -> 4 | C7: =Enrollment!E5 -> 4 | D7: =Enrollment!E5 -> 4 | E7: =Grille_Maternelle!C25 -> 12 | F7: =Grille_Maternelle!C26 -> 4 | H7: Maternelle
A8: GS | B8: =Enrollment!E6 -> 6 | C8: =Enrollment!E6 -> 6 | D8: =Enrollment!E6 -> 6 | E8: =Grille_Maternelle!D25 -> 18 | F8: =Grille_Maternelle!D26 -> 6 | H8: Maternelle
A9: CP | B9: =Enrollment!E7 -> 5 | C9: =Enrollment!E7 -> 5 | D9: 0 | E9: =Grille_Elementaire!B26 -> 20 | F9: =Grille_Elementaire!B27 -> 10 | H9: Élémentaire
A10: CE1 | B10: =Enrollment!E8 -> 5 | C10: =Enrollment!E8 -> 5 | D10: 0 | E10: =Grille_Elementaire!C26 -> 20 | F10: =Grille_Elementaire!C27 -> 10 | H10: Élémentaire
A11: CE2 | B11: =Enrollment!E9 -> 6 | C11: =Enrollment!E9 -> 6 | D11: 0 | E11: =Grille_Elementaire!D26 -> 24 | F11: =Grille_Elementaire!D27 -> 12 | H11: Élémentaire
A12: CM1 | B12: =Enrollment!E10 -> 5 | C12: =Enrollment!E10 -> 5 | D12: 0 | E12: =Grille_Elementaire!E26 -> 15 | F12: =Grille_Elementaire!E27 -> 5 | H12: Élémentaire
A13: CM2 | B13: =Enrollment!E11 -> 5 | C13: =Enrollment!E11 -> 5 | D13: 0 | E13: =Grille_Elementaire!F26 -> 15 | F13: =Grille_Elementaire!F27 -> 5 | H13: Élémentaire
A14: 6ème | B14: =Enrollment!E12 -> 6 | C14: =DHG_College!F18/Parameters!$B$43 -> 8.9230769 | D14: 0 | E14: =DHG_College!F22 -> 18 | F14: =DHG_College!F23 -> 6 | H14: College - FTE = DHG / Effective ORS
A15: 5ème | B15: =Enrollment!E13 -> 6 | C15: =DHG_College!G18/Parameters!$B$43 -> 8.9230769 | D15: 0 | E15: =DHG_College!G22 -> 18 | F15: =DHG_College!G23 -> 6 | H15: College - FTE = DHG / Effective ORS
A16: 4ème | B16: =Enrollment!E14 -> 5 | C16: =DHG_College!H18/Parameters!$B$43 -> 7.4358974 | D16: 0 | E16: =DHG_College!H22 -> 15 | F16: =DHG_College!H23 -> 5 | H16: College - FTE = DHG / Effective ORS
A17: 3ème | B17: =Enrollment!E15 -> 4 | C17: =DHG_College!I18/Parameters!$B$43 -> 5.9487179 | D17: 0 | E17: =DHG_College!I22 -> 12 | F17: =DHG_College!I23 -> 4 | H17: College - FTE = DHG / Effective ORS
A18: 2nde | B18: =Enrollment!E16 -> 5 | C18: =DHG_Lycee!D19/Parameters!$B$43 -> 9.8717949 | D18: 0 | E18: =DHG_Lycee!E68 -> 10 | F18: =DHG_Lycee!E69 -> 5 | H18: Lycee - FTE = DHG / Effective ORS
A19: 1ère | B19: =Enrollment!E17 -> 5 | C19: =DHG_Lycee!D42/Parameters!$B$43 -> 8.7692308 | D19: 0 | E19: =DHG_Lycee!F68 -> 10 | F19: =DHG_Lycee!F69 -> 5 | H19: Lycee - FTE = DHG / Effective ORS
A20: Terminale | B20: =Enrollment!E18 -> 4 | C20: =DHG_Lycee!D64/Parameters!$B$43 -> 7.8974359 | D20: 0 | E20: =DHG_Lycee!G68 -> 8 | F20: =DHG_Lycee!G69 -> 4 | H20: Lycee - FTE = DHG / Effective ORS
A22: TOTAL ALL LEVELS | B22: =SUM(B6:B20) -> 74 | C22: =SUM(C6:C20) -> 96.769231 | D22: =SUM(D6:D20) -> 13 | E22: =SUM(E6:E20) -> 221 | F22: =SUM(F6:F20) -> 90
A24: SECTION B: Arabic & Islamic FTE Conversion
A25: Category | B25: Total h/wk needed | C25: Service Obligation | D25: FTE Needed | H25: Notes
A26: Arabic Teachers | B26: =E22 -> 221 | C26: 24 | D26: =ROUNDUP(B26/C26,0) -> 10 | H26: Rounded up to whole positions
A27: Islamic Studies Teachers | B27: =F22 -> 90 | C27: 24 | D27: =ROUNDUP(B27/C27,0) -> 4
A29: SECTION C: Grand Total Teaching Staff
A30: Category | B30: Headcount | H30: Notes
A31: Professeurs des Écoles (Maternelle) | B31: =SUM(C6:C8) -> 13 | H31: 1 per section
A32: ASEM Assistants (Maternelle) | B32: =SUM(D6:D8) -> 13 | H32: 1 per section
A33: Professeurs des Écoles (Élémentaire) | B33: =SUM(C9:C13) -> 26 | H33: 1 per section
A34: Enseignants Secondaire (Collège+Lycée) — FTE | B34: =SUM(C14:C20) -> 57.769231 | H34: DHG hours / Effective ORS (incl. HSA)
A35: Arabic Teachers | B35: =D26 -> 10
A36: Islamic Studies Teachers | B36: =D27 -> 4
A37: GRAND TOTAL TEACHING STAFF | B37: =SUM(B31:B36) -> 123.76923

Sheet Staffing_By_Subject
A1: EFIR — Staffing Requirements by Subject Type
A2: All levels PS to Terminale — AY 2025-2026 (Current) vs AY 2026-2027 (Projected)
A4: SECTION A: Enrollment Summary & Projections
A5: Band | B5: Grade | C5: Sections | D5: AY1 Enrollment (Current) | E5: AY2 Enrollment (2026-27) | F5: Delta
A6: Maternelle | B6: PS | C6: =Enrollment!E4 -> 3 | E6: =Enrollment!C4 -> 65 | F6: =IF(D6="","",E6-D6)
A7: Maternelle | B7: MS | C7: =Enrollment!E5 -> 4 | E7: =Enrollment!C5 -> 77 | F7: =IF(D7="","",E7-D7)
A8: Maternelle | B8: GS | C8: =Enrollment!E6 -> 6 | E8: =Enrollment!C6 -> 124 | F8: =IF(D8="","",E8-D8)
A9: Élémentaire | B9: CP | C9: =Enrollment!E7 -> 5 | E9: =Enrollment!C7 -> 126 | F9: =IF(D9="","",E9-D9)
A10: Élémentaire | B10: CE1 | C10: =Enrollment!E8 -> 5 | E10: =Enrollment!C8 -> 118 | F10: =IF(D10="","",E10-D10)
A11: Élémentaire | B11: CE2 | C11: =Enrollment!E9 -> 6 | E11: =Enrollment!C9 -> 132 | F11: =IF(D11="","",E11-D11)
A12: Élémentaire | B12: CM1 | C12: =Enrollment!E10 -> 5 | E12: =Enrollment!C10 -> 121 | F12: =IF(D12="","",E12-D12)
A13: Élémentaire | B13: CM2 | C13: =Enrollment!E11 -> 5 | E13: =Enrollment!C11 -> 121 | F13: =IF(D13="","",E13-D13)
A14: Collège | B14: 6ème | C14: =Enrollment!E12 -> 6 | E14: =Enrollment!C12 -> 151 | F14: =IF(D14="","",E14-D14)
A15: Collège | B15: 5ème | C15: =Enrollment!E13 -> 6 | E15: =Enrollment!C13 -> 139 | F15: =IF(D15="","",E15-D15)
A16: Collège | B16: 4ème | C16: =Enrollment!E14 -> 5 | E16: =Enrollment!C14 -> 120 | F16: =IF(D16="","",E16-D16)
A17: Collège | B17: 3ème | C17: =Enrollment!E15 -> 4 | E17: =Enrollment!C15 -> 103 | F17: =IF(D17="","",E17-D17)
... A20: Lycée | B20: Terminale | C20: =Enrollment!E18 -> 4 | E20: =Enrollment!C18 -> 111 | F20: =IF(D20="","",E20-D20)
B21: TOTAL | C21: =SUM(C6:C20) -> 74 | D21: =IF(COUNTA(D6:D20)=0,"",SUM(D6:D20)) | E21: =SUM(E6:E20) -> 1753 | F21: =IF(D21="","",E21-D21)
A22: ↑ Column D (AY1): Link to 01_EFIR_Revenue_FY2026_v3.xlsx for current-year enrollment
A24: SECTION B: Teaching Hours & FTE Requirements by Subject Type (AY2 — 2026-2027)
A25: Subject / Discipline | B25: Category | C25: Maternelle (h/wk) | D25: Élémentaire (h/wk) | E25: Collège (h/wk) | F25: Lycée (h/wk) | G25: Total Hours/wk | H25: ORS Basis | I25: FTE (raw) | J25: FTE (rounded) | K25: Staff Type | L25: Language | M25: FTE French-Medium | N25: FTE English/Other
A26: Français | B26: French Curriculum | C26: n/a | D26: n/a | E26: =DHG_College!F6+DHG_College!G6+DHG_College!H6+DHG_College!I6 -> 92.5 | F26: =DHG_Lycee!D7+DHG_Lycee!D24 -> 40 | G26: =E26+F26 -> 132.5 | H26: =Parameters!B43 -> 19.5 | I26: =G26/H26 -> 6.7948718 | J26: =ROUNDUP(I26,0) -> 7 | K26: Certifié | L26: French | M26: =J26 -> 7 | N26: 0
A27: Mathématiques | B27: French Curriculum | C27: n/a | D27: n/a | E27: =DHG_College!F7+DHG_College!G7+DHG_College!H7+DHG_College!I7 -> 79.5 | F27: =DHG_Lycee!D12+DHG_Lycee!D34+DHG_Lycee!D41+DHG_Lycee!D57 -> 53 | G27: =E27+F27 -> 132.5 | H27: =Parameters!B43 -> 19.5 | I27: =G27/H27 -> 6.7948718 | J27: =ROUNDUP(I27,0) -> 7 | K27: Certifié | L27: French | M27: =J27 -> 7 | N27: 0
A28: Histoire-Géo-EMC | B28: French Curriculum | C28: n/a | D28: n/a | E28: =DHG_College!F8+DHG_College!G8+DHG_College!H8+DHG_College!I8 -> 65 | F28: =DHG_Lycee!D8+DHG_Lycee!D16+DHG_Lycee!D25+DHG_Lycee!D30+DHG_Lycee!D38+DHG_Lycee!D48+DHG_Lycee!D53+DHG_Lycee!D61 -> 63 | G28: =E28+F28 -> 128 | H28: =Parameters!B43 -> 19.5 | I28: =G28/H28 -> 6.5641026 | J28: =ROUNDUP(I28,0) -> 7 | K28: Certifié | L28: French | M28: =J28 -> 7 | N28: 0
A29: LVA — Anglais (English) | B29: English | C29: n/a | D29: n/a | E29: =DHG_College!F9+DHG_College!G9+DHG_College!H9+DHG_College!I9 -> 69 | F29: =DHG_Lycee!D9+DHG_Lycee!D26+DHG_Lycee!D49 -> 35.5 | G29: =E29+F29 -> 104.5 | H29: =Parameters!B43 -> 19.5 | I29: =G29/H29 -> 5.3589744 | J29: =ROUNDUP(I29,0) -> 6 | K29: Certifié | L29: English | M29: 0 | N29: =J29 -> 6
A30: LVB — Espagnol (Spanish) | B30: Spanish | C30: n/a | D30: n/a | E30: =DHG_College!F10+DHG_College!G10+DHG_College!H10+DHG_College!I10 -> 37.5 | F30: =DHG_Lycee!D10+DHG_Lycee!D27+DHG_Lycee!D50 -> 30.5 | G30: =E30+F30 -> 68 | H30: =Parameters!B43 -> 19.5 | I30: =G30/H30 -> 3.4871795 | J30: =ROUNDUP(I30,0) -> 4 | K30: Certifié | L30: Spanish | M30: 0 | N30: =J30 -> 4
A31: Sciences (SVT + Physique-Chimie) | B31: French Curriculum | C31: n/a | D31: n/a | E31: =DHG_College!F11+DHG_College!G11+DHG_College!H11+DHG_College!I11+DHG_College!F12+DHG_College!G12+DHG_College!H12+DHG_College!I12 -> 60 | F31: =DHG_Lycee!D13+DHG_Lycee!D14+DHG_Lycee!D28+DHG_Lycee!D35+DHG_Lycee!D36+DHG_Lycee!D51+DHG_Lycee!D58+DHG_Lycee!D59 -> 80.5 | G31: =E31+F31 -> 140.5 | H31: =Parameters!B43 -> 19.5 | I31: =G31/H31 -> 7.2051282 | J31: =ROUNDUP(I31,0) -> 8 | K31: Certifié | L31: French | M31: =J31 -> 8 | N31: 0
A32: EPS (Sports) | B32: French Curriculum | C32: n/a | D32: n/a | E32: =DHG_College!F16+DHG_College!G16+DHG_College!H16+DHG_College!I16 -> 69 | F32: =DHG_Lycee!D15+DHG_Lycee!D29+DHG_Lycee!D52 -> 28 | G32: =E32+F32 -> 97 | H32: =Parameters!B45 -> 21 | I32: =G32/H32 -> 4.6190476 | J32: =ROUNDUP(I32,0) -> 5 | K32: Prof EPS | L32: French | M32: =J32 -> 5 | N32: 0
A33: Technologie / SNT / NSI | B33: French Curriculum | C33: n/a | D33: n/a | E33: =DHG_College!F13+DHG_College!G13+DHG_College!H13+DHG_College!I13 -> 31.5 | F33: =DHG_Lycee!D17+DHG_Lycee!D39+DHG_Lycee!D62 -> 17.5 | G33: =E33+F33 -> 49 | H33: =Parameters!B43 -> 19.5 | I33: =G33/H33 -> 2.5128205 | J33: =ROUNDUP(I33,0) -> 3 | K33: Certifié | L33: French | M33: =J33 -> 3 | N33: 0
A34: Arts Plastiques + Éd. Musicale | B34: French Curriculum | C34: n/a | D34: n/a | E34: =DHG_College!F14+DHG_College!G14+DHG_College!H14+DHG_College!I14+DHG_College!F15+DHG_College!G15+DHG_College!H15+DHG_College!I15 -> 42 | F34: 0 | G34: =E34+F34 -> 42 | H34: =Parameters!B43 -> 19.5 | I34: =G34/H34 -> 2.1538462 | J34: =ROUNDUP(I34,0) -> 3 | K34: Certifié | L34: French | M34: =J34 -> 3 | N34: 0
A35: SES (Économie) | B35: French Curriculum | C35: n/a | D35: n/a | E35: 0 | F35: =DHG_Lycee!D11+DHG_Lycee!D37+DHG_Lycee!D60 -> 21.5 | G35: =E35+F35 -> 21.5 | H35: =Parameters!B43 -> 19.5 | I35: =G35/H35 -> 1.1025641 | J35: =ROUNDUP(I35,0) -> 2 | K35: Certifié | L35: French | M35: =J35 -> 2 | N35: 0
A36: Philosophie | B36: French Curriculum | C36: n/a | D36: n/a | E36: 0 | F36: =DHG_Lycee!D47 -> 16 | G36: =E36+F36 -> 16 | H36: =Parameters!B43 -> 19.5 | I36: =G36/H36 -> 0.82051282 | J36: =ROUNDUP(I36,0) -> 1 | K36: Certifié | L36: French | M36: =J36 -> 1 | N36: 0
A37: Marge autonomie + Heures autonomie | B37: Shared Pool | C37: n/a | D37: n/a | E37: =DHG_College!F17+DHG_College!G17+DHG_College!H17+DHG_College!I17 -> 63 | F37: =DHG_Lycee!D18+DHG_Lycee!D40+DHG_Lycee!D63 -> 132 | G37: =E37+F37 -> 195 | H37: =Parameters!B43 -> 19.5 | I37: =G37/H37 -> 10 | J37: =ROUNDUP(I37,0) -> 10 | K37: Shared | L37: French | M37: =J37 -> 10 | N37: 0
A38: SUBTOTAL: Secondary (DHG-based) | E38: =SUM(E26:E37) -> 609 | F38: =SUM(F26:F37) -> 517.5 | G38: =SUM(G26:G37) -> 1126.5 | J38: =SUM(J26:J37) -> 63 | M38: =SUM(M26:M37) -> 53 | N38: =SUM(N26:N37) -> 10
A39: PRIMARY & HOST-COUNTRY STAFF
A40: Professeurs des Écoles (Maternelle) | B40: Primary | C40: =SUM(Enrollment!E4:E6) -> 13 | D40: n/a | E40: n/a | F40: n/a | H40: 24 (PE) | J40: =C40 -> 13 | K40: PE (Mat.) | L40: French | M40: =J40 -> 13 | N40: 0
A41: ASEM / Assistants (Maternelle) | B41: Primary | C41: =SUM(Enrollment!E4:E6) -> 13 | D41: n/a | E41: n/a | F41: n/a | H41: 35 (ASEM) | J41: =C41 -> 13 | K41: ASEM | L41: n/a
A42: Professeurs des Écoles (Élémentaire) | B42: Primary | C42: n/a | D42: =SUM(Enrollment!E7:E11) -> 26 | E42: n/a | F42: n/a | H42: 24 (PE) | J42: =D42 -> 26 | K42: PE (Élém.) | L42: French | M42: =J42 -> 26 | N42: 0
A43: Arabic Language (Host-Country) | B43: Arabic | C43: =Grille_Maternelle!B25+Grille_Maternelle!C25+Grille_Maternelle!D25 -> 36 | D43: =Grille_Elementaire!B26+Grille_Elementaire!C26+Grille_Elementaire!D26+Grille_Elementaire!E26+Grille_Elementaire!F26 -> 94 | E43: =DHG_College!F22+DHG_College!G22+DHG_College!H22+DHG_College!I22 -> 63 | F43: =DHG_Lycee!E68+DHG_Lycee!F68+DHG_Lycee!G68 -> 28 | G43: =C43+D43+E43+F43 -> 221 | H43: =Parameters!B35 -> 24 | I43: =G43/H43 -> 9.2083333 | J43: =ROUNDUP(I43,0) -> 10 | K43: Arabic Teacher | L43: Arabic | M43: 0 | N43: =J43 -> 10
A44: Islamic Studies (Host-Country) | B44: Islamic | C44: =Grille_Maternelle!B26+Grille_Maternelle!C26+Grille_Maternelle!D26 -> 13 | D44: =Grille_Elementaire!B27+Grille_Elementaire!C27+Grille_Elementaire!D27+Grille_Elementaire!E27+Grille_Elementaire!F27 -> 42 | E44: =DHG_College!F23+DHG_College!G23+DHG_College!H23+DHG_College!I23 -> 21 | F44: =DHG_Lycee!E69+DHG_Lycee!F69+DHG_Lycee!G69 -> 14 | G44: =C44+D44+E44+F44 -> 90 | H44: =Parameters!B35 -> 24 | I44: =G44/H44 -> 3.75 | J44: =ROUNDUP(I44,0) -> 4 | K44: Islamic Teacher | L44: Arabic | M44: 0 | N44: =J44 -> 4
...
