Workbook

Sheet Assumptions & Inputs
A1: EFIR - Staff Costs Budget FY2026 V3 - Key Assumptions & Modifiable Inputs
A2: YELLOW CELLS = Modifiable inputs. All linked sheets update automatically.
A4: EMPLOYMENT STRUCTURE
A5: Total Headcount (Existing + New Positions) | B5: 168
A6: - Existing Staff | B6: 162
A7: - New Positions (Starting Sep 2026) | B7: 6
A8: Saudi Employees | B8: 2
A9: Non-Saudi / Ajeer Employees (Existing) | B9: 160
A10: Non-Saudi / Ajeer Employees (New - Sep start) | B10: 6
A12: AJEER COST PARAMETERS
A13: Annual Ajeer Levy per Non-Saudi Worker (SAR) | B13: 9500 | C13: <-- Modify: SAR 9,500 (non-Nitaqat) or SAR 1,500 (Nitaqat)
A14: Monthly Ajeer Platform Fee per Worker (SAR) | B14: 160
A15: Number of Ajeer Workers (Full Year - Existing) | B15: 160
A16: Number of Ajeer Workers (Sep-Dec - New Positions) | B16: 6
A17: Total Annual Ajeer Cost per Worker (SAR) | B17: =B13+(B14*12) -> 11420
A18: Ajeer Cost - Existing Workers (Full Year) | B18: =B17*B15 -> 1827200
A19: Ajeer Cost - New Positions (Sep-Dec, 4 months) | B19: =(B13*(4/12)+B14*4)*B16 -> 22840
A20: TOTAL ANNUAL AJEER COST (SAR) | B20: =B18+B19 -> 1850040
A21: Monthly Ajeer Cost - Existing (SAR) | B21: =B18/12 -> 152266.67
A22: Monthly Ajeer Cost - New (Sep-Dec only, SAR) | B22: =B19/4 -> 5710
A24: GOSI PARAMETERS
A25: GOSI Rate - Saudi Employees | B25: 0.1175 | C25: 9.75% Pension + 1% SANED + 1% OHI
A26: GOSI Rate - Non-Saudi (Ajeer) Employees | B26: 0 | C26: 0% - Not under EFIR sponsorship (Ajeer workers)
A28: ADDITIONAL YEARLY COST LINES
A29: Contrats Locaux Remplacements | B29: 272167 | C29: Monthly: 22,681 SAR
A30: Contrats Locaux 1% Masse Salariale (Form. Continue) | B30: 306046 | C30: Monthly: 25,504 SAR
A31: Résidents Salaires | B31: 7356097 | C31: Monthly: 613,008 SAR
A32: Résidents Logement & Billets Avion | B32: 647400 | C32: Monthly: 53,950 SAR
A33: TOTAL ADDITIONAL YEARLY COSTS | B33: =SUM(B29:B32) -> 8581710
A35: SALARY AUGMENTATION (2026-2027)
A36: Augmentation applies from September 2026
A37: Jan-Aug: Current salaries | Sep-Dec: Current + Aug | Jul-Aug: No HSA
A38: Total planned monthly augmentation (SAR) | B38: 30900
A40: NEW POSITIONS (Starting September 2026)
A41: Position | B41: Monthly Gross | C41: Base Salary | D41: IL | E41: IT | F41: FY2026 Cost (4 months)
A42: Infirmière (1/2 temps) | B42: 5200 | C42: 3700 | D42: 1250 | E42: 250 | F42: 20800
A43: Administratif RH | B43: 10400 | C43: 7400 | D43: 2500 | E43: 500 | F43: 41600
A44: Administratif Odoo | B44: 10400 | C44: 7400 | D44: 2500 | E44: 500 | F44: 41600
A45: Administratif MG | B45: 10400 | C45: 7400 | D45: 2500 | E45: 500 | F45: 41600
A46: Administratif Technicien IT | B46: 10600 | C46: 7600 | D46: 2500 | E46: 500 | F46: 42400
...

Sheet Staff Master Data
A1: EFIR - Staff Master Data FY2026 (V3 - New Positions Start Sep 2026)
A2: Headcount: 168 (Existing: 162 + New: 6 from Sep) | Saudi: 2 | Ajeer: 166 | Currency: SAR
A4: # | B4: Last Name | C4: First Name | D4: Function / Role | E4: Department | F4: Status | G4: Joining Date | H4: YoS | I4: Base Salary | J4: Housing (IL) | K4: Transport (IT) | L4: Resp. Premium | M4: HSA (10m) | N4: Monthly Gross | O4: Hourly % | P4: Saudi/Ajeer | Q4: Payment | R4: Aug. 2026-27
A5: 1 | B5: ABED | C5: Ghina | D5: Assistant(e) d'éducation | E5: Vie Scolaire & Support | F5: Existing | G5: 45170 | H5: 3.3 | I5: 7400 | J5: 2500 | K5: 500 | L5: 0 | M5: 0 | N5: =SUM(I5:M5) -> 10400 | O5: 1 | P5: Ajeer | Q5: Liquide | R5: 200
A6: 2 | B6: ABID | C6: Hamdi | D6: Assistant(e) d'éducation | E6: Vie Scolaire & Support | F6: Existing | G6: 42614 | H6: 10.3 | I6: 9000 | J6: 2500 | K6: 500 | L6: 0 | M6: 0 | N6: =SUM(I6:M6) -> 12000 | O6: 1 | P6: Ajeer | Q6: Virement | R6: 400
A7: 3 | B7: ABOU RJEILI | C7: Christina | D7: Assistant(e) d'éducation | E7: Vie Scolaire & Support | F7: Existing | G7: 45536 | H7: 2.3 | I7: 7200 | J7: 2500 | K7: 500 | L7: 0 | M7: 0 | N7: =SUM(I7:M7) -> 10200 | O7: 1 | P7: Ajeer | Q7: Virement | R7: 200
A8: 4 | B8: ABOUTALEB | C8: Hasnae | D8: Professeur(e) des écoles | E8: Élémentaire | F8: Existing | G8: 44440 | H8: 5.3 | I8: 9000 | J8: 2500 | K8: 500 | L8: 0 | M8: 0 | N8: =SUM(I8:M8) -> 12000 | O8: 1 | P8: Ajeer | Q8: Virement | R8: 250
A9: 5 | B9: ABSIL | C9: Marie-Savine | D9: Professeur(e) des écoles | E9: Élémentaire | F9: Existing | G9: 45901 | H9: 1.3 | I9: 10500 | J9: 2500 | K9: 500 | L9: 0 | M9: 0 | N9: =SUM(I9:M9) -> 13500 | O9: 1 | P9: Ajeer | Q9: Liquide | R9: Nouveau Contrat
A10: 6 | B10: ACHATOU | C10: Nadia | D10: Responsable RH | E10: Administration | F10: Existing | G10: 42614 | H10: 10.3 | I10: 12250 | J10: 2500 | K10: 500 | L10: 1000 | M10: 0 | N10: =SUM(I10:M10) -> 16250 | O10: 1 | P10: Ajeer | Q10: Mudad | R10: 250
A11: 7 | B11: ADJTOUTAH | C11: Anissa | D11: Professeur(e) des écoles | E11: Élémentaire | F11: Existing | G11: 45901 | H11: 1.3 | I11: 8250 | J11: 2500 | K11: 500 | L11: 0 | M11: 0 | N11: =SUM(I11:M11) -> 11250 | O11: 1 | P11: Ajeer | Q11: Liquide | R11: Nouveau Contrat
A12: 8 | B12: AHYOUD | C12: Hanan | D12: Professeur(e) des écoles | E12: Élémentaire | F12: Existing | G12: 42614 | H12: 10.3 | I12: 10250 | J12: 2500 | K12: 500 | L12: 0 | M12: 0 | N12: =SUM(I12:M12) -> 13250 | O12: 1 | P12: Ajeer | Q12: Virement | R12: 250
A13: 9 | B13: AL JUNDI | C13: Tamara | D13: Enseignant de langue étrangère | E13: Élémentaire | F13: Existing | G13: 35309 | H13: 30.3 | I13: 9750 | J13: 2500 | K13: 500 | L13: 0 | M13: 1140 | N13: =SUM(I13:M13) -> 13890 | O13: 1 | P13: Ajeer | Q13: Virement | R13: 250
A14: 10 | B14: AL NAHED | C14: Saliha | D14: Professeur(e) des écoles | E14: Élémentaire | F14: Existing | G14: 45536 | H14: 2.3 | I14: 8750 | J14: 2500 | K14: 500 | L14: 0 | M14: 0 | N14: =SUM(I14:M14) -> 11750 | O14: 1 | P14: Ajeer | Q14: Virement | R14: 250
A15: 11 | B15: AL OSSAIMI AL OTAIBI | C15: BADR | D15: Démarcheur | E15: Administration | F15: Existing | I15: 2000 | J15: 2500 | K15: 500 | L15: 0 | M15: 0 | N15: =SUM(I15:M15) -> 5000 | O15: 1 | P15: Saudi | Q15: Virement | R15: Nouveau Contrat
A16: 12 | B16: AL SHAKHAA | C16: Nada | D16: Chargé(e) du programme noor | E16: Administration | F16: Existing | G16: 42283 | H16: 11.2 | I16: 9500 | J16: 2500 | K16: 500 | L16: 0 | M16: 0 | N16: =SUM(I16:M16) -> 12500 | O16: 1 | P16: Ajeer | Q16: Mudad | R16: 250
A17: 13 | B17: ALAMRI | C17: Shalan | D17: Chargé(e) des relations publiques | E17: Administration | F17: Existing | G17: 44867 | H17: 4.2 | I17: 12250 | J17: 2500 | K17: 500 | L17: 1000 | M17: 0 | N17: =SUM(I17:M17) -> 16250 | O17: 1 | P17: Saudi | Q17: Mudad | R17: 250
A18: 14 | B18: ALNACHAR | C18: Farah | D18: Assistant(e) d'éducation | E18: Vie Scolaire & Support | F18: Existing | G18: 45901 | H18: 1.3 | I18: 7000 | J18: 2500 | K18: 500 | L18: 0 | M18: 0 | N18: =SUM(I18:M18) -> 10000 | O18: 1 | P18: Ajeer | Q18: Virement | R18: Nouveau Contrat
A19: 15 | B19: AMANAT | C19: Aisha | D19: Professeur(e) des écoles | E19: Élémentaire | F19: Existing | G19: 45536 | H19: 2.3 | I19: 8250 | J19: 2500 | K19: 500 | L19: 0 | M19: 0 | N19: =SUM(I19:M19) -> 11250 | O19: 1 | P19: Ajeer | Q19: Liquide | R19: 250
A20: 16 | B20: AMRI | C20: Kehena | D20: Enseignant second degré | E20: Collège / Lycée | F20: Existing | G20: 40787 | H20: 15.3 | I20: 12000 | J20: 2500 | K20: 500 | L20: 0 | M20: 900 | N20: =SUM(I20:M20) -> 15900 | O20: 1 | P20: Ajeer | Q20: Virement | R20: 250
A21: 17 | B21: ASSEKOUR | C21: Soufiane | D21: Enseignant second degré | E21: Collège / Lycée | F21: Existing | G21: 45901 | H21: 1.3 | I21: 8750 | J21: 2500 | K21: 500 | L21: 0 | M21: 700 | N21: =SUM(I21:M21) -> 12450 | O21: 1 | P21: Ajeer | Q21: Liquide | R21: Nouveau Contrat
A22: 18 | B22: AYACHI | C22: Amen | D22: Professeur(e) des écoles | E22: Élémentaire | F22: Existing | G22: 45536 | H22: 2.3 | I22: 9000 | J22: 2500 | K22: 500 | L22: 0 | M22: 0 | N22: =SUM(I22:M22) -> 12000 | O22: 1 | P22: Ajeer | Q22: Virement | R22: 250
A23: 19 | B23: BACHOUR | C23: Reem | D23: Enseignant de langue étrangère | E23: Élémentaire | F23: Existing | G23: 36404 | H23: 27.3 | I23: 13250 | J23: 2500 | K23: 500 | L23: 0 | M23: 1140 | N23: =SUM(I23:M23) -> 17390 | O23: 1 | P23: Ajeer | Q23: Virement | R23: 250
A24: 20 | B24: BADR | C24: Chantal | D24: Enseignant de langue étrangère | E24: Élémentaire | F24: Existing | G24: 40787 | H24: 15.3 | I24: 10250 | J24: 2500 | K24: 500 | L24: 0 | M24: 70 | N24: =SUM(I24:M24) -> 13320 | O24: 1 | P24: Ajeer | Q24: Virement | R24: 250
A25: 21 | B25: BALLAN | C25: Christiane | D25: Enseignant de langue étrangère second degré | E25: Collège / Lycée | F25: Existing | G25: 44805 | H25: 4.3 | I25: 8750 | J25: 2500 | K25: 500 | L25: 0 | M25: 1300 | N25: =SUM(I25:M25) -> 13050 | O25: 1 | P25: Ajeer | Q25: Virement | R25: 250
A26: 22 | B26: BASBOUS | C26: Carla | D26: Enseignant de langue étrangère second degré | E26: Collège / Lycée | F26: Existing | G26: 36770 | H26: 26.3 | I26: 9500 | J26: 2500 | K26: 500 | L26: 0 | M26: 400 | N26: =SUM(I26:M26) -> 12900 | O26: 1 | P26: Ajeer | Q26: Liquide | R26: -3250 (nouveau contrat retraite)
A27: 23 | B27: BAYDOUN | C27: Fayza | D27: Assistante de direction | E27: Administration | F27: Existing | G27: 45902 | H27: 1.3 | I27: 7400 | J27: 2500 | K27: 500 | L27: 0 | M27: 0 | N27: =SUM(I27:M27) -> 10400 | O27: 1 | P27: Ajeer | Q27: Virement | R27: Nouveau Contrat
A28: 24 | B28: BELLILA LAOUATI | C28: Ilham | D28: Enseignant second degré | E28: Collège / Lycée | F28: Existing | G28: 45170 | H28: 3.3 | I28: 9500 | J28: 2500 | K28: 500 | L28: 0 | M28: 880 | N28: =SUM(I28:M28) -> 13380 | O28: 1 | P28: Ajeer | Q28: Liquide | R28: 250
A29: 25 | B29: BEN ABDESSALEM | C29: Yousra | D29: Professeur(e) des écoles | E29: Élémentaire | F29: Existing | G29: 45536 | H29: 2.3 | I29: 9000 | J29: 2500 | K29: 500 | L29: 0 | M29: 0 | N29: =SUM(I29:M29) -> 12000 | O29: 1 | P29: Ajeer | Q29: Liquide | R29: 250
A30: 26 | B30: BEN AMAR | C30: Amira | D30: Professeur(e) des écoles | E30: Élémentaire | F30: Existing | G30: 45170 | H30: 3.3 | I30: 11000 | J30: 2500 | K30: 500 | L30: 0 | M30: 0 | N30: =SUM(I30:M30) -> 14000 | O30: 1 | P30: Ajeer | Q30: Virement | R30: 250
A31: 27 | B31: BEN FGUIRA | C31: Fares | D31: Professeur(e) d'EPS | E31: Collège / Lycée | F31: Existing | G31: 44805 | H31: 4.3 | I31: 8750 | J31: 2500 | K31: 500 | L31: 0 | M31: 500 | N31: =SUM(I31:M31) -> 12250 | O31: 1 | P31: Ajeer | Q31: Liquide | R31: 250
A32: 28 | B32: BEN HIBA | C32: Nesrine | D32: Enseignant second degré | E32: Collège / Lycée | F32: Existing | G32: 45901 | H32: 1.3 | I32: 7200 | J32: 2250 | K32: 450 | L32: 0 | M32: 0 | N32: =SUM(I32:M32) -> 9900 | O32: 0.9 | P32: Ajeer | Q32: Liquide | R32: Nouveau Contrat
A33: 29 | B33: BEN KIRAN | C33: Ambre | D33: Responsable APS | E33: Vie Scolaire & Support | F33: Existing | G33: 45908 | H33: 1.3 | I33: 13000 | J33: 2500 | K33: 500 | L33: 0 | M33: 0 | N33: =SUM(I33:M33) -> 16000 | O33: 1 | P33: Ajeer | Q33: Liquide | R33: Nouveau Contrat
A34: 30 | B34: BEN OTHMAN | C34: Noelle | D34: Enseignant second degré | E34: Collège / Lycée | F34: Existing | G34: 44075 | H34: 6.3 | I34: 9250 | J34: 2500 | K34: 500 | L34: 0 | M34: 0 | N34: =SUM(I34:M34) -> 12250 | O34: 1 | P34: Ajeer | Q34: Virement | R34: 250
A35: 31 | B35: BEN SMIDA ÉP BEN IDRIS | C35: Khadija | D35: Enseignant second degré | E35: Collège / Lycée | F35: Existing | G35: 44440 | H35: 5.3 | I35: 9000 | J35: 2500 | K35: 500 | L35: 0 | M35: 1080 | N35: =SUM(I35:M35) -> 13080 | O35: 1 | P35: Ajeer | Q35: Liquide | R35: 250
A36: 32 | B36: BENBERNOU | C36: Rabia | D36: Assistante maternelle | E36: Maternelle | F36: Existing | G36: 42979 | H36: 9.3 | I36: 7200 | J36: 2500 | K36: 500 | L36: 0 | M36: 0 | N36: =SUM(I36:M36) -> 10200 | O36: 1 | P36: Ajeer | Q36: Virement | R36: 200
A37: 33 | B37: BOUGATFA | C37: Rim | D37: Enseignant second degré | E37: Collège / Lycée | F37: Existing | G37: 45901 | H37: 1.3 | I37: 8250 | J37: 2500 | K37: 500 | L37: 0 | M37: 0 | N37: =SUM(I37:M37) -> 11250 | O37: 1 | P37: Ajeer | Q37: Virement | R37: Nouveau Contrat
A38: 34 | B38: BOUHJAR | C38: Fahmi | D38: Enseignant second degré | E38: Collège / Lycée | F38: Existing | G38: 43344 | H38: 8.3 | I38: 10000 | J38: 2500 | K38: 500 | L38: 0 | M38: 1300 | N38: =SUM(I38:M38) -> 14300 | O38: 1 | P38: Ajeer | Q38: Virement | R38: 250
A39: 35 | B39: BOULMANE | C39: Lala-Malika | D39: Coordinatrice inclusion | E39: Vie Scolaire & Support | F39: Existing | G39: 44805 | H39: 4.3 | I39: 11750 | J39: 2500 | K39: 500 | L39: 0 | M39: 0 | N39: =SUM(I39:M39) -> 14750 | O39: 1 | P39: Ajeer | Q39: Virement | R39: 250
A40: 36 | B40: BOURAOUI | C40: Nasri | D40: Assistant(e) d'éducation | E40: Vie Scolaire & Support | F40: Existing | G40: 45536 | H40: 2.3 | I40: 7600 | J40: 2500 | K40: 500 | L40: 0 | M40: 0 | N40: =SUM(I40:M40) -> 10600 | O40: 1 | P40: Ajeer | Q40: Virement | R40: 200
A41: 37 | B41: BOURSAULT | C41: Géraldine | D41: Enseignant second degré | E41: Collège / Lycée | F41: Existing | G41: 45536 | H41: 2.3 | I41: 10000 | J41: 2500 | K41: 500 | L41: 0 | M41: 900 | N41: =SUM(I41:M41) -> 13900 | O41: 1 | P41: Ajeer | Q41: Virement | R41: 250
...

Sheet FY2026 Monthly Budget
A1: EFIR - Staff Costs Budget FY2026 (V3 - New Positions Start Sep 2026)
A2: Includes: Local staff (existing + new from Sep) + Residents + Local contracts + Ajeer + GOSI (Saudi only) + EoS
A4: Cost Component | B4: Jan-26 | C4: Feb-26 | D4: Mar-26 | E4: Apr-26 | F4: May-26 | G4: Jun-26 | H4: Jul-26 | I4: Aug-26 | J4: Sep-26 | K4: Oct-26 | L4: Nov-26 | M4: Dec-26 | N4: FY2026 Total
A5: A. LOCAL STAFF SALARIES
A6: Base Salaries (Existing Staff) | B6: 1447910 | C6: 1447910 | D6: 1447910 | E6: 1447910 | F6: 1447910 | G6: 1447910 | H6: 1447910 | I6: 1447910 | J6: 1478810 | K6: 1478810 | L6: 1478810 | M6: 1478810 | N6: =SUM(B6:M6) -> 17498520
A7: Housing Allowance IL (Existing) | B7: 391300 | C7: 391300 | D7: 391300 | E7: 391300 | F7: 391300 | G7: 391300 | H7: 391300 | I7: 391300 | J7: 391300 | K7: 391300 | L7: 391300 | M7: 391300 | N7: =SUM(B7:M7) -> 4695600
A8: Transport Allowance IT (Existing) | B8: 78259 | C8: 78259 | D8: 78259 | E8: 78259 | F8: 78259 | G8: 78259 | H8: 78259 | I8: 78259 | J8: 78259 | K8: 78259 | L8: 78259 | M8: 78259 | N8: =SUM(B8:M8) -> 939108
A9: Responsibility Premium (Existing) | B9: 12500 | C9: 12500 | D9: 12500 | E9: 12500 | F9: 12500 | G9: 12500 | H9: 12500 | I9: 12500 | J9: 12500 | K9: 12500 | L9: 12500 | M9: 12500 | N9: =SUM(B9:M9) -> 150000
A10: HSA Overtime (Existing) | B10: 57424 | C10: 57424 | D10: 57424 | E10: 57424 | F10: 57424 | G10: 57424 | H10: 0 | I10: 0 | J10: 57424 | K10: 57424 | L10: 57424 | M10: 57424 | N10: =SUM(B10:M10) -> 574240
A11: Subtotal Existing Staff | B11: =SUM(B6:B10) -> 1987393 | C11: =SUM(C6:C10) -> 1987393 | D11: =SUM(D6:D10) -> 1987393 | E11: =SUM(E6:E10) -> 1987393 | F11: =SUM(F6:F10) -> 1987393 | G11: =SUM(G6:G10) -> 1987393 | H11: =SUM(H6:H10) -> 1929969 | I11: =SUM(I6:I10) -> 1929969 | ... M11: =SUM(M6:M10) -> 2018293 | N11: =SUM(B11:M11) -> 23857468
A12: New Positions (6 FTE - Starting Sep 2026) | B12: 0 | C12: 0 | D12: 0 | E12: 0 | F12: 0 | G12: 0 | H12: 0 | I12: 0 | J12: 57400 | K12: 57400 | L12: 57400 | M12: 57400 | N12: =SUM(B12:M12) -> 229600
A13: TOTAL LOCAL STAFF SALARIES (A) | B13: =B11+B12 -> 1987393 | C13: =C11+C12 -> 1987393 | D13: =D11+D12 -> 1987393 | E13: =E11+E12 -> 1987393 | F13: =F11+F12 -> 1987393 | G13: =G11+G12 -> 1987393 | H13: =H11+H12 -> 1929969 | I13: =I11+I12 -> 1929969 | ... M13: =M11+M12 -> 2075693 | N13: =SUM(B13:M13) -> 24087068
A15: B. ADDITIONAL STAFF COSTS
A16: Contrats Locaux Remplacements | B16: 22681 | C16: 22681 | D16: 22681 | E16: 22681 | F16: 22681 | G16: 22681 | H16: 22681 | I16: 22681 | J16: 22681 | K16: 22681 | L16: 22681 | M16: 22681 | N16: =SUM(B16:M16) -> 272172
A17: Contrats Locaux 1% Masse Salariale (Form. Continue) | B17: 25504 | C17: 25504 | D17: 25504 | E17: 25504 | F17: 25504 | G17: 25504 | H17: 25504 | I17: 25504 | J17: 25504 | K17: 25504 | L17: 25504 | M17: 25504 | N17: =SUM(B17:M17) -> 306048
A18: Résidents Salaires | B18: 613008 | C18: 613008 | D18: 613008 | E18: 613008 | F18: 613008 | G18: 613008 | H18: 613008 | I18: 613008 | J18: 613008 | K18: 613008 | L18: 613008 | M18: 613008 | N18: =SUM(B18:M18) -> 7356096
A19: Pension Contribution (35% share) | B19: 69750 | C19: 69750 | D19: 69750 | E19: 69750 | F19: 69750 | G19: 69750 | H19: 69750 | I19: 69750 | J19: 69750 | K19: 69750 | L19: 69750 | M19: 69750 | N19: =SUM(B19:M19) -> 837000
A20: Résidents Logement & Billets Avion | B20: 53950 | C20: 53950 | D20: 53950 | E20: 53950 | F20: 53950 | G20: 53950 | H20: 53950 | I20: 53950 | J20: 53950 | K20: 53950 | L20: 53950 | M20: 53950 | N20: =SUM(B20:M20) -> 647400
A21: TOTAL ADDITIONAL STAFF COSTS (B) | B21: =SUM(B16:B20) -> 784893 | C21: =SUM(C16:C20) -> 784893 | D21: =SUM(D16:D20) -> 784893 | E21: =SUM(E16:E20) -> 784893 | F21: =SUM(F16:F20) -> 784893 | G21: =SUM(G16:G20) -> 784893 | H21: =SUM(H16:H20) -> 784893 | I21: =SUM(I16:I20) -> 784893 | ... M21: =SUM(M16:M20) -> 784893 | N21: =SUM(B21:M21) -> 9418716
A23: C. EMPLOYER CHARGES & REGULATORY COSTS
A24: GOSI - Saudi Employees Only | B24: 2497 | C24: 2497 | D24: 2497 | E24: 2497 | F24: 2497 | G24: 2497 | H24: 2497 | I24: 2497 | J24: 2526 | K24: 2526 | L24: 2526 | M24: 2526 | N24: =SUM(B24:M24) -> 30080
A25: End of Service Provision | B25: 125579 | C25: 125579 | D25: 125579 | E25: 125579 | F25: 125579 | G25: 125579 | H25: 125579 | I25: 125579 | J25: 125579 | K25: 125579 | L25: 125579 | M25: 125579 | N25: =SUM(B25:M25) -> 1506948
A26: Ajeer Costs - Existing Workers (160) | B26: ='Assumptions & Inputs'!B21 -> 152266.67 | C26: ='Assumptions & Inputs'!B21 -> 152266.67 | D26: ='Assumptions & Inputs'!B21 -> 152266.67 | E26: ='Assumptions & Inputs'!B21 -> 152266.67 | F26: ='Assumptions & Inputs'!B21 -> 152266.67 | G26: ='Assumptions & Inputs'!B21 -> 152266.67 | H26: ='Assumptions & Inputs'!B21 -> 152266.67 | I26: ='Assumptions & Inputs'!B21 -> 152266.67 | J26: ='Assumptions & Inputs'!B21 -> 152266.67 | K26: ='Assumptions & Inputs'!B21 -> 152266.67 | L26: ='Assumptions & Inputs'!B21 -> 152266.67 | M26: ='Assumptions & Inputs'!B21 -> 152266.67 | N26: =SUM(B26:M26) -> 1827200
A27: Ajeer Costs - New Positions (6, Sep-Dec) | B27: 0 | C27: 0 | D27: 0 | E27: 0 | F27: 0 | G27: 0 | H27: 0 | I27: 0 | J27: ='Assumptions & Inputs'!B22 -> 5710 | K27: ='Assumptions & Inputs'!B22 -> 5710 | L27: ='Assumptions & Inputs'!B22 -> 5710 | M27: ='Assumptions & Inputs'!B22 -> 5710 | N27: =SUM(B27:M27) -> 22840
A28: TOTAL EMPLOYER CHARGES (C) | B28: =B24+B25+B26+B27 -> 280342.67 | C28: =C24+C25+C26+C27 -> 280342.67 | D28: =D24+D25+D26+D27 -> 280342.67 | E28: =E24+E25+E26+E27 -> 280342.67 | F28: =F24+F25+F26+F27 -> 280342.67 | G28: =G24+G25+G26+G27 -> 280342.67 | H28: =H24+H25+H26+H27 -> 280342.67 | I28: =I24+I25+I26+I27 -> 280342.67 | ... M28: =M24+M25+M26+M27 -> 286081.67 | N28: =SUM(B28:M28) -> 3387068
A30: GRAND TOTAL STAFF COSTS (A + B + C) | B30: =B13+B21+B28 -> 3052628.7 | C30: =C13+C21+C28 -> 3052628.7 | D30: =D13+D21+D28 -> 3052628.7 | E30: =E13+E21+E28 -> 3052628.7 | F30: =F13+F21+F28 -> 3052628.7 | G30: =G13+G21+G28 -> 3052628.7 | H30: =H13+H21+H28 -> 2995204.7 | I30: =I13+I21+I28 -> 2995204.7 | ... M30: =M13+M21+M28 -> 3146667.7 | N30: =SUM(B30:M30) -> 36892852
F41: =68*0.95*6% -> 3.876

Sheet End of Service
A1: EFIR - End of Service Benefit Provision (Saudi Labor Law) - V3
A2: First 5 yrs = 0.5 month/yr | After 5 yrs = 1 month/yr | Base = Salary + IL + IT + Premium | Purple = New Positions (Sep 2026 start)
A4: # | B4: Last Name | C4: First Name | D4: Function | E4: Joining Date | F4: YoS (Dec 2025) | G4: YoS (Dec 2026) | H4: EoS Base | I4: EoS Dec 2025 | J4: EoS Dec 2026 | K4: FY2026 Charge | L4: Monthly Accrual | N4: Gratuity Provision (Dec 2026)
A5: 1 | B5: ABED | C5: Ghina | D5: Assistant(e) d'éducation | E5: 45170 | F5: 2.3 | G5: 3.3 | H5: 10400 | I5: 12116 | J5: 17649 | K5: =J5-I5 -> 5533 | L5: =K5/12 -> 461.08333 | N5: =_xlfn.LET(_xlpm.yos,ROUND(YEARFRAC(E5,DATE(2026,12,31),0),2),IF(E5>DATE(2026,12,31),0,ROUND(IF(_xlpm.yos<=5,H5/2*_xlpm.yos,H5/2*5+H5*(_xlpm.yos-5)),0))) -> 17316
A6: 2 | B6: ABID | C6: Hamdi | D6: Assistant(e) d'éducation | E6: 42614 | F6: 9.3 | G6: 10.3 | H6: 12000 | I6: 81960 | J6: 97092 | K6: =J6-I6 -> 15132 | L6: =K6/12 -> 1261 | N6: =_xlfn.LET(_xlpm.yos,ROUND(YEARFRAC(E6,DATE(2026,12,31),0),2),IF(E6>DATE(2026,12,31),0,ROUND(IF(_xlpm.yos<=5,H6/2*_xlpm.yos,H6/2*5+H6*(_xlpm.yos-5)),0))) -> 93960
A7: 3 | B7: ABOU RJEILI | C7: Christina | D7: Assistant(e) d'éducation | E7: 45536 | F7: 1.3 | G7: 2.3 | H7: 10200 | I7: 6783 | J7: 12116 | K7: =J7-I7 -> 5333 | L7: =K7/12 -> 444.41667 | N7: =_xlfn.LET(_xlpm.yos,ROUND(YEARFRAC(E7,DATE(2026,12,31),0),2),IF(E7>DATE(2026,12,31),0,ROUND(IF(_xlpm.yos<=5,H7/2*_xlpm.yos,H7/2*5+H7*(_xlpm.yos-5)),0))) -> 11883
A8: 4 | B8: ABOUTALEB | C8: Hasnae | D8: Professeur(e) des écoles | E8: 44440 | F8: 4.3 | G8: 5.3 | H8: 12000 | I8: 25980 | J8: 34668 | K8: =J8-I8 -> 8688 | L8: =K8/12 -> 724 | N8: =_xlfn.LET(_xlpm.yos,ROUND(YEARFRAC(E8,DATE(2026,12,31),0),2),IF(E8>DATE(2026,12,31),0,ROUND(IF(_xlpm.yos<=5,H8/2*_xlpm.yos,H8/2*5+H8*(_xlpm.yos-5)),0))) -> 33960
A9: 5 | B9: ABSIL | C9: Marie-Savine | D9: Professeur(e) des écoles | E9: 45901 | F9: 0.3 | G9: 1.3 | H9: 13500 | I9: 2228 | J9: 8978 | K9: =J9-I9 -> 6750 | L9: =K9/12 -> 562.5 | N9: =_xlfn.LET(_xlpm.yos,ROUND(YEARFRAC(E9,DATE(2026,12,31),0),2),IF(E9>DATE(2026,12,31),0,ROUND(IF(_xlpm.yos<=5,H9/2*_xlpm.yos,H9/2*5+H9*(_xlpm.yos-5)),0))) -> 8978
A10: 6 | B10: ACHATOU | C10: Nadia | D10: Responsable RH | E10: 42614 | F10: 9.3 | G10: 10.3 | H10: 16250 | I10: 110988 | J10: 129195 | K10: =J10-I10 -> 18207 | L10: =K10/12 -> 1517.25 | N10: =_xlfn.LET(_xlpm.yos,ROUND(YEARFRAC(E10,DATE(2026,12,31),0),2),IF(E10>DATE(2026,12,31),0,ROUND(IF(_xlpm.yos<=5,H10/2*_xlpm.yos,H10/2*5+H10*(_xlpm.yos-5)),0))) -> 127238
A11: 7 | B11: ADJTOUTAH | C11: Anissa | D11: Professeur(e) des écoles | E11: 45901 | F11: 0.3 | G11: 1.3 | H11: 11250 | I11: 1856 | J11: 7481 | K11: =J11-I11 -> 5625 | L11: =K11/12 -> 468.75 | N11: =_xlfn.LET(_xlpm.yos,ROUND(YEARFRAC(E11,DATE(2026,12,31),0),2),IF(E11>DATE(2026,12,31),0,ROUND(IF(_xlpm.yos<=5,H11/2*_xlpm.yos,H11/2*5+H11*(_xlpm.yos-5)),0))) -> 7481
A12: 8 | B12: AHYOUD | C12: Hanan | D12: Professeur(e) des écoles | E12: 42614 | F12: 9.3 | G12: 10.3 | H12: 13250 | I12: 90498 | J12: 105705 | K12: =J12-I12 -> 15207 | L12: =K12/12 -> 1267.25 | N12: =_xlfn.LET(_xlpm.yos,ROUND(YEARFRAC(E12,DATE(2026,12,31),0),2),IF(E12>DATE(2026,12,31),0,ROUND(IF(_xlpm.yos<=5,H12/2*_xlpm.yos,H12/2*5+H12*(_xlpm.yos-5)),0))) -> 103748
A13: 9 | B13: AL JUNDI | C13: Tamara | D13: Enseignant de langue étrangère | E13: 35309 | F13: 29.3 | G13: 30.3 | H13: 12750 | I13: 342082 | J13: 361790 | K13: =J13-I13 -> 19708 | L13: =K13/12 -> 1642.3333 | N13: =_xlfn.LET(_xlpm.yos,ROUND(YEARFRAC(E13,DATE(2026,12,31),0),2),IF(E13>DATE(2026,12,31),0,ROUND(IF(_xlpm.yos<=5,H13/2*_xlpm.yos,H13/2*5+H13*(_xlpm.yos-5)),0))) -> 354833
A14: 10 | B14: AL NAHED | C14: Saliha | D14: Professeur(e) des écoles | E14: 45536 | F14: 1.3 | G14: 2.3 | H14: 11750 | I14: 7814 | J14: 13980 | K14: =J14-I14 -> 6166 | L14: =K14/12 -> 513.83333 | N14: =_xlfn.LET(_xlpm.yos,ROUND(YEARFRAC(E14,DATE(2026,12,31),0),2),IF(E14>DATE(2026,12,31),0,ROUND(IF(_xlpm.yos<=5,H14/2*_xlpm.yos,H14/2*5+H14*(_xlpm.yos-5)),0))) -> 13689
A15: 11 | B15: AL OSSAIMI AL OTAIBI | C15: BADR | D15: Démarcheur | H15: 5000 | I15: 0 | J15: 0 | K15: =J15-I15 -> 0 | L15: =K15/12 -> 0 | N15: =_xlfn.LET(_xlpm.yos,ROUND(YEARFRAC(E15,DATE(2026,12,31),0),2),IF(E15>DATE(2026,12,31),0,ROUND(IF(_xlpm.yos<=5,H15/2*_xlpm.yos,H15/2*5+H15*(_xlpm.yos-5)),0))) -> 622500
A16: 12 | B16: AL SHAKHAA | C16: Nada | D16: Chargé(e) du programme noor | E16: 42283 | F16: 10.2 | G16: 11.2 | H16: 12500 | I16: 96750 | J16: 111435 | K16: =J16-I16 -> 14685 | L16: =K16/12 -> 1223.75 | N16: =_xlfn.LET(_xlpm.yos,ROUND(YEARFRAC(E16,DATE(2026,12,31),0),2),IF(E16>DATE(2026,12,31),0,ROUND(IF(_xlpm.yos<=5,H16/2*_xlpm.yos,H16/2*5+H16*(_xlpm.yos-5)),0))) -> 109250
A17: 13 | B17: ALAMRI | C17: Shalan | D17: Chargé(e) des relations publiques | E17: 44867 | F17: 3.2 | G17: 4.2 | H17: 16250 | I17: 25675 | J17: 34320 | K17: =J17-I17 -> 8645 | L17: =K17/12 -> 720.41667 | N17: =_xlfn.LET(_xlpm.yos,ROUND(YEARFRAC(E17,DATE(2026,12,31),0),2),IF(E17>DATE(2026,12,31),0,ROUND(IF(_xlpm.yos<=5,H17/2*_xlpm.yos,H17/2*5+H17*(_xlpm.yos-5)),0))) -> 33800
A18: 14 | B18: ALNACHAR | C18: Farah | D18: Assistant(e) d'éducation | E18: 45901 | F18: 0.3 | G18: 1.3 | H18: 10000 | I18: 1650 | J18: 6650 | K18: =J18-I18 -> 5000 | L18: =K18/12 -> 416.66667 | N18: =_xlfn.LET(_xlpm.yos,ROUND(YEARFRAC(E18,DATE(2026,12,31),0),2),IF(E18>DATE(2026,12,31),0,ROUND(IF(_xlpm.yos<=5,H18/2*_xlpm.yos,H18/2*5+H18*(_xlpm.yos-5)),0))) -> 6650
A19: 15 | B19: AMANAT | C19: Aisha | D19: Professeur(e) des écoles | E19: 45536 | F19: 1.3 | G19: 2.3 | H19: 11250 | I19: 7481 | J19: 13398 | K19: =J19-I19 -> 5917 | L19: =K19/12 -> 493.08333 | N19: =_xlfn.LET(_xlpm.yos,ROUND(YEARFRAC(E19,DATE(2026,12,31),0),2),IF(E19>DATE(2026,12,31),0,ROUND(IF(_xlpm.yos<=5,H19/2*_xlpm.yos,H19/2*5+H19*(_xlpm.yos-5)),0))) -> 13106
A20: 16 | B20: AMRI | C20: Kehena | D20: Enseignant second degré | E20: 40787 | F20: 14.3 | G20: 15.3 | H20: 15000 | I20: 177450 | J20: 195658 | K20: =J20-I20 -> 18208 | L20: =K20/12 -> 1517.3333 | N20: =_xlfn.LET(_xlpm.yos,ROUND(YEARFRAC(E20,DATE(2026,12,31),0),2),IF(E20>DATE(2026,12,31),0,ROUND(IF(_xlpm.yos<=5,H20/2*_xlpm.yos,H20/2*5+H20*(_xlpm.yos-5)),0))) -> 192450
A21: 17 | B21: ASSEKOUR | C21: Soufiane | D21: Enseignant second degré | E21: 45901 | F21: 0.3 | G21: 1.3 | H21: 11750 | I21: 1939 | J21: 7814 | K21: =J21-I21 -> 5875 | L21: =K21/12 -> 489.58333 | N21: =_xlfn.LET(_xlpm.yos,ROUND(YEARFRAC(E21,DATE(2026,12,31),0),2),IF(E21>DATE(2026,12,31),0,ROUND(IF(_xlpm.yos<=5,H21/2*_xlpm.yos,H21/2*5+H21*(_xlpm.yos-5)),0))) -> 7814
A22: 18 | B22: AYACHI | C22: Amen | D22: Professeur(e) des écoles | E22: 45536 | F22: 1.3 | G22: 2.3 | H22: 12000 | I22: 7980 | J22: 14271 | K22: =J22-I22 -> 6291 | L22: =K22/12 -> 524.25 | N22: =_xlfn.LET(_xlpm.yos,ROUND(YEARFRAC(E22,DATE(2026,12,31),0),2),IF(E22>DATE(2026,12,31),0,ROUND(IF(_xlpm.yos<=5,H22/2*_xlpm.yos,H22/2*5+H22*(_xlpm.yos-5)),0))) -> 13980
A23: 19 | B23: BACHOUR | C23: Reem | D23: Enseignant de langue étrangère | E23: 36404 | F23: 26.3 | G23: 27.3 | H23: 16250 | I23: 387238 | J23: 409695 | K23: =J23-I23 -> 22457 | L23: =K23/12 -> 1871.4167 | N23: =_xlfn.LET(_xlpm.yos,ROUND(YEARFRAC(E23,DATE(2026,12,31),0),2),IF(E23>DATE(2026,12,31),0,ROUND(IF(_xlpm.yos<=5,H23/2*_xlpm.yos,H23/2*5+H23*(_xlpm.yos-5)),0))) -> 403488
A24: 20 | B24: BADR | C24: Chantal | D24: Enseignant de langue étrangère | E24: 40787 | F24: 14.3 | G24: 15.3 | H24: 13250 | I24: 156748 | J24: 173205 | K24: =J24-I24 -> 16457 | L24: =K24/12 -> 1371.4167 | N24: =_xlfn.LET(_xlpm.yos,ROUND(YEARFRAC(E24,DATE(2026,12,31),0),2),IF(E24>DATE(2026,12,31),0,ROUND(IF(_xlpm.yos<=5,H24/2*_xlpm.yos,H24/2*5+H24*(_xlpm.yos-5)),0))) -> 169998
A25: 21 | B25: BALLAN | C25: Christiane | D25: Enseignant de langue étrangère second degré | E25: 44805 | F25: 3.3 | G25: 4.3 | H25: 11750 | I25: 19564 | J25: 25980 | K25: =J25-I25 -> 6416 | L25: =K25/12 -> 534.66667 | N25: =_xlfn.LET(_xlpm.yos,ROUND(YEARFRAC(E25,DATE(2026,12,31),0),2),IF(E25>DATE(2026,12,31),0,ROUND(IF(_xlpm.yos<=5,H25/2*_xlpm.yos,H25/2*5+H25*(_xlpm.yos-5)),0))) -> 25439
A26: 22 | B26: BASBOUS | C26: Carla | D26: Enseignant de langue étrangère second degré | E26: 36770 | F26: 25.3 | G26: 26.3 | H26: 12500 | I26: 285375 | J26: 297875 | K26: =J26-I26 -> 12500 | L26: =K26/12 -> 1041.6667 | N26: =_xlfn.LET(_xlpm.yos,ROUND(YEARFRAC(E26,DATE(2026,12,31),0),2),IF(E26>DATE(2026,12,31),0,ROUND(IF(_xlpm.yos<=5,H26/2*_xlpm.yos,H26/2*5+H26*(_xlpm.yos-5)),0))) -> 297875
A27: 23 | B27: BAYDOUN | C27: Fayza | D27: Assistante de direction | E27: 45902 | F27: 0.3 | G27: 1.3 | H27: 10400 | I27: 1716 | J27: 6916 | K27: =J27-I27 -> 5200 | L27: =K27/12 -> 433.33333 | N27: =_xlfn.LET(_xlpm.yos,ROUND(YEARFRAC(E27,DATE(2026,12,31),0),2),IF(E27>DATE(2026,12,31),0,ROUND(IF(_xlpm.yos<=5,H27/2*_xlpm.yos,H27/2*5+H27*(_xlpm.yos-5)),0))) -> 6916
... A172: 168 | B172: NEW POSITION | C172: - | D172: Administratif Inscription | E172: 46266 | F172: 0 | G172: 0.3 | H172: 10400 | I172: 0 | J172: 1716 | K172: =J172-I172 -> 1716 | L172: =K172/12 -> 143 | N172: =_xlfn.LET(_xlpm.yos,ROUND(YEARFRAC(E172,DATE(2026,12,31),0),2),IF(E172>DATE(2026,12,31),0,ROUND(IF(_xlpm.yos<=5,H172/2*_xlpm.yos,H172/2*5+H172*(_xlpm.yos-5)),0))) -> 1716
A173: TOTAL | H173: =SUM(H5:H172) -> 1987369 | I173: =SUM(I5:I172) -> 8149071 | J173: =SUM(J5:J172) -> 9656019 | K173: =SUM(K5:K172) -> 1506948 | L173: =SUM(L5:L172) -> 125579 | N173: =SUM(N5:N172) -> 10116848
N174: 7948000
N175: =H173 -> 1987369
N176: =N174+N175 -> 9935369
N177: =N173-N176 -> 181479

Sheet GOSI
A1: EFIR - GOSI Employer Contribution FY2026 (V3 - Saudi Only)
A2: Ajeer/Non-Saudi: GOSI = 0% | Saudi: 11.75% | Purple = New Positions (all Ajeer, Sep start)
A4: # | B4: Last Name | C4: First Name | D4: Function | E4: Saudi/Ajeer | F4: GOSI Base | G4: GOSI Rate | H4: Monthly GOSI | I4: GOSI (Jan-Aug) | J4: GOSI (Sep-Dec) | K4: FY2026 Total
A5: 1 | B5: ABED | C5: Ghina | D5: Assistant(e) d'éducation | E5: Ajeer | F5: 10400 | G5: 0 | H5: =F5*G5 -> 0 | I5: =H5*8 -> 0 | J5: 0 | K5: =I5+J5 -> 0
A6: 2 | B6: ABID | C6: Hamdi | D6: Assistant(e) d'éducation | E6: Ajeer | F6: 12000 | G6: 0 | H6: =F6*G6 -> 0 | I6: =H6*8 -> 0 | J6: 0 | K6: =I6+J6 -> 0
A7: 3 | B7: ABOU RJEILI | C7: Christina | D7: Assistant(e) d'éducation | E7: Ajeer | F7: 10200 | G7: 0 | H7: =F7*G7 -> 0 | I7: =H7*8 -> 0 | J7: 0 | K7: =I7+J7 -> 0
A8: 4 | B8: ABOUTALEB | C8: Hasnae | D8: Professeur(e) des écoles | E8: Ajeer | F8: 12000 | G8: 0 | H8: =F8*G8 -> 0 | I8: =H8*8 -> 0 | J8: 0 | K8: =I8+J8 -> 0
A9: 5 | B9: ABSIL | C9: Marie-Savine | D9: Professeur(e) des écoles | E9: Ajeer | F9: 13500 | G9: 0 | H9: =F9*G9 -> 0 | I9: =H9*8 -> 0 | J9: 0 | K9: =I9+J9 -> 0
A10: 6 | B10: ACHATOU | C10: Nadia | D10: Responsable RH | E10: Ajeer | F10: 16250 | G10: 0 | H10: =F10*G10 -> 0 | I10: =H10*8 -> 0 | J10: 0 | K10: =I10+J10 -> 0
A11: 7 | B11: ADJTOUTAH | C11: Anissa | D11: Professeur(e) des écoles | E11: Ajeer | F11: 11250 | G11: 0 | H11: =F11*G11 -> 0 | I11: =H11*8 -> 0 | J11: 0 | K11: =I11+J11 -> 0
A12: 8 | B12: AHYOUD | C12: Hanan | D12: Professeur(e) des écoles | E12: Ajeer | F12: 13250 | G12: 0 | H12: =F12*G12 -> 0 | I12: =H12*8 -> 0 | J12: 0 | K12: =I12+J12 -> 0
A13: 9 | B13: AL JUNDI | C13: Tamara | D13: Enseignant de langue étrangère | E13: Ajeer | F13: 12750 | G13: 0 | H13: =F13*G13 -> 0 | I13: =H13*8 -> 0 | J13: 0 | K13: =I13+J13 -> 0
A14: 10 | B14: AL NAHED | C14: Saliha | D14: Professeur(e) des écoles | E14: Ajeer | F14: 11750 | G14: 0 | H14: =F14*G14 -> 0 | I14: =H14*8 -> 0 | J14: 0 | K14: =I14+J14 -> 0
A15: 11 | B15: AL OSSAIMI AL OTAIBI | C15: BADR | D15: Démarcheur | E15: Saudi | F15: 5000 | G15: 0.1175 | H15: =F15*G15 -> 587.5 | I15: =H15*8 -> 4700 | J15: 2350 | K15: =I15+J15 -> 7050
A16: 12 | B16: AL SHAKHAA | C16: Nada | D16: Chargé(e) du programme noor | E16: Ajeer | F16: 12500 | G16: 0 | H16: =F16*G16 -> 0 | I16: =H16*8 -> 0 | J16: 0 | K16: =I16+J16 -> 0
... A172: 168 | B172: NEW POSITION | C172: - | D172: Administratif Inscription | E172: Ajeer | F172: 10400 | G172: 0 | H172: =F172*G172 -> 0 | I172: =H172*8 -> 0 | J172: 0 | K172: =I172+J172 -> 0
A173: TOTAL | F173: =SUM(F5:F172) -> 1987369 | H173: =SUM(H5:H172) -> 2496.875 | I173: =SUM(I5:I172) -> 19975 | J173: =SUM(J5:J172) -> 10105 | K173: =SUM(K5:K172) -> 30080

Sheet Ajeer Costs
A1: EFIR - Ajeer Registration Costs FY2026 (V3 - 166 Workers)
A2: Community school - no sponsorship. Existing: 12 months | New positions: Sep-Dec (4 months). Rates linked to Assumptions sheet.
A4: Ajeer Levy (per worker/year) | C4: ='Assumptions & Inputs'!B13 -> 9500
A5: Platform Fee (per worker/month) | C5: ='Assumptions & Inputs'!B14 -> 160
A6: Total Annual Cost per Worker (Full Year) | C6: ='Assumptions & Inputs'!B17 -> 11420
A8: # | B8: Last Name | C8: First Name | D8: Function | E8: Saudi/Ajeer | F8: Months | G8: Annual Levy | H8: Annual Platform | I8: Total FY2026
A9: 1 | B9: ABED | C9: Ghina | D9: Assistant(e) d'éducation | E9: Ajeer | F9: 12 | G9: ='Assumptions & Inputs'!B13*(F9/12) -> 9500 | H9: ='Assumptions & Inputs'!B14*F9 -> 1920 | I9: =G9+H9 -> 11420
A10: 2 | B10: ABID | C10: Hamdi | D10: Assistant(e) d'éducation | E10: Ajeer | F10: 12 | G10: ='Assumptions & Inputs'!B13*(F10/12) -> 9500 | H10: ='Assumptions & Inputs'!B14*F10 -> 1920 | I10: =G10+H10 -> 11420
A11: 3 | B11: ABOU RJEILI | C11: Christina | D11: Assistant(e) d'éducation | E11: Ajeer | F11: 12 | G11: ='Assumptions & Inputs'!B13*(F11/12) -> 9500 | H11: ='Assumptions & Inputs'!B14*F11 -> 1920 | I11: =G11+H11 -> 11420
A12: 4 | B12: ABOUTALEB | C12: Hasnae | D12: Professeur(e) des écoles | E12: Ajeer | F12: 12 | G12: ='Assumptions & Inputs'!B13*(F12/12) -> 9500 | H12: ='Assumptions & Inputs'!B14*F12 -> 1920 | I12: =G12+H12 -> 11420
A13: 5 | B13: ABSIL | C13: Marie-Savine | D13: Professeur(e) des écoles | E13: Ajeer | F13: 12 | G13: ='Assumptions & Inputs'!B13*(F13/12) -> 9500 | H13: ='Assumptions & Inputs'!B14*F13 -> 1920 | I13: =G13+H13 -> 11420
A14: 6 | B14: ACHATOU | C14: Nadia | D14: Responsable RH | E14: Ajeer | F14: 12 | G14: ='Assumptions & Inputs'!B13*(F14/12) -> 9500 | H14: ='Assumptions & Inputs'!B14*F14 -> 1920 | I14: =G14+H14 -> 11420
A15: 7 | B15: ADJTOUTAH | C15: Anissa | D15: Professeur(e) des écoles | E15: Ajeer | F15: 12 | G15: ='Assumptions & Inputs'!B13*(F15/12) -> 9500 | H15: ='Assumptions & Inputs'!B14*F15 -> 1920 | I15: =G15+H15 -> 11420
A16: 8 | B16: AHYOUD | C16: Hanan | D16: Professeur(e) des écoles | E16: Ajeer | F16: 12 | G16: ='Assumptions & Inputs'!B13*(F16/12) -> 9500 | H16: ='Assumptions & Inputs'!B14*F16 -> 1920 | I16: =G16+H16 -> 11420
A17: 9 | B17: AL JUNDI | C17: Tamara | D17: Enseignant de langue étrangère | E17: Ajeer | F17: 12 | G17: ='Assumptions & Inputs'!B13*(F17/12) -> 9500 | H17: ='Assumptions & Inputs'!B14*F17 -> 1920 | I17: =G17+H17 -> 11420
A18: 10 | B18: AL NAHED | C18: Saliha | D18: Professeur(e) des écoles | E18: Ajeer | F18: 12 | G18: ='Assumptions & Inputs'!B13*(F18/12) -> 9500 | H18: ='Assumptions & Inputs'!B14*F18 -> 1920 | I18: =G18+H18 -> 11420
A19: 11 | B19: AL OSSAIMI AL OTAIBI | C19: BADR | D19: Démarcheur | E19: Saudi | F19: 0 | G19: 0 | H19: 0 | I19: 0
A20: 12 | B20: AL SHAKHAA | C20: Nada | D20: Chargé(e) du programme noor | E20: Ajeer | F20: 12 | G20: ='Assumptions & Inputs'!B13*(F20/12) -> 9500 | H20: ='Assumptions & Inputs'!B14*F20 -> 1920 | I20: =G20+H20 -> 11420
A21: 13 | B21: ALAMRI | C21: Shalan | D21: Chargé(e) des relations publiques | E21: Saudi | F21: 0 | G21: 0 | H21: 0 | I21: 0
A22: 14 | B22: ALNACHAR | C22: Farah | D22: Assistant(e) d'éducation | E22: Ajeer | F22: 12 | G22: ='Assumptions & Inputs'!B13*(F22/12) -> 9500 | H22: ='Assumptions & Inputs'!B14*F22 -> 1920 | I22: =G22+H22 -> 11420
A23: 15 | B23: AMANAT | C23: Aisha | D23: Professeur(e) des écoles | E23: Ajeer | F23: 12 | G23: ='Assumptions & Inputs'!B13*(F23/12) -> 9500 | H23: ='Assumptions & Inputs'!B14*F23 -> 1920 | I23: =G23+H23 -> 11420
A24: 16 | B24: AMRI | C24: Kehena | D24: Enseignant second degré | E24: Ajeer | F24: 12 | G24: ='Assumptions & Inputs'!B13*(F24/12) -> 9500 | H24: ='Assumptions & Inputs'!B14*F24 -> 1920 | I24: =G24+H24 -> 11420
A25: 17 | B25: ASSEKOUR | C25: Soufiane | D25: Enseignant second degré | E25: Ajeer | F25: 12 | G25: ='Assumptions & Inputs'!B13*(F25/12) -> 9500 | H25: ='Assumptions & Inputs'!B14*F25 -> 1920 | I25: =G25+H25 -> 11420
A26: 18 | B26: AYACHI | C26: Amen | D26: Professeur(e) des écoles | E26: Ajeer | F26: 12 | G26: ='Assumptions & Inputs'!B13*(F26/12) -> 9500 | H26: ='Assumptions & Inputs'!B14*F26 -> 1920 | I26: =G26+H26 -> 11420
A27: 19 | B27: BACHOUR | C27: Reem | D27: Enseignant de langue étrangère | E27: Ajeer | F27: 12 | G27: ='Assumptions & Inputs'!B13*(F27/12) -> 9500 | H27: ='Assumptions & Inputs'!B14*F27 -> 1920 | I27: =G27+H27 -> 11420
A28: 20 | B28: BADR | C28: Chantal | D28: Enseignant de langue étrangère | E28: Ajeer | F28: 12 | G28: ='Assumptions & Inputs'!B13*(F28/12) -> 9500 | H28: ='Assumptions & Inputs'!B14*F28 -> 1920 | I28: =G28+H28 -> 11420
A29: 21 | B29: BALLAN | C29: Christiane | D29: Enseignant de langue étrangère second degré | E29: Ajeer | F29: 12 | G29: ='Assumptions & Inputs'!B13*(F29/12) -> 9500 | H29: ='Assumptions & Inputs'!B14*F29 -> 1920 | I29: =G29+H29 -> 11420
A30: 22 | B30: BASBOUS | C30: Carla | D30: Enseignant de langue étrangère second degré | E30: Ajeer | F30: 12 | G30: ='Assumptions & Inputs'!B13*(F30/12) -> 9500 | H30: ='Assumptions & Inputs'!B14*F30 -> 1920 | I30: =G30+H30 -> 11420
A31: 23 | B31: BAYDOUN | C31: Fayza | D31: Assistante de direction | E31: Ajeer | F31: 12 | G31: ='Assumptions & Inputs'!B13*(F31/12) -> 9500 | H31: ='Assumptions & Inputs'!B14*F31 -> 1920 | I31: =G31+H31 -> 11420
A32: 24 | B32: BELLILA LAOUATI | C32: Ilham | D32: Enseignant second degré | E32: Ajeer | F32: 12 | G32: ='Assumptions & Inputs'!B13*(F32/12) -> 9500 | H32: ='Assumptions & Inputs'!B14*F32 -> 1920 | I32: =G32+H32 -> 11420
A33: 25 | B33: BEN ABDESSALEM | C33: Yousra | D33: Professeur(e) des écoles | E33: Ajeer | F33: 12 | G33: ='Assumptions & Inputs'!B13*(F33/12) -> 9500 | H33: ='Assumptions & Inputs'!B14*F33 -> 1920 | I33: =G33+H33 -> 11420
A34: 26 | B34: BEN AMAR | C34: Amira | D34: Professeur(e) des écoles | E34: Ajeer | F34: 12 | G34: ='Assumptions & Inputs'!B13*(F34/12) -> 9500 | H34: ='Assumptions & Inputs'!B14*F34 -> 1920 | I34: =G34+H34 -> 11420
A35: 27 | B35: BEN FGUIRA | C35: Fares | D35: Professeur(e) d'EPS | E35: Ajeer | F35: 12 | G35: ='Assumptions & Inputs'!B13*(F35/12) -> 9500 | H35: ='Assumptions & Inputs'!B14*F35 -> 1920 | I35: =G35+H35 -> 11420
A36: 28 | B36: BEN HIBA | C36: Nesrine | D36: Enseignant second degré | E36: Ajeer | F36: 12 | G36: ='Assumptions & Inputs'!B13*(F36/12) -> 9500 | H36: ='Assumptions & Inputs'!B14*F36 -> 1920 | I36: =G36+H36 -> 11420
A37: 29 | B37: BEN KIRAN | C37: Ambre | D37: Responsable APS | E37: Ajeer | F37: 12 | G37: ='Assumptions & Inputs'!B13*(F37/12) -> 9500 | H37: ='Assumptions & Inputs'!B14*F37 -> 1920 | I37: =G37+H37 -> 11420
A38: 30 | B38: BEN OTHMAN | C38: Noelle | D38: Enseignant second degré | E38: Ajeer | F38: 12 | G38: ='Assumptions & Inputs'!B13*(F38/12) -> 9500 | H38: ='Assumptions & Inputs'!B14*F38 -> 1920 | I38: =G38+H38 -> 11420
A39: 31 | B39: BEN SMIDA ÉP BEN IDRIS | C39: Khadija | D39: Enseignant second degré | E39: Ajeer | F39: 12 | G39: ='Assumptions & Inputs'!B13*(F39/12) -> 9500 | H39: ='Assumptions & Inputs'!B14*F39 -> 1920 | I39: =G39+H39 -> 11420
A40: 32 | B40: BENBERNOU | C40: Rabia | D40: Assistante maternelle | E40: Ajeer | F40: 12 | G40: ='Assumptions & Inputs'!B13*(F40/12) -> 9500 | H40: ='Assumptions & Inputs'!B14*F40 -> 1920 | I40: =G40+H40 -> 11420
A41: 33 | B41: BOUGATFA | C41: Rim | D41: Enseignant second degré | E41: Ajeer | F41: 12 | G41: ='Assumptions & Inputs'!B13*(F41/12) -> 9500 | H41: ='Assumptions & Inputs'!B14*F41 -> 1920 | I41: =G41+H41 -> 11420
A42: 34 | B42: BOUHJAR | C42: Fahmi | D42: Enseignant second degré | E42: Ajeer | F42: 12 | G42: ='Assumptions & Inputs'!B13*(F42/12) -> 9500 | H42: ='Assumptions & Inputs'!B14*F42 -> 1920 | I42: =G42+H42 -> 11420
...

Sheet YoY Comparison
A1: EFIR - Year-over-Year Salary Comparison (2024-2025 vs 2025-2026)
A3: # | B3: Last Name | C3: First Name | D3: Function | E3: Status | F3: Gross 24-25 | G3: Gross 25-26 | H3: Variance | I3: Var %
A4: 1 | B4: ABED | C4: Ghina | D4: Assistant(e) d'éducation | E4: Continuing | F4: 10200 | G4: 10400 | H4: =G4-F4 -> 200 | I4: =IF(F4=0,"N/A",H4/F4) -> 0.019607843
A5: 2 | B5: ABID | C5: Hamdi | D5: Assistant(e) d'éducation | E5: Continuing | F5: 11600 | G5: 12000 | H5: =G5-F5 -> 400 | I5: =IF(F5=0,"N/A",H5/F5) -> 0.034482759
A6: 3 | B6: ABOU RJEILI | C6: Christina | D6: Assistant(e) d'éducation | E6: Continuing | F6: 10000 | G6: 10200 | H6: =G6-F6 -> 200 | I6: =IF(F6=0,"N/A",H6/F6) -> 0.02
A7: 4 | B7: ABOUTALEB | C7: Hasnae | D7: Professeur(e) des écoles | E7: Continuing | F7: 11750 | G7: 12000 | H7: =G7-F7 -> 250 | I7: =IF(F7=0,"N/A",H7/F7) -> 0.021276596
A8: 5 | B8: ABSIL | C8: Marie-Savine | D8: Professeur(e) des écoles | E8: New Joiner | F8: 0 | G8: 13500 | H8: =G8-F8 -> 13500 | I8: =IF(F8=0,"N/A",H8/F8) -> N/A
A9: 6 | B9: ACHATOU | C9: Nadia | D9: Responsable RH | E9: Continuing | F9: 16000 | G9: 16250 | H9: =G9-F9 -> 250 | I9: =IF(F9=0,"N/A",H9/F9) -> 0.015625
A10: 7 | B10: ADJTOUTAH | C10: Anissa | D10: Professeur(e) des écoles | E10: New Joiner | F10: 0 | G10: 11250 | H10: =G10-F10 -> 11250 | I10: =IF(F10=0,"N/A",H10/F10) -> N/A
A11: 8 | B11: AHYOUD | C11: Hanan | D11: Professeur(e) des écoles | E11: Continuing | F11: 13000 | G11: 13250 | H11: =G11-F11 -> 250 | I11: =IF(F11=0,"N/A",H11/F11) -> 0.019230769
A12: 9 | B12: AL JUNDI | C12: Tamara | D12: Enseignant de langue étrangère | E12: Continuing | F12: 13640 | G12: 13890 | H12: =G12-F12 -> 250 | I12: =IF(F12=0,"N/A",H12/F12) -> 0.018328446
A13: 10 | B13: AL NAHED | C13: Saliha | D13: Professeur(e) des écoles | E13: Continuing | F13: 11500 | G13: 11750 | H13: =G13-F13 -> 250 | I13: =IF(F13=0,"N/A",H13/F13) -> 0.02173913
A14: 11 | B14: AL OSSAIMI AL OTAIBI | C14: BADR | D14: Démarcheur | E14: Continuing | F14: 5000 | G14: 5000 | H14: =G14-F14 -> 0 | I14: =IF(F14=0,"N/A",H14/F14) -> 0
A15: 12 | B15: AL SHAKHAA | C15: Nada | D15: Chargé(e) du programme noor | E15: Continuing | F15: 12250 | G15: 12500 | H15: =G15-F15 -> 250 | I15: =IF(F15=0,"N/A",H15/F15) -> 0.020408163
... A18: 15 | B18: AMANAT | C18: Aisha | D18: Professeur(e) des écoles | E18: Continuing | F18: 11000 | G18: 11250 | H18: =G18-F18 -> 250 | I18: =IF(F18=0,"N/A",H18/F18) -> 0.022727273
A19: 16 | B19: AMGHAR | C19: Jihane | E19: Departed | F19: 14250 | G19: 0 | H19: =G19-F19 -> -14250 | I19: =IF(F19=0,"N/A",H19/F19) -> -1
A20: 17 | B20: AMRI | C20: Kehena | D20: Enseignant second degré | E20: Continuing | F20: 15650 | G20: 15900 | H20: =G20-F20 -> 250 | I20: =IF(F20=0,"N/A",H20/F20) -> 0.015974441
A21: 18 | B21: ASSEKOUR | C21: Soufiane | D21: Enseignant second degré | E21: New Joiner | F21: 0 | G21: 12450 | H21: =G21-F21 -> 12450 | I21: =IF(F21=0,"N/A",H21/F21) -> N/A
A22: 19 | B22: AYACHI | C22: Amen | D22: Professeur(e) des écoles | E22: Continuing | F22: 11750 | G22: 12000 | H22: =G22-F22 -> 250 | I22: =IF(F22=0,"N/A",H22/F22) -> 0.021276596
A23: 20 | B23: BACHOUR | C23: Reem | D23: Enseignant de langue étrangère | E23: Continuing | F23: 17140 | G23: 17390 | H23: =G23-F23 -> 250 | I23: =IF(F23=0,"N/A",H23/F23) -> 0.014585764
A24: 21 | B24: BADER | C24: Grace | E24: Departed | F24: 12000 | G24: 0 | H24: =G24-F24 -> -12000 | I24: =IF(F24=0,"N/A",H24/F24) -> -1
A25: 22 | B25: BADR | C25: Chantal | D25: Enseignant de langue étrangère | E25: Continuing | F25: 13035 | G25: 13320 | H25: =G25-F25 -> 285 | I25: =IF(F25=0,"N/A",H25/F25) -> 0.021864212
A26: 23 | B26: BALLAN | C26: Christiane | D26: Enseignant de langue étrangère second degré | E26: Continuing | F26: 12800 | G26: 13050 | H26: =G26-F26 -> 250 | I26: =IF(F26=0,"N/A",H26/F26) -> 0.01953125
A27: 24 | B27: BASBOUS | C27: Carla | D27: Enseignant de langue étrangère second degré | E27: Continuing | F27: 16150 | G27: 12900 | H27: =G27-F27 -> -3250 | I27: =IF(F27=0,"N/A",H27/F27) -> -0.20123839
A28: 25 | B28: BAYDOUN | C28: Fayza | D28: Assistante de direction | E28: New Joiner | F28: 0 | G28: 10400 | H28: =G28-F28 -> 10400 | I28: =IF(F28=0,"N/A",H28/F28) -> N/A
A29: 26 | B29: BELLILA LAOUATI | C29: Ilham | D29: Enseignant second degré | E29: Continuing | F29: 13910 | G29: 13380 | H29: =G29-F29 -> -530 | I29: =IF(F29=0,"N/A",H29/F29) -> -0.038102085
A30: 27 | B30: BEN ABDESSALEM | C30: Yousra | D30: Professeur(e) des écoles | E30: Continuing | F30: 11750 | G30: 12000 | H30: =G30-F30 -> 250 | I30: =IF(F30=0,"N/A",H30/F30) -> 0.021276596
A31: 28 | B31: BEN AMAR | C31: Amira | D31: Professeur(e) des écoles | E31: Continuing | F31: 13750 | G31: 14000 | H31: =G31-F31 -> 250 | I31: =IF(F31=0,"N/A",H31/F31) -> 0.018181818
A32: 29 | B32: BEN FGUIRA | C32: Fares | D32: Professeur(e) d'EPS | E32: Continuing | F32: 12800 | G32: 12250 | H32: =G32-F32 -> -550 | I32: =IF(F32=0,"N/A",H32/F32) -> -0.04296875
A33: 30 | B33: BEN HIBA | C33: Nesrine | D33: Enseignant second degré | E33: New Joiner | F33: 0 | G33: 9900 | H33: =G33-F33 -> 9900 | I33: =IF(F33=0,"N/A",H33/F33) -> N/A
A34: 31 | B34: BEN KIRAN | C34: Ambre | D34: Responsable APS | E34: New Joiner | F34: 0 | G34: 16000 | H34: =G34-F34 -> 16000 | I34: =IF(F34=0,"N/A",H34/F34) -> N/A
A35: 32 | B35: BEN OTHMAN | C35: Noelle | D35: Enseignant second degré | E35: Continuing | F35: 11333 | G35: 12250 | H35: =G35-F35 -> 917 | I35: =IF(F35=0,"N/A",H35/F35) -> 0.080914145
A36: 33 | B36: BEN SMIDA ÉP BEN IDRIS | C36: Khadija | D36: Enseignant second degré | E36: Continuing | F36: 12530 | G36: 13080 | H36: =G36-F36 -> 550 | I36: =IF(F36=0,"N/A",H36/F36) -> 0.043894653
... A43: 40 | B43: BOUSSAID | C43: Amira | D43: Professeur(e) des écoles | E43: Continuing | F43: 12250 | G43: 12500 | H43: =G43-F43 -> 250 | I43: =IF(F43=0,"N/A",H43/F43) -> 0.020408163
A44: 41 | B44: BOUSSOUGA | C44: Zineb | E44: Departed | F44: 12500 | G44: 0 | H44: =G44-F44 -> -12500 | I44: =IF(F44=0,"N/A",H44/F44) -> -1
A45: 42 | B45: BOUTARHA SAIDI | C45: Naaima | E45: Departed | F45: 11900 | G45: 0 | H45: =G45-F45 -> -11900 | I45: =IF(F45=0,"N/A",H45/F45) -> -1
A46: 43 | B46: BOUZID | C46: Rafahiya | D46: Assistante maternelle | E46: Continuing | F46: 9000 | G46: 9200 | H46: =G46-F46 -> 200 | I46: =IF(F46=0,"N/A",H46/F46) -> 0.022222222
A47: 44 | B47: BRAX | C47: Nathalie | D47: Assistante maternelle | E47: Continuing | F47: 11250 | G47: 11500 | H47: =G47-F47 -> 250 | I47: =IF(F47=0,"N/A",H47/F47) -> 0.022222222
A48: 45 | B48: BRUNET | C48: Clemence | D48: Professeur(e) des écoles | E48: Continuing | F48: 11750 | G48: 12000 | H48: =G48-F48 -> 250 | I48: =IF(F48=0,"N/A",H48/F48) -> 0.021276596
A49: 46 | B49: BUZIT | C49: Cécile | D49: Chargée des moyens généraux | E49: New Joiner | F49: 0 | G49: 10400 | H49: =G49-F49 -> 10400 | I49: =IF(F49=0,"N/A",H49/F49) -> N/A
...

Sheet Analysis & Summary
A1: EFIR - Staff Costs Analysis & Summary FY2026 (V3)
A3: FULL COST SUMMARY
A4: HEADCOUNT
A5: Total Employees (at year end) | B5: 168
A6: Existing Staff (Full Year) | B6: 162
A7: New Positions (Sep-Dec 2026) | B7: 6
A8: Saudi / Ajeer | B8: 2 / 166
A9: FTE (year-end) | B9: 162
A11: ANNUAL COST BREAKDOWN | B11: Amount (SAR)
A12: A. Local Staff Salaries (Existing) | B12: 23857468 | C12: 0.66168089
A13: A. Local Staff Salaries (New - 4 months) | B13: 229600 | C13: 0.0063678984
A14: B. Contrats Locaux Remplacements | B14: 272167 | C14: 0.0075484834
A15: B. Contrats Locaux 1% Masse Salariale | B15: 306046 | C15: 0.008488109
A16: B. Résidents Salaires | B16: 7356097 | C16: 0.2040195
A17: B. Résidents Logement & Billets Avion | B17: 647400 | C17: 0.017955477
A18: C. GOSI (Saudi only) | B18: 30080 | C18: 0.00083426125
A19: C. End of Service Provision | B19: 1506954 | C19: 0.041794991
A20: C. Ajeer Costs | B20: 1850040 | C20: 0.051310395
A22: GRAND TOTAL STAFF COSTS FY2026 | B22: 36055852
A24: COST REPARTITION BY DEPARTMENT
A25: Department | B25: Headcount | C25: FTE | D25: Monthly Gross | E25: Annual Salary Cost | F25: Annual EoS Charge | G25: Annual Ajeer | H25: Total Dept Cost
A26: Administration | B26: 23 | C26: 23 | D26: 298050 | E26: 3159000 | F26: 174121 | G26: 201753 | H26: =SUM(E26:G26) -> 3534874
A27: Maternelle | B27: 13 | C27: 13 | D27: 128700 | E27: 1544400 | F27: 104766 | G27: 148460 | H27: =SUM(E27:G27) -> 1797626
A28: Élémentaire | B28: 42 | C28: 41.8 | D28: 542808 | E28: 6513696 | F28: 421991 | G28: 479640 | H28: =SUM(E28:G28) -> 7415327
A29: Collège / Lycée | B29: 63 | C29: 59.7 | D29: 797791 | E29: 9573492 | F29: 617385 | G29: 719460 | H29: =SUM(E29:G29) -> 10910337
A30: Vie Scolaire & Support | B30: 27 | C30: 24.5 | D30: 277444 | E30: 3287728 | F30: 188690 | G30: 300727 | H30: =SUM(E30:G30) -> 3777145
A31: TOTAL (Local Staff) | B31: =SUM(B26:B30) -> 168 | C31: =SUM(C26:C30) -> 162 | D31: =SUM(D26:D30) -> 2044793 | E31: =SUM(E26:E30) -> 24078316 | F31: =SUM(F26:F30) -> 1506953 | G31: =SUM(G26:G30) -> 1850040 | H31: =SUM(H26:H30) -> 27435309
A33: Department Share (% of Local Staff Total)
A34: Administration | B34: =H26/H31 -> 0.12884397
A35: Maternelle | B35: =H27/H31 -> 0.065522353
A36: Élémentaire | B36: =H28/H31 -> 0.27028407
A37: Collège / Lycée | B37: =H29/H31 -> 0.39767502
A38: Vie Scolaire & Support | B38: =H30/H31 -> 0.13767459
A40: COST STRUCTURE ANALYSIS
A41: Cost Category | B41: Amount (SAR) | C41: % of Grand Total | D41: Notes
A42: A. Local Staff Salaries | B42: 24087068 | C42: 0.66804879 | D42: Direct payroll costs (existing + 6 new from Sep)
A43: B. Additional Staff Costs | B43: 8581710 | C43: 0.23801157 | D43: Residents, replacements, training levy
A44: C. Employer Charges | B44: 3387074 | C44: 0.093939647 | D44: GOSI + EoS + Ajeer regulatory costs
A45: GRAND TOTAL | B45: 36055852 | C45: 1
A47: PER-EMPLOYEE COST RATIOS
...
