Workbook
Name ACAD_BONAPARTE: ASSUMPTIONS!#REF!
Name ACADEMIC_MONTHS: ASSUMPTIONS!$B$9
Name APS_MONTHLY: ASSUMPTIONS!$B$37
Name AY1_LABEL: ASSUMPTIONS!$B$5
Name AY1_MONTHS: ASSUMPTIONS!$B$7
Name AY2_LABEL: ASSUMPTIONS!$B$6
Name AY2_MONTHS: ASSUMPTIONS!$B$8
Name BAC_FEES: ASSUMPTIONS!$B$42
Name BAD_DEBT_RATE: ASSUMPTIONS!#REF!
Name BANK_CHARGES: ASSUMPTIONS!#REF!
Name BOURSES_AEFE: ASSUMPTIONS!$B$50
Name BOURSES_AESH: ASSUMPTIONS!$B$51
Name BOUTIQUE: ASSUMPTIONS!#REF!
Name CAMPS_VACANCES: ASSUMPTIONS!#REF!
Name CENTRE_LOISIRS: ASSUMPTIONS!#REF!
Name CLASS_PHOTOS: ASSUMPTIONS!$B$39
Name CURRENCY: ASSUMPTIONS!$B$10
Name DAI_FEE_AUT: FEE_GRID!$B$22
Name DAI_FEE_FR: FEE_GRID!$B$6
Name DAI_FEE_NAT: FEE_GRID!$B$14
Name DISCOUNT_REDUIT: ASSUMPTIONS!$B$15
Name DISCOUNT_REDUIT_3PLUS: ASSUMPTIONS!$B$16
Name DNB_FEES: ASSUMPTIONS!$B$43
Name DPI_FEE: ASSUMPTIONS!#REF!
Name EAF_FEES: ASSUMPTIONS!$B$44
Name EVAL_TESTS: ASSUMPTIONS!$B$34
Name FISCAL_YEAR: ASSUMPTIONS!$B$4
Name FX_GAINS: ASSUMPTIONS!#REF!
Name FX_LOSSES: ASSUMPTIONS!#REF!
Name GARDERIE_MONTHLY: ASSUMPTIONS!$B$38
Name INVEST_INCOME: ASSUMPTIONS!#REF!
Name KERMESSE: ASSUMPTIONS!#REF!
Name LATERAL_1ERE: ASSUMPTIONS!#REF!
Name LATERAL_2NDE: ASSUMPTIONS!#REF!
Name LATERAL_3EME: ASSUMPTIONS!#REF!
Name LATERAL_4EME: ASSUMPTIONS!#REF!
Name LATERAL_5EME: ASSUMPTIONS!#REF!
Name LATERAL_6EME: ASSUMPTIONS!#REF!
Name LATERAL_CE1: ASSUMPTIONS!#REF!
Name LATERAL_CE2: ASSUMPTIONS!#REF!
Name LATERAL_CM1: ASSUMPTIONS!#REF!
Name LATERAL_CM2: ASSUMPTIONS!#REF!
Name LATERAL_CP: ASSUMPTIONS!#REF!
Name LATERAL_GS: ASSUMPTIONS!#REF!
Name LATERAL_MS: ASSUMPTIONS!#REF!
Name LATERAL_PS: ASSUMPTIONS!#REF!
Name LATERAL_TERM: ASSUMPTIONS!#REF!
Name LATERAL_WEIGHT_RECENT: ASSUMPTIONS!$B$61
Name LOCATION_LOCAUX: ASSUMPTIONS!#REF!
Name MAX_CLASS_COLLEGE: ASSUMPTIONS!#REF!
Name MAX_CLASS_ELEMENTAIRE: ASSUMPTIONS!#REF!
Name MAX_CLASS_LYCEE: ASSUMPTIONS!#REF!
Name MAX_CLASS_MATERNELLE: ASSUMPTIONS!#REF!
Name MAX_CLASS_MATERNELLE_PS: ASSUMPTIONS!#REF!
Name MOYASAR_RATE: ASSUMPTIONS!#REF!
Name NEW_PS_INTAKE: ASSUMPTIONS!$B$60
Name NEW_STUDENTS: ASSUMPTIONS!$B$19
Name NEW_STUDENTS_AUT: ASSUMPTIONS!$B$23
Name NEW_STUDENTS_FR: ASSUMPTIONS!$B$21
Name NEW_STUDENTS_MATERNELLE: ASSUMPTIONS!$B$27

Sheet INPUT_MAP
B5: 🔢 TOTAL INPUTS | C5: 📄 SHEETS WITH INPUTS | D5: 🎯 CRITICAL INPUTS | F5: ⚡ LARGEST INPUT BLOCK
B6: 694 | C6: 10 of 12 | D6: 24 (ASSUMPTIONS) | F6: FEE_GRID (174)
B8: CATEGORY | C8: DESCRIPTION | D8: SHEET → RANGE | E8: # INPUTS | F8: PRIORITY | G8: NOTES / GUIDANCE
B9: 🔧 | C9: General Parameters (FY, AY, Months, Currency) | D9: ASSUMPTIONS → B4:B10 | E9: 7 | F9: 🔴 CRITICAL | G9: Fiscal year, academic year periods, currency. Change annually.
B10: 🔧 | C10: VAT & Tax Parameters | D10: ASSUMPTIONS → B13:B16 | E10: 4 | F10: 🔴 CRITICAL | G10: VAT rate 15%, nationality threshold, discount caps. Regulatory.
B11: 🔧 | C11: School Calendar (Working Days) | D11: ASSUMPTIONS → B19 | E11: 1 | F11: 🟡 HIGH | G11: 312 working days. Update if calendar changes.
B12: 🔧 | C12: Examination Fee Rates (BAC/DNB/EAF) | D12: ASSUMPTIONS → D42:D44 | E12: 3 | F12: 🟡 HIGH | G12: Exam fees per student. Set by zone/AEFE policy annually.
B13: 🔧 | C13: DPI Contribution Base | D13: ASSUMPTIONS → B37:B39 | E13: 3 | F13: 🟡 HIGH | G13: DPI annual amount, monthly supplement, and yearly total.
B14: 🔧 | C14: Activity Fee Base | D14: ASSUMPTIONS → B45 | E14: 1 | F14: 🟡 HIGH | G14: Annual activity fee per student (15,000 SAR).
B15: 🔧 | C15: Eval & Certification Amounts | D15: ASSUMPTIONS → B50:B51 | E15: 2 | F15: 🟡 HIGH | G15: Evaluation + certification revenue amounts.
B16: 🔧 | C16: Provision for Bad Debt | D16: ASSUMPTIONS → B54 | E16: 1 | F16: 🟡 HIGH | G16: Bad debt provision amount (51,230 SAR).
B17: 🔧 | C17: Registration Capacity & Rate | D17: ASSUMPTIONS → B60:B61 | E17: 2 | F17: 🟡 HIGH | G17: Max new students (64) and registration rate (80%).
B19: 💰 | C19: Tuition Fees — AY1 (Jan–Jun) Français | D19: FEE_GRID → B6:G10 | E19: 25 | F19: 🔴 CRITICAL | G19: Annual + trimester tuition by level. Review vs AY1 prior year.
B20: 💰 | C20: Tuition Fees — AY1 Nationaux KSA | D20: FEE_GRID → B14:G18 | E20: 25 | F20: 🔴 CRITICAL | G20: Nationaux tariff rates. Must align with school fee policy.
B21: 💰 | C21: Tuition Fees — AY1 Autres | D21: FEE_GRID → B22:G26 | E21: 25 | F21: 🔴 CRITICAL | G21: International/other tariff rates. Highest fee tier.
... B23: 💰 | C23: New Student Registration Fees | D23: FEE_GRID → B66:B105 | E23: 24 | F23: 🟡 HIGH | G23: Registration/inscription fees by level + nationality.
B24: 💰 | C24: VAT Exemptions (Zero-Rated) — REMOVED | D24: FEE_GRID → D73:D98 | E24: — | F24: ⛔ REMOVED | G24: Structural zeros (always 0 for Nationaux). Not a data entry point.
B26: 👥 | C26: AY1 Nationality Mix — Headcount by Grade | D26: ENROLLMENT → C7:M21 | E26: 135 | F26: 🔴 CRITICAL | G26: Core enrollment input: students by grade × nationality × tariff.
B27: 👥 | C27: AY2 Retention Rates by Grade | D27: ENROLLMENT → D35:D48 | E27: 14 | F27: 🔴 CRITICAL | G27: % of AY1 students continuing into AY2. Key revenue driver.
B28: 👥 | C28: New PS Intake & Base | D28: ENROLLMENT → C34, E34 | E28: 2 | F28: 🟡 HIGH | G28: Petite Section new enrollment count override.
B30: 📊 | C30: Nationality Proportions (All Grades) | D30: ENROLLMENT_DETAIL → C7:M21 | E30: 135 | F30: 🟡 HIGH | G30: % breakdown: Français/Nationaux/Autres × RP/R3+/Plein.
B32: 📈 | C32: Retention Rates (Headcount Layer) | D32: ENROLLMENT_HEADCOUNT → D33:D46 | E32: 14 | F32: 🔴 CRITICAL | G32: Grade-level retention expectations. Drives AY2 projection.
B33: 📈 | C33: Manual Override Column | D33: ENROLLMENT_HEADCOUNT → H32:H46 | E33: 15 | F33: 🟡 HIGH | G33: Override calculated headcount. Use for known adjustments.
B34: 📈 | C34: Prior Year Comparison Data — REMOVED | D34: ENROLLMENT_HEADCOUNT → K6:K20 | E34: — | F34: ⛔ REMOVED | G34: Reference/comparison values, not primary data entry. Formulas in F6:F20 also de-highlighted.
B36: 📁 | C36: 5-Year Historical Enrollment (FY21–FY25) | D36: HISTORICAL → C5:G19 | E36: 75 | F36: 🟢 LOW | G36: Static archive. Update only when new year is finalized.
B38: 🏫 | C38: Maximum Class Size by Grade | D38: CLASS_CAPACITY → D5:D19 | E38: 15 | F38: 🟡 HIGH | G38: Capacity constraints per grade. Triggers alerts if exceeded.
B40: 📋 | C40: Monthly Weight Distributions | D40: OTHER_REVENUES → D13:O41 | E40: 84 | F40: 🟡 HIGH | G40: Revenue timing across 12 months (Jan–Dec). Rows 13,15,29,35,37,39,41.
B42: 🎛️ | C42: Scenario Parameters (Base/Up/Down) | D42: SCENARIOS → B5:D9 | E42: 15 | F42: 🟡 HIGH | G42: Enrollment Δ, fee Δ, discount Δ, other rev Δ, cost Δ adjustments.
B45: 📖 LEGEND
B46: 🟡 | C46: Yellow cell = Hardcoded input (modifiable) | D46: Highlighted across all sheets. These are your data entry points.
B47: 🔴 | C47: CRITICAL priority = Revenue-impacting inputs | D47: Changes directly affect revenue calculations. Verify before saving.
B48: 🟡 | C48: HIGH priority = Important parameters | D48: Operational parameters that affect model behavior.
B49: 🟢 | C49: LOW priority = Reference/archive data | D49: Historical or static data. Rarely changed during budget cycle.
B50: 🔵 | C50: Blue font = Already blue-coded in model | D50: Original model convention for editable fields (retained).
B51: 📐 | C51: Gold left border = Input indicator bar | D51: Visual marker on every hardcoded cell for quick scanning.
B53: 🔄 DATA FLOW | C53: ASSUMPTIONS + FEE_GRID + DISCOUNTS → ENROLLMENT layers → REVENUE_ENGINE → SCENARIOS → EXECUTIVE_SUMMARY

Sheet ASSUMPTIONS
A1: EFIR Revenue Module - Assumptions & Parameters
A3: GENERAL PARAMETERS
A4: Fiscal Year | B4: 2026 | C4: Calendar year Jan-Dec
A5: Academic Year 1 (AY1) | B5: 2025-2026 | C5: Drives Jan-Jun 2026 revenue
A6: Academic Year 2 (AY2) | B6: 2026-2027 | C6: Drives Sep-Dec 2026 revenue
A7: AY1 Months in FY (Jan-Jun) | B7: 6 | C7: 6 months
A8: AY2 Months in FY (Sep-Dec) | B8: 4 | C8: 4 months
A9: Academic Months per Year | B9: 10 | C9: Sep-Jun (10 months)
A10: Currency | B10: SAR | C10: Saudi Arabian Riyal
A12: VAT & DISCOUNTS
A13: VAT Rate | B13: 0.15 | C13: 15% for French & Other nationalities
A14: VAT-Exempt Nationalities | B14: Nationaux | C14: Saudi nationals exempt from VAT
A15: Discount - Reduit Personnel | B15: 0.75 | C15: 75% of Plein (staff children)
A16: Discount - Reduit 3+ Enfants | B16: 0.75 | C16: 75% of Plein (3+ siblings)
A18: REGISTRATION FEES
A19: Estimated New Students (Total) | B19: {=ENROLLMENT_HEADCOUNT!I32+SUMPRODUCT((ENROLLMENT_HEADCOUNT!I33:I46-ENROLLMENT_HEADCOUNT!E33:E46)*(ENROLLMENT_HEADCOUNT!I33:I46>ENROLLMENT_HEADCOUNT!E33:E46))} -> 223 | C19: Total new enrollments (all nationalities)
A20: NEW STUDENT BREAKDOWN
A21: New Students - Francais | B21: =ROUND(B19*ENROLLMENT_DETAIL!$F$56/ENROLLMENT_DETAIL!$O$56,0) -> 76 | C21: Proportional to FR share of AY2 enrollment
A22: New Students - Nationaux | B22: =ROUND(B19*ENROLLMENT_DETAIL!$J$56/ENROLLMENT_DETAIL!$O$56,0) -> 5 | C22: Proportional to NAT share of AY2 enrollment
A23: New Students - Autres | B23: =B19-B21-B22 -> 142 | C23: Residual (Total minus FR minus NAT)
A24: Check: Total | B24: =B21+B22+B23 -> 223 | C24: Should match B23
A26: NEW STUDENT BY LEVEL (for Eval)
A27: New Students - Maternelle (PS+MS+GS) | B27: =ROUND(B19*(ENROLLMENT_DETAIL!$O$51+ENROLLMENT_DETAIL!$O$52)/ENROLLMENT_DETAIL!$O$56,0) -> 34 | C27: No eval test for Maternelle
A28: New Students - Primaire (CP-CM2) | B28: =ROUND(B19*ENROLLMENT_DETAIL!$O$53/ENROLLMENT_DETAIL!$O$56,0) -> 79 | C28: Eval Primaire rate applies
A29: New Students - College+Lycee (6E-TERM) | B29: =B19-B27-B28 -> 110 | C29: Eval College+Lycee rate applies
A31: FEES REFERENCED FROM FEE_GRID
A32: DPI HT - Francais | B32: =FEE_GRID!$C$89 -> 2000 | C32: From FEE_GRID AY2 (Sep-Dec period)
A33: DPI HT - Nationaux | B33: =FEE_GRID!$C$96 -> 2000 | C33: From FEE_GRID AY2 (Sep-Dec period)
A34: Evaluation Tests (Total) | B34: =B28*FEE_GRID!$C$90+B29*FEE_GRID!$C$91 -> 48800 | C34: Primaire × Eval rate + Secondaire × Eval rate (HT)
A36: ACTIVITIES & SERVICES
A37: APS Monthly | B37: 123000 | C37: After-school activities per month
A38: Garderie Monthly | B38: 3000 | C38: Daycare per month
A39: Class Photos (Annual) | B39: 52800 | C39: Split Nov-Dec
A41: EXAMINATION FEES | D41: Zone Rate / Student (SAR) | E41: AY1 Headcount
A42: BAC Fees (TERM × zone rate) | B42: =ROUND(D42*E42,0) -> 222000 | C42: Apr-May · Zone rate × AY1 TERM | D42: 2000 | E42: =ENROLLMENT_HEADCOUNT!F20 -> 111
A43: DNB Fees (3EME × zone rate) | B43: =ROUND(D43*E43,0) -> 61800 | C43: Apr-May · Zone rate × AY1 3EME | D43: 600 | E43: =ENROLLMENT_HEADCOUNT!F17 -> 103
A44: EAF Fees (1ERE × zone rate) | B44: =ROUND(D44*E44,0) -> 96000 | C44: Apr-May · Zone rate × AY1 1ERE | D44: 800 | E44: =ENROLLMENT_HEADCOUNT!F19 -> 120
A45: SIELE Fees (Annual) | B45: 15000 | C45: Split Oct-Nov
A49: SOCIAL AID (Negative Revenue)
A50: Bourses AEFE (Annual) | B50: 151906 | C50: Academic months /10
...

Sheet FEE_GRID
A1: EFIR - Master Fee Grid FY2026
A3: Fee Grid - AY2025-2026
A4: Francais
A5: Level | B5: DAI (TTC) | C5: Tuition TTC | D5: Tuition HT | E5: T1 TTC | F5: T2 TTC | G5: T3 TTC | H5: VAT Status
A6: Maternelle PS | B6: 5000 | C6: 30000 | D6: =C6/(1+VAT_RATE) -> 26086.957 | E6: 12000 | F6: 9000 | G6: 9000 | H6: 15% VAT
A7: Maternelle | B7: 5000 | C7: 34500 | D7: =C7/(1+VAT_RATE) -> 30000 | E7: 13800 | F7: 10350 | G7: 10350 | H7: 15% VAT
A8: Elementaire | B8: 5000 | C8: 34500 | D8: =C8/(1+VAT_RATE) -> 30000 | E8: 13800 | F8: 10350 | G8: 10350 | H8: 15% VAT
A9: College | B9: 5000 | C9: 34500 | D9: =C9/(1+VAT_RATE) -> 30000 | E9: 13800 | F9: 10350 | G9: 10350 | H9: 15% VAT
A10: Lycee | B10: 5000 | C10: 38500 | D10: =C10/(1+VAT_RATE) -> 33478.261 | E10: 15400 | F10: 11550 | G10: 11550 | H10: 15% VAT
A12: Nationaux (KSA)
A13: Level | B13: DAI (TTC) | C13: Tuition TTC | D13: Tuition HT | E13: T1 TTC | F13: T2 TTC | G13: T3 TTC | H13: VAT Status
A14: Maternelle PS | B14: 4350 | C14: 34783 | D14: =C14 -> 34783 | E14: 13913 | F14: 10435 | G14: 10435 | H14: Exempt
A15: Maternelle | B15: 4350 | C15: 35650 | D15: =C15 -> 35650 | E15: 14260 | F15: 10695 | G15: 10695 | H15: Exempt
A16: Elementaire | B16: 4350 | C16: 35650 | D16: =C16 -> 35650 | E16: 14260 | F16: 10695 | G16: 10695 | H16: Exempt
A17: College | B17: 4350 | C17: 35650 | D17: =C17 -> 35650 | E17: 14260 | F17: 10695 | G17: 10695 | H17: Exempt
A18: Lycee | B18: 4350 | C18: 40000 | D18: =C18 -> 40000 | E18: 16000 | F18: 12000 | G18: 12000 | H18: Exempt
A20: Autres Nationalites
A21: Level | B21: DAI (TTC) | C21: Tuition TTC | D21: Tuition HT | E21: T1 TTC | F21: T2 TTC | G21: T3 TTC | H21: VAT Status
A22: Maternelle PS | B22: 5000 | C22: 40000 | D22: =C22/(1+VAT_RATE) -> 34782.609 | E22: 16000 | F22: 12000 | G22: 12000 | H22: 15% VAT
A23: Maternelle | B23: 5000 | C23: 41000 | D23: =C23/(1+VAT_RATE) -> 35652.174 | E23: 16400 | F23: 12300 | G23: 12300 | H23: 15% VAT
A24: Elementaire | B24: 5000 | C24: 41000 | D24: =C24/(1+VAT_RATE) -> 35652.174 | E24: 16400 | F24: 12300 | G24: 12300 | H24: 15% VAT
A25: College | B25: 5000 | C25: 41000 | D25: =C25/(1+VAT_RATE) -> 35652.174 | E25: 16400 | F25: 12300 | G25: 12300 | H25: 15% VAT
A26: Lycee | B26: 5000 | C26: 46000 | D26: =C26/(1+VAT_RATE) -> 40000 | E26: 18400 | F26: 13800 | G26: 13800 | H26: 15% VAT
A29: Fee Grid - AY2026-2027
A30: Francais
A31: Level | B31: DAI (TTC) | C31: Tuition TTC | D31: Tuition HT | E31: T1 TTC | F31: T2 TTC | G31: T3 TTC | H31: VAT Status
A32: Maternelle PS | B32: 5000 | C32: 30000 | D32: =C32/(1+VAT_RATE) -> 26086.957 | E32: 12000 | F32: 9000 | G32: 9000 | H32: 15% VAT
A33: Maternelle | B33: 5000 | C33: 35500 | D33: =C33/(1+VAT_RATE) -> 30869.565 | E33: 14200 | F33: 10650 | G33: 10650 | H33: 15% VAT
A34: Elementaire | B34: 5000 | C34: 36000 | D34: =C34/(1+VAT_RATE) -> 31304.348 | E34: 14400 | F34: 10800 | G34: 10800 | H34: 15% VAT
A35: College | B35: 5000 | C35: 36500 | D35: =C35/(1+VAT_RATE) -> 31739.13 | E35: 14600 | F35: 10950 | G35: 10950 | H35: 15% VAT
A36: Lycee | B36: 5000 | C36: 40800 | D36: =C36/(1+VAT_RATE) -> 35478.261 | E36: 16320 | F36: 12240 | G36: 12240 | H36: 15% VAT
A38: Nationaux (KSA)
A39: Level | B39: DAI (TTC) | C39: Tuition TTC | D39: Tuition HT | E39: T1 TTC | F39: T2 TTC | G39: T3 TTC | H39: VAT Status
A40: Maternelle PS | B40: 4350 | C40: 34783 | D40: =C40 -> 34783 | E40: 13913 | F40: 10435 | G40: 10435 | H40: Exempt
A41: Maternelle | B41: 4350 | C41: 36650 | D41: =C41 -> 36650 | E41: 14660 | F41: 10995 | G41: 10995 | H41: Exempt
A42: Elementaire | B42: 4350 | C42: 36650 | D42: =C42 -> 36650 | E42: 14660 | F42: 10995 | G42: 10995 | H42: Exempt
A43: College | B43: 4350 | C43: 36650 | D43: =C43 -> 36650 | E43: 14660 | F43: 10995 | G43: 10995 | H43: Exempt
A44: Lycee | B44: 4350 | C44: 41000 | D44: =C44 -> 41000 | E44: 16400 | F44: 12300 | G44: 12300 | H44: Exempt
A46: Autres Nationalites
A47: Level | B47: DAI (TTC) | C47: Tuition TTC | D47: Tuition HT | E47: T1 TTC | F47: T2 TTC | G47: T3 TTC | H47: VAT Status
...

Sheet DISCOUNTS
A1: EFIR - Discount Analysis FY2026
A3: Section A - Discount Policy Parameters
A4: Reduit Personnel Rate | B4: =DISCOUNT_REDUIT -> 0.75 | C4: Staff children discount (% of Plein)
A5: Reduit 3+ Enfants Rate | B5: =DISCOUNT_REDUIT_3PLUS -> 0.75 | C5: 3+ siblings discount (% of Plein)
A7: Section B - Discount Rate Card (AY2025-2026)
A8: Francais
A9: Band | B9: Plein HT | C9: Reduit Pers HT | D9: Reduit 3+ HT | E9: Discount/Student RP | F9: Discount/Student R3+ | G9: VAT Status
A10: Maternelle PS | B10: =FEE_GRID!$D$6 -> 26086.957 | C10: =B10*DISCOUNT_REDUIT -> 19565.217 | D10: =B10*DISCOUNT_REDUIT_3PLUS -> 19565.217 | E10: =B10-C10 -> 6521.7391 | F10: =B10-D10 -> 6521.7391 | G10: 15% VAT
A11: Maternelle | B11: =FEE_GRID!$D$7 -> 30000 | C11: =B11*DISCOUNT_REDUIT -> 22500 | D11: =B11*DISCOUNT_REDUIT_3PLUS -> 22500 | E11: =B11-C11 -> 7500 | F11: =B11-D11 -> 7500 | G11: 15% VAT
A12: Elementaire | B12: =FEE_GRID!$D$8 -> 30000 | C12: =B12*DISCOUNT_REDUIT -> 22500 | D12: =B12*DISCOUNT_REDUIT_3PLUS -> 22500 | E12: =B12-C12 -> 7500 | F12: =B12-D12 -> 7500 | G12: 15% VAT
A13: College | B13: =FEE_GRID!$D$9 -> 30000 | C13: =B13*DISCOUNT_REDUIT -> 22500 | D13: =B13*DISCOUNT_REDUIT_3PLUS -> 22500 | E13: =B13-C13 -> 7500 | F13: =B13-D13 -> 7500 | G13: 15% VAT
A14: Lycee | B14: =FEE_GRID!$D$10 -> 33478.261 | C14: =B14*DISCOUNT_REDUIT -> 25108.696 | D14: =B14*DISCOUNT_REDUIT_3PLUS -> 25108.696 | E14: =B14-C14 -> 8369.5652 | F14: =B14-D14 -> 8369.5652 | G14: 15% VAT
A16: Nationaux (KSA)
A17: Band | B17: Plein HT | C17: Reduit Pers HT | D17: Reduit 3+ HT | E17: Discount/Student RP | F17: Discount/Student R3+ | G17: VAT Status
A18: Maternelle PS | B18: =FEE_GRID!$D$14 -> 34783 | C18: =B18*DISCOUNT_REDUIT -> 26087.25 | D18: =B18*DISCOUNT_REDUIT_3PLUS -> 26087.25 | E18: =B18-C18 -> 8695.75 | F18: =B18-D18 -> 8695.75 | G18: Exempt
A19: Maternelle | B19: =FEE_GRID!$D$15 -> 35650 | C19: =B19*DISCOUNT_REDUIT -> 26737.5 | D19: =B19*DISCOUNT_REDUIT_3PLUS -> 26737.5 | E19: =B19-C19 -> 8912.5 | F19: =B19-D19 -> 8912.5 | G19: Exempt
A20: Elementaire | B20: =FEE_GRID!$D$16 -> 35650 | C20: =B20*DISCOUNT_REDUIT -> 26737.5 | D20: =B20*DISCOUNT_REDUIT_3PLUS -> 26737.5 | E20: =B20-C20 -> 8912.5 | F20: =B20-D20 -> 8912.5 | G20: Exempt
A21: College | B21: =FEE_GRID!$D$17 -> 35650 | C21: =B21*DISCOUNT_REDUIT -> 26737.5 | D21: =B21*DISCOUNT_REDUIT_3PLUS -> 26737.5 | E21: =B21-C21 -> 8912.5 | F21: =B21-D21 -> 8912.5 | G21: Exempt
A22: Lycee | B22: =FEE_GRID!$D$18 -> 40000 | C22: =B22*DISCOUNT_REDUIT -> 30000 | D22: =B22*DISCOUNT_REDUIT_3PLUS -> 30000 | E22: =B22-C22 -> 10000 | F22: =B22-D22 -> 10000 | G22: Exempt
A24: Autres Nationalites
A25: Band | B25: Plein HT | C25: Reduit Pers HT | D25: Reduit 3+ HT | E25: Discount/Student RP | F25: Discount/Student R3+ | G25: VAT Status
A26: Maternelle PS | B26: =FEE_GRID!$D$22 -> 34782.609 | C26: =B26*DISCOUNT_REDUIT -> 26086.957 | D26: =B26*DISCOUNT_REDUIT_3PLUS -> 26086.957 | E26: =B26-C26 -> 8695.6522 | F26: =B26-D26 -> 8695.6522 | G26: 15% VAT
A27: Maternelle | B27: =FEE_GRID!$D$23 -> 35652.174 | C27: =B27*DISCOUNT_REDUIT -> 26739.13 | D27: =B27*DISCOUNT_REDUIT_3PLUS -> 26739.13 | E27: =B27-C27 -> 8913.0435 | F27: =B27-D27 -> 8913.0435 | G27: 15% VAT
A28: Elementaire | B28: =FEE_GRID!$D$24 -> 35652.174 | C28: =B28*DISCOUNT_REDUIT -> 26739.13 | D28: =B28*DISCOUNT_REDUIT_3PLUS -> 26739.13 | E28: =B28-C28 -> 8913.0435 | F28: =B28-D28 -> 8913.0435 | G28: 15% VAT
A29: College | B29: =FEE_GRID!$D$25 -> 35652.174 | C29: =B29*DISCOUNT_REDUIT -> 26739.13 | D29: =B29*DISCOUNT_REDUIT_3PLUS -> 26739.13 | E29: =B29-C29 -> 8913.0435 | F29: =B29-D29 -> 8913.0435 | G29: 15% VAT
A30: Lycee | B30: =FEE_GRID!$D$26 -> 40000 | C30: =B30*DISCOUNT_REDUIT -> 30000 | D30: =B30*DISCOUNT_REDUIT_3PLUS -> 30000 | E30: =B30-C30 -> 10000 | F30: =B30-D30 -> 10000 | G30: 15% VAT
A33: Section B - Discount Rate Card (AY2026-2027)
A34: Francais
A35: Band | B35: Plein HT | C35: Reduit Pers HT | D35: Reduit 3+ HT | E35: Discount/Student RP | F35: Discount/Student R3+ | G35: VAT Status
A36: Maternelle PS | B36: =FEE_GRID!$D$32 -> 26086.957 | C36: =B36*DISCOUNT_REDUIT -> 19565.217 | D36: =B36*DISCOUNT_REDUIT_3PLUS -> 19565.217 | E36: =B36-C36 -> 6521.7391 | F36: =B36-D36 -> 6521.7391 | G36: 15% VAT
A37: Maternelle | B37: =FEE_GRID!$D$33 -> 30869.565 | C37: =B37*DISCOUNT_REDUIT -> 23152.174 | D37: =B37*DISCOUNT_REDUIT_3PLUS -> 23152.174 | E37: =B37-C37 -> 7717.3913 | F37: =B37-D37 -> 7717.3913 | G37: 15% VAT
A38: Elementaire | B38: =FEE_GRID!$D$34 -> 31304.348 | C38: =B38*DISCOUNT_REDUIT -> 23478.261 | D38: =B38*DISCOUNT_REDUIT_3PLUS -> 23478.261 | E38: =B38-C38 -> 7826.087 | F38: =B38-D38 -> 7826.087 | G38: 15% VAT
A39: College | B39: =FEE_GRID!$D$35 -> 31739.13 | C39: =B39*DISCOUNT_REDUIT -> 23804.348 | D39: =B39*DISCOUNT_REDUIT_3PLUS -> 23804.348 | E39: =B39-C39 -> 7934.7826 | F39: =B39-D39 -> 7934.7826 | G39: 15% VAT
A40: Lycee | B40: =FEE_GRID!$D$36 -> 35478.261 | C40: =B40*DISCOUNT_REDUIT -> 26608.696 | D40: =B40*DISCOUNT_REDUIT_3PLUS -> 26608.696 | E40: =B40-C40 -> 8869.5652 | F40: =B40-D40 -> 8869.5652 | G40: 15% VAT
A42: Nationaux (KSA)
A43: Band | B43: Plein HT | C43: Reduit Pers HT | D43: Reduit 3+ HT | E43: Discount/Student RP | F43: Discount/Student R3+ | G43: VAT Status
A44: Maternelle PS | B44: =FEE_GRID!$D$40 -> 34783 | C44: =B44*DISCOUNT_REDUIT -> 26087.25 | D44: =B44*DISCOUNT_REDUIT_3PLUS -> 26087.25 | E44: =B44-C44 -> 8695.75 | F44: =B44-D44 -> 8695.75 | G44: Exempt
A45: Maternelle | B45: =FEE_GRID!$D$41 -> 36650 | C45: =B45*DISCOUNT_REDUIT -> 27487.5 | D45: =B45*DISCOUNT_REDUIT_3PLUS -> 27487.5 | E45: =B45-C45 -> 9162.5 | F45: =B45-D45 -> 9162.5 | G45: Exempt
A46: Elementaire | B46: =FEE_GRID!$D$42 -> 36650 | C46: =B46*DISCOUNT_REDUIT -> 27487.5 | D46: =B46*DISCOUNT_REDUIT_3PLUS -> 27487.5 | E46: =B46-C46 -> 9162.5 | F46: =B46-D46 -> 9162.5 | G46: Exempt
A47: College | B47: =FEE_GRID!$D$43 -> 36650 | C47: =B47*DISCOUNT_REDUIT -> 27487.5 | D47: =B47*DISCOUNT_REDUIT_3PLUS -> 27487.5 | E47: =B47-C47 -> 9162.5 | F47: =B47-D47 -> 9162.5 | G47: Exempt
...

Sheet HISTORICAL
A1: EFIR - Historical Enrollment Data (5 Years)
A3: Table A - Raw Enrollment by Grade
A4: Grade | B4: Full Name | C4: 2021-22 | D4: 2022-23 | E4: 2023-24 | F4: 2024-25 | G4: 2025-26
A5: PS | B5: Petite Section | C5: 60 | D5: 67 | E5: 68 | F5: 59 | G5: 65
A6: MS | B6: Moyenne Section | C6: 94 | D6: 85 | E6: 86 | F6: 109 | G6: 71
A7: GS | B7: Grande Section | C7: 97 | D7: 115 | E7: 95 | F7: 123 | G7: 124
A8: CP | B8: Cours Preparatoire | C8: 118 | D8: 103 | E8: 126 | F8: 116 | G8: 126
A9: CE1 | B9: Cours Elementaire 1 | C9: 119 | D9: 116 | E9: 108 | F9: 140 | G9: 118
A10: CE2 | B10: Cours Elementaire 2 | C10: 113 | D10: 120 | E10: 122 | F10: 126 | G10: 132
A11: CM1 | B11: Cours Moyen 1 | C11: 108 | D11: 123 | E11: 125 | F11: 124 | G11: 121
A12: CM2 | B12: Cours Moyen 2 | C12: 98 | D12: 112 | E12: 126 | F12: 145 | G12: 121
A13: 6EME | B13: Sixieme | C13: 115 | D13: 99 | E13: 112 | F13: 146 | G13: 151
A14: 5EME | B14: Cinquieme | C14: 90 | D14: 117 | E14: 102 | F14: 121 | G14: 139
A15: 4EME | B15: Quatrieme | C15: 98 | D15: 96 | E15: 126 | F15: 104 | G15: 120
A16: 3EME | B16: Troisieme | C16: 86 | D16: 101 | E16: 110 | F16: 128 | G16: 103
... A19: TERM | B19: Terminale | C19: 74 | D19: 78 | E19: 75 | F19: 109 | G19: 111
A21: BAND TOTALS
A22: Maternelle PS | C22: 60 | D22: 67 | E22: 68 | F22: 59 | G22: 65
A23: Maternelle | C23: 191 | D23: 200 | E23: 181 | F23: 232 | G23: 195
A24: Elementaire | C24: 556 | D24: 574 | E24: 607 | F24: 651 | G24: 618
A25: College | C25: 389 | D25: 413 | E25: 450 | F25: 499 | G25: 513
A26: Lycee | C26: 238 | D26: 245 | E26: 281 | F26: 353 | G26: 356
A27: TOTAL | C27: 1434 | D27: 1499 | E27: 1587 | F27: 1794 | G27: 1747
A29: Table B - Grade-to-Grade Retention Rates
A30: Transition | B30: 2022-23 | C30: 2023-24 | D30: 2024-25 | E30: 2025-26 | F30: Avg
A31: PS -> MS | B31: 1.4166667 | C31: 1.2835821 | D31: 1.6029412 | E31: 1.2033898 | F31: 1.3766449
A32: MS -> GS | B32: 1.2234043 | C32: 1.1176471 | D32: 1.4302326 | E32: 1.1376147 | F32: 1.2272246
A33: GS -> CP | B33: 1.0618557 | C33: 1.0956522 | D33: 1.2210526 | E33: 1.0243902 | F33: 1.1007377
A34: CP -> CE1 | B34: 0.98305085 | C34: 1.0485437 | D34: 1.1111111 | E34: 1.0172414 | F34: 1.0399868
A35: CE1 -> CE2 | B35: 1.0084034 | C35: 1.0517241 | D35: 1.1666667 | E35: 0.94285714 | F35: 1.0424128
A36: CE2 -> CM1 | B36: 1.0884956 | C36: 1.0416667 | D36: 1.0163934 | E36: 0.96031746 | F36: 1.0267183
A37: CM1 -> CM2 | B37: 1.037037 | C37: 1.0243902 | D37: 1.16 | E37: 0.97580645 | F37: 1.0493084
A38: CM2 -> 6EME | B38: 1.0102041 | C38: 1 | D38: 1.1587302 | E38: 1.0413793 | F38: 1.0525784
A39: 6EME -> 5EME | B39: 1.0173913 | C39: 1.030303 | D39: 1.0803571 | E39: 0.95205479 | F39: 1.0200266
A40: 5EME -> 4EME | B40: 1.0666667 | C40: 1.0769231 | D40: 1.0196078 | E40: 0.99173554 | F40: 1.0387333
A41: 4EME -> 3EME | B41: 1.0306122 | C41: 1.1458333 | D41: 1.015873 | E41: 0.99038462 | F41: 1.0456758
A42: 3EME -> 2NDE | B42: 1.0465116 | C42: 1.029703 | D42: 1.1818182 | E42: 0.9765625 | F42: 1.0586488
... A44: 1ERE -> TERM | B44: 0.89655172 | C44: 0.97402597 | D44: 1.0686275 | E44: 0.97368421 | F44: 0.97822234
A47: Table C - Enrollment Summary by Band
A48: Band | B48: 2021-22 | C48: 2022-23 | D48: 2023-24 | E48: 2024-25 | F48: 2025-26 | G48: CAGR
...

Sheet ENROLLMENT_HEADCOUNT
A1: EFIR - Enrollment Headcount FY2026
A2: Stage 1: Total headcount by grade. Yellow cells are editable. AY2 uses retention + smart lateral entry.
A4: Section A - AY1 Enrollment by Grade (2025-2026, Jan-Jun)
A5: Grade | B5: Band | C5: Historical 2023-24 | D5: Historical 2024-25 | E5: Historical 2025-26 | F5: AY1 Headcount | G5: Δ vs 2025-26
A6: PS | B6: Maternelle PS | C6: =HISTORICAL!E5 -> 68 | D6: =HISTORICAL!F5 -> 59 | E6: =HISTORICAL!G5 -> 65 | F6: =HISTORICAL!G5 -> 65 | G6: =F6-E6 -> 0
A7: MS | B7: Maternelle | C7: =HISTORICAL!E6 -> 86 | D7: =HISTORICAL!F6 -> 109 | E7: =HISTORICAL!G6 -> 71 | F7: =HISTORICAL!G6+6 -> 77 | G7: =F7-E7 -> 6
A8: GS | B8: Maternelle | C8: =HISTORICAL!E7 -> 95 | D8: =HISTORICAL!F7 -> 123 | E8: =HISTORICAL!G7 -> 124 | F8: =HISTORICAL!G7 -> 124 | G8: =F8-E8 -> 0
A9: CP | B9: Elementaire | C9: =HISTORICAL!E8 -> 126 | D9: =HISTORICAL!F8 -> 116 | E9: =HISTORICAL!G8 -> 126 | F9: =HISTORICAL!G8 -> 126 | G9: =F9-E9 -> 0
A10: CE1 | B10: Elementaire | C10: =HISTORICAL!E9 -> 108 | D10: =HISTORICAL!F9 -> 140 | E10: =HISTORICAL!G9 -> 118 | F10: =HISTORICAL!G9 -> 118 | G10: =F10-E10 -> 0
A11: CE2 | B11: Elementaire | C11: =HISTORICAL!E10 -> 122 | D11: =HISTORICAL!F10 -> 126 | E11: =HISTORICAL!G10 -> 132 | F11: =HISTORICAL!G10 -> 132 | G11: =F11-E11 -> 0
A12: CM1 | B12: Elementaire | C12: =HISTORICAL!E11 -> 125 | D12: =HISTORICAL!F11 -> 124 | E12: =HISTORICAL!G11 -> 121 | F12: =HISTORICAL!G11 -> 121 | G12: =F12-E12 -> 0
A13: CM2 | B13: Elementaire | C13: =HISTORICAL!E12 -> 126 | D13: =HISTORICAL!F12 -> 145 | E13: =HISTORICAL!G12 -> 121 | F13: =HISTORICAL!G12 -> 121 | G13: =F13-E13 -> 0
A14: 6EME | B14: College | C14: =HISTORICAL!E13 -> 112 | D14: =HISTORICAL!F13 -> 146 | E14: =HISTORICAL!G13 -> 151 | F14: =HISTORICAL!G13 -> 151 | G14: =F14-E14 -> 0
A15: 5EME | B15: College | C15: =HISTORICAL!E14 -> 102 | D15: =HISTORICAL!F14 -> 121 | E15: =HISTORICAL!G14 -> 139 | F15: =HISTORICAL!G14 -> 139 | G15: =F15-E15 -> 0
A16: 4EME | B16: College | C16: =HISTORICAL!E15 -> 126 | D16: =HISTORICAL!F15 -> 104 | E16: =HISTORICAL!G15 -> 120 | F16: =HISTORICAL!G15 -> 120 | G16: =F16-E16 -> 0
A17: 3EME | B17: College | C17: =HISTORICAL!E16 -> 110 | D17: =HISTORICAL!F16 -> 128 | E17: =HISTORICAL!G16 -> 103 | F17: =HISTORICAL!G16 -> 103 | G17: =F17-E17 -> 0
A18: 2NDE | B18: Lycee | C18: =HISTORICAL!E17 -> 104 | D18: =HISTORICAL!F17 -> 130 | E18: =HISTORICAL!G17 -> 125 | F18: =HISTORICAL!G17 -> 125 | G18: =F18-E18 -> 0
A19: 1ERE | B19: Lycee | C19: =HISTORICAL!E18 -> 102 | D19: =HISTORICAL!F18 -> 114 | E19: =HISTORICAL!G18 -> 120 | F19: =HISTORICAL!G18 -> 120 | G19: =F19-E19 -> 0
A20: TERM | B20: Lycee | C20: =HISTORICAL!E19 -> 75 | D20: =HISTORICAL!F19 -> 109 | E20: =HISTORICAL!G19 -> 111 | F20: =HISTORICAL!G19 -> 111 | G20: =F20-E20 -> 0
A22: BAND SUBTOTALS
A23: Maternelle PS | C23: =C6 -> 68 | D23: =D6 -> 59 | E23: =E6 -> 65 | F23: =F6 -> 65 | G23: =G6 -> 0
A24: Maternelle | C24: =SUM(C7:C8) -> 181 | D24: =SUM(D7:D8) -> 232 | E24: =SUM(E7:E8) -> 195 | F24: =SUM(F7:F8) -> 201 | G24: =SUM(G7:G8) -> 6
A25: Elementaire | C25: =SUM(C9:C13) -> 607 | D25: =SUM(D9:D13) -> 651 | E25: =SUM(E9:E13) -> 618 | F25: =SUM(F9:F13) -> 618 | G25: =SUM(G9:G13) -> 0
A26: College | C26: =SUM(C14:C17) -> 450 | D26: =SUM(D14:D17) -> 499 | E26: =SUM(E14:E17) -> 513 | F26: =SUM(F14:F17) -> 513 | G26: =SUM(G14:G17) -> 0
A27: Lycee | C27: =SUM(C18:C20) -> 281 | D27: =SUM(D18:D20) -> 353 | E27: =SUM(E18:E20) -> 356 | F27: =SUM(F18:F20) -> 356 | G27: =SUM(G18:G20) -> 0
A28: TOTAL AY1 | C28: =SUM(C23:C27) -> 1587 | D28: =SUM(D23:D27) -> 1794 | E28: =SUM(E23:E27) -> 1747 | F28: =SUM(F23:F27) -> 1753 | G28: =SUM(G23:G27) -> 6
A30: Section B - Retention & Lateral Entry (AY1 → AY2)
A31: Grade | B31: Feeder Grade | C31: AY1 Feeder Count | D31: Retention Rate | E31: Retained | F31: Wtd Hist Target | G31: Lateral Entry | H31: Override (±) | I31: AY2 Total
A32: PS | B32: New Intake | C32: 0 | D32: N/A | E32: N/A | F32: N/A | G32: N/A | H32: 1 | I32: =NEW_PS_INTAKE+H32 -> 65 | J32: =I32 -> 65
A33: MS | B33: PS | C33: =F6 -> 65 | D33: 0.97 | E33: =ROUND(C33*D33,0) -> 63 | F33: =ROUND(LATERAL_WEIGHT_RECENT*HISTORICAL!G6+(1-LATERAL_WEIGHT_RECENT)*HISTORICAL!F6,0) -> 79 | G33: =MAX(0,F33-E33) -> 16 | H33: -2 | I33: =E33+G33+H33 -> 77 | J33: =I33-E33 -> 14
A34: GS | B34: MS | C34: =F7 -> 77 | D34: 0.97 | E34: =ROUND(C34*D34,0) -> 75 | F34: =ROUND(LATERAL_WEIGHT_RECENT*HISTORICAL!G7+(1-LATERAL_WEIGHT_RECENT)*HISTORICAL!F7,0) -> 124 | G34: =MAX(0,F34-E34) -> 49 | H34: 0 | I34: =E34+G34+H34 -> 124 | J34: =I34-E34 -> 49
A35: CP | B35: GS | C35: =F8 -> 124 | D35: 0.97 | E35: =ROUND(C35*D35,0) -> 120 | F35: =ROUND(LATERAL_WEIGHT_RECENT*HISTORICAL!G8+(1-LATERAL_WEIGHT_RECENT)*HISTORICAL!F8,0) -> 124 | G35: =MAX(0,F35-E35) -> 4 | H35: 2 | I35: =E35+G35+H35 -> 126 | J35: =I35-E35 -> 6
A36: CE1 | B36: CP | C36: =F9 -> 126 | D36: 0.98 | E36: =ROUND(C36*D36,0) -> 123 | F36: =ROUND(LATERAL_WEIGHT_RECENT*HISTORICAL!G9+(1-LATERAL_WEIGHT_RECENT)*HISTORICAL!F9,0) -> 122 | G36: =MAX(0,F36-E36) -> 0 | H36: -5 | I36: =E36+G36+H36 -> 118
A37: CE2 | B37: CE1 | C37: =F10 -> 118 | D37: 0.94 | E37: =ROUND(C37*D37,0) -> 111 | F37: =ROUND(LATERAL_WEIGHT_RECENT*HISTORICAL!G10+(1-LATERAL_WEIGHT_RECENT)*HISTORICAL!F10,0) -> 131 | G37: =MAX(0,F37-E37) -> 20 | H37: 1 | I37: =E37+G37+H37 -> 132 | J37: =I37-E37 -> 21
A38: CM1 | B38: CE2 | C38: =F11 -> 132 | D38: 0.96 | E38: =ROUND(C38*D38,0) -> 127 | F38: =ROUND(LATERAL_WEIGHT_RECENT*HISTORICAL!G11+(1-LATERAL_WEIGHT_RECENT)*HISTORICAL!F11,0) -> 122 | G38: =MAX(0,F38-E38) -> 0 | H38: -6 | I38: =E38+G38+H38 -> 121
A39: CM2 | B39: CM1 | C39: =F12 -> 121 | D39: 0.98 | E39: =ROUND(C39*D39,0) -> 119 | F39: =ROUND(LATERAL_WEIGHT_RECENT*HISTORICAL!G12+(1-LATERAL_WEIGHT_RECENT)*HISTORICAL!F12,0) -> 126 | G39: =MAX(0,F39-E39) -> 7 | H39: -5 | I39: =E39+G39+H39 -> 121 | J39: =I39-E39 -> 2
A40: 6EME | B40: CM2 | C40: =F13 -> 121 | D40: 0.97 | E40: =ROUND(C40*D40,0) -> 117 | F40: =ROUND(LATERAL_WEIGHT_RECENT*HISTORICAL!G13+(1-LATERAL_WEIGHT_RECENT)*HISTORICAL!F13,0) -> 150 | G40: =MAX(0,F40-E40) -> 33 | H40: 1 | I40: =E40+G40+H40 -> 151 | J40: =I40-E40 -> 34
A41: 5EME | B41: 6EME | C41: =F14 -> 151 | D41: 0.95 | E41: =ROUND(C41*D41,0) -> 143 | F41: =ROUND(LATERAL_WEIGHT_RECENT*HISTORICAL!G14+(1-LATERAL_WEIGHT_RECENT)*HISTORICAL!F14,0) -> 135 | G41: =MAX(0,F41-E41) -> 0 | H41: -4 | I41: =E41+G41+H41 -> 139
A42: 4EME | B42: 5EME | C42: =F15 -> 139 | D42: 0.99 | E42: =ROUND(C42*D42,0) -> 138 | F42: =ROUND(LATERAL_WEIGHT_RECENT*HISTORICAL!G15+(1-LATERAL_WEIGHT_RECENT)*HISTORICAL!F15,0) -> 117 | G42: =MAX(0,F42-E42) -> 0 | H42: -18 | I42: =E42+G42+H42 -> 120
A43: 3EME | B43: 4EME | C43: =F16 -> 120 | D43: 0.99 | E43: =ROUND(C43*D43,0) -> 119 | F43: =ROUND(LATERAL_WEIGHT_RECENT*HISTORICAL!G16+(1-LATERAL_WEIGHT_RECENT)*HISTORICAL!F16,0) -> 108 | G43: =MAX(0,F43-E43) -> 0 | H43: -16 | I43: =E43+G43+H43 -> 103
...

Sheet ENROLLMENT_DETAIL
A1: EFIR - Enrollment Detail FY2026 (Nationality × Tariff)
A2: Stage 2: Nationality & tariff breakdown. Yellow cells are overridable proportions. Totals linked from ENROLLMENT_HEADCOUNT.
A4: Section A - AY1 Detail by Grade (2025-2026, Jan-Jun)
C5: Francais | G5: Nationaux | K5: Autres
A6: Grade | B6: Band | C6: RP | D6: R3+ | E6: Plein | F6: Total | G6: RP | H6: R3+ | I6: Plein | J6: Total | K6: RP | L6: R3+ | M6: Plein | N6: Total | O6: Grand Total | P6: Revenue HT
A7: PS | B7: Maternelle PS | C7: 1 | D7: 6 | E7: 17 | F7: =SUM(C7:E7) -> 24 | G7: 0 | H7: 1 | I7: 1 | J7: =SUM(G7:I7) -> 2 | K7: 0 | L7: 5 | M7: 34 | N7: =SUM(K7:M7) -> 39 | O7: =F7+J7+N7 -> 65 | P7: =C7*DISCOUNTS!$C$10+D7*DISCOUNTS!$D$10+E7*FEE_GRID!$D$6+G7*DISCOUNTS!$C$18+H7*DISCOUNTS!$D$18+I7*FEE_GRID!$D$14+K7*DISCOUNTS!$C$26+L7*DISCOUNTS!$D$26+M7*FEE_GRID!$D$22 -> 1954348.5
A8: MS | B8: Maternelle | C8: 1 | D8: 8 | E8: 18 | F8: =SUM(C8:E8) -> 27 | G8: 0 | H8: 1 | I8: 1 | J8: =SUM(G8:I8) -> 2 | K8: 1 | L8: 10 | M8: 37 | N8: =SUM(K8:M8) -> 48 | O8: =F8+J8+N8 -> 77 | P8: =C8*DISCOUNTS!$C$11+D8*DISCOUNTS!$D$11+E8*FEE_GRID!$D$7+G8*DISCOUNTS!$C$19+H8*DISCOUNTS!$D$19+I8*FEE_GRID!$D$15+K8*DISCOUNTS!$C$27+L8*DISCOUNTS!$D$27+M8*FEE_GRID!$D$23 -> 2418148.4
A9: GS | B9: Maternelle | C9: 2 | D9: 12 | E9: 29 | F9: =SUM(C9:E9) -> 43 | G9: 0 | H9: 2 | I9: 2 | J9: =SUM(G9:I9) -> 4 | K9: 2 | L9: 15 | M9: 60 | N9: =SUM(K9:M9) -> 77 | O9: =F9+J9+N9 -> 124 | P9: =C9*DISCOUNTS!$C$11+D9*DISCOUNTS!$D$11+E9*FEE_GRID!$D$7+G9*DISCOUNTS!$C$19+H9*DISCOUNTS!$D$19+I9*FEE_GRID!$D$15+K9*DISCOUNTS!$C$27+L9*DISCOUNTS!$D$27+M9*FEE_GRID!$D$23 -> 3903470.7
A10: CP | B10: Elementaire | C10: 2 | D10: 10 | E10: 32 | F10: =SUM(C10:E10) -> 44 | G10: 0 | H10: 1 | I10: 2 | J10: =SUM(G10:I10) -> 3 | K10: 2 | L10: 11 | M10: 66 | N10: =SUM(K10:M10) -> 79 | O10: =F10+J10+N10 -> 126 | P10: =C10*DISCOUNTS!$C$12+D10*DISCOUNTS!$D$12+E10*FEE_GRID!$D$8+G10*DISCOUNTS!$C$20+H10*DISCOUNTS!$D$20+I10*FEE_GRID!$D$16+K10*DISCOUNTS!$C$28+L10*DISCOUNTS!$D$28+M10*FEE_GRID!$D$24 -> 4028689.7
A11: CE1 | B11: Elementaire | C11: 2 | D11: 9 | E11: 30 | F11: =SUM(C11:E11) -> 41 | G11: 0 | H11: 1 | I11: 2 | J11: =SUM(G11:I11) -> 3 | K11: 2 | L11: 10 | M11: 62 | N11: =SUM(K11:M11) -> 74 | O11: =F11+J11+N11 -> 118 | P11: =C11*DISCOUNTS!$C$12+D11*DISCOUNTS!$D$12+E11*FEE_GRID!$D$8+G11*DISCOUNTS!$C$20+H11*DISCOUNTS!$D$20+I11*FEE_GRID!$D$16+K11*DISCOUNTS!$C$28+L11*DISCOUNTS!$D$28+M11*FEE_GRID!$D$24 -> 3776841.8
A12: CE2 | B12: Elementaire | C12: 2 | D12: 10 | E12: 34 | F12: =SUM(C12:E12) -> 46 | G12: 0 | H12: 1 | I12: 2 | J12: =SUM(G12:I12) -> 3 | K12: 2 | L12: 11 | M12: 70 | N12: =SUM(K12:M12) -> 83 | O12: =F12+J12+N12 -> 132 | P12: =C12*DISCOUNTS!$C$12+D12*DISCOUNTS!$D$12+E12*FEE_GRID!$D$8+G12*DISCOUNTS!$C$20+H12*DISCOUNTS!$D$20+I12*FEE_GRID!$D$16+K12*DISCOUNTS!$C$28+L12*DISCOUNTS!$D$28+M12*FEE_GRID!$D$24 -> 4231298.4
A13: CM1 | B13: Elementaire | C13: 2 | D13: 9 | E13: 31 | F13: =SUM(C13:E13) -> 42 | G13: 0 | H13: 1 | I13: 2 | J13: =SUM(G13:I13) -> 3 | K13: 2 | L13: 10 | M13: 64 | N13: =SUM(K13:M13) -> 76 | O13: =F13+J13+N13 -> 121 | P13: =C13*DISCOUNTS!$C$12+D13*DISCOUNTS!$D$12+E13*FEE_GRID!$D$8+G13*DISCOUNTS!$C$20+H13*DISCOUNTS!$D$20+I13*FEE_GRID!$D$16+K13*DISCOUNTS!$C$28+L13*DISCOUNTS!$D$28+M13*FEE_GRID!$D$24 -> 3878146.2
A14: CM2 | B14: Elementaire | C14: 2 | D14: 9 | E14: 31 | F14: =SUM(C14:E14) -> 42 | G14: 0 | H14: 1 | I14: 2 | J14: =SUM(G14:I14) -> 3 | K14: 2 | L14: 10 | M14: 64 | N14: =SUM(K14:M14) -> 76 | O14: =F14+J14+N14 -> 121 | P14: =C14*DISCOUNTS!$C$12+D14*DISCOUNTS!$D$12+E14*FEE_GRID!$D$8+G14*DISCOUNTS!$C$20+H14*DISCOUNTS!$D$20+I14*FEE_GRID!$D$16+K14*DISCOUNTS!$C$28+L14*DISCOUNTS!$D$28+M14*FEE_GRID!$D$24 -> 3878146.2
A15: 6EME | B15: College | C15: 2 | D15: 5 | E15: 43 | F15: =SUM(C15:E15) -> 50 | G15: 0 | H15: 0 | I15: 3 | J15: =SUM(G15:I15) -> 3 | K15: 4 | L15: 5 | M15: 89 | N15: =SUM(K15:M15) -> 98 | O15: =F15+J15+N15 -> 151 | P15: =C15*DISCOUNTS!$C$13+D15*DISCOUNTS!$D$13+E15*FEE_GRID!$D$9+G15*DISCOUNTS!$C$21+H15*DISCOUNTS!$D$21+I15*FEE_GRID!$D$17+K15*DISCOUNTS!$C$29+L15*DISCOUNTS!$D$29+M15*FEE_GRID!$D$25 -> 4968145.7
A16: 5EME | B16: College | C16: 1 | D16: 5 | E16: 40 | F16: =SUM(C16:E16) -> 46 | G16: 0 | H16: 0 | I16: 3 | J16: =SUM(G16:I16) -> 3 | K16: 4 | L16: 4 | M16: 82 | N16: =SUM(K16:M16) -> 90 | O16: =F16+J16+N16 -> 139 | P16: =C16*DISCOUNTS!$C$13+D16*DISCOUNTS!$D$13+E16*FEE_GRID!$D$9+G16*DISCOUNTS!$C$21+H16*DISCOUNTS!$D$21+I16*FEE_GRID!$D$17+K16*DISCOUNTS!$C$29+L16*DISCOUNTS!$D$29+M16*FEE_GRID!$D$25 -> 4579341.3
A17: 4EME | B17: College | C17: 1 | D17: 4 | E17: 34 | F17: =SUM(C17:E17) -> 39 | G17: 0 | H17: 0 | I17: 2 | J17: =SUM(G17:I17) -> 2 | K17: 4 | L17: 4 | M17: 71 | N17: =SUM(K17:M17) -> 79 | O17: =F17+J17+N17 -> 120 | P17: =C17*DISCOUNTS!$C$13+D17*DISCOUNTS!$D$13+E17*FEE_GRID!$D$9+G17*DISCOUNTS!$C$21+H17*DISCOUNTS!$D$21+I17*FEE_GRID!$D$17+K17*DISCOUNTS!$C$29+L17*DISCOUNTS!$D$29+M17*FEE_GRID!$D$25 -> 3949017.4
A18: 3EME | B18: College | C18: 1 | D18: 4 | E18: 29 | F18: =SUM(C18:E18) -> 34 | G18: 0 | H18: 0 | I18: 2 | J18: =SUM(G18:I18) -> 2 | K18: 3 | L18: 3 | M18: 61 | N18: =SUM(K18:M18) -> 67 | O18: =F18+J18+N18 -> 103 | P18: =C18*DISCOUNTS!$C$13+D18*DISCOUNTS!$D$13+E18*FEE_GRID!$D$9+G18*DISCOUNTS!$C$21+H18*DISCOUNTS!$D$21+I18*FEE_GRID!$D$17+K18*DISCOUNTS!$C$29+L18*DISCOUNTS!$D$29+M18*FEE_GRID!$D$25 -> 3389017.4
A19: 2NDE | B19: Lycee | C19: 2 | D19: 0 | E19: 37 | F19: =SUM(C19:E19) -> 39 | G19: 0 | H19: 0 | I19: 3 | J19: =SUM(G19:I19) -> 3 | K19: 6 | L19: 0 | M19: 77 | N19: =SUM(K19:M19) -> 83 | O19: =F19+J19+N19 -> 125 | P19: =C19*DISCOUNTS!$C$14+D19*DISCOUNTS!$D$14+E19*FEE_GRID!$D$10+G19*DISCOUNTS!$C$22+H19*DISCOUNTS!$D$22+I19*FEE_GRID!$D$18+K19*DISCOUNTS!$C$30+L19*DISCOUNTS!$D$30+M19*FEE_GRID!$D$26 -> 4668913
A20: 1ERE | B20: Lycee | C20: 2 | D20: 0 | E20: 36 | F20: =SUM(C20:E20) -> 38 | G20: 0 | H20: 0 | I20: 3 | J20: =SUM(G20:I20) -> 3 | K20: 5 | L20: 0 | M20: 74 | N20: =SUM(K20:M20) -> 79 | O20: =F20+J20+N20 -> 120 | P20: =C20*DISCOUNTS!$C$14+D20*DISCOUNTS!$D$14+E20*FEE_GRID!$D$10+G20*DISCOUNTS!$C$22+H20*DISCOUNTS!$D$22+I20*FEE_GRID!$D$18+K20*DISCOUNTS!$C$30+L20*DISCOUNTS!$D$30+M20*FEE_GRID!$D$26 -> 4485434.8
A21: TERM | B21: Lycee | C21: 2 | D21: 0 | E21: 33 | F21: =SUM(C21:E21) -> 35 | G21: 0 | H21: 0 | I21: 2 | J21: =SUM(G21:I21) -> 2 | K21: 5 | L21: 0 | M21: 69 | N21: =SUM(K21:M21) -> 74 | O21: =F21+J21+N21 -> 111 | P21: =C21*DISCOUNTS!$C$14+D21*DISCOUNTS!$D$14+E21*FEE_GRID!$D$10+G21*DISCOUNTS!$C$22+H21*DISCOUNTS!$D$22+I21*FEE_GRID!$D$18+K21*DISCOUNTS!$C$30+L21*DISCOUNTS!$D$30+M21*FEE_GRID!$D$26 -> 4145000
A23: BAND SUBTOTALS
A24: Maternelle PS | C24: =C7 -> 1 | D24: =D7 -> 6 | E24: =E7 -> 17 | F24: =F7 -> 24 | G24: =G7 -> 0 | H24: =H7 -> 1 | I24: =I7 -> 1 | J24: =J7 -> 2 | ... P24: =P7 -> 1954348.5
A25: Maternelle | C25: =SUM(C8:C9) -> 3 | D25: =SUM(D8:D9) -> 20 | E25: =SUM(E8:E9) -> 47 | F25: =SUM(F8:F9) -> 70 | G25: =SUM(G8:G9) -> 0 | H25: =SUM(H8:H9) -> 3 | I25: =SUM(I8:I9) -> 3 | J25: =SUM(J8:J9) -> 6 | ... P25: =SUM(P8:P9) -> 6321619
A26: Elementaire | C26: =SUM(C10:C14) -> 10 | D26: =SUM(D10:D14) -> 47 | E26: =SUM(E10:E14) -> 158 | F26: =SUM(F10:F14) -> 215 | G26: =SUM(G10:G14) -> 0 | H26: =SUM(H10:H14) -> 5 | I26: =SUM(I10:I14) -> 10 | J26: =SUM(J10:J14) -> 15 | ... P26: =SUM(P10:P14) -> 19793122
A27: College | C27: =SUM(C15:C18) -> 5 | D27: =SUM(D15:D18) -> 18 | E27: =SUM(E15:E18) -> 146 | F27: =SUM(F15:F18) -> 169 | G27: =SUM(G15:G18) -> 0 | H27: =SUM(H15:H18) -> 0 | I27: =SUM(I15:I18) -> 10 | J27: =SUM(J15:J18) -> 10 | ... P27: =SUM(P15:P18) -> 16885522
A28: Lycee | C28: =SUM(C19:C21) -> 6 | D28: =SUM(D19:D21) -> 0 | E28: =SUM(E19:E21) -> 106 | F28: =SUM(F19:F21) -> 112 | G28: =SUM(G19:G21) -> 0 | H28: =SUM(H19:H21) -> 0 | I28: =SUM(I19:I21) -> 8 | J28: =SUM(J19:J21) -> 8 | ... P28: =SUM(P19:P21) -> 13299348
A29: TOTAL AY1 | C29: =SUM(C24:C28) -> 25 | D29: =SUM(D24:D28) -> 91 | E29: =SUM(E24:E28) -> 474 | F29: =SUM(F24:F28) -> 590 | G29: =SUM(G24:G28) -> 0 | H29: =SUM(H24:H28) -> 9 | I29: =SUM(I24:I28) -> 32 | J29: =SUM(J24:J28) -> 41 | ... P29: =SUM(P24:P28) -> 58253959
A31: Section B - AY2 Detail by Grade (2026-2027, Sep-Dec)
C32: Francais | G32: Nationaux | K32: Autres
A33: Grade | B33: Band | C33: RP | D33: R3+ | E33: Plein | F33: Total | G33: RP | H33: R3+ | I33: Plein | J33: Total | K33: RP | L33: R3+ | M33: Plein | N33: Total | O33: Grand Total | P33: Revenue HT
A34: PS | B34: Maternelle PS | C34: =IF($O$7=0,0,ROUND(ENROLLMENT_HEADCOUNT!$C$52*C7/$O$7,0)) -> 1 | D34: =IF($O$7=0,0,ROUND(ENROLLMENT_HEADCOUNT!$C$52*D7/$O$7,0)) -> 6 | E34: =IF($O$7=0,0,ROUND(ENROLLMENT_HEADCOUNT!$C$52*E7/$O$7,0)) -> 17 | F34: =SUM(C34:E34) -> 24 | G34: =IF($O$7=0,0,ROUND(ENROLLMENT_HEADCOUNT!$C$52*G7/$O$7,0)) -> 0 | H34: =IF($O$7=0,0,ROUND(ENROLLMENT_HEADCOUNT!$C$52*H7/$O$7,0)) -> 1 | I34: =IF($O$7=0,0,ROUND(ENROLLMENT_HEADCOUNT!$C$52*I7/$O$7,0)) -> 1 | J34: =SUM(G34:I34) -> 2 | K34: =IF($O$7=0,0,ROUND(ENROLLMENT_HEADCOUNT!$C$52*K7/$O$7,0)) -> 0 | L34: =IF($O$7=0,0,ROUND(ENROLLMENT_HEADCOUNT!$C$52*L7/$O$7,0)) -> 5 | M34: =ENROLLMENT_HEADCOUNT!$C$52-C34-D34-E34-G34-H34-I34-K34-L34 -> 34 | N34: =SUM(K34:M34) -> 39 | O34: =F34+J34+N34 -> 65 | P34: =C34*DISCOUNTS!$C$36+D34*DISCOUNTS!$D$36+E34*FEE_GRID!$D$32+G34*DISCOUNTS!$C$44+H34*DISCOUNTS!$D$44+I34*FEE_GRID!$D$40+K34*DISCOUNTS!$C$52+L34*DISCOUNTS!$D$52+M34*FEE_GRID!$D$48 -> 1954348.5
A35: MS | B35: Maternelle | C35: =IF($O$7=0,0,ROUND(ENROLLMENT_HEADCOUNT!$C$53*C7/$O$7,0)) -> 1 | D35: =IF($O$7=0,0,ROUND(ENROLLMENT_HEADCOUNT!$C$53*D7/$O$7,0)) -> 7 | E35: =IF($O$7=0,0,ROUND(ENROLLMENT_HEADCOUNT!$C$53*E7/$O$7,0)) -> 20 | F35: =SUM(C35:E35) -> 28 | G35: =IF($O$7=0,0,ROUND(ENROLLMENT_HEADCOUNT!$C$53*G7/$O$7,0)) -> 0 | H35: =IF($O$7=0,0,ROUND(ENROLLMENT_HEADCOUNT!$C$53*H7/$O$7,0)) -> 1 | I35: =IF($O$7=0,0,ROUND(ENROLLMENT_HEADCOUNT!$C$53*I7/$O$7,0)) -> 1 | J35: =SUM(G35:I35) -> 2 | K35: =IF($O$7=0,0,ROUND(ENROLLMENT_HEADCOUNT!$C$53*K7/$O$7,0)) -> 0 | L35: =IF($O$7=0,0,ROUND(ENROLLMENT_HEADCOUNT!$C$53*L7/$O$7,0)) -> 6 | M35: =ENROLLMENT_HEADCOUNT!$C$53-C35-D35-E35-G35-H35-I35-K35-L35 -> 41 | N35: =SUM(K35:M35) -> 47 | O35: =F35+J35+N35 -> 77 | P35: =C35*DISCOUNTS!$C$37+D35*DISCOUNTS!$D$37+E35*FEE_GRID!$D$33+G35*DISCOUNTS!$C$45+H35*DISCOUNTS!$D$45+I35*FEE_GRID!$D$41+K35*DISCOUNTS!$C$53+L35*DISCOUNTS!$D$53+M35*FEE_GRID!$D$49 -> 2528485.3
A36: GS | B36: Maternelle | C36: =IF($O$8=0,0,ROUND(ENROLLMENT_HEADCOUNT!$C$54*C8/$O$8,0)) -> 2 | D36: =IF($O$8=0,0,ROUND(ENROLLMENT_HEADCOUNT!$C$54*D8/$O$8,0)) -> 13 | E36: =IF($O$8=0,0,ROUND(ENROLLMENT_HEADCOUNT!$C$54*E8/$O$8,0)) -> 29 | F36: =SUM(C36:E36) -> 44 | G36: =IF($O$8=0,0,ROUND(ENROLLMENT_HEADCOUNT!$C$54*G8/$O$8,0)) -> 0 | H36: =IF($O$8=0,0,ROUND(ENROLLMENT_HEADCOUNT!$C$54*H8/$O$8,0)) -> 2 | I36: =IF($O$8=0,0,ROUND(ENROLLMENT_HEADCOUNT!$C$54*I8/$O$8,0)) -> 2 | J36: =SUM(G36:I36) -> 4 | K36: =IF($O$8=0,0,ROUND(ENROLLMENT_HEADCOUNT!$C$54*K8/$O$8,0)) -> 2 | L36: =IF($O$8=0,0,ROUND(ENROLLMENT_HEADCOUNT!$C$54*L8/$O$8,0)) -> 16 | M36: =ENROLLMENT_HEADCOUNT!$C$54-C36-D36-E36-G36-H36-I36-K36-L36 -> 58 | N36: =SUM(K36:M36) -> 76 | O36: =F36+J36+N36 -> 124 | P36: =C36*DISCOUNTS!$C$37+D36*DISCOUNTS!$D$37+E36*FEE_GRID!$D$33+G36*DISCOUNTS!$C$45+H36*DISCOUNTS!$D$45+I36*FEE_GRID!$D$41+K36*DISCOUNTS!$C$53+L36*DISCOUNTS!$D$53+M36*FEE_GRID!$D$49 -> 3982079.3
A37: CP | B37: Elementaire | C37: =IF($O$9=0,0,ROUND(ENROLLMENT_HEADCOUNT!$C$55*C9/$O$9,0)) -> 2 | D37: =IF($O$9=0,0,ROUND(ENROLLMENT_HEADCOUNT!$C$55*D9/$O$9,0)) -> 12 | E37: =IF($O$9=0,0,ROUND(ENROLLMENT_HEADCOUNT!$C$55*E9/$O$9,0)) -> 29 | F37: =SUM(C37:E37) -> 43 | G37: =IF($O$9=0,0,ROUND(ENROLLMENT_HEADCOUNT!$C$55*G9/$O$9,0)) -> 0 | H37: =IF($O$9=0,0,ROUND(ENROLLMENT_HEADCOUNT!$C$55*H9/$O$9,0)) -> 2 | I37: =IF($O$9=0,0,ROUND(ENROLLMENT_HEADCOUNT!$C$55*I9/$O$9,0)) -> 2 | J37: =SUM(G37:I37) -> 4 | K37: =IF($O$9=0,0,ROUND(ENROLLMENT_HEADCOUNT!$C$55*K9/$O$9,0)) -> 2 | L37: =IF($O$9=0,0,ROUND(ENROLLMENT_HEADCOUNT!$C$55*L9/$O$9,0)) -> 15 | M37: =ENROLLMENT_HEADCOUNT!$C$55-C37-D37-E37-G37-H37-I37-K37-L37 -> 62 | N37: =SUM(K37:M37) -> 79 | O37: =F37+J37+N37 -> 126 | P37: =C37*DISCOUNTS!$C$38+D37*DISCOUNTS!$D$38+E37*FEE_GRID!$D$34+G37*DISCOUNTS!$C$46+H37*DISCOUNTS!$D$46+I37*FEE_GRID!$D$42+K37*DISCOUNTS!$C$54+L37*DISCOUNTS!$D$54+M37*FEE_GRID!$D$50 -> 4094796.7
A38: CE1 | B38: Elementaire | C38: =IF($O$10=0,0,ROUND(ENROLLMENT_HEADCOUNT!$C$56*C10/$O$10,0)) -> 2 | D38: =IF($O$10=0,0,ROUND(ENROLLMENT_HEADCOUNT!$C$56*D10/$O$10,0)) -> 9 | E38: =IF($O$10=0,0,ROUND(ENROLLMENT_HEADCOUNT!$C$56*E10/$O$10,0)) -> 30 | F38: =SUM(C38:E38) -> 41 | G38: =IF($O$10=0,0,ROUND(ENROLLMENT_HEADCOUNT!$C$56*G10/$O$10,0)) -> 0 | H38: =IF($O$10=0,0,ROUND(ENROLLMENT_HEADCOUNT!$C$56*H10/$O$10,0)) -> 1 | I38: =IF($O$10=0,0,ROUND(ENROLLMENT_HEADCOUNT!$C$56*I10/$O$10,0)) -> 2 | J38: =SUM(G38:I38) -> 3 | K38: =IF($O$10=0,0,ROUND(ENROLLMENT_HEADCOUNT!$C$56*K10/$O$10,0)) -> 2 | L38: =IF($O$10=0,0,ROUND(ENROLLMENT_HEADCOUNT!$C$56*L10/$O$10,0)) -> 10 | M38: =ENROLLMENT_HEADCOUNT!$C$56-C38-D38-E38-G38-H38-I38-K38-L38 -> 62 | N38: =SUM(K38:M38) -> 74 | O38: =F38+J38+N38 -> 118 | P38: =C38*DISCOUNTS!$C$38+D38*DISCOUNTS!$D$38+E38*FEE_GRID!$D$34+G38*DISCOUNTS!$C$46+H38*DISCOUNTS!$D$46+I38*FEE_GRID!$D$42+K38*DISCOUNTS!$C$54+L38*DISCOUNTS!$D$54+M38*FEE_GRID!$D$50 -> 3891222.3
A39: CE2 | B39: Elementaire | C39: =IF($O$11=0,0,ROUND(ENROLLMENT_HEADCOUNT!$C$57*C11/$O$11,0)) -> 2 | D39: =IF($O$11=0,0,ROUND(ENROLLMENT_HEADCOUNT!$C$57*D11/$O$11,0)) -> 10 | E39: =IF($O$11=0,0,ROUND(ENROLLMENT_HEADCOUNT!$C$57*E11/$O$11,0)) -> 34 | F39: =SUM(C39:E39) -> 46 | G39: =IF($O$11=0,0,ROUND(ENROLLMENT_HEADCOUNT!$C$57*G11/$O$11,0)) -> 0 | H39: =IF($O$11=0,0,ROUND(ENROLLMENT_HEADCOUNT!$C$57*H11/$O$11,0)) -> 1 | I39: =IF($O$11=0,0,ROUND(ENROLLMENT_HEADCOUNT!$C$57*I11/$O$11,0)) -> 2 | J39: =SUM(G39:I39) -> 3 | K39: =IF($O$11=0,0,ROUND(ENROLLMENT_HEADCOUNT!$C$57*K11/$O$11,0)) -> 2 | L39: =IF($O$11=0,0,ROUND(ENROLLMENT_HEADCOUNT!$C$57*L11/$O$11,0)) -> 11 | M39: =ENROLLMENT_HEADCOUNT!$C$57-C39-D39-E39-G39-H39-I39-K39-L39 -> 70 | N39: =SUM(K39:M39) -> 83 | O39: =F39+J39+N39 -> 132 | P39: =C39*DISCOUNTS!$C$38+D39*DISCOUNTS!$D$38+E39*FEE_GRID!$D$34+G39*DISCOUNTS!$C$46+H39*DISCOUNTS!$D$46+I39*FEE_GRID!$D$42+K39*DISCOUNTS!$C$54+L39*DISCOUNTS!$D$54+M39*FEE_GRID!$D$50 -> 4359483.2
A40: CM1 | B40: Elementaire | C40: =IF($O$12=0,0,ROUND(ENROLLMENT_HEADCOUNT!$C$58*C12/$O$12,0)) -> 2 | D40: =IF($O$12=0,0,ROUND(ENROLLMENT_HEADCOUNT!$C$58*D12/$O$12,0)) -> 9 | E40: =IF($O$12=0,0,ROUND(ENROLLMENT_HEADCOUNT!$C$58*E12/$O$12,0)) -> 31 | F40: =SUM(C40:E40) -> 42 | G40: =IF($O$12=0,0,ROUND(ENROLLMENT_HEADCOUNT!$C$58*G12/$O$12,0)) -> 0 | H40: =IF($O$12=0,0,ROUND(ENROLLMENT_HEADCOUNT!$C$58*H12/$O$12,0)) -> 1 | I40: =IF($O$12=0,0,ROUND(ENROLLMENT_HEADCOUNT!$C$58*I12/$O$12,0)) -> 2 | J40: =SUM(G40:I40) -> 3 | K40: =IF($O$12=0,0,ROUND(ENROLLMENT_HEADCOUNT!$C$58*K12/$O$12,0)) -> 2 | L40: =IF($O$12=0,0,ROUND(ENROLLMENT_HEADCOUNT!$C$58*L12/$O$12,0)) -> 10 | M40: =ENROLLMENT_HEADCOUNT!$C$58-C40-D40-E40-G40-H40-I40-K40-L40 -> 64 | N40: =SUM(K40:M40) -> 76 | O40: =F40+J40+N40 -> 121 | P40: =C40*DISCOUNTS!$C$38+D40*DISCOUNTS!$D$38+E40*FEE_GRID!$D$34+G40*DISCOUNTS!$C$46+H40*DISCOUNTS!$D$46+I40*FEE_GRID!$D$42+K40*DISCOUNTS!$C$54+L40*DISCOUNTS!$D$54+M40*FEE_GRID!$D$50 -> 3995570.1
A41: CM2 | B41: Elementaire | C41: =IF($O$13=0,0,ROUND(ENROLLMENT_HEADCOUNT!$C$59*C13/$O$13,0)) -> 2 | D41: =IF($O$13=0,0,ROUND(ENROLLMENT_HEADCOUNT!$C$59*D13/$O$13,0)) -> 9 | E41: =IF($O$13=0,0,ROUND(ENROLLMENT_HEADCOUNT!$C$59*E13/$O$13,0)) -> 31 | F41: =SUM(C41:E41) -> 42 | G41: =IF($O$13=0,0,ROUND(ENROLLMENT_HEADCOUNT!$C$59*G13/$O$13,0)) -> 0 | H41: =IF($O$13=0,0,ROUND(ENROLLMENT_HEADCOUNT!$C$59*H13/$O$13,0)) -> 1 | I41: =IF($O$13=0,0,ROUND(ENROLLMENT_HEADCOUNT!$C$59*I13/$O$13,0)) -> 2 | J41: =SUM(G41:I41) -> 3 | K41: =IF($O$13=0,0,ROUND(ENROLLMENT_HEADCOUNT!$C$59*K13/$O$13,0)) -> 2 | L41: =IF($O$13=0,0,ROUND(ENROLLMENT_HEADCOUNT!$C$59*L13/$O$13,0)) -> 10 | M41: =ENROLLMENT_HEADCOUNT!$C$59-C41-D41-E41-G41-H41-I41-K41-L41 -> 64 | N41: =SUM(K41:M41) -> 76 | O41: =F41+J41+N41 -> 121 | P41: =C41*DISCOUNTS!$C$38+D41*DISCOUNTS!$D$38+E41*FEE_GRID!$D$34+G41*DISCOUNTS!$C$46+H41*DISCOUNTS!$D$46+I41*FEE_GRID!$D$42+K41*DISCOUNTS!$C$54+L41*DISCOUNTS!$D$54+M41*FEE_GRID!$D$50 -> 3995570.1
A42: 6EME | B42: College | C42: =IF($O$14=0,0,ROUND(ENROLLMENT_HEADCOUNT!$C$60*C14/$O$14,0)) -> 2 | D42: =IF($O$14=0,0,ROUND(ENROLLMENT_HEADCOUNT!$C$60*D14/$O$14,0)) -> 11 | E42: =IF($O$14=0,0,ROUND(ENROLLMENT_HEADCOUNT!$C$60*E14/$O$14,0)) -> 39 | F42: =SUM(C42:E42) -> 52 | G42: =IF($O$14=0,0,ROUND(ENROLLMENT_HEADCOUNT!$C$60*G14/$O$14,0)) -> 0 | H42: =IF($O$14=0,0,ROUND(ENROLLMENT_HEADCOUNT!$C$60*H14/$O$14,0)) -> 1 | I42: =IF($O$14=0,0,ROUND(ENROLLMENT_HEADCOUNT!$C$60*I14/$O$14,0)) -> 2 | J42: =SUM(G42:I42) -> 3 | K42: =IF($O$14=0,0,ROUND(ENROLLMENT_HEADCOUNT!$C$60*K14/$O$14,0)) -> 2 | L42: =IF($O$14=0,0,ROUND(ENROLLMENT_HEADCOUNT!$C$60*L14/$O$14,0)) -> 12 | M42: =ENROLLMENT_HEADCOUNT!$C$60-C42-D42-E42-G42-H42-I42-K42-L42 -> 82 | N42: =SUM(K42:M42) -> 96 | O42: =F42+J42+N42 -> 151 | P42: =C42*DISCOUNTS!$C$39+D42*DISCOUNTS!$D$39+E42*FEE_GRID!$D$35+G42*DISCOUNTS!$C$47+H42*DISCOUNTS!$D$47+I42*FEE_GRID!$D$43+K42*DISCOUNTS!$C$55+L42*DISCOUNTS!$D$55+M42*FEE_GRID!$D$51 -> 5066548.4
A43: 5EME | B43: College | C43: =IF($O$15=0,0,ROUND(ENROLLMENT_HEADCOUNT!$C$61*C15/$O$15,0)) -> 2 | D43: =IF($O$15=0,0,ROUND(ENROLLMENT_HEADCOUNT!$C$61*D15/$O$15,0)) -> 5 | E43: =IF($O$15=0,0,ROUND(ENROLLMENT_HEADCOUNT!$C$61*E15/$O$15,0)) -> 40 | F43: =SUM(C43:E43) -> 47 | G43: =IF($O$15=0,0,ROUND(ENROLLMENT_HEADCOUNT!$C$61*G15/$O$15,0)) -> 0 | H43: =IF($O$15=0,0,ROUND(ENROLLMENT_HEADCOUNT!$C$61*H15/$O$15,0)) -> 0 | I43: =IF($O$15=0,0,ROUND(ENROLLMENT_HEADCOUNT!$C$61*I15/$O$15,0)) -> 3 | J43: =SUM(G43:I43) -> 3 | K43: =IF($O$15=0,0,ROUND(ENROLLMENT_HEADCOUNT!$C$61*K15/$O$15,0)) -> 4 | L43: =IF($O$15=0,0,ROUND(ENROLLMENT_HEADCOUNT!$C$61*L15/$O$15,0)) -> 5 | M43: =ENROLLMENT_HEADCOUNT!$C$61-C43-D43-E43-G43-H43-I43-K43-L43 -> 80 | N43: =SUM(K43:M43) -> 89 | O43: =F43+J43+N43 -> 139 | P43: =C43*DISCOUNTS!$C$39+D43*DISCOUNTS!$D$39+E43*FEE_GRID!$D$35+G43*DISCOUNTS!$C$47+H43*DISCOUNTS!$D$47+I43*FEE_GRID!$D$43+K43*DISCOUNTS!$C$55+L43*DISCOUNTS!$D$55+M43*FEE_GRID!$D$51 -> 4752123.9
...

Sheet CLASS_CAPACITY
A1: EFIR - Class Capacity Planning (Fourchette) - Based on AY2
A3: Section A - Grade-Level Capacity
A4: Grade | B4: Band | C4: AY2 Enrollment | D4: Max Class Size | E4: Sections Needed | F4: Plancher (70%) | G4: Cible (85%) | H4: Plafond (100%) | I4: Utilization % | J4: Alert | L4: Possible Recruitments
A5: PS | B5: Maternelle PS | C5: =ENROLLMENT_DETAIL!$O$34 -> 65 | D5: 24 | E5: =IF(C5=0,0,CEILING(C5/D5,1)) -> 3 | F5: =INT(E5*D5*0.7) -> 50 | G5: =INT(E5*D5*0.85) -> 61 | H5: =E5*D5 -> 72 | I5: =IF(E5=0,0,C5/(E5*D5)) -> 0.90277778 | J5: =IF(C5>H5,"OVER",IF(C5<F5,"UNDER","OK")) -> OK | L5: =H5-C5 -> 7
A6: MS | B6: Maternelle | C6: =ENROLLMENT_DETAIL!$O$35 -> 77 | D6: 24 | E6: =IF(C6=0,0,CEILING(C6/D6,1)) -> 4 | F6: =INT(E6*D6*0.7) -> 67 | G6: =INT(E6*D6*0.85) -> 81 | H6: =E6*D6 -> 96 | I6: =IF(E6=0,0,C6/(E6*D6)) -> 0.80208333 | J6: =IF(C6>H6,"OVER",IF(C6<F6,"UNDER","OK")) -> OK | L6: =H6-C6 -> 19
A7: GS | B7: Maternelle | C7: =ENROLLMENT_DETAIL!$O$36 -> 124 | D7: 24 | E7: =IF(C7=0,0,CEILING(C7/D7,1)) -> 6 | F7: =INT(E7*D7*0.7) -> 100 | G7: =INT(E7*D7*0.85) -> 122 | H7: =E7*D7 -> 144 | I7: =IF(E7=0,0,C7/(E7*D7)) -> 0.86111111 | J7: =IF(C7>H7,"OVER",IF(C7<F7,"UNDER","OK")) -> OK | L7: =H7-C7 -> 20
A8: CP | B8: Elementaire | C8: =ENROLLMENT_DETAIL!$O$37 -> 126 | D8: 26 | E8: =IF(C8=0,0,CEILING(C8/D8,1)) -> 5 | F8: =INT(E8*D8*0.7) -> 91 | G8: =INT(E8*D8*0.85) -> 110 | H8: =E8*D8 -> 130 | I8: =IF(E8=0,0,C8/(E8*D8)) -> 0.96923077 | J8: =IF(C8>H8,"OVER",IF(C8<F8,"UNDER","OK")) -> OK | L8: =H8-C8 -> 4
A9: CE1 | B9: Elementaire | C9: =ENROLLMENT_DETAIL!$O$38 -> 118 | D9: 26 | E9: =IF(C9=0,0,CEILING(C9/D9,1)) -> 5 | F9: =INT(E9*D9*0.7) -> 91 | G9: =INT(E9*D9*0.85) -> 110 | H9: =E9*D9 -> 130 | I9: =IF(E9=0,0,C9/(E9*D9)) -> 0.90769231 | J9: =IF(C9>H9,"OVER",IF(C9<F9,"UNDER","OK")) -> OK | L9: =H9-C9 -> 12
A10: CE2 | B10: Elementaire | C10: =ENROLLMENT_DETAIL!$O$39 -> 132 | D10: 26 | E10: =IF(C10=0,0,CEILING(C10/D10,1)) -> 6 | F10: =INT(E10*D10*0.7) -> 109 | G10: =INT(E10*D10*0.85) -> 132 | H10: =E10*D10 -> 156 | I10: =IF(E10=0,0,C10/(E10*D10)) -> 0.84615385 | J10: =IF(C10>H10,"OVER",IF(C10<F10,"UNDER","OK")) -> OK | L10: =H10-C10 -> 24
A11: CM1 | B11: Elementaire | C11: =ENROLLMENT_DETAIL!$O$40 -> 121 | D11: 26 | E11: =IF(C11=0,0,CEILING(C11/D11,1)) -> 5 | F11: =INT(E11*D11*0.7) -> 91 | G11: =INT(E11*D11*0.85) -> 110 | H11: =E11*D11 -> 130 | I11: =IF(E11=0,0,C11/(E11*D11)) -> 0.93076923 | J11: =IF(C11>H11,"OVER",IF(C11<F11,"UNDER","OK")) -> OK | L11: =H11-C11 -> 9
A12: CM2 | B12: Elementaire | C12: =ENROLLMENT_DETAIL!$O$41 -> 121 | D12: 26 | E12: =IF(C12=0,0,CEILING(C12/D12,1)) -> 5 | F12: =INT(E12*D12*0.7) -> 91 | G12: =INT(E12*D12*0.85) -> 110 | H12: =E12*D12 -> 130 | I12: =IF(E12=0,0,C12/(E12*D12)) -> 0.93076923 | J12: =IF(C12>H12,"OVER",IF(C12<F12,"UNDER","OK")) -> OK | L12: =H12-C12 -> 9
A13: 6EME | B13: College | C13: =ENROLLMENT_DETAIL!$O$42 -> 151 | D13: 26 | E13: =IF(C13=0,0,CEILING(C13/D13,1)) -> 6 | F13: =INT(E13*D13*0.7) -> 109 | G13: =INT(E13*D13*0.85) -> 132 | H13: =E13*D13 -> 156 | I13: =IF(E13=0,0,C13/(E13*D13)) -> 0.96794872 | J13: =IF(C13>H13,"OVER",IF(C13<F13,"UNDER","OK")) -> OK | L13: =H13-C13 -> 5
A14: 5EME | B14: College | C14: =ENROLLMENT_DETAIL!$O$43 -> 139 | D14: 26 | E14: =IF(C14=0,0,CEILING(C14/D14,1)) -> 6 | F14: =INT(E14*D14*0.7) -> 109 | G14: =INT(E14*D14*0.85) -> 132 | H14: =E14*D14 -> 156 | I14: =IF(E14=0,0,C14/(E14*D14)) -> 0.89102564 | J14: =IF(C14>H14,"OVER",IF(C14<F14,"UNDER","OK")) -> OK | L14: =H14-C14 -> 17
A15: 4EME | B15: College | C15: =ENROLLMENT_DETAIL!$O$44 -> 120 | D15: 26 | E15: =IF(C15=0,0,CEILING(C15/D15,1)) -> 5 | F15: =INT(E15*D15*0.7) -> 91 | G15: =INT(E15*D15*0.85) -> 110 | H15: =E15*D15 -> 130 | I15: =IF(E15=0,0,C15/(E15*D15)) -> 0.92307692 | J15: =IF(C15>H15,"OVER",IF(C15<F15,"UNDER","OK")) -> OK | L15: =H15-C15 -> 10
A16: 3EME | B16: College | C16: =ENROLLMENT_DETAIL!$O$45 -> 103 | D16: 26 | E16: =IF(C16=0,0,CEILING(C16/D16,1)) -> 4 | F16: =INT(E16*D16*0.7) -> 72 | G16: =INT(E16*D16*0.85) -> 88 | H16: =E16*D16 -> 104 | I16: =IF(E16=0,0,C16/(E16*D16)) -> 0.99038462 | J16: =IF(C16>H16,"OVER",IF(C16<F16,"UNDER","OK")) -> OK | L16: =H16-C16 -> 1
A17: 2NDE | B17: Lycee | C17: =ENROLLMENT_DETAIL!$O$46 -> 125 | D17: 28 | E17: =IF(C17=0,0,CEILING(C17/D17,1)) -> 5 | F17: =INT(E17*D17*0.7) -> 98 | G17: =INT(E17*D17*0.85) -> 119 | H17: =E17*D17 -> 140 | I17: =IF(E17=0,0,C17/(E17*D17)) -> 0.89285714 | J17: =IF(C17>H17,"OVER",IF(C17<F17,"UNDER","OK")) -> OK | L17: =H17-C17 -> 15
A18: 1ERE | B18: Lycee | C18: =ENROLLMENT_DETAIL!$O$47 -> 120 | D18: 28 | E18: =IF(C18=0,0,CEILING(C18/D18,1)) -> 5 | F18: =INT(E18*D18*0.7) -> 98 | G18: =INT(E18*D18*0.85) -> 119 | H18: =E18*D18 -> 140 | I18: =IF(E18=0,0,C18/(E18*D18)) -> 0.85714286 | J18: =IF(C18>H18,"OVER",IF(C18<F18,"UNDER","OK")) -> OK | L18: =H18-C18 -> 20
A19: TERM | B19: Lycee | C19: =ENROLLMENT_DETAIL!$O$48 -> 111 | D19: 28 | E19: =IF(C19=0,0,CEILING(C19/D19,1)) -> 4 | F19: =INT(E19*D19*0.7) -> 78 | G19: =INT(E19*D19*0.85) -> 95 | H19: =E19*D19 -> 112 | I19: =IF(E19=0,0,C19/(E19*D19)) -> 0.99107143 | J19: =IF(C19>H19,"OVER",IF(C19<F19,"UNDER","OK")) -> OK | L19: =H19-C19 -> 1
A21: Section B - Band-Level Summary
A22: Band | B22: Total Enrollment | C22: Total Sections | D22: Avg Utilization | E22: Status
A23: Maternelle PS | B23: =C5 -> 65 | C23: =E5 -> 3 | D23: =IF((H5)=0,0,B23/(H5)) -> 0.90277778 | E23: =IF(D23>=1,"OVER",IF(D23<0.7,"UNDER","OK")) -> OK
A24: Maternelle | B24: =C6+C7 -> 201 | C24: =E6+E7 -> 10 | D24: =IF((H6+H7)=0,0,B24/(H6+H7)) -> 0.8375 | E24: =IF(D24>=1,"OVER",IF(D24<0.7,"UNDER","OK")) -> OK
A25: Elementaire | B25: =C8+C9+C10+C11+C12 -> 618 | C25: =E8+E9+E10+E11+E12 -> 26 | D25: =IF((H8+H9+H10+H11+H12)=0,0,B25/(H8+H9+H10+H11+H12)) -> 0.91420118 | E25: =IF(D25>=1,"OVER",IF(D25<0.7,"UNDER","OK")) -> OK
A26: College | B26: =C13+C14+C15+C16 -> 513 | C26: =E13+E14+E15+E16 -> 21 | D26: =IF((H13+H14+H15+H16)=0,0,B26/(H13+H14+H15+H16)) -> 0.93956044 | E26: =IF(D26>=1,"OVER",IF(D26<0.7,"UNDER","OK")) -> OK
A27: Lycee | B27: =C17+C18+C19 -> 356 | C27: =E17+E18+E19 -> 14 | D27: =IF((H17+H18+H19)=0,0,B27/(H17+H18+H19)) -> 0.90816327 | E27: =IF(D27>=1,"OVER",IF(D27<0.7,"UNDER","OK")) -> OK
A29: Section C - Total School Summary
A30: Total Students | B30: =B23+B24+B25+B26+B27 -> 1753
A31: Total Sections | B31: =C23+C24+C25+C26+C27 -> 74
A32: Overall Utilization | B32: =IF((H5+H6+H7+H8+H9+H10+H11+H12+H13+H14+H15+H16+H17+H18+H19)=0,0,CLASS_CAPACITY!$B$30/(H5+H6+H7+H8+H9+H10+H11+H12+H13+H14+H15+H16+H17+H18+H19)) -> 0.91017653

Sheet OTHER_REVENUES
A1: OTHER REVENUES - Driver-Based Monthly Breakdown
A2: FY2026 Budget
A4: Line Item | B4: Annual Driver (SAR) | C4: Distribution | D4: Jan | E4: Feb | F4: Mar | G4: Apr | H4: May | I4: Jun | J4: Jul | K4: Aug | L4: Sep | M4: Oct | N4: Nov | O4: Dec | P4: FY2026 Total | Q4: Check
A5: Section A - Registration Fees
A6: Frais de Dossier - Francais | B6: =NEW_STUDENTS_FR*FEE_GRID!$C$88 -> 76000 | C6: May-Jun | D6: =IF($C6="Academic /10",IF(OR(D$4="Jul",D$4="Aug"),0,$B6/10),IF($C6="Year-round /12",$B6/12,IF($C6="May-Jun",IF(OR(D$4="May",D$4="Jun"),$B6/2,0),IF($C6="Jul-Aug",IF(OR(D$4="Jul",D$4="Aug"),$B6/2,0),IF($C6="Jun only",IF(D$4="Jun",$B6,0),IF($C6="Custom months",0,0)))))) -> 0 | E6: =IF($C6="Academic /10",IF(OR(E$4="Jul",E$4="Aug"),0,$B6/10),IF($C6="Year-round /12",$B6/12,IF($C6="May-Jun",IF(OR(E$4="May",E$4="Jun"),$B6/2,0),IF($C6="Jul-Aug",IF(OR(E$4="Jul",E$4="Aug"),$B6/2,0),IF($C6="Jun only",IF(E$4="Jun",$B6,0),IF($C6="Custom months",0,0)))))) -> 0 | F6: =IF($C6="Academic /10",IF(OR(F$4="Jul",F$4="Aug"),0,$B6/10),IF($C6="Year-round /12",$B6/12,IF($C6="May-Jun",IF(OR(F$4="May",F$4="Jun"),$B6/2,0),IF($C6="Jul-Aug",IF(OR(F$4="Jul",F$4="Aug"),$B6/2,0),IF($C6="Jun only",IF(F$4="Jun",$B6,0),IF($C6="Custom months",0,0)))))) -> 0 | G6: =IF($C6="Academic /10",IF(OR(G$4="Jul",G$4="Aug"),0,$B6/10),IF($C6="Year-round /12",$B6/12,IF($C6="May-Jun",IF(OR(G$4="May",G$4="Jun"),$B6/2,0),IF($C6="Jul-Aug",IF(OR(G$4="Jul",G$4="Aug"),$B6/2,0),IF($C6="Jun only",IF(G$4="Jun",$B6,0),IF($C6="Custom months",0,0)))))) -> 0 | H6: =IF($C6="Academic /10",IF(OR(H$4="Jul",H$4="Aug"),0,$B6/10),IF($C6="Year-round /12",$B6/12,IF($C6="May-Jun",IF(OR(H$4="May",H$4="Jun"),$B6/2,0),IF($C6="Jul-Aug",IF(OR(H$4="Jul",H$4="Aug"),$B6/2,0),IF($C6="Jun only",IF(H$4="Jun",$B6,0),IF($C6="Custom months",0,0)))))) -> 38000 | I6: =IF($C6="Academic /10",IF(OR(I$4="Jul",I$4="Aug"),0,$B6/10),IF($C6="Year-round /12",$B6/12,IF($C6="May-Jun",IF(OR(I$4="May",I$4="Jun"),$B6/2,0),IF($C6="Jul-Aug",IF(OR(I$4="Jul",I$4="Aug"),$B6/2,0),IF($C6="Jun only",IF(I$4="Jun",$B6,0),IF($C6="Custom months",0,0)))))) -> 38000 | J6: =IF($C6="Academic /10",IF(OR(J$4="Jul",J$4="Aug"),0,$B6/10),IF($C6="Year-round /12",$B6/12,IF($C6="May-Jun",IF(OR(J$4="May",J$4="Jun"),$B6/2,0),IF($C6="Jul-Aug",IF(OR(J$4="Jul",J$4="Aug"),$B6/2,0),IF($C6="Jun only",IF(J$4="Jun",$B6,0),IF($C6="Custom months",0,0)))))) -> 0 | K6: =IF($C6="Academic /10",IF(OR(K$4="Jul",K$4="Aug"),0,$B6/10),IF($C6="Year-round /12",$B6/12,IF($C6="May-Jun",IF(OR(K$4="May",K$4="Jun"),$B6/2,0),IF($C6="Jul-Aug",IF(OR(K$4="Jul",K$4="Aug"),$B6/2,0),IF($C6="Jun only",IF(K$4="Jun",$B6,0),IF($C6="Custom months",0,0)))))) -> 0 | ... O6: =IF($C6="Academic /10",IF(OR(O$4="Jul",O$4="Aug"),0,$B6/10),IF($C6="Year-round /12",$B6/12,IF($C6="May-Jun",IF(OR(O$4="May",O$4="Jun"),$B6/2,0),IF($C6="Jul-Aug",IF(OR(O$4="Jul",O$4="Aug"),$B6/2,0),IF($C6="Jun only",IF(O$4="Jun",$B6,0),IF($C6="Custom months",0,0)))))) -> 0 | P6: =SUM(D6:O6) -> 76000 | Q6: =P6-B6 -> 0
