Workbook

Sheet Assumptions
A1: EFIR — Staff Costs Budget Assumptions
A3: GENERAL PARAMETERS
A4: Budget Year | B4: 2026 | C4: Calendar year for budget
A5: Salary Increase Effective Month | B5: 9 | C5: 9 = September
A6: Seniority Threshold (years) | B6: 1 | C6: >1 year as of Sep 1 to qualify for increase
A7: Budget Start Date | B7: =DATE(B4,1,1) -> 46023 | C7: Auto-calculated
A8: Budget End Date | B8: =DATE(B4,12,31) -> 46387 | C8: Auto-calculated
A9: Increase Effective Date | B9: =DATE(B4,B5,1) -> 46266 | C9: Auto-calculated
A11: GOSI RATES
A12: Employer Rate — Saudi | B12: 0.1175 | C12: 9% pension + 2% OccHaz + 0.75% SANED
A13: Employer Rate — Non-Saudi | B13: 0 | C13: 0% — Ajeer/dependent workers exempt
A14: GOSI Salary Cap (monthly) | B14: 45000 | C14: Max base for GOSI calculation
A15: GOSI Basis | B15: Base + Housing | C15: Components subject to GOSI
A17: END OF SERVICE (EoS)
A18: Rate — First 5 years (months/year) | B18: 0.5 | C18: 0.5 month salary per year of service
A19: Rate — After 5 years (months/year) | B19: 1 | C19: 1 month salary per year of service
A20: YoS Threshold (years) | B20: 5 | C20: Tier breakpoint
A21: EoS Basis | B21: Full Monthly Gross | C21: Base+Housing+Transport+Premium+HSA
A23: AJEER COSTS
A24: Annual Ajeer Fee per Worker (incl. VAT) | B24: 10925 | C24: SAR 10,925/year — dependent education permit
A25: Monthly Ajeer Fee per Worker | B25: =B24/12 -> 910.41667 | C25: Auto-calculated
A27: HEADCOUNT (auto-calculated)
A28: Total Contrat Local | B28: =COUNTIF('Master Data'!D5:D194,"Contrat Local") -> 160 | C28: Auto from Master Data
A29: Saudi Employees | B29: =COUNTIFS('Master Data'!D5:D194,"Contrat Local",'Master Data'!M5:M194,"Saudi") -> 2 | C29: Auto from Master Data
A30: Non-Saudi Employees (Ajeer) | B30: =COUNTIFS('Master Data'!D5:D194,"Contrat Local",'Master Data'!M5:M194,"Non-Saudi") -> 158 | C30: Auto from Master Data
A32: NEW POSITIONS
A33: New Positions Start Month | B33: 9 | C33: 9 = September — change to shift all new position costs
A34: New Positions Start Date | B34: =DATE(B4,B33,1) -> 46266 | C34: Auto-calculated
A36: Position | B36: Monthly Gross | C36: Base Salary | D36: IL (Housing) | E36: IT (Transport) | F36: FY Cost
A37: Infirmière (1/2 temps) | B37: 5200 | C37: 3700 | D37: 1250 | E37: 250 | F37: =B37*MAX(0,13-B33) -> 20800
A38: Administratif RH | B38: 10400 | C38: 7400 | D38: 2500 | E38: 500 | F38: =B38*MAX(0,13-$B$33) -> 41600
A39: Administratif Odoo | B39: 10400 | C39: 7400 | D39: 2500 | E39: 500 | F39: =B39*MAX(0,13-$B$33) -> 41600
A40: Administratif MG | B40: 10400 | C40: 7400 | D40: 2500 | E40: 500 | F40: =B40*MAX(0,13-$B$33) -> 41600
A41: Administratif Technicien IT | B41: 10600 | C41: 7600 | D41: 2500 | E41: 500 | F41: =B41*MAX(0,13-$B$33) -> 42400
A42: Administratif Inscription | B42: 10400 | C42: 7400 | D42: 2500 | E42: 500 | F42: =B42*MAX(0,13-$B$33) -> 41600
A43: TOTAL NEW POSITIONS | B43: =SUM(B37:B42) -> 57400 | C43: =SUM(C37:C42) -> 40900 | D43: =SUM(D37:D42) -> 13750 | E43: =SUM(E37:E42) -> 2750 | F43: =SUM(F37:F42) -> 229600
A45: CALCULATED OUTPUTS
A46: Number of New Positions | B46: =COUNTA(A37:A42) -> 6 | C46: Auto-counted from table above
A47: FY Months Active | B47: =MAX(0,13-B33) -> 4 | C47: Months from start month to Dec
A48: Total Monthly Gross (all new) | B48: =B43 -> 57400 | C48: Sum of all new positions monthly gross
...

Sheet Number of class 2025-26
A1: École Française Internationale de Riyad (EFIR) - Classes by Level
A3: Cycle | B3: Level | C3: Number of students | D3: Number of Classes
A4: Maternelle | B4: Petite Section (PS) | C4: 65 | D4: 3
A5: Maternelle | B5: Moyenne Section (MS) | C5: 77 | D5: 4
A6: Maternelle | B6: Grande Section (GS) | C6: 124 | D6: 6
A7: Élémentaire | B7: CP (Cours Préparatoire) | C7: 126 | D7: 5
A8: Élémentaire | B8: CE1 | C8: 118 | D8: 5
A9: Élémentaire | B9: CE2 | C9: 132 | D9: 6
A10: Élémentaire | B10: CM1 | C10: 121 | D10: 5
A11: Élémentaire | B11: CM2 | C11: 121 | D11: 5
A12: Collège | B12: 6ème | C12: 151 | D12: 6
A13: Collège | B13: 5ème | C13: 139 | D13: 6
A14: Collège | B14: 4ème | C14: 120 | D14: 5
A15: Collège | B15: 3ème | C15: 103 | D15: 4
... A18: Lycée | B18: Terminale | C18: 111 | D18: 4
A20: SUMMARY BY CYCLE
A21: Maternelle (Kindergarten) | C21: =SUM(C4:C6) -> 266 | D21: =SUM(D4:D6) -> 13
A22: Élémentaire (Elementary) | C22: =SUM(C7:C11) -> 618 | D22: =SUM(D7:D11) -> 26
A23: Collège (Middle School) | C23: =SUM(C12:C15) -> 513 | D23: =SUM(D12:D15) -> 21
A24: Lycée (High School) | C24: =SUM(C16:C18) -> 356 | D24: =SUM(D16:D18) -> 14
A26: TOTAL CLASSES | C26: =SUM(C21:C24) -> 1753 | D26: =SUM(D21:D24) -> 74
A27: Source: EFIR Structure Pédagogique — https://www.efiriyad.com/structure-pedagogique/

Sheet Teacher Requirements
A1: EFIR — Teacher Staffing Requirements Matrix 2025-26
A2: Purpose: Calculate FTE requirements per teacher profile. Blue cells = editable assumptions.
A4: PARAMETERS
A5: Statutory Hours / Week | C5: Certifié | D5: 18 | E5: h/week | G5: HSA (Supp. Hrs) | H5: 2 | I5: h/week
C6: Prof. des Écoles (PE) | D6: 24 | E6: h/week | G6: Effective Certifié | H6: =$D$5+$H$5 -> 20 | I6: h/week
A7: LV2/LVB Student Split | C7: % Arabic | D7: 0.5 | E7: % German | F7: 0.1 | G7: % Spanish | H7: 0.4 | I7: =IF(D7+F7+H7=1,"✓","≠100%!") -> ✓
G8: MATERNELLE | J8: ÉLÉMENTAIRE | O8: COLLÈGE | S8: LYCÉE | V8: COMPUTATION
A9: Category | B9: Type | C9: Subject / Matière | D9: Teacher Profile | E9: Groups / Class | G9: PS | H9: MS | I9: GS | J9: CP | K9: CE1 | L9: CE2 | M9: CM1 | N9: CM2 | O9: 6ème | P9: 5ème | Q9: 4ème | R9: 3ème | S9: 2nde | T9: 1ère | U9: Tle | V9: Total Hrs/Wk | W9: Statutory | X9: FTE Req. | Y9: Headcount
C10: Number of Classes | G10: 3 | H10: 3 | I10: 5 | J10: 6 | K10: 5 | L10: 6 | M10: 5 | N10: 5 | O10: 6 | P10: 6 | Q10: 5 | R10: 4 | S10: 5 | T10: 5 | U10: 4
A11: BLOCK 1 — MATERNELLE / PRIMAIRE
A12: HOMEROOM
A13: Homeroom | C13: Homeroom Maternelle | D13: Professeur des écoles (PE) | E13: 1 | G13: 24 | H13: 24 | I13: 24 | V13: {=SUMPRODUCT(IF(ISNUMBER(G13:U13),G13:U13,0),$G$10:$U$10)*E13} -> 264 | W13: =IF(ISNUMBER(SEARCH("PE",D13)),$D$6,$D$5) -> 24 | X13: =SUM($G$10:$I$10) -> 11 | Y13: =X13 -> 11
A14: Homeroom | B14: Homeroom | C14: ASEM Maternelle | D14: ASEM | E14: 1 | G14: 24 | H14: 24 | I14: 24 | V14: {=SUMPRODUCT(IF(ISNUMBER(G14:U14),G14:U14,0),$G$10:$U$10)*E14} -> 264 | W14: =$D$6 -> 24 | X14: =SUM($G$10:$I$10) -> 11 | Y14: =X14 -> 11
B15: Homeroom | C15: ⬛ Subtotal Maternelle | V15: =V13+V14 -> 528 | W15: =$D$6 -> 24 | X15: =X13 -> 11 | Y15: =X15 -> 11
A16: Homeroom | C16: Homeroom Élémentaire | D16: Professeur des écoles (PE) | E16: 1 | J16: 24 | K16: 24 | L16: 24 | M16: 24 | N16: 24 | V16: {=SUMPRODUCT(IF(ISNUMBER(G16:U16),G16:U16,0),$G$10:$U$10)*E16} -> 648 | W16: =IF(ISNUMBER(SEARCH("PE",D16)),$D$6,$D$5) -> 24 | X16: =SUM($J$10:$N$10) -> 27 | Y16: =X16 -> 27
B17: Homeroom | C17: ⬛ Subtotal Élémentaire | V17: =V16 -> 648 | W17: =$D$6 -> 24 | X17: =X16 -> 27 | Y17: =X16 -> 27
A18: ARABIC LANGUAGE
A19: ▸ Primaire | C19: Arabe (Arabophone group) | D19: Enseignant Arabe | E19: 1 | G19: 2 | H19: 2 | I19: 2.67 | J19: 2 | K19: 2 | L19: 2 | M19: 2 | N19: 2 | V19: {=SUMPRODUCT(IF(ISNUMBER(G19:U19),G19:U19,0),$G$10:$U$10)*E19} -> 79.35 | W19: =IF(ISNUMBER(SEARCH("PE",D19)),$D$6,$D$5) -> 18 | X19: =IF(V19=0,"",V19/$H$6) -> 3.9675 | Y19: =IF(X19="","",ROUNDUP(X19,0)) -> 4
A20: ▸ Primaire | B20: Core | C20: Arabe (Non-Arabophone group) | D20: Enseignant Arabe | E20: 1 | I20: 2.67 | J20: 2 | K20: 2 | L20: 2 | M20: 2 | N20: 2 | V20: {=SUMPRODUCT(IF(ISNUMBER(G20:U20),G20:U20,0),$G$10:$U$10)*E20} -> 67.35 | W20: =IF(ISNUMBER(SEARCH("PE",D20)),$D$6,$D$5) -> 18 | X20: =IF(V20=0,"",V20/$H$6) -> 3.3675 | Y20: =IF(X20="","",ROUNDUP(X20,0)) -> 4
B21: Core | C21: ⬛ Subtotal Primaire (shared pool) | V21: =V19+V20 -> 146.7 | W21: =$D$5 -> 18 | X21: =IF(V21=0,"",V21/$H$6) -> 7.335 | Y21: =IF(X21="","",ROUNDUP(X21,0)) -> 8
A22: ENGLISH LANGUAGE
A23: ▸ Primaire | C23: Anglais (Primaire) | D23: Enseignant Anglais Primaire | E23: 1 | I23: 0.67 | J23: 1.5 | K23: 1.5 | L23: 1.5 | M23: 1.5 | N23: 1.5 | V23: {=SUMPRODUCT(IF(ISNUMBER(G23:U23),G23:U23,0),$G$10:$U$10)*E23} -> 43.85 | W23: =IF(ISNUMBER(SEARCH("PE",D23)),$D$6,$D$5) -> 18 | X23: =IF(V23=0,"",V23/$H$6) -> 2.1925 | Y23: =IF(X23="","",ROUNDUP(X23,0)) -> 3
B24: Core | C24: ⬛ Subtotal Primaire (shared pool) | V24: =V23 -> 43.85 | W24: =$D$5 -> 18 | X24: =IF(V24=0,"",V24/$H$6) -> 2.1925 | Y24: =IF(X24="","",ROUNDUP(X24,0)) -> 3
A26: BLOCK 2 — COLLÈGE / LYCÉE
A27: CORE SUBJECTS — TRONC COMMUN
A28: FRENCH LANGUAGE
A29: Français | B29: Core | C29: Français | D29: Certifié Lettres | E29: 1 | O29: {=IFERROR(INDEX(Curriculum_Detail!H:H,MATCH(1,(Curriculum_Detail!D:D="6e")*(Curriculum_Detail!F:F="Français")*(Curriculum_Detail!E:E="Core"),0)),"")} -> 4.5 | P29: {=IFERROR(INDEX(Curriculum_Detail!H:H,MATCH(1,(Curriculum_Detail!D:D="5e")*(Curriculum_Detail!F:F="Français")*(Curriculum_Detail!E:E="Core"),0)),"")} -> 4.5 | Q29: {=IFERROR(INDEX(Curriculum_Detail!H:H,MATCH(1,(Curriculum_Detail!D:D="4e")*(Curriculum_Detail!F:F="Français")*(Curriculum_Detail!E:E="Core"),0)),"")} -> 4.5 | R29: {=IFERROR(INDEX(Curriculum_Detail!H:H,MATCH(1,(Curriculum_Detail!D:D="3e")*(Curriculum_Detail!F:F="Français")*(Curriculum_Detail!E:E="Core"),0)),"")} -> 4 | S29: {=IFERROR(INDEX(Curriculum_Detail!H:H,MATCH(1,(Curriculum_Detail!D:D="Seconde")*(Curriculum_Detail!F:F="Français")*(Curriculum_Detail!E:E="Core"),0)),"")} -> 4 | T29: {=IFERROR(INDEX(Curriculum_Detail!H:H,MATCH(1,(Curriculum_Detail!D:D="Première")*(Curriculum_Detail!F:F="Français")*(Curriculum_Detail!E:E="Core"),0)),"")} -> 4 | V29: {=SUMPRODUCT(IF(ISNUMBER(G29:U29),G29:U29,0),$G$10:$U$10)*E29} -> 132.5 | W29: =IF(ISNUMBER(SEARCH("PE",D29)),$D$6,$D$5) -> 18 | X29: =IF(V29=0,"",V29/$H$6) -> 6.625 | Y29: =IF(X29="","",ROUNDUP(X29,0)) -> 7
A30: Français | B30: Core | C30: Philosophie | D30: Certifié Philosophie | E30: 1 | U30: {=IFERROR(INDEX(Curriculum_Detail!H:H,MATCH(1,(Curriculum_Detail!D:D="Terminale")*(Curriculum_Detail!F:F="Philosophie")*(Curriculum_Detail!E:E="Core"),0)),"")} -> 4 | V30: {=SUMPRODUCT(IF(ISNUMBER(G30:U30),G30:U30,0),$G$10:$U$10)*E30} -> 16 | W30: =IF(ISNUMBER(SEARCH("PE",D30)),$D$6,$D$5) -> 18 | X30: =IF(V30=0,"",V30/$H$6) -> 0.8 | Y30: =IF(X30="","",ROUNDUP(X30,0)) -> 1
A31: Français | B31: Specialty | C31: Spé. HLP (1ère) | D31: Certifié Lettres | E31: 1 | T31: {=IFERROR(INDEX(Curriculum_Detail!H:H,MATCH(1,(Curriculum_Detail!D:D="Première")*(Curriculum_Detail!F:F="Humanités, littérature et philosophie")*(Curriculum_Detail!E:E="Specialty"),0)),0)} -> 4 | V31: =T31*E31 -> 4 | W31: =$D$5 -> 18 | X31: =IF(V31=0,"",V31/$H$6) -> 0.2 | Y31: =IF(X31="","",ROUNDUP(X31,0)) -> 1
A32: Français | B32: Specialty | C32: Spé. HLP (Tle) | D32: Certifié Philosophie | F32: 1 | U32: {=IFERROR(INDEX(Curriculum_Detail!H:H,MATCH(1,(Curriculum_Detail!D:D="Terminale")*(Curriculum_Detail!F:F="Humanités, littérature et philosophie")*(Curriculum_Detail!E:E="Specialty"),0)),0)} -> 6 | V32: =U32*F32 -> 6 | W32: =$D$5 -> 18 | X32: =IF(V32=0,"",V32/$H$6) -> 0.3 | Y32: =IF(X32="","",ROUNDUP(X32,0)) -> 1
A33: MATHEMATICS
A34: Maths | B34: Core | C34: Mathématiques | D34: Certifié Maths | E34: 1 | O34: {=IFERROR(INDEX(Curriculum_Detail!H:H,MATCH(1,(Curriculum_Detail!D:D="6e")*(Curriculum_Detail!F:F="Mathématiques")*(Curriculum_Detail!E:E="Core"),0)),"")} -> 4.5 | P34: {=IFERROR(INDEX(Curriculum_Detail!H:H,MATCH(1,(Curriculum_Detail!D:D="5e")*(Curriculum_Detail!F:F="Mathématiques")*(Curriculum_Detail!E:E="Core"),0)),"")} -> 3.5 | Q34: {=IFERROR(INDEX(Curriculum_Detail!H:H,MATCH(1,(Curriculum_Detail!D:D="4e")*(Curriculum_Detail!F:F="Mathématiques")*(Curriculum_Detail!E:E="Core"),0)),"")} -> 3.5 | R34: {=IFERROR(INDEX(Curriculum_Detail!H:H,MATCH(1,(Curriculum_Detail!D:D="3e")*(Curriculum_Detail!F:F="Mathématiques")*(Curriculum_Detail!E:E="Core"),0)),"")} -> 3.5 | S34: {=IFERROR(INDEX(Curriculum_Detail!H:H,MATCH(1,(Curriculum_Detail!D:D="Seconde")*(Curriculum_Detail!F:F="Mathématiques")*(Curriculum_Detail!E:E="Core"),0)),"")} -> 4 | V34: {=SUMPRODUCT(IF(ISNUMBER(G34:U34),G34:U34,0),$G$10:$U$10)*E34} -> 99.5 | W34: =IF(ISNUMBER(SEARCH("PE",D34)),$D$6,$D$5) -> 18 | X34: =IF(V34=0,"",V34/$H$6) -> 4.975 | Y34: =IF(X34="","",ROUNDUP(X34,0)) -> 5
A35: Maths | B35: Core | C35: Soutien / approfondissement | D35: Certifié Maths | E35: 1 | O35: {=IFERROR(INDEX(Curriculum_Detail!H:H,MATCH(1,(Curriculum_Detail!D:D="6e")*(Curriculum_Detail!F:F="Soutien / approfondissement en français ou mathématiques")*(Curriculum_Detail!E:E="Core"),0)),"")} -> 1 | V35: {=SUMPRODUCT(IF(ISNUMBER(G35:U35),G35:U35,0),$G$10:$U$10)*E35} -> 6 | W35: =IF(ISNUMBER(SEARCH("PE",D35)),$D$6,$D$5) -> 18 | X35: =IF(V35=0,"",V35/$H$6) -> 0.3 | Y35: =IF(X35="","",ROUNDUP(X35,0)) -> 1
A36: Maths | B36: Specialty | C36: Spé. Mathématiques | D36: Certifié Maths | E36: 2 | F36: 2 | T36: {=IFERROR(INDEX(Curriculum_Detail!H:H,MATCH(1,(Curriculum_Detail!D:D="Première")*(Curriculum_Detail!F:F="Mathématiques")*(Curriculum_Detail!E:E="Specialty"),0)),0)} -> 4 | U36: {=IFERROR(INDEX(Curriculum_Detail!H:H,MATCH(1,(Curriculum_Detail!D:D="Terminale")*(Curriculum_Detail!F:F="Mathématiques")*(Curriculum_Detail!E:E="Specialty"),0)),0)} -> 6 | V36: =T36*E36+U36*F36 -> 20 | W36: =$D$5 -> 18 | X36: =IF(V36=0,"",V36/$H$6) -> 1 | Y36: =IF(X36="","",ROUNDUP(X36,0)) -> 1
A37: Maths | B37: Option | C37: Maths Complémentaires (opt.) | D37: Certifié Maths | E37: 0 | F37: 4 | T37: 0 | U37: 3 | V37: =T37*E37+U37*F37 -> 12 | W37: =$D$5 -> 18 | X37: =IF(V37=0,"",V37/$H$6) -> 0.6 | Y37: =IF(X37="","",ROUNDUP(X37,0)) -> 1
A38: Maths | B38: Option | C38: Maths Expertes (opt.) | D38: Certifié Maths | E38: 0 | F38: 2 | T38: 0 | U38: 3 | V38: =T38*E38+U38*F38 -> 6 | W38: =$D$5 -> 18 | X38: =IF(V38=0,"",V38/$H$6) -> 0.3 | Y38: =IF(X38="","",ROUNDUP(X38,0)) -> 1
A39: HISTORY, GEOGRAPHY & CIVICS
A40: HG-EMC | B40: Core | C40: Histoire-Géographie | D40: Certifié Hist-Géo | E40: 1 | O40: {=IFERROR(INDEX(Curriculum_Detail!H:H,MATCH(1,(Curriculum_Detail!D:D="6e")*(Curriculum_Detail!F:F="Histoire-géographie")*(Curriculum_Detail!E:E="Core"),0)),"")} -> 2.5 | P40: {=IFERROR(INDEX(Curriculum_Detail!H:H,MATCH(1,(Curriculum_Detail!D:D="5e")*(Curriculum_Detail!F:F="Histoire-géographie")*(Curriculum_Detail!E:E="Core"),0)),"")} -> 2.5 | Q40: {=IFERROR(INDEX(Curriculum_Detail!H:H,MATCH(1,(Curriculum_Detail!D:D="4e")*(Curriculum_Detail!F:F="Histoire-géographie")*(Curriculum_Detail!E:E="Core"),0)),"")} -> 2.5 | R40: {=IFERROR(INDEX(Curriculum_Detail!H:H,MATCH(1,(Curriculum_Detail!D:D="3e")*(Curriculum_Detail!F:F="Histoire-géographie")*(Curriculum_Detail!E:E="Core"),0)),"")} -> 3 | S40: {=IFERROR(INDEX(Curriculum_Detail!H:H,MATCH(1,(Curriculum_Detail!D:D="Seconde")*(Curriculum_Detail!F:F="Histoire-géographie")*(Curriculum_Detail!E:E="Core"),0)),"")} -> 3 | T40: {=IFERROR(INDEX(Curriculum_Detail!H:H,MATCH(1,(Curriculum_Detail!D:D="Première")*(Curriculum_Detail!F:F="Histoire-géographie")*(Curriculum_Detail!E:E="Core"),0)),"")} -> 3 | U40: {=IFERROR(INDEX(Curriculum_Detail!H:H,MATCH(1,(Curriculum_Detail!D:D="Terminale")*(Curriculum_Detail!F:F="Histoire-géographie")*(Curriculum_Detail!E:E="Core"),0)),"")} -> 3 | V40: {=SUMPRODUCT(IF(ISNUMBER(G40:U40),G40:U40,0),$G$10:$U$10)*E40} -> 96.5 | W40: =IF(ISNUMBER(SEARCH("PE",D40)),$D$6,$D$5) -> 18 | X40: =IF(V40=0,"",V40/$H$6) -> 4.825 | Y40: =IF(X40="","",ROUNDUP(X40,0)) -> 5
A41: HG-EMC | B41: Core | C41: Enseignement moral et civique | D41: Certifié EMC | E41: 1 | O41: {=IFERROR(INDEX(Curriculum_Detail!H:H,MATCH(1,(Curriculum_Detail!D:D="6e")*(Curriculum_Detail!F:F="Enseignement moral et civique")*(Curriculum_Detail!E:E="Core"),0)),"")} -> 0.5 | P41: {=IFERROR(INDEX(Curriculum_Detail!H:H,MATCH(1,(Curriculum_Detail!D:D="5e")*(Curriculum_Detail!F:F="Enseignement moral et civique")*(Curriculum_Detail!E:E="Core"),0)),"")} -> 0.5 | Q41: {=IFERROR(INDEX(Curriculum_Detail!H:H,MATCH(1,(Curriculum_Detail!D:D="4e")*(Curriculum_Detail!F:F="Enseignement moral et civique")*(Curriculum_Detail!E:E="Core"),0)),"")} -> 0.5 | R41: {=IFERROR(INDEX(Curriculum_Detail!H:H,MATCH(1,(Curriculum_Detail!D:D="3e")*(Curriculum_Detail!F:F="Enseignement moral et civique")*(Curriculum_Detail!E:E="Core"),0)),"")} -> 0.5 | S41: {=IFERROR(INDEX(Curriculum_Detail!H:H,MATCH(1,(Curriculum_Detail!D:D="Seconde")*(Curriculum_Detail!F:F="Enseignement moral et civique")*(Curriculum_Detail!E:E="Core"),0)),"")} -> 0.5 | T41: {=IFERROR(INDEX(Curriculum_Detail!H:H,MATCH(1,(Curriculum_Detail!D:D="Première")*(Curriculum_Detail!F:F="Enseignement moral et civique")*(Curriculum_Detail!E:E="Core"),0)),"")} -> 0.5 | U41: {=IFERROR(INDEX(Curriculum_Detail!H:H,MATCH(1,(Curriculum_Detail!D:D="Terminale")*(Curriculum_Detail!F:F="Enseignement moral et civique")*(Curriculum_Detail!E:E="Core"),0)),"")} -> 0.5 | V41: {=SUMPRODUCT(IF(ISNUMBER(G41:U41),G41:U41,0),$G$10:$U$10)*E41} -> 17.5 | W41: =IF(ISNUMBER(SEARCH("PE",D41)),$D$6,$D$5) -> 18 | X41: =IF(V41=0,"",V41/$H$6) -> 0.875 | Y41: =IF(X41="","",ROUNDUP(X41,0)) -> 1
A42: HG-EMC | B42: Specialty | C42: Spé. HGGSP | D42: Certifié Hist-Géo | E42: 2 | F42: 1 | T42: {=IFERROR(INDEX(Curriculum_Detail!H:H,MATCH(1,(Curriculum_Detail!D:D="Première")*(Curriculum_Detail!F:F="Histoire-géographie, géopolitique et sciences politiques")*(Curriculum_Detail!E:E="Specialty"),0)),0)} -> 4 | U42: {=IFERROR(INDEX(Curriculum_Detail!H:H,MATCH(1,(Curriculum_Detail!D:D="Terminale")*(Curriculum_Detail!F:F="Histoire-géographie, géopolitique et sciences politiques")*(Curriculum_Detail!E:E="Specialty"),0)),0)} -> 6 | V42: =T42*E42+U42*F42 -> 14 | W42: =$D$5 -> 18 | X42: =IF(V42=0,"",V42/$H$6) -> 0.7 | Y42: =IF(X42="","",ROUNDUP(X42,0)) -> 1
...

Sheet Curriculum_Detail
A1: Sort Order | B1: Cycle | C1: Stage | D1: Level | E1: Track | F1: Subject | G1: Hour Status | H1: Weekly Hours | I1: Annual Hours | J1: Planning Groups | K1: Delivered Hours/Wk | L1: Teacher Load Hrs/Wk | M1: Required FTE | N1: Avg Cost per FTE | O1: Est Annual Cost | P1: Source URL | Q1: Notes
A2: 300 | B2: Cycle 3 | C2: Collège | D2: 6e | E2: Core | F2: Français | G2: Official | H2: 4.5 | I2: 162 | J2: 6 | K2: 27 | L2: 18 | M2: 1.5 | N2: 0 | O2: 0 | P2: https://www.education.gouv.fr/les-horaires-par-cycle-au-college-9884
A3: 301 | B3: Cycle 3 | C3: Collège | D3: 6e | E3: Core | F3: Mathématiques | G3: Official | H3: 4.5 | I3: 162 | J3: 6 | K3: 27 | L3: 18 | M3: 1.5 | N3: 0 | O3: 0 | P3: https://www.education.gouv.fr/les-horaires-par-cycle-au-college-9884
A4: 302 | B4: Cycle 3 | C4: Collège | D4: 6e | E4: Core | F4: Histoire-géographie | G4: Derived from official grouped block | H4: 2.5 | I4: 90 | J4: 6 | K4: 15 | L4: 18 | M4: 0.83333333 | N4: 0 | O4: 0 | P4: https://www.education.gouv.fr/les-horaires-par-cycle-au-college-9884 | Q4: Derived from official 3 h grouped block 'Histoire-géographie + EMC', of which EMC is 30 minutes.
A5: 303 | B5: Cycle 3 | C5: Collège | D5: 6e | E5: Core | F5: Enseignement moral et civique | G5: Derived from official grouped block | H5: 0.5 | I5: 18 | J5: 6 | K5: 3 | L5: 18 | M5: 0.16666667 | N5: 0 | O5: 0 | P5: https://www.education.gouv.fr/les-horaires-par-cycle-au-college-9884 | Q5: Derived from official 3 h grouped block 'Histoire-géographie + EMC', of which EMC is 30 minutes.
A6: 304 | B6: Cycle 3 | C6: Collège | D6: 6e | E6: Core | F6: Langue vivante 1 | G6: Official | H6: 4 | I6: 144 | J6: 6 | K6: 24 | L6: 18 | M6: 1.3333333 | N6: 0 | O6: 0 | P6: https://www.education.gouv.fr/les-horaires-par-cycle-au-college-9884
A7: 305 | B7: Cycle 3 | C7: Collège | D7: 6e | E7: Core | F7: Sciences de la vie et de la Terre + Physique-chimie | G7: Official grouped sciences block | H7: 3 | I7: 108 | J7: 6 | K7: 18 | L7: 18 | M7: 1 | N7: 0 | O7: 0 | P7: https://www.education.gouv.fr/les-horaires-par-cycle-au-college-9884 | Q7: Current official 6e timetable groups the sciences block at 3 h/week.
A8: 306 | B8: Cycle 3 | C8: Collège | D8: 6e | E8: Core | F8: Éducation physique et sportive | G8: Official | H8: 4 | I8: 144 | J8: 6 | K8: 24 | L8: 18 | M8: 1.3333333 | N8: 0 | O8: 0 | P8: https://www.education.gouv.fr/les-horaires-par-cycle-au-college-9884
A9: 307 | B9: Cycle 3 | C9: Collège | D9: 6e | E9: Core | F9: Arts plastiques | G9: Official | H9: 1 | I9: 36 | J9: 6 | K9: 6 | L9: 18 | M9: 0.33333333 | N9: 0 | O9: 0 | P9: https://www.education.gouv.fr/les-horaires-par-cycle-au-college-9884
A10: 308 | B10: Cycle 3 | C10: Collège | D10: 6e | E10: Core | F10: Éducation musicale | G10: Official | H10: 1 | I10: 36 | J10: 6 | K10: 6 | L10: 18 | M10: 0.33333333 | N10: 0 | O10: 0 | P10: https://www.education.gouv.fr/les-horaires-par-cycle-au-college-9884
A11: 309 | B11: Cycle 3 | C11: Collège | D11: 6e | E11: Core | F11: Soutien / approfondissement en français ou mathématiques | G11: Official | H11: 1 | I11: 36 | J11: 6 | K11: 6 | L11: 18 | M11: 0.33333333 | N11: 0 | O11: 0 | P11: https://www.education.gouv.fr/les-horaires-par-cycle-au-college-9884
A12: 400 | B12: Cycle 4 | C12: Collège | D12: 5e | E12: Core | F12: Français | G12: Official | H12: 4.5 | I12: 162 | J12: 6 | K12: 27 | L12: 18 | M12: 1.5 | N12: 0 | O12: 0 | P12: https://www.education.gouv.fr/les-horaires-par-cycle-au-college-9884
A13: 401 | B13: Cycle 4 | C13: Collège | D13: 5e | E13: Core | F13: Mathématiques | G13: Official | H13: 3.5 | I13: 126 | J13: 6 | K13: 21 | L13: 18 | M13: 1.1666667 | N13: 0 | O13: 0 | P13: https://www.education.gouv.fr/les-horaires-par-cycle-au-college-9884
A14: 402 | B14: Cycle 4 | C14: Collège | D14: 5e | E14: Core | F14: Histoire-géographie | G14: Derived from official grouped block | H14: 2.5 | I14: 90 | J14: 6 | K14: 15 | L14: 18 | M14: 0.83333333 | N14: 0 | O14: 0 | P14: https://www.education.gouv.fr/les-horaires-par-cycle-au-college-9884 | Q14: Derived from official grouped block 'Histoire-géographie + EMC' with EMC = 30 minutes.
A15: 403 | B15: Cycle 4 | C15: Collège | D15: 5e | E15: Core | F15: Enseignement moral et civique | G15: Derived from official grouped block | H15: 0.5 | I15: 18 | J15: 6 | K15: 3 | L15: 18 | M15: 0.16666667 | N15: 0 | O15: 0 | P15: https://www.education.gouv.fr/les-horaires-par-cycle-au-college-9884 | Q15: Derived from official grouped block 'Histoire-géographie + EMC' with EMC = 30 minutes.
A16: 404 | B16: Cycle 4 | C16: Collège | D16: 5e | E16: Core | F16: Langue vivante 1 | G16: Official | H16: 3 | I16: 108 | J16: 6 | K16: 18 | L16: 18 | M16: 1 | N16: 0 | O16: 0 | P16: https://www.education.gouv.fr/les-horaires-par-cycle-au-college-9884
A17: 405 | B17: Cycle 4 | C17: Collège | D17: 5e | E17: Core | F17: Langue vivante 2 | G17: Official | H17: 2.5 | I17: 90 | J17: 6 | K17: 15 | L17: 18 | M17: 0.83333333 | N17: 0 | O17: 0 | P17: https://www.education.gouv.fr/les-horaires-par-cycle-au-college-9884
A18: 406 | B18: Cycle 4 | C18: Collège | D18: 5e | E18: Core | F18: Sciences de la vie et de la Terre | G18: Official | H18: 1.5 | I18: 54 | J18: 6 | K18: 9 | L18: 18 | M18: 0.5 | N18: 0 | O18: 0 | P18: https://www.education.gouv.fr/les-horaires-par-cycle-au-college-9884
A19: 407 | B19: Cycle 4 | C19: Collège | D19: 5e | E19: Core | F19: Physique-chimie | G19: Official | H19: 1.5 | I19: 54 | J19: 6 | K19: 9 | L19: 18 | M19: 0.5 | N19: 0 | O19: 0 | P19: https://www.education.gouv.fr/les-horaires-par-cycle-au-college-9884
A20: 408 | B20: Cycle 4 | C20: Collège | D20: 5e | E20: Core | F20: Technologie | G20: Official | H20: 1.5 | I20: 54 | J20: 6 | K20: 9 | L20: 18 | M20: 0.5 | N20: 0 | O20: 0 | P20: https://www.education.gouv.fr/les-horaires-par-cycle-au-college-9884
A21: 409 | B21: Cycle 4 | C21: Collège | D21: 5e | E21: Core | F21: Éducation physique et sportive | G21: Official | H21: 3 | I21: 108 | J21: 6 | K21: 18 | L21: 18 | M21: 1 | N21: 0 | O21: 0 | P21: https://www.education.gouv.fr/les-horaires-par-cycle-au-college-9884
A22: 410 | B22: Cycle 4 | C22: Collège | D22: 5e | E22: Core | F22: Arts plastiques | G22: Official | H22: 1 | I22: 36 | J22: 6 | K22: 6 | L22: 18 | M22: 0.33333333 | N22: 0 | O22: 0 | P22: https://www.education.gouv.fr/les-horaires-par-cycle-au-college-9884
A23: 411 | B23: Cycle 4 | C23: Collège | D23: 5e | E23: Core | F23: Éducation musicale | G23: Official | H23: 1 | I23: 36 | J23: 6 | K23: 6 | L23: 18 | M23: 0.33333333 | N23: 0 | O23: 0 | P23: https://www.education.gouv.fr/les-horaires-par-cycle-au-college-9884
A24: 412 | B24: Cycle 4 | C24: Collège | D24: 4e | E24: Core | F24: Français | G24: Official | H24: 4.5 | I24: 162 | J24: 5 | K24: 22.5 | L24: 18 | M24: 1.25 | N24: 0 | O24: 0 | P24: https://www.education.gouv.fr/les-horaires-par-cycle-au-college-9884
A25: 413 | B25: Cycle 4 | C25: Collège | D25: 4e | E25: Core | F25: Mathématiques | G25: Official | H25: 3.5 | I25: 126 | J25: 5 | K25: 17.5 | L25: 18 | M25: 0.97222222 | N25: 0 | O25: 0 | P25: https://www.education.gouv.fr/les-horaires-par-cycle-au-college-9884
A26: 414 | B26: Cycle 4 | C26: Collège | D26: 4e | E26: Core | F26: Histoire-géographie | G26: Derived from official grouped block | H26: 2.5 | I26: 90 | J26: 5 | K26: 12.5 | L26: 18 | M26: 0.69444444 | N26: 0 | O26: 0 | P26: https://www.education.gouv.fr/les-horaires-par-cycle-au-college-9884 | Q26: Derived from official grouped block 'Histoire-géographie + EMC' with EMC = 30 minutes.
A27: 415 | B27: Cycle 4 | C27: Collège | D27: 4e | E27: Core | F27: Enseignement moral et civique | G27: Derived from official grouped block | H27: 0.5 | I27: 18 | J27: 5 | K27: 2.5 | L27: 18 | M27: 0.13888889 | N27: 0 | O27: 0 | P27: https://www.education.gouv.fr/les-horaires-par-cycle-au-college-9884 | Q27: Derived from official grouped block 'Histoire-géographie + EMC' with EMC = 30 minutes.
A28: 416 | B28: Cycle 4 | C28: Collège | D28: 4e | E28: Core | F28: Langue vivante 1 | G28: Official | H28: 3 | I28: 108 | J28: 5 | K28: 15 | L28: 18 | M28: 0.83333333 | N28: 0 | O28: 0 | P28: https://www.education.gouv.fr/les-horaires-par-cycle-au-college-9884
A29: 417 | B29: Cycle 4 | C29: Collège | D29: 4e | E29: Core | F29: Langue vivante 2 | G29: Official | H29: 2.5 | I29: 90 | J29: 5 | K29: 12.5 | L29: 18 | M29: 0.69444444 | N29: 0 | O29: 0 | P29: https://www.education.gouv.fr/les-horaires-par-cycle-au-college-9884
A30: 418 | B30: Cycle 4 | C30: Collège | D30: 4e | E30: Core | F30: Sciences de la vie et de la Terre | G30: Official | H30: 1.5 | I30: 54 | J30: 5 | K30: 7.5 | L30: 18 | M30: 0.41666667 | N30: 0 | O30: 0 | P30: https://www.education.gouv.fr/les-horaires-par-cycle-au-college-9884
A31: 419 | B31: Cycle 4 | C31: Collège | D31: 4e | E31: Core | F31: Physique-chimie | G31: Official | H31: 1.5 | I31: 54 | J31: 5 | K31: 7.5 | L31: 18 | M31: 0.41666667 | N31: 0 | O31: 0 | P31: https://www.education.gouv.fr/les-horaires-par-cycle-au-college-9884
A32: 420 | B32: Cycle 4 | C32: Collège | D32: 4e | E32: Core | F32: Technologie | G32: Official | H32: 1.5 | I32: 54 | J32: 5 | K32: 7.5 | L32: 18 | M32: 0.41666667 | N32: 0 | O32: 0 | P32: https://www.education.gouv.fr/les-horaires-par-cycle-au-college-9884
A33: 421 | B33: Cycle 4 | C33: Collège | D33: 4e | E33: Core | F33: Éducation physique et sportive | G33: Official | H33: 3 | I33: 108 | J33: 5 | K33: 15 | L33: 18 | M33: 0.83333333 | N33: 0 | O33: 0 | P33: https://www.education.gouv.fr/les-horaires-par-cycle-au-college-9884
A34: 422 | B34: Cycle 4 | C34: Collège | D34: 4e | E34: Core | F34: Arts plastiques | G34: Official | H34: 1 | I34: 36 | J34: 5 | K34: 5 | L34: 18 | M34: 0.27777778 | N34: 0 | O34: 0 | P34: https://www.education.gouv.fr/les-horaires-par-cycle-au-college-9884
A35: 423 | B35: Cycle 4 | C35: Collège | D35: 4e | E35: Core | F35: Éducation musicale | G35: Official | H35: 1 | I35: 36 | J35: 5 | K35: 5 | L35: 18 | M35: 0.27777778 | N35: 0 | O35: 0 | P35: https://www.education.gouv.fr/les-horaires-par-cycle-au-college-9884
A36: 424 | B36: Cycle 4 | C36: Collège | D36: 3e | E36: Core | F36: Français | G36: Official | H36: 4 | I36: 144 | J36: 4 | K36: 16 | L36: 18 | M36: 0.88888889 | N36: 0 | O36: 0 | P36: https://www.education.gouv.fr/les-horaires-par-cycle-au-college-9884
A37: 425 | B37: Cycle 4 | C37: Collège | D37: 3e | E37: Core | F37: Mathématiques | G37: Official | H37: 3.5 | I37: 126 | J37: 4 | K37: 14 | L37: 18 | M37: 0.77777778 | N37: 0 | O37: 0 | P37: https://www.education.gouv.fr/les-horaires-par-cycle-au-college-9884
A38: 426 | B38: Cycle 4 | C38: Collège | D38: 3e | E38: Core | F38: Histoire-géographie | G38: Derived from official grouped block | H38: 3 | I38: 108 | J38: 4 | K38: 12 | L38: 18 | M38: 0.66666667 | N38: 0 | O38: 0 | P38: https://www.education.gouv.fr/les-horaires-par-cycle-au-college-9884 | Q38: Derived from official grouped block 'Histoire-géographie + EMC' with EMC = 30 minutes.
A39: 427 | B39: Cycle 4 | C39: Collège | D39: 3e | E39: Core | F39: Enseignement moral et civique | G39: Derived from official grouped block | H39: 0.5 | I39: 18 | J39: 4 | K39: 2 | L39: 18 | M39: 0.11111111 | N39: 0 | O39: 0 | P39: https://www.education.gouv.fr/les-horaires-par-cycle-au-college-9884 | Q39: Derived from official grouped block 'Histoire-géographie + EMC' with EMC = 30 minutes.
A40: 428 | B40: Cycle 4 | C40: Collège | D40: 3e | E40: Core | F40: Langue vivante 1 | G40: Official | H40: 3 | I40: 108 | J40: 4 | K40: 12 | L40: 18 | M40: 0.66666667 | N40: 0 | O40: 0 | P40: https://www.education.gouv.fr/les-horaires-par-cycle-au-college-9884
...

Sheet Master Data
A1: EFIR — Staff Master Data FY2025-2026 | Y1: Calc Engine — Per-Employee Monthly Calculations (auto-generated)
A2: Active: 186 (160 Local + 26 AEFE) | Departed: 7 | Total rows: 193 | Currency: SAR | Updated: Feb 2026 payroll reconciliation | Y2: Do not edit — all formulas driven from Master Data columns & Assumptions
Y3: =DATE(Assumptions!$B$4,1,28) -> 46050 | AD3: =DATE(Assumptions!$B$4,2,28) -> 46081 | AI3: =DATE(Assumptions!$B$4,3,28) -> 46109 | AN3: =DATE(Assumptions!$B$4,4,28) -> 46140 | AS3: =DATE(Assumptions!$B$4,5,28) -> 46170 | AX3: =DATE(Assumptions!$B$4,6,28) -> 46201 | BC3: =DATE(Assumptions!$B$4,7,28) -> 46231 | BH3: =DATE(Assumptions!$B$4,8,28) -> 46262 | BM3: =DATE(Assumptions!$B$4,9,28) -> 46293 | BR3: =DATE(Assumptions!$B$4,10,28) -> 46323 | BW3: =DATE(Assumptions!$B$4,11,28) -> 46354 | CB3: =DATE(Assumptions!$B$4,12,28) -> 46384 | CG3: FY2026 Total
A4: # | B4: Last Name | C4: First Name | D4: Contract Type | E4: Contract Status | F4: Function / Role | G4: Department | H4: Subject / Discipline | I4: Teacher / Non-Teacher | J4: Teacher Profile | K4: Level | L4: Status | M4: Nationality | N4: Joining Date | O4: YoS | P4: Base Salary (SAR) | Q4: Housing (IL) | R4: Transport (IT) | S4: Resp. Premium | T4: HSA (10m) | U4: Monthly Gross (SAR) | V4: Hourly % | W4: Payment Method | X4: Increase | Y4: Eff. Base | Z4: Mth Gross | AA4: Cumul EoS | AB4: GOSI | AC4: Ajeer | AD4: Eff. Base | AE4: Mth Gross | AF4: Cumul EoS | AG4: GOSI | AH4: Ajeer | AI4: Eff. Base | AJ4: Mth Gross | AK4: Cumul EoS | AL4: GOSI | AM4: Ajeer | AN4: Eff. Base | AO4: Mth Gross | AP4: Cumul EoS | AQ4: GOSI | AR4: Ajeer | AS4: Eff. Base | AT4: Mth Gross | AU4: Cumul EoS | AV4: GOSI | AW4: Ajeer | AX4: Eff. Base | AY4: Mth Gross | AZ4: Cumul EoS | BA4: GOSI | BB4: Ajeer | BC4: Eff. Base | BD4: Mth Gross | BE4: Cumul EoS | BF4: GOSI | BG4: Ajeer | BH4: Eff. Base | BI4: Mth Gross | BJ4: Cumul EoS | BK4: GOSI | BL4: Ajeer | BM4: Eff. Base | BN4: Mth Gross | BO4: Cumul EoS | BP4: GOSI | BQ4: Ajeer | BR4: Eff. Base | BS4: Mth Gross | BT4: Cumul EoS | BU4: GOSI | BV4: Ajeer | BW4: Eff. Base | BX4: Mth Gross | BY4: Cumul EoS | BZ4: GOSI | CA4: Ajeer | CB4: Eff. Base | CC4: Mth Gross | CD4: Cumul EoS | CE4: GOSI | CF4: Ajeer | CG4: FY Base | CH4: FY Gross | CI4: FY EoS Prov | CJ4: FY GOSI | CK4: FY Ajeer
A5: 1 | B5: ABED | C5: Ghina | D5: Contrat Local | E5: Permanent | F5: Assistant(e) d'éducation | G5: Vie Scolaire & Support | H5: Vie scolaire | I5: Non-Teacher | K5: Vie Scolaire & Support | L5: Existing | M5: =IF(D5="Titulaire EN","",IF(OR(B5="AL OSSAIMI AL OTAIBI",B5="ALAMRI"),"Saudi","Non-Saudi")) -> Non-Saudi | N5: 45170 | O5: 3.3 | P5: 7400 | Q5: 2500 | R5: 500 | U5: 10400 | V5: 1 | W5: Liquide | X5: 200 | Y5: =IF(AND($D5="Contrat Local",$N5<>""),$P5*$V5,0) -> 7400 | Z5: =IF(Y5>0,Y5+($Q5+$R5+IF(ISNUMBER($S5),$S5,0)+IF(ISNUMBER($T5),$T5,0))*$V5,0) -> 10400 | AA5: =IF(AND(Z5>0,$N5<>""),IF((DATE(Assumptions!$B$4,1,28)-$N5)/365.25<=Assumptions!$B$20,(DATE(Assumptions!$B$4,1,28)-$N5)/365.25*Assumptions!$B$18*Z5,(Assumptions!$B$20*Assumptions!$B$18+((DATE(Assumptions!$B$4,1,28)-$N5)/365.25-Assumptions!$B$20)*Assumptions!$B$19)*Z5),0) -> 12528.405 | AB5: =IF(Y5>0,IF($M5="Saudi",MIN(Y5+$Q5*$V5,Assumptions!$B$14)*Assumptions!$B$12,MIN(Y5+$Q5*$V5,Assumptions!$B$14)*Assumptions!$B$13),0) -> 0 | AC5: =IF(AND(Y5>0,$M5="Non-Saudi"),Assumptions!$B$25,0) -> 910.41667 | AD5: =IF(AND($D5="Contrat Local",$N5<>""),$P5*$V5,0) -> 7400 | AE5: =IF(AD5>0,AD5+($Q5+$R5+IF(ISNUMBER($S5),$S5,0)+IF(ISNUMBER($T5),$T5,0))*$V5,0) -> 10400 | AF5: =IF(AND(AE5>0,$N5<>""),IF((DATE(Assumptions!$B$4,2,28)-$N5)/365.25<=Assumptions!$B$20,(DATE(Assumptions!$B$4,2,28)-$N5)/365.25*Assumptions!$B$18*AE5,(Assumptions!$B$20*Assumptions!$B$18+((DATE(Assumptions!$B$4,2,28)-$N5)/365.25-Assumptions!$B$20)*Assumptions!$B$19)*AE5),0) -> 12969.747 | AG5: =IF(AD5>0,IF($M5="Saudi",MIN(AD5+$Q5*$V5,Assumptions!$B$14)*Assumptions!$B$12,MIN(AD5+$Q5*$V5,Assumptions!$B$14)*Assumptions!$B$13),0) -> 0 | AH5: =IF(AND(AD5>0,$M5="Non-Saudi"),Assumptions!$B$25,0) -> 910.41667 | AI5: =IF(AND($D5="Contrat Local",$N5<>""),$P5*$V5,0) -> 7400 | AJ5: =IF(AI5>0,AI5+($Q5+$R5+IF(ISNUMBER($S5),$S5,0)+IF(ISNUMBER($T5),$T5,0))*$V5,0) -> 10400 | AK5: =IF(AND(AJ5>0,$N5<>""),IF((DATE(Assumptions!$B$4,3,28)-$N5)/365.25<=Assumptions!$B$20,(DATE(Assumptions!$B$4,3,28)-$N5)/365.25*Assumptions!$B$18*AJ5,(Assumptions!$B$20*Assumptions!$B$18+((DATE(Assumptions!$B$4,3,28)-$N5)/365.25-Assumptions!$B$20)*Assumptions!$B$19)*AJ5),0) -> 13368.378 | AL5: =IF(AI5>0,IF($M5="Saudi",MIN(AI5+$Q5*$V5,Assumptions!$B$14)*Assumptions!$B$12,MIN(AI5+$Q5*$V5,Assumptions!$B$14)*Assumptions!$B$13),0) -> 0 | AM5: =IF(AND(AI5>0,$M5="Non-Saudi"),Assumptions!$B$25,0) -> 910.41667 | AN5: =IF(AND($D5="Contrat Local",$N5<>""),$P5*$V5,0) -> 7400 | AO5: =IF(AN5>0,AN5+($Q5+$R5+IF(ISNUMBER($S5),$S5,0)+IF(ISNUMBER($T5),$T5,0))*$V5,0) -> 10400 | AP5: =IF(AND(AO5>0,$N5<>""),IF((DATE(Assumptions!$B$4,4,28)-$N5)/365.25<=Assumptions!$B$20,(DATE(Assumptions!$B$4,4,28)-$N5)/365.25*Assumptions!$B$18*AO5,(Assumptions!$B$20*Assumptions!$B$18+((DATE(Assumptions!$B$4,4,28)-$N5)/365.25-Assumptions!$B$20)*Assumptions!$B$19)*AO5),0) -> 13809.719 | AQ5: =IF(AN5>0,IF($M5="Saudi",MIN(AN5+$Q5*$V5,Assumptions!$B$14)*Assumptions!$B$12,MIN(AN5+$Q5*$V5,Assumptions!$B$14)*Assumptions!$B$13),0) -> 0 | AR5: =IF(AND(AN5>0,$M5="Non-Saudi"),Assumptions!$B$25,0) -> 910.41667 | AS5: =IF(AND($D5="Contrat Local",$N5<>""),$P5*$V5,0) -> 7400 | AT5: =IF(AS5>0,AS5+($Q5+$R5+IF(ISNUMBER($S5),$S5,0)+IF(ISNUMBER($T5),$T5,0))*$V5,0) -> 10400 | AU5: =IF(AND(AT5>0,$N5<>""),IF((DATE(Assumptions!$B$4,5,28)-$N5)/365.25<=Assumptions!$B$20,(DATE(Assumptions!$B$4,5,28)-$N5)/365.25*Assumptions!$B$18*AT5,(Assumptions!$B$20*Assumptions!$B$18+((DATE(Assumptions!$B$4,5,28)-$N5)/365.25-Assumptions!$B$20)*Assumptions!$B$19)*AT5),0) -> 14236.824 | AV5: =IF(AS5>0,IF($M5="Saudi",MIN(AS5+$Q5*$V5,Assumptions!$B$14)*Assumptions!$B$12,MIN(AS5+$Q5*$V5,Assumptions!$B$14)*Assumptions!$B$13),0) -> 0 | AW5: =IF(AND(AS5>0,$M5="Non-Saudi"),Assumptions!$B$25,0) -> 910.41667 | AX5: =IF(AND($D5="Contrat Local",$N5<>""),$P5*$V5,0) -> 7400 | AY5: =IF(AX5>0,AX5+($Q5+$R5+IF(ISNUMBER($S5),$S5,0)+IF(ISNUMBER($T5),$T5,0))*$V5,0) -> 10400 | AZ5: =IF(AND(AY5>0,$N5<>""),IF((DATE(Assumptions!$B$4,6,28)-$N5)/365.25<=Assumptions!$B$20,(DATE(Assumptions!$B$4,6,28)-$N5)/365.25*Assumptions!$B$18*AY5,(Assumptions!$B$20*Assumptions!$B$18+((DATE(Assumptions!$B$4,6,28)-$N5)/365.25-Assumptions!$B$20)*Assumptions!$B$19)*AY5),0) -> 14678.166 | BA5: =IF(AX5>0,IF($M5="Saudi",MIN(AX5+$Q5*$V5,Assumptions!$B$14)*Assumptions!$B$12,MIN(AX5+$Q5*$V5,Assumptions!$B$14)*Assumptions!$B$13),0) -> 0 | BB5: =IF(AND(AX5>0,$M5="Non-Saudi"),Assumptions!$B$25,0) -> 910.41667 | BC5: =IF(AND($D5="Contrat Local",$N5<>""),$P5*$V5,0) -> 7400 | BD5: =IF(BC5>0,BC5+($Q5+$R5+IF(ISNUMBER($S5),$S5,0)+IF(ISNUMBER($T5),$T5,0))*$V5,0) -> 10400 | BE5: =IF(AND(BD5>0,$N5<>""),IF((DATE(Assumptions!$B$4,7,28)-$N5)/365.25<=Assumptions!$B$20,(DATE(Assumptions!$B$4,7,28)-$N5)/365.25*Assumptions!$B$18*BD5,(Assumptions!$B$20*Assumptions!$B$18+((DATE(Assumptions!$B$4,7,28)-$N5)/365.25-Assumptions!$B$20)*Assumptions!$B$19)*BD5),0) -> 15105.27 | BF5: =IF(BC5>0,IF($M5="Saudi",MIN(BC5+$Q5*$V5,Assumptions!$B$14)*Assumptions!$B$12,MIN(BC5+$Q5*$V5,Assumptions!$B$14)*Assumptions!$B$13),0) -> 0 | BG5: =IF(AND(BC5>0,$M5="Non-Saudi"),Assumptions!$B$25,0) -> 910.41667 | BH5: =IF(AND($D5="Contrat Local",$N5<>""),$P5*$V5,0) -> 7400 | BI5: =IF(BH5>0,BH5+($Q5+$R5+IF(ISNUMBER($S5),$S5,0)+IF(ISNUMBER($T5),$T5,0))*$V5,0) -> 10400 | BJ5: =IF(AND(BI5>0,$N5<>""),IF((DATE(Assumptions!$B$4,8,28)-$N5)/365.25<=Assumptions!$B$20,(DATE(Assumptions!$B$4,8,28)-$N5)/365.25*Assumptions!$B$18*BI5,(Assumptions!$B$20*Assumptions!$B$18+((DATE(Assumptions!$B$4,8,28)-$N5)/365.25-Assumptions!$B$20)*Assumptions!$B$19)*BI5),0) -> 15546.612 | BK5: =IF(BH5>0,IF($M5="Saudi",MIN(BH5+$Q5*$V5,Assumptions!$B$14)*Assumptions!$B$12,MIN(BH5+$Q5*$V5,Assumptions!$B$14)*Assumptions!$B$13),0) -> 0 | BL5: =IF(AND(BH5>0,$M5="Non-Saudi"),Assumptions!$B$25,0) -> 910.41667 | BM5: =IF(AND($D5="Contrat Local",$N5<>""),IF(AND(9>=Assumptions!$B$5,ISNUMBER($X5),$N5<EDATE(Assumptions!$B$9,-Assumptions!$B$6*12)),($P5+$X5)*$V5,$P5*$V5),0) -> 7600 | BN5: =IF(BM5>0,BM5+($Q5+$R5+IF(ISNUMBER($S5),$S5,0)+IF(ISNUMBER($T5),$T5,0))*$V5,0) -> 10600 | BO5: =IF(AND(BN5>0,$N5<>""),IF((DATE(Assumptions!$B$4,9,28)-$N5)/365.25<=Assumptions!$B$20,(DATE(Assumptions!$B$4,9,28)-$N5)/365.25*Assumptions!$B$18*BN5,(Assumptions!$B$20*Assumptions!$B$18+((DATE(Assumptions!$B$4,9,28)-$N5)/365.25-Assumptions!$B$20)*Assumptions!$B$19)*BN5),0) -> 16295.414 | BP5: =IF(BM5>0,IF($M5="Saudi",MIN(BM5+$Q5*$V5,Assumptions!$B$14)*Assumptions!$B$12,MIN(BM5+$Q5*$V5,Assumptions!$B$14)*Assumptions!$B$13),0) -> 0 | BQ5: =IF(AND(BM5>0,$M5="Non-Saudi"),Assumptions!$B$25,0) -> 910.41667 | BR5: =IF(AND($D5="Contrat Local",$N5<>""),IF(AND(10>=Assumptions!$B$5,ISNUMBER($X5),$N5<EDATE(Assumptions!$B$9,-Assumptions!$B$6*12)),($P5+$X5)*$V5,$P5*$V5),0) -> 7600 | BS5: =IF(BR5>0,BR5+($Q5+$R5+IF(ISNUMBER($S5),$S5,0)+IF(ISNUMBER($T5),$T5,0))*$V5,0) -> 10600 | BT5: =IF(AND(BS5>0,$N5<>""),IF((DATE(Assumptions!$B$4,10,28)-$N5)/365.25<=Assumptions!$B$20,(DATE(Assumptions!$B$4,10,28)-$N5)/365.25*Assumptions!$B$18*BS5,(Assumptions!$B$20*Assumptions!$B$18+((DATE(Assumptions!$B$4,10,28)-$N5)/365.25-Assumptions!$B$20)*Assumptions!$B$19)*BS5),0) -> 16730.732 | BU5: =IF(BR5>0,IF($M5="Saudi",MIN(BR5+$Q5*$V5,Assumptions!$B$14)*Assumptions!$B$12,MIN(BR5+$Q5*$V5,Assumptions!$B$14)*Assumptions!$B$13),0) -> 0 | BV5: =IF(AND(BR5>0,$M5="Non-Saudi"),Assumptions!$B$25,0) -> 910.41667 | BW5: =IF(AND($D5="Contrat Local",$N5<>""),IF(AND(11>=Assumptions!$B$5,ISNUMBER($X5),$N5<EDATE(Assumptions!$B$9,-Assumptions!$B$6*12)),($P5+$X5)*$V5,$P5*$V5),0) -> 7600 | BX5: =IF(BW5>0,BW5+($Q5+$R5+IF(ISNUMBER($S5),$S5,0)+IF(ISNUMBER($T5),$T5,0))*$V5,0) -> 10600 | BY5: =IF(AND(BX5>0,$N5<>""),IF((DATE(Assumptions!$B$4,11,28)-$N5)/365.25<=Assumptions!$B$20,(DATE(Assumptions!$B$4,11,28)-$N5)/365.25*Assumptions!$B$18*BX5,(Assumptions!$B$20*Assumptions!$B$18+((DATE(Assumptions!$B$4,11,28)-$N5)/365.25-Assumptions!$B$20)*Assumptions!$B$19)*BX5),0) -> 17180.561 | BZ5: =IF(BW5>0,IF($M5="Saudi",MIN(BW5+$Q5*$V5,Assumptions!$B$14)*Assumptions!$B$12,MIN(BW5+$Q5*$V5,Assumptions!$B$14)*Assumptions!$B$13),0) -> 0 | CA5: =IF(AND(BW5>0,$M5="Non-Saudi"),Assumptions!$B$25,0) -> 910.41667 | CB5: =IF(AND($D5="Contrat Local",$N5<>""),IF(AND(12>=Assumptions!$B$5,ISNUMBER($X5),$N5<EDATE(Assumptions!$B$9,-Assumptions!$B$6*12)),($P5+$X5)*$V5,$P5*$V5),0) -> 7600 | CC5: =IF(CB5>0,CB5+($Q5+$R5+IF(ISNUMBER($S5),$S5,0)+IF(ISNUMBER($T5),$T5,0))*$V5,0) -> 10600 | CD5: =IF(AND(CC5>0,$N5<>""),IF((DATE(Assumptions!$B$4,12,28)-$N5)/365.25<=Assumptions!$B$20,(DATE(Assumptions!$B$4,12,28)-$N5)/365.25*Assumptions!$B$18*CC5,(Assumptions!$B$20*Assumptions!$B$18+((DATE(Assumptions!$B$4,12,28)-$N5)/365.25-Assumptions!$B$20)*Assumptions!$B$19)*CC5),0) -> 17615.88 | CE5: =IF(CB5>0,IF($M5="Saudi",MIN(CB5+$Q5*$V5,Assumptions!$B$14)*Assumptions!$B$12,MIN(CB5+$Q5*$V5,Assumptions!$B$14)*Assumptions!$B$13),0) -> 0 | CF5: =IF(AND(CB5>0,$M5="Non-Saudi"),Assumptions!$B$25,0) -> 910.41667 | CG5: =Y5+AD5+AI5+AN5+AS5+AX5+BC5+BH5+BM5+BR5+BW5+CB5 -> 89600 | CH5: =Z5+AE5+AJ5+AO5+AT5+AY5+BD5+BI5+BN5+BS5+BX5+CC5 -> 125600 | CI5: =CD5-IF(AND(Z5>0,$N5<>""),IF((DATE(Assumptions!$B$4-1,12,28)-$N5)/365.25<=Assumptions!$B$20,(DATE(Assumptions!$B$4-1,12,28)-$N5)/365.25*Assumptions!$B$18*Z5,(Assumptions!$B$20*Assumptions!$B$18+((DATE(Assumptions!$B$4-1,12,28)-$N5)/365.25-Assumptions!$B$20)*Assumptions!$B$19)*Z5),0) -> 5528.8159 | CJ5: =AB5+AG5+AL5+AQ5+AV5+BA5+BF5+BK5+BP5+BU5+BZ5+CE5 -> 0 | CK5: =AC5+AH5+AM5+AR5+AW5+BB5+BG5+BL5+BQ5+BV5+CA5+CF5 -> 10925
A6: 2 | B6: ABID | C6: Hamdi | D6: Contrat Local | E6: Permanent | F6: Assistant(e) d'éducation | G6: Vie Scolaire & Support | H6: Vie scolaire | I6: Non-Teacher | K6: Vie Scolaire & Support | L6: Existing | M6: =IF(D6="Titulaire EN","",IF(OR(B6="AL OSSAIMI AL OTAIBI",B6="ALAMRI"),"Saudi","Non-Saudi")) -> Non-Saudi | N6: 42614 | O6: 10.3 | P6: 9000 | Q6: 2500 | R6: 500 | U6: 12000 | V6: 1 | W6: Virement | X6: 400 | Y6: =IF(AND($D6="Contrat Local",$N6<>""),$P6*$V6,0) -> 9000 | Z6: =IF(Y6>0,Y6+($Q6+$R6+IF(ISNUMBER($S6),$S6,0)+IF(ISNUMBER($T6),$T6,0))*$V6,0) -> 12000 | AA6: =IF(AND(Z6>0,$N6<>""),IF((DATE(Assumptions!$B$4,1,28)-$N6)/365.25<=Assumptions!$B$20,(DATE(Assumptions!$B$4,1,28)-$N6)/365.25*Assumptions!$B$18*Z6,(Assumptions!$B$20*Assumptions!$B$18+((DATE(Assumptions!$B$4,1,28)-$N6)/365.25-Assumptions!$B$20)*Assumptions!$B$19)*Z6),0) -> 82887.064 | AB6: =IF(Y6>0,IF($M6="Saudi",MIN(Y6+$Q6*$V6,Assumptions!$B$14)*Assumptions!$B$12,MIN(Y6+$Q6*$V6,Assumptions!$B$14)*Assumptions!$B$13),0) -> 0 | AC6: =IF(AND(Y6>0,$M6="Non-Saudi"),Assumptions!$B$25,0) -> 910.41667 | AD6: =IF(AND($D6="Contrat Local",$N6<>""),$P6*$V6,0) -> 9000 | AE6: =IF(AD6>0,AD6+($Q6+$R6+IF(ISNUMBER($S6),$S6,0)+IF(ISNUMBER($T6),$T6,0))*$V6,0) -> 12000 | AF6: =IF(AND(AE6>0,$N6<>""),IF((DATE(Assumptions!$B$4,2,28)-$N6)/365.25<=Assumptions!$B$20,(DATE(Assumptions!$B$4,2,28)-$N6)/365.25*Assumptions!$B$18*AE6,(Assumptions!$B$20*Assumptions!$B$18+((DATE(Assumptions!$B$4,2,28)-$N6)/365.25-Assumptions!$B$20)*Assumptions!$B$19)*AE6),0) -> 83905.544 | AG6: =IF(AD6>0,IF($M6="Saudi",MIN(AD6+$Q6*$V6,Assumptions!$B$14)*Assumptions!$B$12,MIN(AD6+$Q6*$V6,Assumptions!$B$14)*Assumptions!$B$13),0) -> 0 | AH6: =IF(AND(AD6>0,$M6="Non-Saudi"),Assumptions!$B$25,0) -> 910.41667 | AI6: =IF(AND($D6="Contrat Local",$N6<>""),$P6*$V6,0) -> 9000 | AJ6: =IF(AI6>0,AI6+($Q6+$R6+IF(ISNUMBER($S6),$S6,0)+IF(ISNUMBER($T6),$T6,0))*$V6,0) -> 12000 | AK6: =IF(AND(AJ6>0,$N6<>""),IF((DATE(Assumptions!$B$4,3,28)-$N6)/365.25<=Assumptions!$B$20,(DATE(Assumptions!$B$4,3,28)-$N6)/365.25*Assumptions!$B$18*AJ6,(Assumptions!$B$20*Assumptions!$B$18+((DATE(Assumptions!$B$4,3,28)-$N6)/365.25-Assumptions!$B$20)*Assumptions!$B$19)*AJ6),0) -> 84825.462 | AL6: =IF(AI6>0,IF($M6="Saudi",MIN(AI6+$Q6*$V6,Assumptions!$B$14)*Assumptions!$B$12,MIN(AI6+$Q6*$V6,Assumptions!$B$14)*Assumptions!$B$13),0) -> 0 | AM6: =IF(AND(AI6>0,$M6="Non-Saudi"),Assumptions!$B$25,0) -> 910.41667 | AN6: =IF(AND($D6="Contrat Local",$N6<>""),$P6*$V6,0) -> 9000 | AO6: =IF(AN6>0,AN6+($Q6+$R6+IF(ISNUMBER($S6),$S6,0)+IF(ISNUMBER($T6),$T6,0))*$V6,0) -> 12000 | AP6: =IF(AND(AO6>0,$N6<>""),IF((DATE(Assumptions!$B$4,4,28)-$N6)/365.25<=Assumptions!$B$20,(DATE(Assumptions!$B$4,4,28)-$N6)/365.25*Assumptions!$B$18*AO6,(Assumptions!$B$20*Assumptions!$B$18+((DATE(Assumptions!$B$4,4,28)-$N6)/365.25-Assumptions!$B$20)*Assumptions!$B$19)*AO6),0) -> 85843.943 | AQ6: =IF(AN6>0,IF($M6="Saudi",MIN(AN6+$Q6*$V6,Assumptions!$B$14)*Assumptions!$B$12,MIN(AN6+$Q6*$V6,Assumptions!$B$14)*Assumptions!$B$13),0) -> 0 | AR6: =IF(AND(AN6>0,$M6="Non-Saudi"),Assumptions!$B$25,0) -> 910.41667 | AS6: =IF(AND($D6="Contrat Local",$N6<>""),$P6*$V6,0) -> 9000 | AT6: =IF(AS6>0,AS6+($Q6+$R6+IF(ISNUMBER($S6),$S6,0)+IF(ISNUMBER($T6),$T6,0))*$V6,0) -> 12000 | AU6: =IF(AND(AT6>0,$N6<>""),IF((DATE(Assumptions!$B$4,5,28)-$N6)/365.25<=Assumptions!$B$20,(DATE(Assumptions!$B$4,5,28)-$N6)/365.25*Assumptions!$B$18*AT6,(Assumptions!$B$20*Assumptions!$B$18+((DATE(Assumptions!$B$4,5,28)-$N6)/365.25-Assumptions!$B$20)*Assumptions!$B$19)*AT6),0) -> 86829.569 | AV6: =IF(AS6>0,IF($M6="Saudi",MIN(AS6+$Q6*$V6,Assumptions!$B$14)*Assumptions!$B$12,MIN(AS6+$Q6*$V6,Assumptions!$B$14)*Assumptions!$B$13),0) -> 0 | AW6: =IF(AND(AS6>0,$M6="Non-Saudi"),Assumptions!$B$25,0) -> 910.41667 | AX6: =IF(AND($D6="Contrat Local",$N6<>""),$P6*$V6,0) -> 9000 | AY6: =IF(AX6>0,AX6+($Q6+$R6+IF(ISNUMBER($S6),$S6,0)+IF(ISNUMBER($T6),$T6,0))*$V6,0) -> 12000 | AZ6: =IF(AND(AY6>0,$N6<>""),IF((DATE(Assumptions!$B$4,6,28)-$N6)/365.25<=Assumptions!$B$20,(DATE(Assumptions!$B$4,6,28)-$N6)/365.25*Assumptions!$B$18*AY6,(Assumptions!$B$20*Assumptions!$B$18+((DATE(Assumptions!$B$4,6,28)-$N6)/365.25-Assumptions!$B$20)*Assumptions!$B$19)*AY6),0) -> 87848.049 | BA6: =IF(AX6>0,IF($M6="Saudi",MIN(AX6+$Q6*$V6,Assumptions!$B$14)*Assumptions!$B$12,MIN(AX6+$Q6*$V6,Assumptions!$B$14)*Assumptions!$B$13),0) -> 0 | BB6: =IF(AND(AX6>0,$M6="Non-Saudi"),Assumptions!$B$25,0) -> 910.41667 | BC6: =IF(AND($D6="Contrat Local",$N6<>""),$P6*$V6,0) -> 9000 | BD6: =IF(BC6>0,BC6+($Q6+$R6+IF(ISNUMBER($S6),$S6,0)+IF(ISNUMBER($T6),$T6,0))*$V6,0) -> 12000 | BE6: =IF(AND(BD6>0,$N6<>""),IF((DATE(Assumptions!$B$4,7,28)-$N6)/365.25<=Assumptions!$B$20,(DATE(Assumptions!$B$4,7,28)-$N6)/365.25*Assumptions!$B$18*BD6,(Assumptions!$B$20*Assumptions!$B$18+((DATE(Assumptions!$B$4,7,28)-$N6)/365.25-Assumptions!$B$20)*Assumptions!$B$19)*BD6),0) -> 88833.676 | BF6: =IF(BC6>0,IF($M6="Saudi",MIN(BC6+$Q6*$V6,Assumptions!$B$14)*Assumptions!$B$12,MIN(BC6+$Q6*$V6,Assumptions!$B$14)*Assumptions!$B$13),0) -> 0 | BG6: =IF(AND(BC6>0,$M6="Non-Saudi"),Assumptions!$B$25,0) -> 910.41667 | BH6: =IF(AND($D6="Contrat Local",$N6<>""),$P6*$V6,0) -> 9000 | BI6: =IF(BH6>0,BH6+($Q6+$R6+IF(ISNUMBER($S6),$S6,0)+IF(ISNUMBER($T6),$T6,0))*$V6,0) -> 12000 | BJ6: =IF(AND(BI6>0,$N6<>""),IF((DATE(Assumptions!$B$4,8,28)-$N6)/365.25<=Assumptions!$B$20,(DATE(Assumptions!$B$4,8,28)-$N6)/365.25*Assumptions!$B$18*BI6,(Assumptions!$B$20*Assumptions!$B$18+((DATE(Assumptions!$B$4,8,28)-$N6)/365.25-Assumptions!$B$20)*Assumptions!$B$19)*BI6),0) -> 89852.156 | BK6: =IF(BH6>0,IF($M6="Saudi",MIN(BH6+$Q6*$V6,Assumptions!$B$14)*Assumptions!$B$12,MIN(BH6+$Q6*$V6,Assumptions!$B$14)*Assumptions!$B$13),0) -> 0 | BL6: =IF(AND(BH6>0,$M6="Non-Saudi"),Assumptions!$B$25,0) -> 910.41667 | BM6: =IF(AND($D6="Contrat Local",$N6<>""),IF(AND(9>=Assumptions!$B$5,ISNUMBER($X6),$N6<EDATE(Assumptions!$B$9,-Assumptions!$B$6*12)),($P6+$X6)*$V6,$P6*$V6),0) -> 9400 | BN6: =IF(BM6>0,BM6+($Q6+$R6+IF(ISNUMBER($S6),$S6,0)+IF(ISNUMBER($T6),$T6,0))*$V6,0) -> 12400 | BO6: =IF(AND(BN6>0,$N6<>""),IF((DATE(Assumptions!$B$4,9,28)-$N6)/365.25<=Assumptions!$B$20,(DATE(Assumptions!$B$4,9,28)-$N6)/365.25*Assumptions!$B$18*BN6,(Assumptions!$B$20*Assumptions!$B$18+((DATE(Assumptions!$B$4,9,28)-$N6)/365.25-Assumptions!$B$20)*Assumptions!$B$19)*BN6),0) -> 93899.658 | BP6: =IF(BM6>0,IF($M6="Saudi",MIN(BM6+$Q6*$V6,Assumptions!$B$14)*Assumptions!$B$12,MIN(BM6+$Q6*$V6,Assumptions!$B$14)*Assumptions!$B$13),0) -> 0 | BQ6: =IF(AND(BM6>0,$M6="Non-Saudi"),Assumptions!$B$25,0) -> 910.41667 | BR6: =IF(AND($D6="Contrat Local",$N6<>""),IF(AND(10>=Assumptions!$B$5,ISNUMBER($X6),$N6<EDATE(Assumptions!$B$9,-Assumptions!$B$6*12)),($P6+$X6)*$V6,$P6*$V6),0) -> 9400 | BS6: =IF(BR6>0,BR6+($Q6+$R6+IF(ISNUMBER($S6),$S6,0)+IF(ISNUMBER($T6),$T6,0))*$V6,0) -> 12400 | BT6: =IF(AND(BS6>0,$N6<>""),IF((DATE(Assumptions!$B$4,10,28)-$N6)/365.25<=Assumptions!$B$20,(DATE(Assumptions!$B$4,10,28)-$N6)/365.25*Assumptions!$B$18*BS6,(Assumptions!$B$20*Assumptions!$B$18+((DATE(Assumptions!$B$4,10,28)-$N6)/365.25-Assumptions!$B$20)*Assumptions!$B$19)*BS6),0) -> 94918.138 | BU6: =IF(BR6>0,IF($M6="Saudi",MIN(BR6+$Q6*$V6,Assumptions!$B$14)*Assumptions!$B$12,MIN(BR6+$Q6*$V6,Assumptions!$B$14)*Assumptions!$B$13),0) -> 0 | BV6: =IF(AND(BR6>0,$M6="Non-Saudi"),Assumptions!$B$25,0) -> 910.41667 | BW6: =IF(AND($D6="Contrat Local",$N6<>""),IF(AND(11>=Assumptions!$B$5,ISNUMBER($X6),$N6<EDATE(Assumptions!$B$9,-Assumptions!$B$6*12)),($P6+$X6)*$V6,$P6*$V6),0) -> 9400 | BX6: =IF(BW6>0,BW6+($Q6+$R6+IF(ISNUMBER($S6),$S6,0)+IF(ISNUMBER($T6),$T6,0))*$V6,0) -> 12400 | BY6: =IF(AND(BX6>0,$N6<>""),IF((DATE(Assumptions!$B$4,11,28)-$N6)/365.25<=Assumptions!$B$20,(DATE(Assumptions!$B$4,11,28)-$N6)/365.25*Assumptions!$B$18*BX6,(Assumptions!$B$20*Assumptions!$B$18+((DATE(Assumptions!$B$4,11,28)-$N6)/365.25-Assumptions!$B$20)*Assumptions!$B$19)*BX6),0) -> 95970.568 | BZ6: =IF(BW6>0,IF($M6="Saudi",MIN(BW6+$Q6*$V6,Assumptions!$B$14)*Assumptions!$B$12,MIN(BW6+$Q6*$V6,Assumptions!$B$14)*Assumptions!$B$13),0) -> 0 | CA6: =IF(AND(BW6>0,$M6="Non-Saudi"),Assumptions!$B$25,0) -> 910.41667 | CB6: =IF(AND($D6="Contrat Local",$N6<>""),IF(AND(12>=Assumptions!$B$5,ISNUMBER($X6),$N6<EDATE(Assumptions!$B$9,-Assumptions!$B$6*12)),($P6+$X6)*$V6,$P6*$V6),0) -> 9400 | CC6: =IF(CB6>0,CB6+($Q6+$R6+IF(ISNUMBER($S6),$S6,0)+IF(ISNUMBER($T6),$T6,0))*$V6,0) -> 12400 | CD6: =IF(AND(CC6>0,$N6<>""),IF((DATE(Assumptions!$B$4,12,28)-$N6)/365.25<=Assumptions!$B$20,(DATE(Assumptions!$B$4,12,28)-$N6)/365.25*Assumptions!$B$18*CC6,(Assumptions!$B$20*Assumptions!$B$18+((DATE(Assumptions!$B$4,12,28)-$N6)/365.25-Assumptions!$B$20)*Assumptions!$B$19)*CC6),0) -> 96989.049 | CE6: =IF(CB6>0,IF($M6="Saudi",MIN(CB6+$Q6*$V6,Assumptions!$B$14)*Assumptions!$B$12,MIN(CB6+$Q6*$V6,Assumptions!$B$14)*Assumptions!$B$13),0) -> 0 | CF6: =IF(AND(CB6>0,$M6="Non-Saudi"),Assumptions!$B$25,0) -> 910.41667 | CG6: =Y6+AD6+AI6+AN6+AS6+AX6+BC6+BH6+BM6+BR6+BW6+CB6 -> 109600 | CH6: =Z6+AE6+AJ6+AO6+AT6+AY6+BD6+BI6+BN6+BS6+BX6+CC6 -> 145600 | CI6: =CD6-IF(AND(Z6>0,$N6<>""),IF((DATE(Assumptions!$B$4-1,12,28)-$N6)/365.25<=Assumptions!$B$20,(DATE(Assumptions!$B$4-1,12,28)-$N6)/365.25*Assumptions!$B$18*Z6,(Assumptions!$B$20*Assumptions!$B$18+((DATE(Assumptions!$B$4-1,12,28)-$N6)/365.25-Assumptions!$B$20)*Assumptions!$B$19)*Z6),0) -> 15120.465 | CJ6: =AB6+AG6+AL6+AQ6+AV6+BA6+BF6+BK6+BP6+BU6+BZ6+CE6 -> 0 | CK6: =AC6+AH6+AM6+AR6+AW6+BB6+BG6+BL6+BQ6+BV6+CA6+CF6 -> 10925
A7: 3 | B7: ABOU RJEILI | C7: Christina | D7: Contrat Local | E7: Permanent | F7: Assistant(e) d'éducation | G7: Vie Scolaire & Support | H7: Vie scolaire | I7: Non-Teacher | K7: Vie Scolaire & Support | L7: Existing | M7: =IF(D7="Titulaire EN","",IF(OR(B7="AL OSSAIMI AL OTAIBI",B7="ALAMRI"),"Saudi","Non-Saudi")) -> Non-Saudi | N7: 45536 | O7: 2.3 | P7: 7200 | Q7: 2500 | R7: 500 | U7: 10200 | V7: 1 | W7: Virement | X7: 200 | Y7: =IF(AND($D7="Contrat Local",$N7<>""),$P7*$V7,0) -> 7200 | Z7: =IF(Y7>0,Y7+($Q7+$R7+IF(ISNUMBER($S7),$S7,0)+IF(ISNUMBER($T7),$T7,0))*$V7,0) -> 10200 | AA7: =IF(AND(Z7>0,$N7<>""),IF((DATE(Assumptions!$B$4,1,28)-$N7)/365.25<=Assumptions!$B$20,(DATE(Assumptions!$B$4,1,28)-$N7)/365.25*Assumptions!$B$18*Z7,(Assumptions!$B$20*Assumptions!$B$18+((DATE(Assumptions!$B$4,1,28)-$N7)/365.25-Assumptions!$B$20)*Assumptions!$B$19)*Z7),0) -> 7177.0021 | AB7: =IF(Y7>0,IF($M7="Saudi",MIN(Y7+$Q7*$V7,Assumptions!$B$14)*Assumptions!$B$12,MIN(Y7+$Q7*$V7,Assumptions!$B$14)*Assumptions!$B$13),0) -> 0 | AC7: =IF(AND(Y7>0,$M7="Non-Saudi"),Assumptions!$B$25,0) -> 910.41667 | AD7: =IF(AND($D7="Contrat Local",$N7<>""),$P7*$V7,0) -> 7200 | AE7: =IF(AD7>0,AD7+($Q7+$R7+IF(ISNUMBER($S7),$S7,0)+IF(ISNUMBER($T7),$T7,0))*$V7,0) -> 10200 | AF7: =IF(AND(AE7>0,$N7<>""),IF((DATE(Assumptions!$B$4,2,28)-$N7)/365.25<=Assumptions!$B$20,(DATE(Assumptions!$B$4,2,28)-$N7)/365.25*Assumptions!$B$18*AE7,(Assumptions!$B$20*Assumptions!$B$18+((DATE(Assumptions!$B$4,2,28)-$N7)/365.25-Assumptions!$B$20)*Assumptions!$B$19)*AE7),0) -> 7609.8563 | AG7: =IF(AD7>0,IF($M7="Saudi",MIN(AD7+$Q7*$V7,Assumptions!$B$14)*Assumptions!$B$12,MIN(AD7+$Q7*$V7,Assumptions!$B$14)*Assumptions!$B$13),0) -> 0 | AH7: =IF(AND(AD7>0,$M7="Non-Saudi"),Assumptions!$B$25,0) -> 910.41667 | AI7: =IF(AND($D7="Contrat Local",$N7<>""),$P7*$V7,0) -> 7200 | AJ7: =IF(AI7>0,AI7+($Q7+$R7+IF(ISNUMBER($S7),$S7,0)+IF(ISNUMBER($T7),$T7,0))*$V7,0) -> 10200 | AK7: =IF(AND(AJ7>0,$N7<>""),IF((DATE(Assumptions!$B$4,3,28)-$N7)/365.25<=Assumptions!$B$20,(DATE(Assumptions!$B$4,3,28)-$N7)/365.25*Assumptions!$B$18*AJ7,(Assumptions!$B$20*Assumptions!$B$18+((DATE(Assumptions!$B$4,3,28)-$N7)/365.25-Assumptions!$B$20)*Assumptions!$B$19)*AJ7),0) -> 8000.8214 | AL7: =IF(AI7>0,IF($M7="Saudi",MIN(AI7+$Q7*$V7,Assumptions!$B$14)*Assumptions!$B$12,MIN(AI7+$Q7*$V7,Assumptions!$B$14)*Assumptions!$B$13),0) -> 0 | AM7: =IF(AND(AI7>0,$M7="Non-Saudi"),Assumptions!$B$25,0) -> 910.41667 | AN7: =IF(AND($D7="Contrat Local",$N7<>""),$P7*$V7,0) -> 7200 | AO7: =IF(AN7>0,AN7+($Q7+$R7+IF(ISNUMBER($S7),$S7,0)+IF(ISNUMBER($T7),$T7,0))*$V7,0) -> 10200 | AP7: =IF(AND(AO7>0,$N7<>""),IF((DATE(Assumptions!$B$4,4,28)-$N7)/365.25<=Assumptions!$B$20,(DATE(Assumptions!$B$4,4,28)-$N7)/365.25*Assumptions!$B$18*AO7,(Assumptions!$B$20*Assumptions!$B$18+((DATE(Assumptions!$B$4,4,28)-$N7)/365.25-Assumptions!$B$20)*Assumptions!$B$19)*AO7),0) -> 8433.6756 | AQ7: =IF(AN7>0,IF($M7="Saudi",MIN(AN7+$Q7*$V7,Assumptions!$B$14)*Assumptions!$B$12,MIN(AN7+$Q7*$V7,Assumptions!$B$14)*Assumptions!$B$13),0) -> 0 | AR7: =IF(AND(AN7>0,$M7="Non-Saudi"),Assumptions!$B$25,0) -> 910.41667 | AS7: =IF(AND($D7="Contrat Local",$N7<>""),$P7*$V7,0) -> 7200 | AT7: =IF(AS7>0,AS7+($Q7+$R7+IF(ISNUMBER($S7),$S7,0)+IF(ISNUMBER($T7),$T7,0))*$V7,0) -> 10200 | AU7: =IF(AND(AT7>0,$N7<>""),IF((DATE(Assumptions!$B$4,5,28)-$N7)/365.25<=Assumptions!$B$20,(DATE(Assumptions!$B$4,5,28)-$N7)/365.25*Assumptions!$B$18*AT7,(Assumptions!$B$20*Assumptions!$B$18+((DATE(Assumptions!$B$4,5,28)-$N7)/365.25-Assumptions!$B$20)*Assumptions!$B$19)*AT7),0) -> 8852.5667 | AV7: =IF(AS7>0,IF($M7="Saudi",MIN(AS7+$Q7*$V7,Assumptions!$B$14)*Assumptions!$B$12,MIN(AS7+$Q7*$V7,Assumptions!$B$14)*Assumptions!$B$13),0) -> 0 | AW7: =IF(AND(AS7>0,$M7="Non-Saudi"),Assumptions!$B$25,0) -> 910.41667 | AX7: =IF(AND($D7="Contrat Local",$N7<>""),$P7*$V7,0) -> 7200 | AY7: =IF(AX7>0,AX7+($Q7+$R7+IF(ISNUMBER($S7),$S7,0)+IF(ISNUMBER($T7),$T7,0))*$V7,0) -> 10200 | AZ7: =IF(AND(AY7>0,$N7<>""),IF((DATE(Assumptions!$B$4,6,28)-$N7)/365.25<=Assumptions!$B$20,(DATE(Assumptions!$B$4,6,28)-$N7)/365.25*Assumptions!$B$18*AY7,(Assumptions!$B$20*Assumptions!$B$18+((DATE(Assumptions!$B$4,6,28)-$N7)/365.25-Assumptions!$B$20)*Assumptions!$B$19)*AY7),0) -> 9285.4209 | BA7: =IF(AX7>0,IF($M7="Saudi",MIN(AX7+$Q7*$V7,Assumptions!$B$14)*Assumptions!$B$12,MIN(AX7+$Q7*$V7,Assumptions!$B$14)*Assumptions!$B$13),0) -> 0 | BB7: =IF(AND(AX7>0,$M7="Non-Saudi"),Assumptions!$B$25,0) -> 910.41667 | BC7: =IF(AND($D7="Contrat Local",$N7<>""),$P7*$V7,0) -> 7200 | BD7: =IF(BC7>0,BC7+($Q7+$R7+IF(ISNUMBER($S7),$S7,0)+IF(ISNUMBER($T7),$T7,0))*$V7,0) -> 10200 | BE7: =IF(AND(BD7>0,$N7<>""),IF((DATE(Assumptions!$B$4,7,28)-$N7)/365.25<=Assumptions!$B$20,(DATE(Assumptions!$B$4,7,28)-$N7)/365.25*Assumptions!$B$18*BD7,(Assumptions!$B$20*Assumptions!$B$18+((DATE(Assumptions!$B$4,7,28)-$N7)/365.25-Assumptions!$B$20)*Assumptions!$B$19)*BD7),0) -> 9704.3121 | BF7: =IF(BC7>0,IF($M7="Saudi",MIN(BC7+$Q7*$V7,Assumptions!$B$14)*Assumptions!$B$12,MIN(BC7+$Q7*$V7,Assumptions!$B$14)*Assumptions!$B$13),0) -> 0 | BG7: =IF(AND(BC7>0,$M7="Non-Saudi"),Assumptions!$B$25,0) -> 910.41667 | BH7: =IF(AND($D7="Contrat Local",$N7<>""),$P7*$V7,0) -> 7200 | BI7: =IF(BH7>0,BH7+($Q7+$R7+IF(ISNUMBER($S7),$S7,0)+IF(ISNUMBER($T7),$T7,0))*$V7,0) -> 10200 | BJ7: =IF(AND(BI7>0,$N7<>""),IF((DATE(Assumptions!$B$4,8,28)-$N7)/365.25<=Assumptions!$B$20,(DATE(Assumptions!$B$4,8,28)-$N7)/365.25*Assumptions!$B$18*BI7,(Assumptions!$B$20*Assumptions!$B$18+((DATE(Assumptions!$B$4,8,28)-$N7)/365.25-Assumptions!$B$20)*Assumptions!$B$19)*BI7),0) -> 10137.166 | BK7: =IF(BH7>0,IF($M7="Saudi",MIN(BH7+$Q7*$V7,Assumptions!$B$14)*Assumptions!$B$12,MIN(BH7+$Q7*$V7,Assumptions!$B$14)*Assumptions!$B$13),0) -> 0 | BL7: =IF(AND(BH7>0,$M7="Non-Saudi"),Assumptions!$B$25,0) -> 910.41667 | BM7: =IF(AND($D7="Contrat Local",$N7<>""),IF(AND(9>=Assumptions!$B$5,ISNUMBER($X7),$N7<EDATE(Assumptions!$B$9,-Assumptions!$B$6*12)),($P7+$X7)*$V7,$P7*$V7),0) -> 7400 | BN7: =IF(BM7>0,BM7+($Q7+$R7+IF(ISNUMBER($S7),$S7,0)+IF(ISNUMBER($T7),$T7,0))*$V7,0) -> 10400 | BO7: =IF(AND(BN7>0,$N7<>""),IF((DATE(Assumptions!$B$4,9,28)-$N7)/365.25<=Assumptions!$B$20,(DATE(Assumptions!$B$4,9,28)-$N7)/365.25*Assumptions!$B$18*BN7,(Assumptions!$B$20*Assumptions!$B$18+((DATE(Assumptions!$B$4,9,28)-$N7)/365.25-Assumptions!$B$20)*Assumptions!$B$19)*BN7),0) -> 10777.276 | BP7: =IF(BM7>0,IF($M7="Saudi",MIN(BM7+$Q7*$V7,Assumptions!$B$14)*Assumptions!$B$12,MIN(BM7+$Q7*$V7,Assumptions!$B$14)*Assumptions!$B$13),0) -> 0 | BQ7: =IF(AND(BM7>0,$M7="Non-Saudi"),Assumptions!$B$25,0) -> 910.41667 | BR7: =IF(AND($D7="Contrat Local",$N7<>""),IF(AND(10>=Assumptions!$B$5,ISNUMBER($X7),$N7<EDATE(Assumptions!$B$9,-Assumptions!$B$6*12)),($P7+$X7)*$V7,$P7*$V7),0) -> 7400 | BS7: =IF(BR7>0,BR7+($Q7+$R7+IF(ISNUMBER($S7),$S7,0)+IF(ISNUMBER($T7),$T7,0))*$V7,0) -> 10400 | BT7: =IF(AND(BS7>0,$N7<>""),IF((DATE(Assumptions!$B$4,10,28)-$N7)/365.25<=Assumptions!$B$20,(DATE(Assumptions!$B$4,10,28)-$N7)/365.25*Assumptions!$B$18*BS7,(Assumptions!$B$20*Assumptions!$B$18+((DATE(Assumptions!$B$4,10,28)-$N7)/365.25-Assumptions!$B$20)*Assumptions!$B$19)*BS7),0) -> 11204.381 | BU7: =IF(BR7>0,IF($M7="Saudi",MIN(BR7+$Q7*$V7,Assumptions!$B$14)*Assumptions!$B$12,MIN(BR7+$Q7*$V7,Assumptions!$B$14)*Assumptions!$B$13),0) -> 0 | BV7: =IF(AND(BR7>0,$M7="Non-Saudi"),Assumptions!$B$25,0) -> 910.41667 | BW7: =IF(AND($D7="Contrat Local",$N7<>""),IF(AND(11>=Assumptions!$B$5,ISNUMBER($X7),$N7<EDATE(Assumptions!$B$9,-Assumptions!$B$6*12)),($P7+$X7)*$V7,$P7*$V7),0) -> 7400 | BX7: =IF(BW7>0,BW7+($Q7+$R7+IF(ISNUMBER($S7),$S7,0)+IF(ISNUMBER($T7),$T7,0))*$V7,0) -> 10400 | BY7: =IF(AND(BX7>0,$N7<>""),IF((DATE(Assumptions!$B$4,11,28)-$N7)/365.25<=Assumptions!$B$20,(DATE(Assumptions!$B$4,11,28)-$N7)/365.25*Assumptions!$B$18*BX7,(Assumptions!$B$20*Assumptions!$B$18+((DATE(Assumptions!$B$4,11,28)-$N7)/365.25-Assumptions!$B$20)*Assumptions!$B$19)*BX7),0) -> 11645.722 | BZ7: =IF(BW7>0,IF($M7="Saudi",MIN(BW7+$Q7*$V7,Assumptions!$B$14)*Assumptions!$B$12,MIN(BW7+$Q7*$V7,Assumptions!$B$14)*Assumptions!$B$13),0) -> 0 | CA7: =IF(AND(BW7>0,$M7="Non-Saudi"),Assumptions!$B$25,0) -> 910.41667 | CB7: =IF(AND($D7="Contrat Local",$N7<>""),IF(AND(12>=Assumptions!$B$5,ISNUMBER($X7),$N7<EDATE(Assumptions!$B$9,-Assumptions!$B$6*12)),($P7+$X7)*$V7,$P7*$V7),0) -> 7400 | CC7: =IF(CB7>0,CB7+($Q7+$R7+IF(ISNUMBER($S7),$S7,0)+IF(ISNUMBER($T7),$T7,0))*$V7,0) -> 10400 | CD7: =IF(AND(CC7>0,$N7<>""),IF((DATE(Assumptions!$B$4,12,28)-$N7)/365.25<=Assumptions!$B$20,(DATE(Assumptions!$B$4,12,28)-$N7)/365.25*Assumptions!$B$18*CC7,(Assumptions!$B$20*Assumptions!$B$18+((DATE(Assumptions!$B$4,12,28)-$N7)/365.25-Assumptions!$B$20)*Assumptions!$B$19)*CC7),0) -> 12072.827 | CE7: =IF(CB7>0,IF($M7="Saudi",MIN(CB7+$Q7*$V7,Assumptions!$B$14)*Assumptions!$B$12,MIN(CB7+$Q7*$V7,Assumptions!$B$14)*Assumptions!$B$13),0) -> 0 | CF7: =IF(AND(CB7>0,$M7="Non-Saudi"),Assumptions!$B$25,0) -> 910.41667 | CG7: =Y7+AD7+AI7+AN7+AS7+AX7+BC7+BH7+BM7+BR7+BW7+CB7 -> 87200 | CH7: =Z7+AE7+AJ7+AO7+AT7+AY7+BD7+BI7+BN7+BS7+BX7+CC7 -> 123200 | CI7: =CD7-IF(AND(Z7>0,$N7<>""),IF((DATE(Assumptions!$B$4-1,12,28)-$N7)/365.25<=Assumptions!$B$20,(DATE(Assumptions!$B$4-1,12,28)-$N7)/365.25*Assumptions!$B$18*Z7,(Assumptions!$B$20*Assumptions!$B$18+((DATE(Assumptions!$B$4-1,12,28)-$N7)/365.25-Assumptions!$B$20)*Assumptions!$B$19)*Z7),0) -> 5328.679 | CJ7: =AB7+AG7+AL7+AQ7+AV7+BA7+BF7+BK7+BP7+BU7+BZ7+CE7 -> 0 | CK7: =AC7+AH7+AM7+AR7+AW7+BB7+BG7+BL7+BQ7+BV7+CA7+CF7 -> 10925
