Workbook

Sheet Data_Links
A1: EFIR — Budget Suite FY2026 — Data Links Map
A2: This sheet documents all external references used in the consolidated budget
A4: # | B4: Source File | C4: Source Sheet | D4: Source Row/Range | E4: Data Pulled | F4: Used In | G4: Status
A5: 1 | B5: 01_EFIR_Revenue_FY2026.xlsx | C5: EXECUTIVE_SUMMARY | D5: Row 31 (monthly totals) | E5: Revenue by category (monthly) | F5: IFRS_Mapping rows 6-22 | G5: Active
A6: 2 | B6: 02_EFIR_Staff_Costs_FY2026.xlsx | C6: Budget Summary | D6: Rows 11,23,28,33,36 | E6: Staff costs by component | F6: IFRS_Mapping rows 30-46 | G6: Active
A7: 3 | B7: 03_EFIR_OpEx_FY2026.xlsx | C7: Operating_Expenses | D7: Row 73 (grand total) + subtotals (9,15,20,25,30,35,45,51,56,61,65,71) | E7: Other operating expenses | F7: IFRS_Mapping rows 49-81 | G7: Active
A8: 4 | B8: 03_EFIR_OpEx_FY2026.xlsx | C8: Non_Operating_Items | D8: Rows 6→7 (D&A), 10→11 (Impairment), 14-15 (Finance Income), 19-20 (Finance Costs) | E8: D&A, Impairment, Finance Income, Finance Costs | F8: IFRS_Mapping rows 62-84 | G8: Active
A9: 5 | B9: 04_EFIR_CapEx_FY2026.xlsx | C9: CAPEX_Summary | D9: Row 14 (total monthly depr) | E9: Monthly depreciation (new) | F9: IFRS_Mapping row 84 | G9: Active
A12: IMPORTANT NOTES:
A13: 1. All source files must be in the SAME folder as this consolidated file for links to work.
A14: 2. Red text in formulas = external file link. Green text = cross-sheet link within this file.
A15: 3. To refresh links: Data → Edit Links → Update Values (or open all source files).
A16: 4. File naming: 01_Revenue, 02_Staff_Costs, 03_OpEx, 04_CapEx, 05_Consolidated

Sheet IFRS_Mapping
A1: EFIR – IFRS RECLASSIFIED MONTHLY BUDGET FY2026
A2: Reclassified per IAS 1 Presentation — Currency: SAR — All data linked to source files
A4: IFRS Category | B4: Line Item | C4: Jan | D4: Feb | E4: Mar | F4: Apr | G4: May | H4: Jun | I4: Jul | J4: Aug | K4: Sep | L4: Oct | M4: Nov | N4: Dec | O4: FY2026 Total | Q4: Source | R4: Audit Flags
A5: REVENUE FROM CONTRACTS WITH CUSTOMERS (IFRS 15)
A6: Tuition Fees | B6: Maternelle PS - Tuition | C6: =[1]REVENUE_ENGINE!C6 -> 195434.85 | D6: =[1]REVENUE_ENGINE!D6 -> 195434.85 | E6: =[1]REVENUE_ENGINE!E6 -> 195434.85 | F6: =[1]REVENUE_ENGINE!F6 -> 195434.85 | G6: =[1]REVENUE_ENGINE!G6 -> 195434.85 | H6: =[1]REVENUE_ENGINE!H6 -> 195434.85 | I6: =[1]REVENUE_ENGINE!I6 -> 0 | J6: =[1]REVENUE_ENGINE!J6 -> 0 | ... O6: =[1]REVENUE_ENGINE!O6 -> 1954348.5 | Q6: 01_efir_revenue_fy2026.xlsx' → REVENUE_ENGINE!Row 6
A7: Tuition Fees | B7: Maternelle - Tuition | C7: =[1]REVENUE_ENGINE!C7 -> 632161.9 | D7: =[1]REVENUE_ENGINE!D7 -> 632161.9 | E7: =[1]REVENUE_ENGINE!E7 -> 632161.9 | F7: =[1]REVENUE_ENGINE!F7 -> 632161.9 | G7: =[1]REVENUE_ENGINE!G7 -> 632161.9 | H7: =[1]REVENUE_ENGINE!H7 -> 632161.9 | I7: =[1]REVENUE_ENGINE!I7 -> 0 | J7: =[1]REVENUE_ENGINE!J7 -> 0 | ... O7: =[1]REVENUE_ENGINE!O7 -> 6397197.3 | Q7: 01_efir_revenue_fy2026.xlsx' → REVENUE_ENGINE!Row 7
A8: Tuition Fees | B8: Élémentaire - Tuition | C8: =[1]REVENUE_ENGINE!C8 -> 1979312.2 | D8: =[1]REVENUE_ENGINE!D8 -> 1979312.2 | E8: =[1]REVENUE_ENGINE!E8 -> 1979312.2 | F8: =[1]REVENUE_ENGINE!F8 -> 1979312.2 | G8: =[1]REVENUE_ENGINE!G8 -> 1979312.2 | H8: =[1]REVENUE_ENGINE!H8 -> 1979312.2 | I8: =[1]REVENUE_ENGINE!I8 -> 0 | J8: =[1]REVENUE_ENGINE!J8 -> 0 | ... O8: =[1]REVENUE_ENGINE!O8 -> 20010530 | Q8: 01_efir_revenue_fy2026.xlsx' → REVENUE_ENGINE!Row 8
A9: Tuition Fees | B9: Collège - Tuition | C9: =[1]REVENUE_ENGINE!C9 -> 1688552.2 | D9: =[1]REVENUE_ENGINE!D9 -> 1688552.2 | E9: =[1]REVENUE_ENGINE!E9 -> 1688552.2 | F9: =[1]REVENUE_ENGINE!F9 -> 1688552.2 | G9: =[1]REVENUE_ENGINE!G9 -> 1688552.2 | H9: =[1]REVENUE_ENGINE!H9 -> 1688552.2 | I9: =[1]REVENUE_ENGINE!I9 -> 0 | J9: =[1]REVENUE_ENGINE!J9 -> 0 | ... O9: =[1]REVENUE_ENGINE!O9 -> 17129430 | Q9: 01_efir_revenue_fy2026.xlsx' → REVENUE_ENGINE!Row 9
A10: Tuition Fees | B10: Lycée - Tuition | C10: =[1]REVENUE_ENGINE!C10 -> 1329934.8 | D10: =[1]REVENUE_ENGINE!D10 -> 1329934.8 | E10: =[1]REVENUE_ENGINE!E10 -> 1329934.8 | F10: =[1]REVENUE_ENGINE!F10 -> 1329934.8 | G10: =[1]REVENUE_ENGINE!G10 -> 1329934.8 | H10: =[1]REVENUE_ENGINE!H10 -> 1329934.8 | I10: =[1]REVENUE_ENGINE!I10 -> 0 | J10: =[1]REVENUE_ENGINE!J10 -> 0 | ... O10: =[1]REVENUE_ENGINE!O10 -> 13480748 | Q10: 01_efir_revenue_fy2026.xlsx' → REVENUE_ENGINE!Row 10
A11: Discount Impact | B11: Discount Impact | C11: =[1]REVENUE_ENGINE!C16 -> -223032.18 | D11: =[1]REVENUE_ENGINE!D16 -> -223032.18 | E11: =[1]REVENUE_ENGINE!E16 -> -223032.18 | F11: =[1]REVENUE_ENGINE!F16 -> -223032.18 | G11: =[1]REVENUE_ENGINE!G16 -> -223032.18 | H11: =[1]REVENUE_ENGINE!H16 -> -223032.18 | I11: =[1]REVENUE_ENGINE!I16 -> 0 | J11: =[1]REVENUE_ENGINE!J16 -> 0 | ... O11: =[1]REVENUE_ENGINE!O16 -> -2333712.7 | Q11: 01_efir_revenue_fy2026.xlsx' → REVENUE_ENGINE!Row 16
A12: Registration Fees | B12: New Student Fees (Dossier+DPI) | C12: =[1]REVENUE_ENGINE!C19 -> 0 | D12: =[1]REVENUE_ENGINE!D19 -> 0 | E12: =[1]REVENUE_ENGINE!E19 -> 0 | F12: =[1]REVENUE_ENGINE!F19 -> 0 | G12: =[1]REVENUE_ENGINE!G19 -> 334500 | H12: =[1]REVENUE_ENGINE!H19 -> 334500 | I12: =[1]REVENUE_ENGINE!I19 -> 0 | J12: =[1]REVENUE_ENGINE!J19 -> 0 | ... O12: =[1]REVENUE_ENGINE!O19 -> 717800 | Q12: 01_efir_revenue_fy2026.xlsx' → REVENUE_ENGINE!Row 19
A13: Registration Fees | B13: Re-registration (DAI) | C13: =[1]REVENUE_ENGINE!C20 -> 0 | D13: =[1]REVENUE_ENGINE!D20 -> 0 | E13: =[1]REVENUE_ENGINE!E20 -> 0 | F13: =[1]REVENUE_ENGINE!F20 -> 0 | G13: =[1]REVENUE_ENGINE!G20 -> 4368525 | H13: =[1]REVENUE_ENGINE!H20 -> 4368525 | I13: =[1]REVENUE_ENGINE!I20 -> 0 | J13: =[1]REVENUE_ENGINE!J20 -> 0 | ... O13: =[1]REVENUE_ENGINE!O20 -> 8737050 | Q13: 01_efir_revenue_fy2026.xlsx' → REVENUE_ENGINE!Row 20
A14: Registration Fees | B14: Evaluation Tests | C14: =[1]REVENUE_ENGINE!C21 -> 0 | D14: =[1]REVENUE_ENGINE!D21 -> 0 | E14: =[1]REVENUE_ENGINE!E21 -> 0 | F14: =[1]REVENUE_ENGINE!F21 -> 0 | G14: =[1]REVENUE_ENGINE!G21 -> 0 | H14: =[1]REVENUE_ENGINE!H21 -> 0 | I14: =[1]REVENUE_ENGINE!I21 -> 0 | J14: =[1]REVENUE_ENGINE!J21 -> 0 | ... O14: =[1]REVENUE_ENGINE!O21 -> 48800 | Q14: 01_efir_revenue_fy2026.xlsx' → REVENUE_ENGINE!Row 21
A15: Activities & Services | B15: After-School Activities (APS) | C15: =[1]REVENUE_ENGINE!C25 -> 123000 | D15: =[1]REVENUE_ENGINE!D25 -> 123000 | E15: =[1]REVENUE_ENGINE!E25 -> 123000 | F15: =[1]REVENUE_ENGINE!F25 -> 123000 | G15: =[1]REVENUE_ENGINE!G25 -> 123000 | H15: =[1]REVENUE_ENGINE!H25 -> 123000 | I15: =[1]REVENUE_ENGINE!I25 -> 0 | J15: =[1]REVENUE_ENGINE!J25 -> 0 | ... O15: =[1]REVENUE_ENGINE!O25 -> 1230000 | Q15: 01_efir_revenue_fy2026.xlsx' → REVENUE_ENGINE!Row 25
A16: Activities & Services | B16: Daycare (Garderie) | C16: =[1]REVENUE_ENGINE!C26 -> 3000 | D16: =[1]REVENUE_ENGINE!D26 -> 3000 | E16: =[1]REVENUE_ENGINE!E26 -> 3000 | F16: =[1]REVENUE_ENGINE!F26 -> 3000 | G16: =[1]REVENUE_ENGINE!G26 -> 3000 | H16: =[1]REVENUE_ENGINE!H26 -> 3000 | I16: =[1]REVENUE_ENGINE!I26 -> 0 | J16: =[1]REVENUE_ENGINE!J26 -> 0 | ... O16: =[1]REVENUE_ENGINE!O26 -> 30000 | Q16: 01_efir_revenue_fy2026.xlsx' → REVENUE_ENGINE!Row 26
A17: Activities & Services | B17: Class Photos | C17: =[1]REVENUE_ENGINE!C27 -> 0 | D17: =[1]REVENUE_ENGINE!D27 -> 0 | E17: =[1]REVENUE_ENGINE!E27 -> 0 | F17: =[1]REVENUE_ENGINE!F27 -> 0 | G17: =[1]REVENUE_ENGINE!G27 -> 0 | H17: =[1]REVENUE_ENGINE!H27 -> 0 | I17: =[1]REVENUE_ENGINE!I27 -> 0 | J17: =[1]REVENUE_ENGINE!J27 -> 0 | ... O17: =[1]REVENUE_ENGINE!O27 -> 52800 | Q17: 01_efir_revenue_fy2026.xlsx' → REVENUE_ENGINE!Row 27
A18: Examination Fees | B18: BAC Examination Fees | C18: =[1]REVENUE_ENGINE!C31 -> 0 | D18: =[1]REVENUE_ENGINE!D31 -> 0 | E18: =[1]REVENUE_ENGINE!E31 -> 0 | F18: =[1]REVENUE_ENGINE!F31 -> 111000 | G18: =[1]REVENUE_ENGINE!G31 -> 111000 | H18: =[1]REVENUE_ENGINE!H31 -> 0 | I18: =[1]REVENUE_ENGINE!I31 -> 0 | J18: =[1]REVENUE_ENGINE!J31 -> 0 | ... O18: =[1]REVENUE_ENGINE!O31 -> 222000 | Q18: 01_efir_revenue_fy2026.xlsx' → REVENUE_ENGINE!Row 31
A19: Examination Fees | B19: DNB Examination Fees | C19: =[1]REVENUE_ENGINE!C32 -> 0 | D19: =[1]REVENUE_ENGINE!D32 -> 0 | E19: =[1]REVENUE_ENGINE!E32 -> 0 | F19: =[1]REVENUE_ENGINE!F32 -> 30900 | G19: =[1]REVENUE_ENGINE!G32 -> 30900 | H19: =[1]REVENUE_ENGINE!H32 -> 0 | I19: =[1]REVENUE_ENGINE!I32 -> 0 | J19: =[1]REVENUE_ENGINE!J32 -> 0 | ... O19: =[1]REVENUE_ENGINE!O32 -> 61800 | Q19: 01_efir_revenue_fy2026.xlsx' → REVENUE_ENGINE!Row 32
A20: Examination Fees | B20: EAF Examination Fees | C20: =[1]REVENUE_ENGINE!C33 -> 0 | D20: =[1]REVENUE_ENGINE!D33 -> 0 | E20: =[1]REVENUE_ENGINE!E33 -> 0 | F20: =[1]REVENUE_ENGINE!F33 -> 48000 | G20: =[1]REVENUE_ENGINE!G33 -> 48000 | H20: =[1]REVENUE_ENGINE!H33 -> 0 | I20: =[1]REVENUE_ENGINE!I33 -> 0 | J20: =[1]REVENUE_ENGINE!J33 -> 0 | ... O20: =[1]REVENUE_ENGINE!O33 -> 96000 | Q20: 01_efir_revenue_fy2026.xlsx' → REVENUE_ENGINE!Row 33
A21: Examination Fees | B21: SIELE Examination Fees | C21: =[1]REVENUE_ENGINE!C34 -> 0 | D21: =[1]REVENUE_ENGINE!D34 -> 0 | E21: =[1]REVENUE_ENGINE!E34 -> 0 | F21: =[1]REVENUE_ENGINE!F34 -> 0 | G21: =[1]REVENUE_ENGINE!G34 -> 0 | H21: =[1]REVENUE_ENGINE!H34 -> 0 | I21: =[1]REVENUE_ENGINE!I34 -> 0 | J21: =[1]REVENUE_ENGINE!J34 -> 0 | ... O21: =[1]REVENUE_ENGINE!O34 -> 15000 | Q21: 01_efir_revenue_fy2026.xlsx' → REVENUE_ENGINE!Row 34
B22: Total Revenue from Contracts with Customers | C22: =SUM(C6:C21) -> 5728363.8 | D22: =SUM(D6:D21) -> 5728363.8 | E22: =SUM(E6:E21) -> 5728363.8 | F22: =SUM(F6:F21) -> 5918263.8 | G22: =SUM(G6:G21) -> 10621289 | H22: =SUM(H6:H21) -> 10431389 | I22: =SUM(I6:I21) -> 0 | J22: =SUM(J6:J21) -> 0 | ... O22: =SUM(O6:O21) -> 67849791
B23: TOTAL REVENUE | C23: =C22 -> 5728363.8 | D23: =D22 -> 5728363.8 | E23: =E22 -> 5728363.8 | F23: =F22 -> 5918263.8 | G23: =G22 -> 10621289 | H23: =H22 -> 10431389 | I23: =I22 -> 0 | J23: =J22 -> 0 | ... O23: =O22 -> 67849791
A24: STAFF COSTS
A25: Local Staff Salaries | B25: Existing Staff Salaries | C25: ='[2]Budget Summary'!B10 -> 1895394.4 | D25: ='[2]Budget Summary'!C10 -> 1895394.4 | E25: ='[2]Budget Summary'!D10 -> 1895394.4 | F25: ='[2]Budget Summary'!E10 -> 1895394.4 | G25: ='[2]Budget Summary'!F10 -> 1895394.4 | H25: ='[2]Budget Summary'!G10 -> 1895394.4 | I25: ='[2]Budget Summary'!H10 -> 1895394.4 | J25: ='[2]Budget Summary'!I10 -> 1895394.4 | ... N25: ='[2]Budget Summary'!M10 -> 1924743.7 | O25: =SUM(C25:N25) -> 22862130 | Q25: '02_efir_staff_costs_fy2026.xlsx' → Budget Summary!Row 10
A26: Local Staff Salaries | B26: New Positions (Sep-Dec) | C26: ='[2]Budget Summary'!B30 -> 0 | D26: ='[2]Budget Summary'!C30 -> 0 | E26: ='[2]Budget Summary'!D30 -> 0 | F26: ='[2]Budget Summary'!E30 -> 0 | G26: ='[2]Budget Summary'!F30 -> 0 | H26: ='[2]Budget Summary'!G30 -> 0 | I26: ='[2]Budget Summary'!H30 -> 0 | J26: ='[2]Budget Summary'!I30 -> 0 | ... N26: ='[2]Budget Summary'!M30 -> 57400 | O26: =SUM(C26:N26) -> 229600 | Q26: '02_efir_staff_costs_fy2026.xlsx' → Budget Summary!Row 30
A27: Additional Staff Costs | B27: Replacement Contracts | C27: ='[2]Budget Summary'!B13 -> 30000 | D27: ='[2]Budget Summary'!C13 -> 30000 | E27: ='[2]Budget Summary'!D13 -> 30000 | F27: ='[2]Budget Summary'!E13 -> 30000 | G27: ='[2]Budget Summary'!F13 -> 30000 | H27: ='[2]Budget Summary'!G13 -> 30000 | I27: ='[2]Budget Summary'!H13 -> 0 | J27: ='[2]Budget Summary'!I13 -> 0 | ... N27: ='[2]Budget Summary'!M13 -> 30000 | O27: =SUM(C27:N27) -> 300000 | Q27: '02_efir_staff_costs_fy2026.xlsx' → Budget Summary!Row 13
A28: Additional Staff Costs | B28: Continuing Education (1%) | C28: ='[2]Budget Summary'!B14 -> 18953.944 | D28: ='[2]Budget Summary'!C14 -> 18953.944 | E28: ='[2]Budget Summary'!D14 -> 18953.944 | F28: ='[2]Budget Summary'!E14 -> 18953.944 | G28: ='[2]Budget Summary'!F14 -> 18953.944 | H28: ='[2]Budget Summary'!G14 -> 18953.944 | I28: ='[2]Budget Summary'!H14 -> 18953.944 | J28: ='[2]Budget Summary'!I14 -> 18953.944 | ... N28: ='[2]Budget Summary'!M14 -> 19247.437 | O28: =SUM(C28:N28) -> 228621.3 | Q28: '02_efir_staff_costs_fy2026.xlsx' → Budget Summary!Row 14
A29: Additional Staff Costs | B29: Garderie Salaries | C29: ='[2]Budget Summary'!B16 -> 6000 | D29: ='[2]Budget Summary'!C16 -> 6000 | E29: ='[2]Budget Summary'!D16 -> 6000 | F29: ='[2]Budget Summary'!E16 -> 6000 | G29: ='[2]Budget Summary'!F16 -> 6000 | H29: ='[2]Budget Summary'!G16 -> 6000 | I29: ='[2]Budget Summary'!H16 -> 0 | J29: ='[2]Budget Summary'!I16 -> 0 | ... N29: ='[2]Budget Summary'!M16 -> 6000 | O29: =SUM(C29:N29) -> 60000 | Q29: '02_efir_staff_costs_fy2026.xlsx' → Budget Summary!Row 16
A30: Additional Staff Costs | B30: APS Salaries | C30: ='[2]Budget Summary'!B17 -> 60000 | D30: ='[2]Budget Summary'!C17 -> 60000 | E30: ='[2]Budget Summary'!D17 -> 60000 | F30: ='[2]Budget Summary'!E17 -> 60000 | G30: ='[2]Budget Summary'!F17 -> 60000 | H30: ='[2]Budget Summary'!G17 -> 60000 | I30: ='[2]Budget Summary'!H17 -> 0 | J30: ='[2]Budget Summary'!I17 -> 0 | ... N30: ='[2]Budget Summary'!M17 -> 60000 | O30: =SUM(C30:N30) -> 600000 | Q30: '02_efir_staff_costs_fy2026.xlsx' → Budget Summary!Row 17
A31: Additional Staff Costs | B31: Études Dirigées | C31: ='[2]Budget Summary'!B18 -> 4000 | D31: ='[2]Budget Summary'!C18 -> 4000 | E31: ='[2]Budget Summary'!D18 -> 4000 | F31: ='[2]Budget Summary'!E18 -> 4000 | G31: ='[2]Budget Summary'!F18 -> 4000 | H31: ='[2]Budget Summary'!G18 -> 4000 | I31: ='[2]Budget Summary'!H18 -> 0 | J31: ='[2]Budget Summary'!I18 -> 0 | ... N31: ='[2]Budget Summary'!M18 -> 4000 | O31: =SUM(C31:N31) -> 40000 | Q31: '02_efir_staff_costs_fy2026.xlsx' → Budget Summary!Row 18
A32: Additional Staff Costs | B32: Resident Salaries | C32: ='[2]Budget Summary'!B20 -> 800000 | D32: ='[2]Budget Summary'!C20 -> 800000 | E32: ='[2]Budget Summary'!D20 -> 800000 | F32: ='[2]Budget Summary'!E20 -> 800000 | G32: ='[2]Budget Summary'!F20 -> 800000 | H32: ='[2]Budget Summary'!G20 -> 800000 | I32: ='[2]Budget Summary'!H20 -> 0 | J32: ='[2]Budget Summary'!I20 -> 0 | ... N32: ='[2]Budget Summary'!M20 -> 800000 | O32: =SUM(C32:N32) -> 8000000 | Q32: '02_efir_staff_costs_fy2026.xlsx' → Budget Summary!Row 20
A33: Additional Staff Costs | B33: Resident Housing & Flights | C33: ='[2]Budget Summary'!B22 -> 40000 | D33: ='[2]Budget Summary'!C22 -> 40000 | E33: ='[2]Budget Summary'!D22 -> 40000 | F33: ='[2]Budget Summary'!E22 -> 40000 | G33: ='[2]Budget Summary'!F22 -> 40000 | H33: ='[2]Budget Summary'!G22 -> 40000 | I33: ='[2]Budget Summary'!H22 -> 0 | J33: ='[2]Budget Summary'!I22 -> 0 | ... N33: ='[2]Budget Summary'!M22 -> 40000 | O33: =SUM(C33:N33) -> 400000 | Q33: '02_efir_staff_costs_fy2026.xlsx' → Budget Summary!Row 22
A34: Employer Charges | B34: GOSI – Saudi Employees | C34: ='[2]Budget Summary'!B25 -> 1733.125 | D34: ='[2]Budget Summary'!C25 -> 1733.125 | E34: ='[2]Budget Summary'!D25 -> 1733.125 | F34: ='[2]Budget Summary'!E25 -> 1733.125 | G34: ='[2]Budget Summary'!F25 -> 1733.125 | H34: ='[2]Budget Summary'!G25 -> 1733.125 | I34: ='[2]Budget Summary'!H25 -> 1733.125 | J34: ='[2]Budget Summary'!I25 -> 1733.125 | ... N34: ='[2]Budget Summary'!M25 -> 1762.5 | O34: =SUM(C34:N34) -> 20915 | Q34: '02_efir_staff_costs_fy2026.xlsx' → Budget Summary!Row 25
A35: Employer Charges | B35: End of Service Provision | C35: ='[2]Budget Summary'!B26 -> 109531.26 | D35: ='[2]Budget Summary'!C26 -> 109531.26 | E35: ='[2]Budget Summary'!D26 -> 98931.46 | F35: ='[2]Budget Summary'!E26 -> 109531.26 | G35: ='[2]Budget Summary'!F26 -> 105997.99 | H35: ='[2]Budget Summary'!G26 -> 109531.26 | I35: ='[2]Budget Summary'!H26 -> 105997.99 | J35: ='[2]Budget Summary'!I26 -> 109531.26 | ... N35: ='[2]Budget Summary'!M26 -> 117920.45 | O35: =SUM(C35:N35) -> 1484959.3 | Q35: '02_efir_staff_costs_fy2026.xlsx' → Budget Summary!Row 26
A36: Employer Charges | B36: Ajeer Costs – Existing | C36: ='[2]Budget Summary'!B27 -> 136562.5 | D36: ='[2]Budget Summary'!C27 -> 136562.5 | E36: ='[2]Budget Summary'!D27 -> 136562.5 | F36: ='[2]Budget Summary'!E27 -> 136562.5 | G36: ='[2]Budget Summary'!F27 -> 136562.5 | H36: ='[2]Budget Summary'!G27 -> 136562.5 | I36: ='[2]Budget Summary'!H27 -> 136562.5 | J36: ='[2]Budget Summary'!I27 -> 136562.5 | ... N36: ='[2]Budget Summary'!M27 -> 136562.5 | O36: =SUM(C36:N36) -> 1638750 | Q36: '02_efir_staff_costs_fy2026.xlsx' → Budget Summary!Row 27
A37: Employer Charges | B37: Ajeer Costs – New Positions | C37: ='[2]Budget Summary'!B32 -> 0 | D37: ='[2]Budget Summary'!C32 -> 0 | E37: ='[2]Budget Summary'!D32 -> 0 | F37: ='[2]Budget Summary'!E32 -> 0 | G37: ='[2]Budget Summary'!F32 -> 0 | H37: ='[2]Budget Summary'!G32 -> 0 | I37: ='[2]Budget Summary'!H32 -> 0 | J37: ='[2]Budget Summary'!I32 -> 0 | ... N37: ='[2]Budget Summary'!M32 -> 5462.5 | O37: =SUM(C37:N37) -> 21850 | Q37: '02_efir_staff_costs_fy2026.xlsx' → Budget Summary!Row 32
B38: Total Staff Costs | C38: =SUM(C25:C37) -> 3102175.2 | D38: =SUM(D25:D37) -> 3102175.2 | E38: =SUM(E25:E37) -> 3091575.4 | F38: =SUM(F25:F37) -> 3102175.2 | G38: =SUM(G25:G37) -> 3098642 | H38: =SUM(H25:H37) -> 3102175.2 | I38: =SUM(I25:I37) -> 2158642 | J38: =SUM(J25:J37) -> 2162175.2 | ... O38: =SUM(O25:O37) -> 35886826
A39: OTHER OPERATING EXPENSES
A40: Rent & Utilities | B40: Rent & Utilities | C40: =[3]Operating_Expenses!C9 -> 748459.83 | D40: =[3]Operating_Expenses!D9 -> 748459.83 | E40: =[3]Operating_Expenses!E9 -> 748459.83 | F40: =[3]Operating_Expenses!F9 -> 748459.83 | G40: =[3]Operating_Expenses!G9 -> 748459.83 | H40: =[3]Operating_Expenses!H9 -> 748459.83 | I40: =[3]Operating_Expenses!I9 -> 748459.83 | J40: =[3]Operating_Expenses!J9 -> 748459.83 | ... N40: =[3]Operating_Expenses!N9 -> 748459.83 | O40: =SUM(C40:N40) -> 8981518 | Q40: '03_efir_opex_fy2026.xlsx' → Operating_Expenses!Row 9 | R40: ✅ Verified vs source Row 9 — all 12 months match
A41: Building Services | B41: Building Services | C41: =[3]Operating_Expenses!C15 -> 409721 | D41: =[3]Operating_Expenses!D15 -> 409721 | E41: =[3]Operating_Expenses!E15 -> 409721 | F41: =[3]Operating_Expenses!F15 -> 409721 | G41: =[3]Operating_Expenses!G15 -> 409721 | H41: =[3]Operating_Expenses!H15 -> 409721 | I41: =[3]Operating_Expenses!I15 -> 374721 | J41: =[3]Operating_Expenses!J15 -> 374721 | ... N41: =[3]Operating_Expenses!N15 -> 409721 | O41: =SUM(C41:N41) -> 4846652 | Q41: '03_efir_opex_fy2026.xlsx' → Operating_Expenses!Row 15 | R41: ✅ Verified vs source Row 15 — seasonal drops Jul/Aug match
...

Sheet IFRS_Income_Statement
A1: EFIR – BUDGET INCOME STATEMENT FY2026
A2: Presented per IAS 1 — Function of Expense Method — Currency: SAR
B4: Jan | C4: Feb | D4: Mar | E4: Apr | F4: May | G4: Jun | H4: Jul | I4: Aug | J4: Sep | K4: Oct | L4: Nov | M4: Dec | N4: FY2026 Total
A5: Revenue
A6: Tuition fees | B6: =SUM(IFRS_Mapping!C6:C11) -> 5602363.8 | C6: =SUM(IFRS_Mapping!D6:D11) -> 5602363.8 | D6: =SUM(IFRS_Mapping!E6:E11) -> 5602363.8 | E6: =SUM(IFRS_Mapping!F6:F11) -> 5602363.8 | F6: =SUM(IFRS_Mapping!G6:G11) -> 5602363.8 | G6: =SUM(IFRS_Mapping!H6:H11) -> 5602363.8 | H6: =SUM(IFRS_Mapping!I6:I11) -> 0 | I6: =SUM(IFRS_Mapping!J6:J11) -> 0 | ... M6: =SUM(IFRS_Mapping!N6:N11) -> 5756089.6 | N6: =SUM(B6:M6) -> 56638541
A7: Registration & re-registration fees | B7: =SUM(IFRS_Mapping!C12:C14) -> 0 | C7: =SUM(IFRS_Mapping!D12:D14) -> 0 | D7: =SUM(IFRS_Mapping!E12:E14) -> 0 | E7: =SUM(IFRS_Mapping!F12:F14) -> 0 | F7: =SUM(IFRS_Mapping!G12:G14) -> 4703025 | G7: =SUM(IFRS_Mapping!H12:H14) -> 4703025 | H7: =SUM(IFRS_Mapping!I12:I14) -> 0 | I7: =SUM(IFRS_Mapping!J12:J14) -> 0 | ... M7: =SUM(IFRS_Mapping!N12:N14) -> 0 | N7: =SUM(B7:M7) -> 9503650
A8: Activities & services | B8: =SUM(IFRS_Mapping!C15:C17) -> 126000 | C8: =SUM(IFRS_Mapping!D15:D17) -> 126000 | D8: =SUM(IFRS_Mapping!E15:E17) -> 126000 | E8: =SUM(IFRS_Mapping!F15:F17) -> 126000 | F8: =SUM(IFRS_Mapping!G15:G17) -> 126000 | G8: =SUM(IFRS_Mapping!H15:H17) -> 126000 | H8: =SUM(IFRS_Mapping!I15:I17) -> 0 | I8: =SUM(IFRS_Mapping!J15:J17) -> 0 | ... M8: =SUM(IFRS_Mapping!N15:N17) -> 152400 | N8: =SUM(B8:M8) -> 1312800
A9: Examination fees | B9: =SUM(IFRS_Mapping!C18:C21) -> 0 | C9: =SUM(IFRS_Mapping!D18:D21) -> 0 | D9: =SUM(IFRS_Mapping!E18:E21) -> 0 | E9: =SUM(IFRS_Mapping!F18:F21) -> 189900 | F9: =SUM(IFRS_Mapping!G18:G21) -> 189900 | G9: =SUM(IFRS_Mapping!H18:H21) -> 0 | H9: =SUM(IFRS_Mapping!I18:I21) -> 0 | I9: =SUM(IFRS_Mapping!J18:J21) -> 0 | ... M9: =SUM(IFRS_Mapping!N18:N21) -> 0 | N9: =SUM(B9:M9) -> 394800
A10: Revenue from contracts with customers | B10: =IFRS_Mapping!C22 -> 5728363.8 | C10: =IFRS_Mapping!D22 -> 5728363.8 | D10: =IFRS_Mapping!E22 -> 5728363.8 | E10: =IFRS_Mapping!F22 -> 5918263.8 | F10: =IFRS_Mapping!G22 -> 10621289 | G10: =IFRS_Mapping!H22 -> 10431389 | H10: =IFRS_Mapping!I22 -> 0 | I10: =IFRS_Mapping!J22 -> 0 | ... M10: =IFRS_Mapping!N22 -> 5908489.6 | N10: =SUM(B10:M10) -> 67849791
A11: Rental income | B11: =0 -> 0 | C11: =0 -> 0 | D11: =0 -> 0 | E11: =0 -> 0 | F11: =0 -> 0 | G11: =0 -> 0 | H11: =0 -> 0 | I11: =0 -> 0 | ... M11: =0 -> 0 | N11: =SUM(B11:M11) -> 0
A12: Total Revenue | B12: =IFRS_Mapping!C23 -> 5728363.8 | C12: =IFRS_Mapping!D23 -> 5728363.8 | D12: =IFRS_Mapping!E23 -> 5728363.8 | E12: =IFRS_Mapping!F23 -> 5918263.8 | F12: =IFRS_Mapping!G23 -> 10621289 | G12: =IFRS_Mapping!H23 -> 10431389 | H12: =IFRS_Mapping!I23 -> 0 | I12: =IFRS_Mapping!J23 -> 0 | ... M12: =IFRS_Mapping!N23 -> 5908489.6 | N12: =SUM(B12:M12) -> 67849791
A14: Operating Expenses
A15: Staff costs | B15: =-IFRS_Mapping!C38 -> -3102175.2 | C15: =-IFRS_Mapping!D38 -> -3102175.2 | D15: =-IFRS_Mapping!E38 -> -3091575.4 | E15: =-IFRS_Mapping!F38 -> -3102175.2 | F15: =-IFRS_Mapping!G38 -> -3098642 | G15: =-IFRS_Mapping!H38 -> -3102175.2 | H15: =-IFRS_Mapping!I38 -> -2158642 | I15: =-IFRS_Mapping!J38 -> -2162175.2 | ... M15: =-IFRS_Mapping!N38 -> -3203099.1 | N15: =SUM(B15:M15) -> -35886826
A16: Other operating expenses | B16: =-IFRS_Mapping!C52 -> -1922625 | C16: =-IFRS_Mapping!D52 -> -1922625 | D16: =-IFRS_Mapping!E52 -> -1922625 | E16: =-IFRS_Mapping!F52 -> -1922625 | F16: =-IFRS_Mapping!G52 -> -1922625 | G16: =-IFRS_Mapping!H52 -> -2352409.4 | H16: =-IFRS_Mapping!I52 -> -1381825.9 | I16: =-IFRS_Mapping!J52 -> -1381825.9 | ... M16: =-IFRS_Mapping!N52 -> -1922625 | N16: =SUM(B16:M16) -> -22473182
A17: Depreciation & amortization | B17: =-IFRS_Mapping!C55 -> -439818 | C17: =-IFRS_Mapping!D55 -> -439818 | D17: =-IFRS_Mapping!E55 -> -439818 | E17: =-IFRS_Mapping!F55 -> -439818 | F17: =-IFRS_Mapping!G55 -> -439818 | G17: =-IFRS_Mapping!H55 -> -439818 | H17: =-IFRS_Mapping!I55 -> -439818 | I17: =-IFRS_Mapping!J55 -> -439818 | ... M17: =-IFRS_Mapping!N55 -> -439818 | N17: =SUM(B17:M17) -> -5277816
A18: Impairment losses on receivables | B18: =-IFRS_Mapping!C58 -> 0 | C18: =-IFRS_Mapping!D58 -> 0 | D18: =-IFRS_Mapping!E58 -> 0 | E18: =-IFRS_Mapping!F58 -> 0 | F18: =-IFRS_Mapping!G58 -> 0 | G18: =-IFRS_Mapping!H58 -> 0 | H18: =-IFRS_Mapping!I58 -> 0 | I18: =-IFRS_Mapping!J58 -> 0 | ... M18: =-IFRS_Mapping!N58 -> 0 | N18: =SUM(B18:M18) -> 0
A19: Total Operating Expenses | B19: =-IFRS_Mapping!C59 -> -5464618.3 | C19: =-IFRS_Mapping!D59 -> -5464618.3 | D19: =-IFRS_Mapping!E59 -> -5454018.5 | E19: =-IFRS_Mapping!F59 -> -5464618.3 | F19: =-IFRS_Mapping!G59 -> -5461085 | G19: =-IFRS_Mapping!H59 -> -5894402.7 | H19: =-IFRS_Mapping!I59 -> -3980285.9 | I19: =-IFRS_Mapping!J59 -> -3983819.1 | ... M19: =-IFRS_Mapping!N59 -> -5565542.1 | N19: =SUM(B19:M19) -> -63637824
A21: OPERATING PROFIT / (LOSS) | B21: =IFRS_Mapping!C60 -> 263745.5 | C21: =IFRS_Mapping!D60 -> 263745.5 | D21: =IFRS_Mapping!E60 -> 274345.3 | E21: =IFRS_Mapping!F60 -> 453645.5 | F21: =IFRS_Mapping!G60 -> 5160203.8 | G21: =IFRS_Mapping!H60 -> 4536986.1 | H21: =IFRS_Mapping!I60 -> -3980285.9 | I21: =IFRS_Mapping!J60 -> -3983819.1 | ... M21: =IFRS_Mapping!N60 -> 342947.5 | N21: =SUM(B21:M21) -> 4211967.5
A23: Finance
A24: Finance income | B24: =IFRS_Mapping!C64 -> 41666.67 | C24: =IFRS_Mapping!D64 -> 41666.67 | D24: =IFRS_Mapping!E64 -> 41666.67 | E24: =IFRS_Mapping!F64 -> 41666.67 | F24: =IFRS_Mapping!G64 -> 41666.67 | G24: =IFRS_Mapping!H64 -> 41666.67 | H24: =IFRS_Mapping!I64 -> 41666.67 | I24: =IFRS_Mapping!J64 -> 41666.67 | ... M24: =IFRS_Mapping!N64 -> 41666.67 | N24: =SUM(B24:M24) -> 500000.04
A25: Finance costs | B25: =-IFRS_Mapping!C68 -> -23820.85 | C25: =-IFRS_Mapping!D68 -> -23820.85 | D25: =-IFRS_Mapping!E68 -> -23820.85 | E25: =-IFRS_Mapping!F68 -> -23820.85 | F25: =-IFRS_Mapping!G68 -> -23820.85 | G25: =-IFRS_Mapping!H68 -> -23820.85 | H25: =-IFRS_Mapping!I68 -> -23820.85 | I25: =-IFRS_Mapping!J68 -> -23820.85 | ... M25: =-IFRS_Mapping!N68 -> -23820.85 | N25: =SUM(B25:M25) -> -285850.2
A26: Net Finance Income / (Cost) | B26: =IFRS_Mapping!C69 -> 17845.82 | C26: =IFRS_Mapping!D69 -> 17845.82 | D26: =IFRS_Mapping!E69 -> 17845.82 | E26: =IFRS_Mapping!F69 -> 17845.82 | F26: =IFRS_Mapping!G69 -> 17845.82 | G26: =IFRS_Mapping!H69 -> 17845.82 | H26: =IFRS_Mapping!I69 -> 17845.82 | I26: =IFRS_Mapping!J69 -> 17845.82 | ... M26: =IFRS_Mapping!N69 -> 17845.82 | N26: =SUM(B26:M26) -> 214149.84
A28: PROFIT / (LOSS) BEFORE ZAKAT | B28: =IFRS_Mapping!C70 -> 281591.32 | C28: =IFRS_Mapping!D70 -> 281591.32 | D28: =IFRS_Mapping!E70 -> 292191.12 | E28: =IFRS_Mapping!F70 -> 471491.32 | F28: =IFRS_Mapping!G70 -> 5178049.6 | G28: =IFRS_Mapping!H70 -> 4554831.9 | H28: =IFRS_Mapping!I70 -> -3962440 | I28: =IFRS_Mapping!J70 -> -3965973.3 | ... M28: =IFRS_Mapping!N70 -> 360793.32 | N28: =SUM(B28:M28) -> 4426117.3
A29: Estimated Zakat (2.5%) | B29: =-IFRS_Mapping!C71 -> 7039.7829 | C29: =-IFRS_Mapping!D71 -> 7039.7829 | D29: =-IFRS_Mapping!E71 -> 7304.7779 | E29: =-IFRS_Mapping!F71 -> 11787.283 | F29: =-IFRS_Mapping!G71 -> 129451.24 | G29: =-IFRS_Mapping!H71 -> 113870.8 | H29: =-IFRS_Mapping!I71 -> 0 | I29: =-IFRS_Mapping!J71 -> 0 | ... M29: =-IFRS_Mapping!N71 -> 9019.833 | N29: =SUM(B29:M29) -> 308863.27
A31: NET PROFIT / (LOSS) FOR THE PERIOD | B31: =IFRS_Mapping!C72 -> 274551.53 | C31: =IFRS_Mapping!D72 -> 274551.53 | D31: =IFRS_Mapping!E72 -> 284886.34 | E31: =IFRS_Mapping!F72 -> 459704.03 | F31: =IFRS_Mapping!G72 -> 5048598.3 | G31: =IFRS_Mapping!H72 -> 4440961.1 | H31: =IFRS_Mapping!I72 -> -3962440 | I31: =IFRS_Mapping!J72 -> -3965973.3 | ... M31: =IFRS_Mapping!N72 -> 351773.49 | N31: =SUM(B31:M31) -> 4117254.1
A33: Notes:
A34: 1. Revenue presented net per IFRS 15 — Moyasar processing fees reclassified to Finance Costs.
A35: 2. Bad debt provision reclassified to Impairment Losses per IFRS 9 (Expected Credit Loss model).
A36: 3. Bank charges and FX losses reclassified from Administrative & General to Finance Costs per IAS 1.
A37: 4. Financial income (investment returns & FX gains) separated from operating revenue per IAS 1.
A38: 5. Zakat estimated at 2.5% on positive monthly profit — actual computation per ZATCA regulations may differ.
