Workbook

Sheet IFRS Mapping
A1: EFIR – IFRS RECLASSIFIED MONTHLY BUDGET FY2026
A2: Reclassified per IAS 1 Presentation — Currency: SAR
A4: IFRS Category | B4: Line Item | C4: Jan | D4: Feb | E4: Mar | F4: Apr | G4: May | H4: Jun | I4: Jul | J4: Aug | K4: Sep | L4: Oct | M4: Nov | N4: Dec | O4: FY2026 Total | Q4: Comments
A5: REVENUE FROM CONTRACTS WITH CUSTOMERS (IFRS 15)
A6: Tuition Fees | B6: Maternelle – Tarif Réduit | C6: 138227.96 | D6: 138227.96 | E6: 138227.96 | F6: 138227.96 | G6: 138227.96 | H6: 138227.96 | I6: 0 | J6: 0 | K6: 138227.96 | L6: 138227.96 | M6: 138227.96 | N6: 138227.96 | O6: =SUM(C6:N6) -> 1382279.6
A7: Tuition Fees | B7: Maternelle – Tarif Plein | C7: 574782.21 | D7: 574782.21 | E7: 574782.21 | F7: 574782.21 | G7: 574782.21 | H7: 574782.21 | I7: 0 | J7: 0 | K7: 574782.21 | L7: 574782.21 | M7: 574782.21 | N7: 574782.21 | O7: =SUM(C7:N7) -> 5747822.1
A8: Tuition Fees | B8: Élémentaire – Tarif Réduit | C8: 322596.69 | D8: 322596.69 | E8: 322596.69 | F8: 322596.69 | G8: 322596.69 | H8: 322596.69 | I8: 0 | J8: 0 | K8: 322596.69 | L8: 322596.69 | M8: 322596.69 | N8: 322596.69 | O8: =SUM(C8:N8) -> 3225966.9
A9: Tuition Fees | B9: Élémentaire – Tarif Plein | C9: 1712432.6 | D9: 1712432.6 | E9: 1712432.6 | F9: 1712432.6 | G9: 1712432.6 | H9: 1712432.6 | I9: 0 | J9: 0 | K9: 1712432.6 | L9: 1712432.6 | M9: 1712432.6 | N9: 1712432.6 | O9: =SUM(C9:N9) -> 17124326
A10: Tuition Fees | B10: Collège – Tarif Réduit | C10: 142238.8 | D10: 142238.8 | E10: 142238.8 | F10: 142238.8 | G10: 142238.8 | H10: 142238.8 | I10: 0 | J10: 0 | K10: 142238.8 | L10: 142238.8 | M10: 142238.8 | N10: 142238.8 | O10: =SUM(C10:N10) -> 1422388
A11: Tuition Fees | B11: Collège – Tarif Plein | C11: 1631389.1 | D11: 1631389.1 | E11: 1631389.1 | F11: 1631389.1 | G11: 1631389.1 | H11: 1631389.1 | I11: 0 | J11: 0 | K11: 1631389.1 | L11: 1631389.1 | M11: 1631389.1 | N11: 1631389.1 | O11: =SUM(C11:N11) -> 16313891
A12: Tuition Fees | B12: Lycée – Tarif Réduit | C12: 63065.22 | D12: 63065.22 | E12: 63065.22 | F12: 63065.22 | G12: 63065.22 | H12: 63065.22 | I12: 0 | J12: 0 | K12: 63065.22 | L12: 63065.22 | M12: 63065.22 | N12: 63065.22 | O12: =SUM(C12:N12) -> 630652.2
A13: Tuition Fees | B13: Lycée – Tarif Plein | C13: 1236173.9 | D13: 1236173.9 | E13: 1236173.9 | F13: 1236173.9 | G13: 1236173.9 | H13: 1236173.9 | I13: 0 | J13: 0 | K13: 1236173.9 | L13: 1236173.9 | M13: 1236173.9 | N13: 1236173.9 | O13: =SUM(C13:N13) -> 12361739
A14: Registration Fees | B14: New Student Registration (DPI/FD) | C14: 0 | D14: 0 | E14: 0 | F14: 0 | G14: 0 | H14: 0 | I14: 0 | J14: 0 | K14: 936000 | L14: 0 | M14: 0 | N14: 0 | O14: =SUM(C14:N14) -> 936000
A15: Registration Fees | B15: Re-registration (DAI) | C15: 0 | D15: 0 | E15: 0 | F15: 0 | G15: 0 | H15: 7620291 | I15: 0 | J15: 0 | K15: 0 | L15: 0 | M15: 0 | N15: 0 | O15: =SUM(C15:N15) -> 7620291
A16: Registration Fees | B16: Evaluation Tests | C16: 0 | D16: 0 | E16: 0 | F16: 0 | G16: 0 | H16: 0 | I16: 0 | J16: 0 | K16: 6250 | L16: 6250 | M16: 0 | N16: 0 | O16: =SUM(C16:N16) -> 12500
A17: Activities & Services | B17: After-School Activities (APS) | C17: 123000 | D17: 123000 | E17: 123000 | F17: 123000 | G17: 123000 | H17: 123000 | I17: 0 | J17: 0 | K17: 123000 | L17: 123000 | M17: 123000 | N17: 123000 | O17: =SUM(C17:N17) -> 1230000
... A21: Examination Fees | B21: DNB Examination Fees | C21: 0 | D21: 0 | E21: 0 | F21: 30375 | G21: 30375 | H21: 0 | I21: 0 | J21: 0 | K21: 0 | L21: 0 | M21: 0 | N21: 0 | O21: =SUM(C21:N21) -> 60750
A22: Examination Fees | B22: EAF Examination Fees | C22: 0 | D22: 0 | E22: 0 | F22: 45375 | G22: 45375 | H22: 0 | I22: 0 | J22: 0 | K22: 0 | L22: 0 | M22: 0 | N22: 0 | O22: =SUM(C22:N22) -> 90750 | R22: students | S22: fees/student
B23: Total Revenue from Contracts with Customers | C23: =SUM(C6:C22) -> 5946906.5 | D23: =SUM(D6:D22) -> 5946906.5 | E23: =SUM(E6:E22) -> 5946906.5 | F23: =SUM(F6:F22) -> 6129146 | G23: =SUM(G6:G22) -> 6129146 | H23: =SUM(H6:H22) -> 13567198 | I23: =SUM(I6:I22) -> 0 | J23: =SUM(J6:J22) -> 0 | ... O23: =SUM(O6:O22) -> 68455135 | R23: 1753 | S23: =O23/R23 -> 39050.277 | V23: Confirmed
A25: RENTAL INCOME (IFRS 16)
A26: Rental Income | B26: PSG Academy KSA (Rental) | C26: 4269.17 | D26: 4269.17 | E26: 4269.17 | F26: 4269.17 | G26: 4269.17 | H26: 4269.17 | I26: 4269.17 | J26: 4269.17 | K26: 4269.17 | L26: 4269.17 | M26: 4269.17 | N26: 4269.17 | O26: =SUM(C26:N26) -> 51230.04
B27: Total Rental Income | C27: =C26 -> 4269.17 | D27: =D26 -> 4269.17 | E27: =E26 -> 4269.17 | F27: =F26 -> 4269.17 | G27: =G26 -> 4269.17 | H27: =H26 -> 4269.17 | I27: =I26 -> 4269.17 | J27: =J26 -> 4269.17 | ... O27: =O26 -> 51230.04
A29: STAFF COSTS
A30: Local Staff Salaries | B30: Base Salaries (Existing Staff) | C30: 1447910 | D30: 1447910 | E30: 1447910 | F30: 1447910 | G30: 1447910 | H30: 1447910 | I30: 1447910 | J30: 1447910 | K30: 1478810 | L30: 1478810 | M30: 1478810 | N30: 1478810 | O30: =SUM(C30:N30) -> 17498520 | Q30: Extra teacher to be removed??
A31: Local Staff Salaries | B31: Housing Allowance (Existing) | C31: 391300 | D31: 391300 | E31: 391300 | F31: 391300 | G31: 391300 | H31: 391300 | I31: 391300 | J31: 391300 | K31: 391300 | L31: 391300 | M31: 391300 | N31: 391300 | O31: =SUM(C31:N31) -> 4695600
A32: Local Staff Salaries | B32: Transport Allowance (Existing) | C32: 78259 | D32: 78259 | E32: 78259 | F32: 78259 | G32: 78259 | H32: 78259 | I32: 78259 | J32: 78259 | K32: 78259 | L32: 78259 | M32: 78259 | N32: 78259 | O32: =SUM(C32:N32) -> 939108
A33: Local Staff Salaries | B33: Responsibility Premium (Existing) | C33: 12500 | D33: 12500 | E33: 12500 | F33: 12500 | G33: 12500 | H33: 12500 | I33: 12500 | J33: 12500 | K33: 12500 | L33: 12500 | M33: 12500 | N33: 12500 | O33: =SUM(C33:N33) -> 150000
A34: Local Staff Salaries | B34: HSA Overtime (Existing) | C34: 57424 | D34: 57424 | E34: 57424 | F34: 57424 | G34: 57424 | H34: 57424 | I34: 0 | J34: 0 | K34: 57424 | L34: 57424 | M34: 57424 | N34: 57424 | O34: =SUM(C34:N34) -> 574240 | Q34: Why that much? Any optimization
A35: Local Staff Salaries | B35: Subtotal Existing Staff | C35: =SUM(C30:C34) -> 1987393 | D35: =SUM(D30:D34) -> 1987393 | E35: =SUM(E30:E34) -> 1987393 | F35: =SUM(F30:F34) -> 1987393 | G35: =SUM(G30:G34) -> 1987393 | H35: =SUM(H30:H34) -> 1987393 | I35: =SUM(I30:I34) -> 1929969 | J35: =SUM(J30:J34) -> 1929969 | ... O35: =SUM(O30:O34) -> 23857468
A36: Local Staff Salaries | B36: New Positions (6 FTE – Sep 2026) | C36: 0 | D36: 0 | E36: 0 | F36: 0 | G36: 0 | H36: 0 | I36: 0 | J36: 0 | K36: 57400 | L36: 57400 | M36: 57400 | N36: 57400 | O36: =SUM(C36:N36) -> 229600
A37: Additional Staff Costs | B37: Replacement Contracts | C37: 22681 | D37: 22681 | E37: 22681 | F37: 22681 | G37: 22681 | H37: 22681 | I37: 22681 | J37: 22681 | K37: 22681 | L37: 22681 | M37: 22681 | N37: 22681 | O37: =SUM(C37:N37) -> 272172
A38: Additional Staff Costs | B38: Continuing Education (1% Payroll) | C38: 25504 | D38: 25504 | E38: 25504 | F38: 25504 | G38: 25504 | H38: 25504 | I38: 25504 | J38: 25504 | K38: 25504 | L38: 25504 | M38: 25504 | N38: 25504 | O38: =SUM(C38:N38) -> 306048 | Q38: To recalculate with accurate salary base
A39: Additional Staff Costs | B39: Resident Salaries | C39: 613008 | D39: 613008 | E39: 613008 | F39: 613008 | G39: 613008 | H39: 613008 | I39: 613008 | J39: 613008 | K39: 613008 | L39: 613008 | M39: 613008 | N39: 613008 | O39: =SUM(C39:N39) -> 7356096 | Q39: To provide the latest assumptions
A40: Additional Staff Costs | B40: Pension Contribution (35%) | C40: 69750 | D40: 69750 | E40: 69750 | F40: 69750 | G40: 69750 | H40: 69750 | I40: 69750 | J40: 69750 | K40: 69750 | L40: 69750 | M40: 69750 | N40: 69750 | O40: =SUM(C40:N40) -> 837000 | Q40: To validate once AEFE provide invoices
A41: Additional Staff Costs | B41: Resident Housing & Flights | C41: 53950 | D41: 53950 | E41: 53950 | F41: 53950 | G41: 53950 | H41: 53950 | I41: 53950 | J41: 53950 | K41: 53950 | L41: 53950 | M41: 53950 | N41: 53950 | O41: =SUM(C41:N41) -> 647400 | Q41: Negotiations? Is it approved?
A42: Employer Charges | B42: GOSI – Saudi Employees | C42: 2497 | D42: 2497 | E42: 2497 | F42: 2497 | G42: 2497 | H42: 2497 | I42: 2497 | J42: 2497 | K42: 2526 | L42: 2526 | M42: 2526 | N42: 2526 | O42: =SUM(C42:N42) -> 30080
A43: Employer Charges | B43: End of Service Provision | C43: 125579 | D43: 125579 | E43: 125579 | F43: 125579 | G43: 125579 | H43: 125579 | I43: 125579 | J43: 125579 | K43: 125579 | L43: 125579 | M43: 125579 | N43: 125579 | O43: =SUM(C43:N43) -> 1506948
A44: Employer Charges | B44: Ajeer Costs – Existing (160) | C44: 152266.67 | D44: 152266.67 | E44: 152266.67 | F44: 152266.67 | G44: 152266.67 | H44: 152266.67 | I44: 152266.67 | J44: 152266.67 | K44: 152266.67 | L44: 152266.67 | M44: 152266.67 | N44: 152266.67 | O44: =SUM(C44:N44) -> 1827200 | Q44: Actual projection, to clean provisions
A45: Employer Charges | B45: Ajeer Costs – New (6, Sep–Dec) | C45: 0 | D45: 0 | E45: 0 | F45: 0 | G45: 0 | H45: 0 | I45: 0 | J45: 0 | K45: 5710 | L45: 5710 | M45: 5710 | N45: 5710 | O45: =SUM(C45:N45) -> 22840
B46: Total Staff Costs | C46: =C35+SUM(C36:C45) -> 3052628.7 | D46: =D35+SUM(D36:D45) -> 3052628.7 | E46: =E35+SUM(E36:E45) -> 3052628.7 | F46: =F35+SUM(F36:F45) -> 3052628.7 | G46: =G35+SUM(G36:G45) -> 3052628.7 | H46: =H35+SUM(H36:H45) -> 3052628.7 | I46: =I35+SUM(I36:I45) -> 2995204.7 | J46: =J35+SUM(J36:J45) -> 2995204.7 | ... O46: =O35+SUM(O36:O45) -> 36892852 | S46: =O46/S23 -> 944.75264 | V46: Confirmed
...

Sheet IFRS Income Statement
A1: EFIR – BUDGET INCOME STATEMENT FY2026
A2: Presented per IAS 1 — Function of Expense Method — Currency: SAR
B4: Jan | C4: Feb | D4: Mar | E4: Apr | F4: May | G4: Jun | H4: Jul | I4: Aug | J4: Sep | K4: Oct | L4: Nov | M4: Dec | N4: FY2026 Total
A5: Revenue
A6: Tuition fees | B6: =SUM('IFRS Mapping'!C6:C13) -> 5820906.5 | C6: =SUM('IFRS Mapping'!D6:D13) -> 5820906.5 | D6: =SUM('IFRS Mapping'!E6:E13) -> 5820906.5 | E6: =SUM('IFRS Mapping'!F6:F13) -> 5820906.5 | F6: =SUM('IFRS Mapping'!G6:G13) -> 5820906.5 | G6: =SUM('IFRS Mapping'!H6:H13) -> 5820906.5 | H6: =SUM('IFRS Mapping'!I6:I13) -> 0 | I6: =SUM('IFRS Mapping'!J6:J13) -> 0 | ... M6: =SUM('IFRS Mapping'!N6:N13) -> 5820906.5 | N6: =SUM(B6:M6) -> 58209065
A7: Registration & re-registration fees | B7: =SUM('IFRS Mapping'!C14:C16) -> 0 | C7: =SUM('IFRS Mapping'!D14:D16) -> 0 | D7: =SUM('IFRS Mapping'!E14:E16) -> 0 | E7: =SUM('IFRS Mapping'!F14:F16) -> 0 | F7: =SUM('IFRS Mapping'!G14:G16) -> 0 | G7: =SUM('IFRS Mapping'!H14:H16) -> 7620291 | H7: =SUM('IFRS Mapping'!I14:I16) -> 0 | I7: =SUM('IFRS Mapping'!J14:J16) -> 0 | ... M7: =SUM('IFRS Mapping'!N14:N16) -> 0 | N7: =SUM(B7:M7) -> 8568791
A8: Activities & services | B8: =SUM('IFRS Mapping'!C17:C19) -> 126000 | C8: =SUM('IFRS Mapping'!D17:D19) -> 126000 | D8: =SUM('IFRS Mapping'!E17:E19) -> 126000 | E8: =SUM('IFRS Mapping'!F17:F19) -> 126000 | F8: =SUM('IFRS Mapping'!G17:G19) -> 126000 | G8: =SUM('IFRS Mapping'!H17:H19) -> 126000 | H8: =SUM('IFRS Mapping'!I17:I19) -> 0 | I8: =SUM('IFRS Mapping'!J17:J19) -> 0 | ... M8: =SUM('IFRS Mapping'!N17:N19) -> 152400 | N8: =SUM(B8:M8) -> 1312800
A9: Examination fees | B9: =SUM('IFRS Mapping'!C20:C22) -> 0 | C9: =SUM('IFRS Mapping'!D20:D22) -> 0 | D9: =SUM('IFRS Mapping'!E20:E22) -> 0 | E9: =SUM('IFRS Mapping'!F20:F22) -> 182239.5 | F9: =SUM('IFRS Mapping'!G20:G22) -> 182239.5 | G9: =SUM('IFRS Mapping'!H20:H22) -> 0 | H9: =SUM('IFRS Mapping'!I20:I22) -> 0 | I9: =SUM('IFRS Mapping'!J20:J22) -> 0 | ... M9: =SUM('IFRS Mapping'!N20:N22) -> 0 | N9: =SUM(B9:M9) -> 364479
A10: Revenue from contracts with customers | B10: =SUM(B6:B9) -> 5946906.5 | C10: =SUM(C6:C9) -> 5946906.5 | D10: =SUM(D6:D9) -> 5946906.5 | E10: =SUM(E6:E9) -> 6129146 | F10: =SUM(F6:F9) -> 6129146 | G10: =SUM(G6:G9) -> 13567198 | H10: =SUM(H6:H9) -> 0 | I10: =SUM(I6:I9) -> 0 | ... M10: =SUM(M6:M9) -> 5973306.5 | N10: =SUM(B10:M10) -> 68455135
A11: Rental income | B11: ='IFRS Mapping'!C27 -> 4269.17 | C11: ='IFRS Mapping'!D27 -> 4269.17 | D11: ='IFRS Mapping'!E27 -> 4269.17 | E11: ='IFRS Mapping'!F27 -> 4269.17 | F11: ='IFRS Mapping'!G27 -> 4269.17 | G11: ='IFRS Mapping'!H27 -> 4269.17 | H11: ='IFRS Mapping'!I27 -> 4269.17 | I11: ='IFRS Mapping'!J27 -> 4269.17 | ... M11: ='IFRS Mapping'!N27 -> 4269.17 | N11: =SUM(B11:M11) -> 51230.04
A12: Total Revenue | B12: =B10+B11 -> 5951175.7 | C12: =C10+C11 -> 5951175.7 | D12: =D10+D11 -> 5951175.7 | E12: =E10+E11 -> 6133415.2 | F12: =F10+F11 -> 6133415.2 | G12: =G10+G11 -> 13571467 | H12: =H10+H11 -> 4269.17 | I12: =I10+I11 -> 4269.17 | ... M12: =M10+M11 -> 5977575.7 | N12: =SUM(B12:M12) -> 68506365
A14: Operating Expenses
A15: Staff costs | B15: =-'IFRS Mapping'!C46 -> -3052628.7 | C15: =-'IFRS Mapping'!D46 -> -3052628.7 | D15: =-'IFRS Mapping'!E46 -> -3052628.7 | E15: =-'IFRS Mapping'!F46 -> -3052628.7 | F15: =-'IFRS Mapping'!G46 -> -3052628.7 | G15: =-'IFRS Mapping'!H46 -> -3052628.7 | H15: =-'IFRS Mapping'!I46 -> -2995204.7 | I15: =-'IFRS Mapping'!J46 -> -2995204.7 | ... M15: =-'IFRS Mapping'!N46 -> -3146667.7 | N15: =SUM(B15:M15) -> -36892852 | O15: =N15/$N$12 -> -0.53853174
A16: Other operating expenses | B16: =-'IFRS Mapping'!C81 -> -1965876.2 | C16: =-'IFRS Mapping'!D81 -> -1965876.2 | D16: =-'IFRS Mapping'!E81 -> -1965876.2 | E16: =-'IFRS Mapping'!F81 -> -1965876.2 | F16: =-'IFRS Mapping'!G81 -> -1965876.2 | G16: =-'IFRS Mapping'!H81 -> -1965876.2 | H16: =-'IFRS Mapping'!I81 -> -1965876.2 | I16: =-'IFRS Mapping'!J81 -> -1965876.2 | ... M16: =-'IFRS Mapping'!N81 -> -1965876.2 | N16: =SUM(B16:M16) -> -23590515 | O16: =N16/$N$12 -> -0.34435508
A17: Depreciation & amortization | B17: =-'IFRS Mapping'!C85 -> -439818 | C17: =-'IFRS Mapping'!D85 -> -439818 | D17: =-'IFRS Mapping'!E85 -> -439818 | E17: =-'IFRS Mapping'!F85 -> -439818 | F17: =-'IFRS Mapping'!G85 -> -439818 | G17: =-'IFRS Mapping'!H85 -> -439818 | H17: =-'IFRS Mapping'!I85 -> -439818 | I17: =-'IFRS Mapping'!J85 -> -439818 | ... M17: =-'IFRS Mapping'!N85 -> -439818 | N17: =SUM(B17:M17) -> -5277816 | O17: =N17/$N$12 -> -0.07704125
A18: Impairment losses on receivables | B18: =-'IFRS Mapping'!C89 -> -95432.83 | C18: =-'IFRS Mapping'!D89 -> -95432.83 | D18: =-'IFRS Mapping'!E89 -> -95432.83 | E18: =-'IFRS Mapping'!F89 -> -95432.83 | F18: =-'IFRS Mapping'!G89 -> -95432.83 | G18: =-'IFRS Mapping'!H89 -> -95432.83 | H18: =-'IFRS Mapping'!I89 -> -95432.83 | I18: =-'IFRS Mapping'!J89 -> -95432.83 | ... M18: =-'IFRS Mapping'!N89 -> -95432.83 | N18: =SUM(B18:M18) -> -1145194
A19: Total Operating Expenses | B19: =SUM(B15:B18) -> -5553755.7 | C19: =SUM(C15:C18) -> -5553755.7 | D19: =SUM(D15:D18) -> -5553755.7 | E19: =SUM(E15:E18) -> -5553755.7 | F19: =SUM(F15:F18) -> -5553755.7 | G19: =SUM(G15:G18) -> -5553755.7 | H19: =SUM(H15:H18) -> -5496331.7 | I19: =SUM(I15:I18) -> -5496331.7 | ... M19: =SUM(M15:M18) -> -5647794.7 | N19: =SUM(B19:M19) -> -66906377 | O19: =N19/$N$12 -> -0.97664467
A21: OPERATING PROFIT / (LOSS) | B21: =B12+B19 -> 397419.97 | C21: =C12+C19 -> 397419.97 | D21: =D12+D19 -> 397419.97 | E21: =E12+E19 -> 579659.47 | F21: =F12+F19 -> 579659.47 | G21: =G12+G19 -> 8017711 | H21: =H12+H19 -> -5492062.6 | I21: =I12+I19 -> -5492062.6 | ... M21: =M12+M19 -> 329780.97 | N21: =SUM(B21:M21) -> 1599988.6 | O21: =N21/$N$12 -> 0.023355327
A23: Finance
A24: Finance income | B24: ='IFRS Mapping'!C94 -> 49927.92 | C24: ='IFRS Mapping'!D94 -> 49927.92 | D24: ='IFRS Mapping'!E94 -> 49927.92 | E24: ='IFRS Mapping'!F94 -> 49927.92 | F24: ='IFRS Mapping'!G94 -> 49927.92 | G24: ='IFRS Mapping'!H94 -> 49927.92 | H24: ='IFRS Mapping'!I94 -> 49927.92 | I24: ='IFRS Mapping'!J94 -> 49927.92 | ... M24: ='IFRS Mapping'!N94 -> 49927.92 | N24: =SUM(B24:M24) -> 599135.04
A25: Finance costs | B25: =-'IFRS Mapping'!C100 -> -157570.85 | C25: =-'IFRS Mapping'!D100 -> -157570.85 | D25: =-'IFRS Mapping'!E100 -> -157570.85 | E25: =-'IFRS Mapping'!F100 -> -157570.85 | F25: =-'IFRS Mapping'!G100 -> -157570.85 | G25: =-'IFRS Mapping'!H100 -> -157570.85 | H25: =-'IFRS Mapping'!I100 -> -84070.85 | I25: =-'IFRS Mapping'!J100 -> -84070.85 | ... M25: =-'IFRS Mapping'!N100 -> -157570.85 | N25: =SUM(B25:M25) -> -1743850.2
A26: Net Finance Income / (Cost) | B26: =B24+B25 -> -107642.93 | C26: =C24+C25 -> -107642.93 | D26: =D24+D25 -> -107642.93 | E26: =E24+E25 -> -107642.93 | F26: =F24+F25 -> -107642.93 | G26: =G24+G25 -> -107642.93 | H26: =H24+H25 -> -34142.93 | I26: =I24+I25 -> -34142.93 | ... M26: =M24+M25 -> -107642.93 | N26: =SUM(B26:M26) -> -1144715.2 | O26: =N26/$N$12 -> -0.016709617
A28: PROFIT / (LOSS) BEFORE ZAKAT | B28: =B21+B26 -> 289777.04 | C28: =C21+C26 -> 289777.04 | D28: =D21+D26 -> 289777.04 | E28: =E21+E26 -> 472016.54 | F28: =F21+F26 -> 472016.54 | G28: =G21+G26 -> 7910068 | H28: =H21+H26 -> -5526205.5 | I28: =I21+I26 -> -5526205.5 | ... M28: =M21+M26 -> 222138.04 | N28: =SUM(B28:M28) -> 455273.42
A29: Estimated Zakat (2.5%) | B29: =IF(B28>0,-B28*2.5%,0) -> -7244.426 | C29: =IF(C28>0,-C28*2.5%,0) -> -7244.426 | D29: =IF(D28>0,-D28*2.5%,0) -> -7244.426 | E29: =IF(E28>0,-E28*2.5%,0) -> -11800.413 | F29: =IF(F28>0,-F28*2.5%,0) -> -11800.413 | G29: =IF(G28>0,-G28*2.5%,0) -> -197751.7 | H29: =IF(H28>0,-H28*2.5%,0) -> 0 | I29: =IF(I28>0,-I28*2.5%,0) -> 0 | ... M29: =IF(M28>0,-M28*2.5%,0) -> -5553.451 | N29: =SUM(B29:M29) -> -287692.11 | O29: =N29/$N$12 -> -0.0041994946
A31: NET PROFIT / (LOSS) FOR THE PERIOD | B31: =B28+B29 -> 282532.61 | C31: =C28+C29 -> 282532.61 | D31: =D28+D29 -> 282532.61 | E31: =E28+E29 -> 460216.13 | F31: =F28+F29 -> 460216.13 | G31: =G28+G29 -> 7712316.3 | H31: =H28+H29 -> -5526205.5 | I31: =I28+I29 -> -5526205.5 | ... M31: =M28+M29 -> 216584.59 | N31: =SUM(B31:M31) -> 167581.31
A33: Notes:
A34: 1. Revenue presented net per IFRS 15 — Moyasar processing fees reclassified to Finance Costs.
A35: 2. Bad debt provision reclassified to Impairment Losses per IFRS 9 (Expected Credit Loss model).
A36: 3. Bank charges and FX losses reclassified from Administrative & General to Finance Costs per IAS 1.
A37: 4. Financial income (investment returns & FX gains) separated from operating revenue per IAS 1.
A38: 5. Zakat estimated at 2.5% on positive monthly profit — actual computation per ZATCA regulations may differ.
