Workbook

Sheet Méthodo
B3: METHODOLOGIE du modèle de projections financières
C5: Ce modèle est un outil d'aide à la décision, outil de projection dynamique des données fiancières d'un établissement déjà existant de l'EFE.
C6: Il permet de faire des simulations en faisant varier de nombreuses hypothèses telles que l'augmentation des frais de scolarité, de salaire, le nombre d'élèves par division … et en mesurant l'impact sur le résultat et sur l'augmentation induite des frais de scolarité.
C7: Le modèle donne une analyse par niveau, maternelle/élémentaire/collège/lycée.
C8: L'outil n'est pas directement à destination des établissements, il doit être préparé par un expert ou un personnel AEFE pour saisir des données historiques et de base. Ensuite, soit il peut être transmis à l'établissement qui complète et s'empare des prévisions, soit il est piloté en totalité par l'AEFE
C9: Le modèle ne concerne que la partie "fonctionnement pédagogique" cœur de métier de l'établissement. Les services annexes tels que la restauration, le transport, les activités extra scolaires ou les examens ne sont pas, et ne doivent pas être comptabilisés.
C11: Code Couleur :
C12: A saisir par l'AEFE
C13: A saisir par l'établissement - Seules les cellules en jaune sont à saisir ou modifier
C14: Informations concernant la maternelle
C15: Informations concernant l'élémentaire
C16: Informations concernant le collège
C17: Informations concernant le lycée
... C50: - lignes nb intervenants et base H/E et masquées

Sheet Projection Effectifs
A1: PROJECTION D'EFFECTIFS HOMOLOGUES
A3: HYPOTHESES | B3: Taux de croissance des cohortes
B4: Le taux de croissance pondéré par niveau de 2020 à 2023 permet de projeter les effectifs jusqu'à 2030
B5: Par exemple , s'il y a 50 élèves en CP et un taux de "montée" moyen de 110%, on prévoie un effectif de 55 élèves en CE1 l'année suivante
B6: Les cases en Jaune pour la Petite Section et le Préscolaire éventuel sont à saisir
B7: Les autres cases à partir de 2024 peuvent être forcées en cas de situation particulière ou atteinte du potentiel maximum
B8: Le taux de croissance moyen est calculé à partir des 3 années précédentes
A12: Année Scolaire Rentrée 20xx | B12: Taux Croissance moyen | C12: =VLOOKUP('Hypothèses '!$C$10,'table années scolaires'!$C$9:$O$13,'Hypothèses '!D$11,FALSE) -> 2021/2022 | D12: =VLOOKUP('Hypothèses '!$C$10,'table années scolaires'!$C$9:$O$13,'Hypothèses '!E$11,FALSE) -> 2022/2023 | E12: =VLOOKUP('Hypothèses '!$C$10,'table années scolaires'!$C$9:$O$13,'Hypothèses '!F$11,FALSE) -> 2023/2024 | F12: =VLOOKUP('Hypothèses '!$C$10,'table années scolaires'!$C$9:$O$13,'Hypothèses '!G$11,FALSE) -> 2024/2025 | G12: =VLOOKUP('Hypothèses '!$C$10,'table années scolaires'!$C$9:$O$13,'Hypothèses '!H$11,FALSE) -> 2025/2026 | H12: =VLOOKUP('Hypothèses '!$C$10,'table années scolaires'!$C$9:$O$13,'Hypothèses '!I$11,FALSE) -> 2026/2027 | I12: =VLOOKUP('Hypothèses '!$C$10,'table années scolaires'!$C$9:$O$13,'Hypothèses '!J$11,FALSE) -> 2027/2028 | J12: =VLOOKUP('Hypothèses '!$C$10,'table années scolaires'!$C$9:$O$13,'Hypothèses '!K$11,FALSE) -> 2028/2029 | ... M12: =VLOOKUP('Hypothèses '!$C$10,'table années scolaires'!$C$9:$O$13,'Hypothèses '!N$11,FALSE) -> 2031/2032 | O12: POTENTIEL | P12: Nb divisions | Q12: Nb max d'élèves
C13: =SUM(C15:C29) -> 0 | D13: =SUM(D15:D29) -> 0 | E13: =SUM(E15:E29) -> 0 | F13: =SUM(F15:F29) -> 1796 | G13: =SUM(G15:G29) -> 1825 | H13: =SUM(H15:H29) -> 1775 | I13: =SUM(I15:I29) -> 1709 | J13: =SUM(J15:J29) -> 1699 | ... M13: =SUM(M15:M29) -> 1677 | O13: =SUM(O15:O29) -> 1875
A14: 00- Préscolaire
A15: 01- Petite Section | F15: 61 | G15: 70 | H15: 60 | I15: 60 | J15: 120 | K15: 120 | L15: 120 | M15: 120 | O15: =P15*Q15 -> 125 | P15: 5 | Q15: 25
A16: 02- Moyenne Section | B16: =IFERROR((M16/E16)^(1/(8))-1,0) -> 0 | F16: 109 | G16: 72 | H16: =G15 -> 70 | I16: =H15 -> 60 | J16: =I15 -> 60 | K16: =J15 -> 120 | L16: =K15 -> 120 | M16: =L15 -> 120 | O16: =P16*Q16 -> 125 | P16: 5 | Q16: 25
A17: 03- Grande Section | B17: =IFERROR((M17/E17)^(1/(8))-1,0) -> 0 | F17: 123 | G17: 130 | H17: =G16 -> 72 | I17: =H16 -> 70 | J17: =I16 -> 60 | K17: =J16 -> 60 | L17: =K16 -> 120 | M17: =L16 -> 120 | O17: =P17*Q17 -> 125 | P17: 5 | Q17: 25
A18: 04- CP | B18: =IFERROR((M18/E18)^(1/(8))-1,0) -> 0 | F18: 116 | G18: 134 | H18: =G17 -> 130 | I18: =H17 -> 72 | J18: =I17 -> 70 | K18: =J17 -> 60 | L18: =K17 -> 60 | M18: =L17 -> 120 | O18: =P18*Q18 -> 125 | P18: 5 | Q18: 25
A19: 05- CE1 | B19: =IFERROR((M19/E19)^(1/(8))-1,0) -> 0 | F19: 140 | G19: 124 | H19: =G18 -> 134 | I19: =H18 -> 130 | J19: =I18 -> 72 | K19: =J18 -> 70 | L19: =K18 -> 60 | M19: =L18 -> 60 | O19: =P19*Q19 -> 125 | P19: 5 | Q19: 25
A20: 06- CE2 | B20: =IFERROR((M20/E20)^(1/(8))-1,0) -> 0 | F20: 126 | G20: 137 | H20: =G19 -> 124 | I20: =H19 -> 134 | J20: =I19 -> 130 | K20: =J19 -> 72 | L20: =K19 -> 70 | M20: =L19 -> 60 | O20: =P20*Q20 -> 125 | P20: 5 | Q20: 25
A21: 07- CM1 | B21: =IFERROR((M21/E21)^(1/(8))-1,0) -> 0 | F21: 124 | G21: 128 | H21: =G20 -> 137 | I21: =H20 -> 124 | J21: =I20 -> 134 | K21: =J20 -> 130 | L21: =K20 -> 72 | M21: =L20 -> 70 | O21: =P21*Q21 -> 125 | P21: 5 | Q21: 25
A22: 08- CM2 | B22: =IFERROR((M22/E22)^(1/(8))-1,0) -> 0 | F22: 145 | G22: 129 | H22: =G21 -> 128 | I22: =H21 -> 137 | J22: =I21 -> 124 | K22: =J21 -> 134 | L22: =K21 -> 130 | M22: =L21 -> 72 | O22: =P22*Q22 -> 125 | P22: 5 | Q22: 25
A23: 09- 6ème | B23: =IFERROR((M23/E23)^(1/(8))-1,0) -> 0 | F23: 146 | G23: 153 | H23: =G22 -> 129 | I23: =H22 -> 128 | J23: =I22 -> 137 | K23: =J22 -> 124 | L23: =K22 -> 134 | M23: =L22 -> 130 | O23: =P23*Q23 -> 125 | P23: 5 | Q23: 25
A24: 10- 5ème | B24: =IFERROR((M24/E24)^(1/(8))-1,0) -> 0 | F24: 121 | G24: 143 | H24: =G23 -> 153 | I24: =H23 -> 129 | J24: =I23 -> 128 | K24: =J23 -> 137 | L24: =K23 -> 124 | M24: =L23 -> 134 | O24: =P24*Q24 -> 125 | P24: 5 | Q24: 25
A25: 11- 4ème | B25: =IFERROR((M25/E25)^(1/(8))-1,0) -> 0 | F25: 104 | G25: 126 | H25: =G24 -> 143 | I25: =H24 -> 153 | J25: =I24 -> 129 | K25: =J24 -> 128 | L25: =K24 -> 137 | M25: =L24 -> 124 | O25: =P25*Q25 -> 125 | P25: 5 | Q25: 25
A26: 12- 3ème | B26: =IFERROR((M26/E26)^(1/(8))-1,0) -> 0 | F26: 128 | G26: 113 | H26: =G25 -> 126 | I26: =H25 -> 143 | J26: =I25 -> 153 | K26: =J25 -> 129 | L26: =K25 -> 128 | M26: =L25 -> 137 | O26: =P26*Q26 -> 125 | P26: 5 | Q26: 25
A27: 13- Seconde | B27: =IFERROR((M27/E27)^(1/(8))-1,0) -> 0 | F27: 130 | G27: 130 | H27: =G26 -> 113 | I27: =H26 -> 126 | J27: =I26 -> 143 | K27: =J26 -> 153 | L27: =K26 -> 129 | M27: =L26 -> 128 | O27: =P27*Q27 -> 125 | P27: 5 | Q27: 25
... A29: 15- Terminale | B29: =IFERROR((M29/E29)^(1/(8))-1,0) -> 0 | F29: 109 | G29: 110 | H29: =G28 -> 126 | I29: =H28 -> 130 | J29: =I28 -> 113 | K29: =J28 -> 126 | L29: =K28 -> 143 | M29: =L28 -> 153 | O29: =P29*Q29 -> 125 | P29: 5 | Q29: 25
R30: Clés de répartition
C31: =C12 -> 2021/2022 | D31: =D12 -> 2022/2023 | E31: =E12 -> 2023/2024 | F31: =F12 -> 2024/2025 | G31: =G12 -> 2025/2026 | H31: =H12 -> 2026/2027 | I31: =I12 -> 2027/2028 | J31: =J12 -> 2028/2029 | ... M31: =M12 -> 2031/2032 | R31: Pro rata Global | S31: =C12 -> 2021/2022 | T31: =D12 -> 2022/2023 | U31: =E12 -> 2023/2024 | V31: =F12 -> 2024/2025 | W31: =G12 -> 2025/2026 | X31: =H12 -> 2026/2027 | Y31: =I12 -> 2027/2028 | Z31: =J12 -> 2028/2029 | ... AC31: =M12 -> 2031/2032
A32: Maternelle | C32: =SUM(C14:C17) -> 0 | D32: =SUM(D14:D17) -> 0 | E32: =SUM(E14:E17) -> 0 | F32: =SUM(F14:F17) -> 293 | G32: =SUM(G14:G17) -> 272 | H32: =SUM(H14:H17) -> 202 | I32: =SUM(I14:I17) -> 190 | J32: =SUM(J14:J17) -> 240 | ... M32: =SUM(M14:M17) -> 360 | R32: Maternelle | S32: =IFERROR(C32/C$38,0) -> 0 | T32: =IFERROR(D32/D$38,0) -> 0 | U32: =IFERROR(E32/E$38,0) -> 0 | V32: =IFERROR(F32/F$38,0) -> 0.16314031 | W32: =IFERROR(G32/G$38,0) -> 0.1490411 | X32: =IFERROR(H32/H$38,0) -> 0.11380282 | Y32: =IFERROR(I32/I$38,0) -> 0.11117613 | Z32: =IFERROR(J32/J$38,0) -> 0.14125956 | ... AC32: =IFERROR(M32/M$38,0) -> 0.21466905
A33: Elémentaire | C33: =SUM(C18:C22) -> 0 | D33: =SUM(D18:D22) -> 0 | E33: =SUM(E18:E22) -> 0 | F33: =SUM(F18:F22) -> 651 | G33: =SUM(G18:G22) -> 652 | H33: =SUM(H18:H22) -> 653 | I33: =SUM(I18:I22) -> 597 | J33: =SUM(J18:J22) -> 530 | ... M33: =SUM(M18:M22) -> 382 | R33: Elémentaire | S33: =IFERROR(C33/C$38,0) -> 0 | T33: =IFERROR(D33/D$38,0) -> 0 | U33: =IFERROR(E33/E$38,0) -> 0 | V33: =IFERROR(F33/F$38,0) -> 0.36247216 | W33: =IFERROR(G33/G$38,0) -> 0.35726027 | X33: =IFERROR(H33/H$38,0) -> 0.36788732 | Y33: =IFERROR(I33/I$38,0) -> 0.34932709 | Z33: =IFERROR(J33/J$38,0) -> 0.3119482 | ... AC33: =IFERROR(M33/M$38,0) -> 0.22778772
A34: PRIMAIRE | C34: =C33+C32 -> 0 | D34: =D33+D32 -> 0 | E34: =E33+E32 -> 0 | F34: =F33+F32 -> 944 | G34: =G33+G32 -> 924 | H34: =H33+H32 -> 855 | I34: =I33+I32 -> 787 | J34: =J33+J32 -> 770 | ... M34: =M33+M32 -> 742 | R34: Collège | S34: =IFERROR(C35/C$38,0) -> 0 | T34: =IFERROR(D35/D$38,0) -> 0 | U34: =IFERROR(E35/E$38,0) -> 0 | V34: =IFERROR(F35/F$38,0) -> 0.27783964 | W34: =IFERROR(G35/G$38,0) -> 0.29315068 | X34: =IFERROR(H35/H$38,0) -> 0.31042254 | Y34: =IFERROR(I35/I$38,0) -> 0.32358104 | Z34: =IFERROR(J35/J$38,0) -> 0.32195409 | ... AC34: =IFERROR(M35/M$38,0) -> 0.31305903
A35: Collège | C35: =SUM(C23:C26) -> 0 | D35: =SUM(D23:D26) -> 0 | E35: =SUM(E23:E26) -> 0 | F35: =SUM(F23:F26) -> 499 | G35: =SUM(G23:G26) -> 535 | H35: =SUM(H23:H26) -> 551 | I35: =SUM(I23:I26) -> 553 | J35: =SUM(J23:J26) -> 547 | ... M35: =SUM(M23:M26) -> 525 | R35: Lycée | S35: =IFERROR(C36/C$38,0) -> 0 | T35: =IFERROR(D36/D$38,0) -> 0 | U35: =IFERROR(E36/E$38,0) -> 0 | V35: =IFERROR(F36/F$38,0) -> 0.19654788 | W35: =IFERROR(G36/G$38,0) -> 0.20054795 | X35: =IFERROR(H36/H$38,0) -> 0.20788732 | Y35: =IFERROR(I36/I$38,0) -> 0.21591574 | Z35: =IFERROR(J36/J$38,0) -> 0.22483814 | ... AC35: =IFERROR(M36/M$38,0) -> 0.2444842
A36: Lycée | C36: =SUM(C27:C29) -> 0 | D36: =SUM(D27:D29) -> 0 | E36: =SUM(E27:E29) -> 0 | F36: =SUM(F27:F29) -> 353 | G36: =SUM(G27:G29) -> 366 | H36: =SUM(H27:H29) -> 369 | I36: =SUM(I27:I29) -> 369 | J36: =SUM(J27:J29) -> 382 | ... M36: =SUM(M27:M29) -> 410 | S36: =IFERROR(C38/C$38,0) -> 0 | T36: =IFERROR(D38/D$38,0) -> 0 | U36: =IFERROR(E38/E$38,0) -> 0 | V36: =IFERROR(F38/F$38,0) -> 1 | W36: =G38/G$38 -> 1 | X36: =H38/H$38 -> 1 | Y36: =I38/I$38 -> 1 | Z36: =J38/J$38 -> 1 | AA36: =K38/K$38 -> 1 | AB36: =L38/L$38 -> 1 | AC36: =M38/M$38 -> 1
A37: SECONDAIRE | C37: =C36+C35 -> 0 | D37: =D36+D35 -> 0 | E37: =E36+E35 -> 0 | F37: =F36+F35 -> 852 | G37: =G36+G35 -> 901 | H37: =H36+H35 -> 920 | I37: =I36+I35 -> 922 | J37: =J36+J35 -> 929 | ... M37: =M36+M35 -> 935 | R37: Pro rata Niveau | S37: =C12 -> 2021/2022 | T37: =D12 -> 2022/2023 | U37: =E12 -> 2023/2024 | V37: =F12 -> 2024/2025 | W37: =G12 -> 2025/2026 | X37: =H12 -> 2026/2027 | Y37: =I12 -> 2027/2028 | Z37: =J12 -> 2028/2029 | ... AC37: =M12 -> 2031/2032
A38: Total ETABLISSEMENT | C38: =C37+C34 -> 0 | D38: =D37+D34 -> 0 | E38: =E37+E34 -> 0 | F38: =F37+F34 -> 1796 | G38: =G37+G34 -> 1825 | H38: =H37+H34 -> 1775 | I38: =I37+I34 -> 1709 | J38: =J37+J34 -> 1699 | ... M38: =M37+M34 -> 1677 | R38: Maternelle | S38: =IFERROR(C32/C$34,0) -> 0 | T38: =IFERROR(D32/D$34,0) -> 0 | U38: =IFERROR(E32/E$34,0) -> 0 | V38: =IFERROR(F32/F$34,0) -> 0.31038136 | W38: =IFERROR(G32/G$34,0) -> 0.29437229 | X38: =IFERROR(H32/H$34,0) -> 0.23625731 | Y38: =IFERROR(I32/I$34,0) -> 0.24142313 | Z38: =IFERROR(J32/J$34,0) -> 0.31168831 | ... AC38: =IFERROR(M32/M$34,0) -> 0.4851752
R39: Elémentaire | S39: =IFERROR(C33/C$34,0) -> 0 | T39: =IFERROR(D33/D$34,0) -> 0 | U39: =IFERROR(E33/E$34,0) -> 0 | V39: =IFERROR(F33/F$34,0) -> 0.68961864 | W39: =IFERROR(G33/G$34,0) -> 0.70562771 | X39: =IFERROR(H33/H$34,0) -> 0.76374269 | Y39: =IFERROR(I33/I$34,0) -> 0.75857687 | Z39: =IFERROR(J33/J$34,0) -> 0.68831169 | ... AC39: =IFERROR(M33/M$34,0) -> 0.5148248
R40: Primaire | S40: =S39+S38 -> 0 | T40: =T39+T38 -> 0 | U40: =U39+U38 -> 0 | V40: =V39+V38 -> 1 | W40: =W39+W38 -> 1 | X40: =X39+X38 -> 1 | Y40: =Y39+Y38 -> 1 | Z40: =Z39+Z38 -> 1 | ... AC40: =AC39+AC38 -> 1
R41: Collège | S41: =IFERROR(C35/C$37,0) -> 0 | T41: =IFERROR(D35/D$37,0) -> 0 | U41: =IFERROR(E35/E$37,0) -> 0 | V41: =IFERROR(F35/F$37,0) -> 0.58568075 | W41: =IFERROR(G35/G$37,0) -> 0.59378468 | X41: =IFERROR(H35/H$37,0) -> 0.59891304 | Y41: =IFERROR(I35/I$37,0) -> 0.59978308 | Z41: =IFERROR(J35/J$37,0) -> 0.58880517 | ... AC41: =IFERROR(M35/M$37,0) -> 0.56149733
R42: Lycée | S42: =IFERROR(C36/C$37,0) -> 0 | T42: =IFERROR(D36/D$37,0) -> 0 | U42: =IFERROR(E36/E$37,0) -> 0 | V42: =IFERROR(F36/F$37,0) -> 0.41431925 | W42: =IFERROR(G36/G$37,0) -> 0.40621532 | X42: =IFERROR(H36/H$37,0) -> 0.40108696 | Y42: =IFERROR(I36/I$37,0) -> 0.40021692 | Z42: =IFERROR(J36/J$37,0) -> 0.41119483 | ... AC42: =IFERROR(M36/M$37,0) -> 0.43850267
R43: Secondaire | S43: =S41+S42 -> 0 | T43: =T41+T42 -> 0 | U43: =U41+U42 -> 0 | V43: =V41+V42 -> 1 | W43: =W41+W42 -> 1 | X43: =X41+X42 -> 1 | Y43: =Y41+Y42 -> 1 | Z43: =Z41+Z42 -> 1 | ... AC43: =AC41+AC42 -> 1
R44: Taux croissance | S44: =C12 -> 2021/2022 | T44: =D12 -> 2022/2023 | U44: =E12 -> 2023/2024 | V44: =F12 -> 2024/2025 | W44: =G12 -> 2025/2026 | X44: =H12 -> 2026/2027 | Y44: =I12 -> 2027/2028 | Z44: =J12 -> 2028/2029 | ... AC44: =M12 -> 2031/2032
R45: Maternelle | T45: =IFERROR((D32-C32)/C32,0) -> 0 | U45: =IFERROR((E32-D32)/D32,0) -> 0 | V45: =IFERROR((F32-E32)/E32,0) -> 0 | W45: =IFERROR((G32-F32)/F32,0) -> -0.071672355 | X45: =IFERROR((H32-G32)/G32,0) -> -0.25735294 | Y45: =IFERROR((I32-H32)/H32,0) -> -0.059405941 | Z45: =IFERROR((J32-I32)/I32,0) -> 0.26315789 | AA45: =IFERROR((K32-J32)/J32,0) -> 0.25 | ... AC45: =IFERROR((M32-L32)/L32,0) -> 0
...

Sheet Nbre de divisions
B1: R.2024 | E1: R.2025 | H1: R.2026 | K1: R.2027
A2: Année Scolaire Rentrée 20xx | B2: Effectifs | C2: Division | D2: Elève/classe | E2: Effectifs | F2: Division | G2: Elève/classe | H2: Effectifs | I2: Division | J2: Elèves/Classe | K2: Effectifs | L2: Division | M2: Elève/classe
B3: =SUM(B4:B18) -> 1794 | E3: =SUM(E4:E18) -> 1825 | H3: =SUM(H4:H18) -> 1765 | K3: =SUM(K4:K18) -> 1699
A4: 01- Petite Section | B4: 59 | C4: 3 | D4: =B4/C4 -> 19.666667 | E4: 70 | F4: 3 | G4: =E4/F4 -> 23.333333 | H4: 60 | K4: 60 | M4: =K4/L4 -> #DIV/0!
A5: 02- Moyenne Section | B5: 109 | C5: 5 | D5: =B5/C5 -> 21.8 | E5: 72 | F5: 3 | G5: =E5/F5 -> 24 | H5: 60 | K5: =H4 -> 60 | M5: =K5/L5 -> #DIV/0!
A6: 03- Grande Section | B6: 123 | C6: 5 | D6: =B6/C6 -> 24.6 | E6: 130 | F6: 5 | G6: =E6/F6 -> 26 | H6: =E5 -> 72 | K6: =H5 -> 60 | M6: =K6/L6 -> #DIV/0!
A7: 04- CP | B7: 116 | C7: 5 | D7: =B7/C7 -> 23.2 | E7: 134 | F7: 6 | G7: =E7/F7 -> 22.333333 | H7: =E6 -> 130 | K7: =H6 -> 72 | M7: =K7/L7 -> #DIV/0!
A8: 05- CE1 | B8: 140 | C8: 6 | D8: =B8/C8 -> 23.333333 | E8: 124 | F8: 5 | G8: =E8/F8 -> 24.8 | H8: =E7 -> 134 | K8: =H7 -> 130 | M8: =K8/L8 -> #DIV/0!
A9: 06- CE2 | B9: 126 | C9: 5 | D9: =B9/C9 -> 25.2 | E9: 137 | F9: 6 | G9: =E9/F9 -> 22.833333 | H9: =E8 -> 124 | K9: =H8 -> 134 | M9: =K9/L9 -> #DIV/0!
A10: 07- CM1 | B10: 124 | C10: 5 | D10: =B10/C10 -> 24.8 | E10: 128 | F10: 5 | G10: =E10/F10 -> 25.6 | H10: =E9 -> 137 | K10: =H9 -> 124 | M10: =K10/L10 -> #DIV/0!
A11: 08- CM2 | B11: 145 | C11: 6 | D11: =B11/C11 -> 24.166667 | E11: 129 | F11: 5 | G11: =E11/F11 -> 25.8 | H11: =E10 -> 128 | K11: =H10 -> 137 | M11: =K11/L11 -> #DIV/0!
A12: 09- 6ème | B12: 146 | C12: 6 | D12: =B12/C12 -> 24.333333 | E12: 153 | F12: 6 | G12: =E12/F12 -> 25.5 | H12: =E11 -> 129 | K12: =H11 -> 128 | M12: =K12/L12 -> #DIV/0!
A13: 10- 5ème | B13: 121 | C13: 5 | D13: =B13/C13 -> 24.2 | E13: 143 | F13: 6 | G13: =E13/F13 -> 23.833333 | H13: =E12 -> 153 | K13: =H12 -> 129 | M13: =K13/L13 -> #DIV/0!
A14: 11- 4ème | B14: 104 | C14: 4 | D14: =B14/C14 -> 26 | E14: 126 | F14: 5 | G14: =E14/F14 -> 25.2 | H14: =E13 -> 143 | K14: =H13 -> 153 | M14: =K14/L14 -> #DIV/0!
A15: 12- 3ème | B15: 128 | C15: 5 | D15: =B15/C15 -> 25.6 | E15: 113 | F15: 4 | G15: =E15/F15 -> 28.25 | H15: =E14 -> 126 | K15: =H14 -> 143 | M15: =K15/L15 -> #DIV/0!
A16: 13- Seconde | B16: 130 | C16: 5 | D16: =B16/C16 -> 26 | E16: 130 | F16: 5 | G16: =E16/F16 -> 26 | H16: =E15 -> 113 | K16: =H15 -> 126 | M16: =K16/L16 -> #DIV/0!
A17: 14- Première | B17: 114 | C17: 4 | D17: =B17/C17 -> 28.5 | E17: 126 | F17: 5 | G17: =E17/F17 -> 25.2 | H17: =E16 -> 130 | K17: =H16 -> 113 | M17: =K17/L17 -> #DIV/0!
A18: 15- Terminale | B18: 109 | C18: 4 | D18: =B18/C18 -> 27.25 | E18: 110 | F18: 4 | G18: =E18/F18 -> 27.5 | H18: =E17 -> 126 | K18: =H17 -> 130 | M18: =K18/L18 -> #DIV/0!
B20: Effectifs | C20: Division | D20: Elève/classe | E20: Effectifs | F20: Division | G20: Elève/classe | H20: Effectifs | I20: Division | J20: Elèves/Classe | K20: Effectifs | L20: Division | M20: Elève/classe
A21: Maternelle | B21: =B4+B5+B6 -> 291 | C21: =C4+C5+C6 -> 13 | D21: =B21/C21 -> 22.384615 | E21: =E4+E5+E6 -> 272 | F21: =F4+F5+F6 -> 11 | G21: =E21/F21 -> 24.727273 | H21: =H4+H5+H6 -> 192 | I21: =I4+I5+I6 -> 0 | J21: =H21/I21 -> #DIV/0! | K21: =K4+K5+K6 -> 180 | L21: =L4+L5+L6 -> 0 | M21: =K21/L21 -> #DIV/0!
A22: Elémentaire | B22: =B7+B8+B9+B10+B11 -> 651 | C22: =C7+C8+C9+C10+C11 -> 27 | D22: =B22/C22 -> 24.111111 | E22: =E7+E8+E9+E10+E11 -> 652 | F22: =F7+F8+F9+F10+F11 -> 27 | G22: =E22/F22 -> 24.148148 | H22: =H7+H8+H9+H10+H11 -> 653 | I22: =I7+I8+I9+I10+I11 -> 0 | J22: =H22/I22 -> #DIV/0! | K22: =K7+K8+K9+K10+K11 -> 597 | L22: =L7+L8+L9+L10+L11 -> 0 | M22: =K22/L22 -> #DIV/0!
A23: PRIMAIRE | B23: =B21+B22 -> 942 | C23: =C21+C22 -> 40 | D23: =B23/C23 -> 23.55 | E23: =E21+E22 -> 924 | F23: =F21+F22 -> 38 | G23: =E23/F23 -> 24.315789 | H23: =H21+H22 -> 845 | I23: =I21+I22 -> 0 | J23: =H23/I23 -> #DIV/0! | K23: =K21+K22 -> 777 | L23: =L21+L22 -> 0 | M23: =K23/L23 -> #DIV/0!
A24: Collège | B24: =B12+B13+B14+B15 -> 499 | C24: =C12+C13+C14+C15 -> 20 | D24: =B24/C24 -> 24.95 | E24: =E12+E13+E14+E15 -> 535 | F24: =F12+F13+F14+F15 -> 21 | G24: =E24/F24 -> 25.47619 | H24: =H12+H13+H14+H15 -> 551 | I24: =I12+I13+I14+I15 -> 0 | J24: =H24/I24 -> #DIV/0! | K24: =K12+K13+K14+K15 -> 553 | L24: =L12+L13+L14+L15 -> 0 | M24: =K24/L24 -> #DIV/0!
A25: Lycée | B25: =B16+B17+B18 -> 353 | C25: =C16+C17+C18 -> 13 | D25: =B25/C25 -> 27.153846 | E25: =E16+E17+E18 -> 366 | F25: =F16+F17+F18 -> 14 | G25: =E25/F25 -> 26.142857 | H25: =H16+H17+H18 -> 369 | I25: =I16+I17+I18 -> 0 | J25: =H25/I25 -> #DIV/0! | K25: =K16+K17+K18 -> 369 | L25: =L16+L17+L18 -> 0 | M25: =K25/L25 -> #DIV/0!
A26: SECONDAIRE | B26: =B24+B25 -> 852 | C26: =C24+C25 -> 33 | D26: =B26/C26 -> 25.818182 | E26: =E24+E25 -> 901 | F26: =F24+F25 -> 35 | G26: =E26/F26 -> 25.742857 | H26: =H24+H25 -> 920 | I26: =I24+I25 -> 0 | J26: =H26/I26 -> #DIV/0! | K26: =K24+K25 -> 922 | L26: =L24+L25 -> 0 | M26: =K26/L26 -> #DIV/0!
A27: Total ETABLISSEMENT | B27: =B23+B26 -> 1794 | C27: =C23+C26 -> 73 | D27: =B27/C27 -> 24.575342 | E27: =E23+E26 -> 1825 | F27: =F23+F26 -> 73 | G27: =E27/F27 -> 25 | H27: =H23+H26 -> 1765 | I27: =I23+I26 -> 0 | J27: =H27/I27 -> #DIV/0! | K27: =K23+K26 -> 1699 | L27: =L23+L26 -> 0 | M27: =K27/L27 -> #DIV/0!
A30: Structure prévisionnelle Maternelle
A31: PS
A32: MS
A33: GS
A34: CP
A35: CE1
A36: CE2
A37: CM1
A38: CM2
B39: =SUM(B31:B38) -> 0

Sheet Hypothèses 
A2: HYPOTHESES et DONNEES du modèle | M2: RESULTAT des SIMULATIONS du modèle | X2: TABLES du modele
D4: Données à remplir par l'AEFE
D5: Données ou hypothèses à compléter par l'établissement
A6: HYPOTHESES ET DONNEES GENERALES
B7: Statut de l'établissement | C7: conventionné | D7: après homologation
B8: Année 1 de la projection financière | C8: 2025
B9: Année référence compte financier | C9: =C8-1 -> 2024
B10: Année scolaire initiale | C10: =IF(C8=2024,"2022/2023",IF(C8=2025,"2023/2024",IF(C8=2026,"2024/2025",IF(C8=2027,"2025/2026","2026/2027")))) -> 2023/2024
C11: Indice | D11: 3 | E11: 4 | F11: 5 | G11: 6 | H11: 7 | I11: 8 | J11: 9 | K11: 10 | L11: 11 | M11: 12 | N11: 13
B12: Niveaux homologués | C12: =C10 -> 2023/2024 | D12: =VLOOKUP($C$10,'table années scolaires'!$C$2:$L$6,'Hypothèses '!D$11,FALSE) -> 2024/2025 | E12: =VLOOKUP($C$10,'table années scolaires'!$C$2:$L$6,'Hypothèses '!E$11,FALSE) -> 2025/2026 | F12: =VLOOKUP($C$10,'table années scolaires'!$C$2:$L$6,'Hypothèses '!F$11,FALSE) -> 2026/2027 | G12: =VLOOKUP($C$10,'table années scolaires'!$C$2:$L$6,'Hypothèses '!G$11,FALSE) -> 2027/2028 | H12: =VLOOKUP($C$10,'table années scolaires'!$C$2:$L$6,'Hypothèses '!H$11,FALSE) -> 2028/2029 | I12: =VLOOKUP($C$10,'table années scolaires'!$C$2:$L$6,'Hypothèses '!I$11,FALSE) -> 2029/2030 | J12: =VLOOKUP($C$10,'table années scolaires'!$C$2:$L$6,'Hypothèses '!J$11,FALSE) -> 2030/2031 | K12: =VLOOKUP($C$10,'table années scolaires'!$C$2:$L$6,'Hypothèses '!K$11,FALSE) -> 2031/2032
B13: Maternelle | C13: non | D13: non | E13: non | F13: oui | G13: =F13 -> oui | H13: =G13 -> oui | I13: =H13 -> oui | J13: =I13 -> oui | K13: =J13 -> oui
B14: Elémentaire | C14: non | D14: non | E14: non | F14: =E14 -> non | G14: oui | H14: =G14 -> oui | I14: =H14 -> oui | J14: =I14 -> oui | K14: =J14 -> oui
B15: Collège | C15: non | D15: non | E15: non | F15: =E15 -> non | G15: =F15 -> non | H15: =G15 -> non | I15: =H15 -> non | J15: =I15 -> non | K15: =J15 -> non
B16: Lycée | C16: non | D16: non | E16: non | F16: =E16 -> non | G16: =F16 -> non | H16: =G16 -> non | I16: oui | J16: =I16 -> oui | K16: =J16 -> oui
B18: Tarifs - moyens pondérés en fonction des nationalités | M18: RESULTAT OPERATIONNEL SCOLAIRE
C19: =C12 -> 2023/2024 | D19: =D12 -> 2024/2025 | E19: =E12 -> 2025/2026 | F19: =F12 -> 2026/2027 | G19: =G12 -> 2027/2028 | H19: =H12 -> 2028/2029 | I19: =I12 -> 2029/2030 | J19: =J12 -> 2030/2031 | K19: =K12 -> 2031/2032 | M19: =B38 -> Monnaie : Riyal
B20: Frais Reinscription | E20: 65000 | F20: 65000 | G20: 65000 | H20: 65000 | I20: 65000 | J20: 65000 | K20: 65000 | N20: ='Hypothèses '!$C$8 -> 2025 | O20: =N20+1 -> 2026 | P20: =O20+1 -> 2027 | Q20: =P20+1 -> 2028 | R20: =Q20+1 -> 2029 | S20: =R20+1 -> 2030 | T20: =S20+1 -> 2031
B21: Droits Première Inscription | E21: 500000 | F21: 500000 | G21: 500000 | H21: 500000 | I21: 500000 | J21: 500000 | K21: 500000 | M21: GLOBAL | N21: =HLOOKUP(N$20,'Compte Résultat ML'!$C$4:$J$10,3,FALSE) -> #N/A | O21: =HLOOKUP(O$20,'Compte Résultat ML'!$C$4:$J$10,3,FALSE) -> #N/A | P21: =HLOOKUP(P$20,'Compte Résultat ML'!$C$4:$J$10,3,FALSE) -> #N/A | Q21: =HLOOKUP(Q$20,'Compte Résultat ML'!$C$4:$J$10,3,FALSE) -> #N/A | R21: =HLOOKUP(R$20,'Compte Résultat ML'!$C$4:$J$10,3,FALSE) -> #N/A | S21: =HLOOKUP(S$20,'Compte Résultat ML'!$C$4:$J$10,3,FALSE) -> #N/A | T21: =HLOOKUP(T$20,'Compte Résultat ML'!$C$4:$J$10,3,FALSE) -> #N/A
B22: Frais scolarité GLOBAL | E22: =D22*(1+E$32) -> 0 | F22: =E22*(1+F$32) -> 0 | G22: =F22*(1+G$32) -> 0 | H22: =G22*(1+H$32) -> 0 | I22: =H22*(1+I$32) -> 0 | J22: =I22*(1+J$32) -> 0 | K22: =J22*(1+K$32) -> 0 | M22: MATERNELLE | N22: =HLOOKUP(N$20,'Compte Résultat ML'!$C$4:$J$10,4,FALSE) -> #N/A | O22: =HLOOKUP(O$20,'Compte Résultat ML'!$C$4:$J$10,4,FALSE) -> #N/A | P22: =HLOOKUP(P$20,'Compte Résultat ML'!$C$4:$J$10,4,FALSE) -> #N/A | Q22: =HLOOKUP(Q$20,'Compte Résultat ML'!$C$4:$J$10,4,FALSE) -> #N/A | R22: =HLOOKUP(R$20,'Compte Résultat ML'!$C$4:$J$10,4,FALSE) -> #N/A | S22: =HLOOKUP(S$20,'Compte Résultat ML'!$C$4:$J$10,4,FALSE) -> #N/A | T22: =HLOOKUP(T$20,'Compte Résultat ML'!$C$4:$J$10,4,FALSE) -> #N/A
B23: Frais scolarité MATERNELLE | E23: =D23*(1+E$32) -> 0 | F23: =E23*(1+F$32) -> 0 | G23: =F23*(1+G$32) -> 0 | H23: =G23*(1+H$32) -> 0 | I23: =H23*(1+I$32) -> 0 | J23: =I23*(1+J$32) -> 0 | K23: =J23*(1+K$32) -> 0 | M23: MS enseignants PDL | N23: =HLOOKUP(N$20,'Compte Résultat ML'!$C$58:$J$87,29,FALSE) -> 0 | O23: =HLOOKUP(O$20,'Compte Résultat ML'!$C$58:$J$87,29,FALSE) -> 0 | P23: =HLOOKUP(P$20,'Compte Résultat ML'!$C$58:$J$87,29,FALSE) -> 0 | Q23: =HLOOKUP(Q$20,'Compte Résultat ML'!$C$58:$J$87,29,FALSE) -> 0 | R23: =HLOOKUP(R$20,'Compte Résultat ML'!$C$58:$J$87,29,FALSE) -> 0 | S23: =HLOOKUP(S$20,'Compte Résultat ML'!$C$58:$J$87,29,FALSE) -> 0 | T23: =HLOOKUP(T$20,'Compte Résultat ML'!$C$58:$J$87,29,FALSE) -> 0
B24: Frais scolarité ELEMENTAIRE | E24: =D24*(1+E$32) -> 0 | F24: =E24*(1+F$32) -> 0 | G24: =F24*(1+G$32) -> 0 | H24: =G24*(1+H$32) -> 0 | I24: =H24*(1+I$32) -> 0 | J24: =I24*(1+J$32) -> 0 | K24: =J24*(1+K$32) -> 0 | M24: Frais réseau AEFE (FC+Partenariat) | N24: =HLOOKUP(N$20,'Compte Résultat ML'!$C$58:$J$104,47,FALSE) -> 0 | O24: =HLOOKUP(O$20,'Compte Résultat ML'!$C$58:$J$104,47,FALSE) -> 0 | P24: =HLOOKUP(P$20,'Compte Résultat ML'!$C$58:$J$104,47,FALSE) -> #N/A | Q24: =HLOOKUP(Q$20,'Compte Résultat ML'!$C$58:$J$104,47,FALSE) -> #N/A | R24: =HLOOKUP(R$20,'Compte Résultat ML'!$C$58:$J$104,47,FALSE) -> #N/A | S24: =HLOOKUP(S$20,'Compte Résultat ML'!$C$58:$J$104,47,FALSE) -> #N/A | T24: =HLOOKUP(T$20,'Compte Résultat ML'!$C$58:$J$104,47,FALSE) -> #N/A
B25: Frais scolarité COLLEGE | E25: =D25*(1+E$32) -> 0 | F25: =E25*(1+F$32) -> 0 | G25: =F25*(1+G$32) -> 0 | H25: =G25*(1+H$32) -> 0 | I25: =H25*(1+I$32) -> 0 | J25: =I25*(1+J$32) -> 0 | K25: =J25*(1+K$32) -> 0 | M25: ELEMENTAIRE | N25: =HLOOKUP(N$20,'Compte Résultat ML'!$C$4:$J$10,5,FALSE) -> #N/A | O25: =HLOOKUP(O$20,'Compte Résultat ML'!$C$4:$J$10,5,FALSE) -> #N/A | P25: =HLOOKUP(P$20,'Compte Résultat ML'!$C$4:$J$10,5,FALSE) -> #N/A | Q25: =HLOOKUP(Q$20,'Compte Résultat ML'!$C$4:$J$10,5,FALSE) -> #N/A | R25: =HLOOKUP(R$20,'Compte Résultat ML'!$C$4:$J$10,5,FALSE) -> #N/A | S25: =HLOOKUP(S$20,'Compte Résultat ML'!$C$4:$J$10,5,FALSE) -> #N/A | T25: =HLOOKUP(T$20,'Compte Résultat ML'!$C$4:$J$10,5,FALSE) -> #N/A
B26: Frais scolarité LYCEE | E26: =D26*(1+E$32) -> 0 | F26: =E26*(1+F$32) -> 0 | G26: =F26*(1+G$32) -> 0 | H26: =G26*(1+H$32) -> 0 | I26: =H26*(1+I$32) -> 0 | J26: =I26*(1+J$32) -> 0 | K26: =J26*(1+K$32) -> 0 | M26: MS enseignants PDL | N26: =HLOOKUP(N$20,'Compte Résultat ML'!$C$58:$J$112,55,FALSE) -> 0 | O26: =HLOOKUP(O$20,'Compte Résultat ML'!$C$58:$J$112,55,FALSE) -> 0 | P26: =HLOOKUP(P$20,'Compte Résultat ML'!$C$58:$J$112,55,FALSE) -> 0 | Q26: =HLOOKUP(Q$20,'Compte Résultat ML'!$C$58:$J$112,55,FALSE) -> 0 | R26: =HLOOKUP(R$20,'Compte Résultat ML'!$C$58:$J$112,55,FALSE) -> 0 | S26: =HLOOKUP(S$20,'Compte Résultat ML'!$C$58:$J$112,55,FALSE) -> 0 | T26: =HLOOKUP(T$20,'Compte Résultat ML'!$C$58:$J$112,55,FALSE) -> 0
M27: Frais réseau AEFE (FC+Partenariat) | N27: =HLOOKUP(N$20,'Compte Résultat ML'!$C$58:$J$300,73,FALSE) -> 0 | O27: =HLOOKUP(O$20,'Compte Résultat ML'!$C$58:$J$300,73,FALSE) -> 0 | P27: =HLOOKUP(P$20,'Compte Résultat ML'!$C$58:$J$300,73,FALSE) -> 0 | Q27: =HLOOKUP(Q$20,'Compte Résultat ML'!$C$58:$J$300,73,FALSE) -> #N/A | R27: =HLOOKUP(R$20,'Compte Résultat ML'!$C$58:$J$300,73,FALSE) -> #N/A | S27: =HLOOKUP(S$20,'Compte Résultat ML'!$C$58:$J$300,73,FALSE) -> #N/A | T27: =HLOOKUP(T$20,'Compte Résultat ML'!$C$58:$J$300,73,FALSE) -> #N/A
B28: Taux nouveaux inscrits | D28: 0.1 | E28: =D28 -> 0.1 | F28: =E28 -> 0.1 | G28: =F28 -> 0.1 | H28: =G28 -> 0.1 | I28: =H28 -> 0.1 | J28: =I28 -> 0.1 | K28: =J28 -> 0.1 | M28: COLLEGE | N28: =HLOOKUP(N$20,'Compte Résultat ML'!$C$4:$J$10,6,FALSE) -> #N/A | O28: =HLOOKUP(O$20,'Compte Résultat ML'!$C$4:$J$10,6,FALSE) -> #N/A | P28: =HLOOKUP(P$20,'Compte Résultat ML'!$C$4:$J$10,6,FALSE) -> #N/A | Q28: =HLOOKUP(Q$20,'Compte Résultat ML'!$C$4:$J$10,6,FALSE) -> #N/A | R28: =HLOOKUP(R$20,'Compte Résultat ML'!$C$4:$J$10,6,FALSE) -> #N/A | S28: =HLOOKUP(S$20,'Compte Résultat ML'!$C$4:$J$10,6,FALSE) -> #N/A | T28: =HLOOKUP(T$20,'Compte Résultat ML'!$C$4:$J$10,6,FALSE) -> #N/A
B29: Taux abattement (familles nombreuses … ou exonérations personnels) | D29: 0.06 | E29: 0.06 | F29: 0.06 | G29: 0.06 | H29: 0.06 | I29: 0.06 | J29: 0.06 | K29: 0.06 | M29: MS enseignants PDL | N29: =HLOOKUP(N$20,'Compte Résultat ML'!$C$58:$J$138,81,FALSE) -> 0 | O29: =HLOOKUP(O$20,'Compte Résultat ML'!$C$58:$J$138,81,FALSE) -> 0 | P29: =HLOOKUP(P$20,'Compte Résultat ML'!$C$58:$J$138,81,FALSE) -> 0 | Q29: =HLOOKUP(Q$20,'Compte Résultat ML'!$C$58:$J$138,81,FALSE) -> 0 | R29: =HLOOKUP(R$20,'Compte Résultat ML'!$C$58:$J$138,81,FALSE) -> 0 | S29: =HLOOKUP(S$20,'Compte Résultat ML'!$C$58:$J$138,81,FALSE) -> 0 | T29: =HLOOKUP(T$20,'Compte Résultat ML'!$C$58:$J$138,81,FALSE) -> 0
M30: Frais réseau AEFE (FC+Partenariat) | N30: =HLOOKUP(N$20,'Compte Résultat ML'!$C$58:$J$300,99,FALSE) -> 0 | O30: =HLOOKUP(O$20,'Compte Résultat ML'!$C$58:$J$300,99,FALSE) -> 0 | P30: =HLOOKUP(P$20,'Compte Résultat ML'!$C$58:$J$300,99,FALSE) -> 0 | Q30: =HLOOKUP(Q$20,'Compte Résultat ML'!$C$58:$J$300,99,FALSE) -> 0 | R30: =HLOOKUP(R$20,'Compte Résultat ML'!$C$58:$J$300,99,FALSE) -> 0 | S30: =HLOOKUP(S$20,'Compte Résultat ML'!$C$58:$J$300,99,FALSE) -> 0 | T30: =HLOOKUP(T$20,'Compte Résultat ML'!$C$58:$J$300,99,FALSE) -> 0
C31: =C12 -> 2023/2024 | D31: =D12 -> 2024/2025 | E31: =E12 -> 2025/2026 | F31: =F12 -> 2026/2027 | G31: =G12 -> 2027/2028 | H31: =H12 -> 2028/2029 | I31: =I12 -> 2029/2030 | J31: =J12 -> 2030/2031 | K31: =K12 -> 2031/2032 | M31: LYCEE | N31: =HLOOKUP(N$20,'Compte Résultat ML'!$C$4:$J$10,7,FALSE) -> #N/A | O31: =HLOOKUP(O$20,'Compte Résultat ML'!$C$4:$J$10,7,FALSE) -> #N/A | P31: =HLOOKUP(P$20,'Compte Résultat ML'!$C$4:$J$10,7,FALSE) -> #N/A | Q31: =HLOOKUP(Q$20,'Compte Résultat ML'!$C$4:$J$10,7,FALSE) -> #N/A | R31: =HLOOKUP(R$20,'Compte Résultat ML'!$C$4:$J$10,7,FALSE) -> #N/A | S31: =HLOOKUP(S$20,'Compte Résultat ML'!$C$4:$J$10,7,FALSE) -> #N/A | T31: =HLOOKUP(T$20,'Compte Résultat ML'!$C$4:$J$10,7,FALSE) -> #N/A
B32: Taux augmentation frais scolarité | M32: MS enseignants PDL | N32: =HLOOKUP(N$20,'Compte Résultat ML'!$C$58:$J$164,107,FALSE) -> 0 | O32: =HLOOKUP(O$20,'Compte Résultat ML'!$C$58:$J$164,107,FALSE) -> 0 | P32: =HLOOKUP(P$20,'Compte Résultat ML'!$C$58:$J$164,107,FALSE) -> 0 | Q32: =HLOOKUP(Q$20,'Compte Résultat ML'!$C$58:$J$164,107,FALSE) -> 0 | R32: =HLOOKUP(R$20,'Compte Résultat ML'!$C$58:$J$164,107,FALSE) -> 0 | S32: =HLOOKUP(S$20,'Compte Résultat ML'!$C$58:$J$164,107,FALSE) -> 0 | T32: =HLOOKUP(T$20,'Compte Résultat ML'!$C$58:$J$164,107,FALSE) -> 0
M33: Frais réseau AEFE (FC+Partenariat) | N33: =HLOOKUP(N$20,'Compte Résultat ML'!$C$58:$J$300,125,FALSE) -> 0 | O33: =HLOOKUP(O$20,'Compte Résultat ML'!$C$58:$J$300,125,FALSE) -> 0 | P33: =HLOOKUP(P$20,'Compte Résultat ML'!$C$58:$J$300,125,FALSE) -> 0 | Q33: =HLOOKUP(Q$20,'Compte Résultat ML'!$C$58:$J$300,125,FALSE) -> 0 | R33: =HLOOKUP(R$20,'Compte Résultat ML'!$C$58:$J$300,125,FALSE) -> 0 | S33: =HLOOKUP(S$20,'Compte Résultat ML'!$C$58:$J$300,125,FALSE) -> #N/A | T33: =HLOOKUP(T$20,'Compte Résultat ML'!$C$58:$J$300,125,FALSE) -> #N/A
C34: =D34-1 -> 2023 | D34: =C9 -> 2024 | E34: =D34+1 -> 2025 | F34: =E34+1 -> 2026 | G34: =F34+1 -> 2027 | H34: =G34+1 -> 2028 | I34: =H34+1 -> 2029 | J34: =I34+1 -> 2030 | K34: =J34+1 -> 2031 | M34: Résultat en nb jours fonct | N34: =ABS(N$21/(HLOOKUP(N$20,'Compte Résultat ML'!$C$4:$J$120,57,FALSE)/360)) -> #N/A | O34: =ABS(O$21/(HLOOKUP(O$20,'Compte Résultat ML'!$C$4:$J$120,57,FALSE)/360)) -> #N/A | P34: =ABS(P$21/(HLOOKUP(P$20,'Compte Résultat ML'!$C$4:$J$120,57,FALSE)/360)) -> #N/A | Q34: =ABS(Q$21/(HLOOKUP(Q$20,'Compte Résultat ML'!$C$4:$J$120,57,FALSE)/360)) -> #N/A | R34: =ABS(R$21/(HLOOKUP(R$20,'Compte Résultat ML'!$C$4:$J$120,57,FALSE)/360)) -> #N/A | S34: =ABS(S$21/(HLOOKUP(S$20,'Compte Résultat ML'!$C$4:$J$120,57,FALSE)/360)) -> #N/A | T34: =ABS(T$21/(HLOOKUP(T$20,'Compte Résultat ML'!$C$4:$J$120,57,FALSE)/360)) -> #N/A
B35: Taux augmentation annuel salaires | M35: Résultat en nb d'élèves | N35: =ABS(N$21/E$22) -> #N/A | O35: =ABS(O$21/F$22) -> #N/A | P35: =ABS(P$21/G$22) -> #N/A | Q35: =ABS(Q$21/H$22) -> #N/A | R35: =ABS(R$21/I$22) -> #N/A | S35: =ABS(S$21/J$22) -> #N/A | T35: =ABS(T$21/K$22) -> #N/A | U35: =IFERROR(HLOOKUP(U$20,'Compte Résultat ML'!$C$4:$J$10,3,FALSE),"")
B36: Taux annuel inflation | M36: Résultat en point d'augm des FS | N36: =ABS(N21/(HLOOKUP(N$20,'Compte Résultat ML'!$C$4:$J$120,58,FALSE)*1%)) -> #N/A | O36: =ABS(O21/(HLOOKUP(O$20,'Compte Résultat ML'!$C$4:$J$120,58,FALSE)*1%)) -> #N/A | P36: =ABS(P21/(HLOOKUP(P$20,'Compte Résultat ML'!$C$4:$J$120,58,FALSE)*1%)) -> #N/A | Q36: =ABS(Q21/(HLOOKUP(Q$20,'Compte Résultat ML'!$C$4:$J$120,58,FALSE)*1%)) -> #N/A | R36: =ABS(R21/(HLOOKUP(R$20,'Compte Résultat ML'!$C$4:$J$120,58,FALSE)*1%)) -> #N/A | S36: =ABS(S21/(HLOOKUP(S$20,'Compte Résultat ML'!$C$4:$J$120,58,FALSE)*1%)) -> #N/A | T36: =ABS(T21/(HLOOKUP(T$20,'Compte Résultat ML'!$C$4:$J$120,58,FALSE)*1%)) -> #N/A | U36: =IFERROR(HLOOKUP(U$20,'Compte Résultat ML'!$C$4:$J$10,3,FALSE),"")
B37: Taux change / chancellerie
B38: Monnaie : Riyal | C38: =1/4 -> 0.25 | D38: =C38 -> 0.25 | E38: =D38 -> 0.25 | F38: =E38 -> 0.25 | G38: =F38 -> 0.25 | H38: =G38 -> 0.25 | I38: =H38 -> 0.25 | J38: =I38 -> 0.25 | K38: =J38 -> 0.25
B40: Taux remontée PRRD (conventionnés) | C40: 0 | D40: 0 | E40: 0 | F40: 0 | G40: 0 | H40: 0 | I40: 0 | J40: 0 | K40: 0
B42: Nombre de divisions | C42: =C57 -> 2023/2024 | D42: =D57 -> 2024/2025 | E42: =E57 -> 2025/2026 | F42: =F57 -> 2026/2027 | G42: =G57 -> 2027/2028 | H42: =H57 -> 2028/2029 | I42: =I57 -> 2029/2030 | J42: =J57 -> 2030/2031 | K42: =K57 -> 2031/2032
B43: Maternelle | D43: =IFERROR(CEILING(HLOOKUP(D$42,'Projection Effectifs'!$C$31:$M$38,2,FALSE)/'Hypothèses '!D49,0.5),0) -> 1.5 | E43: =IFERROR(CEILING(HLOOKUP(E$42,'Projection Effectifs'!$C$31:$M$38,2,FALSE)/'Hypothèses '!E49,0.5),0) -> 0 | F43: =IFERROR(CEILING(HLOOKUP(F$42,'Projection Effectifs'!$C$31:$M$38,2,FALSE)/'Hypothèses '!F49,0.5),0) -> 0 | G43: =IFERROR(CEILING(HLOOKUP(G$42,'Projection Effectifs'!$C$31:$M$38,2,FALSE)/'Hypothèses '!G49,0.5),0) -> 0 | H43: =IFERROR(CEILING(HLOOKUP(H$42,'Projection Effectifs'!$C$31:$M$38,2,FALSE)/'Hypothèses '!H49,0.5),0) -> 0 | I43: =IFERROR(CEILING(HLOOKUP(I$42,'Projection Effectifs'!$C$31:$M$38,2,FALSE)/'Hypothèses '!I49,0.5),0) -> 0 | J43: =IFERROR(CEILING(HLOOKUP(J$42,'Projection Effectifs'!$C$31:$M$38,2,FALSE)/'Hypothèses '!J49,0.5),0) -> 0 | K43: =IFERROR(CEILING(HLOOKUP(K$42,'Projection Effectifs'!$C$31:$M$38,2,FALSE)/'Hypothèses '!K49,0.5),0) -> 0
B44: Elémentaire | D44: =IFERROR(CEILING(HLOOKUP(D$42,'Projection Effectifs'!$C$31:$M$38,3,FALSE)/'Hypothèses '!D50,0.5),0) -> 1 | E44: =IFERROR(CEILING(HLOOKUP(E$42,'Projection Effectifs'!$C$31:$M$38,3,FALSE)/'Hypothèses '!E50,0.5),0) -> 0 | F44: =IFERROR(CEILING(HLOOKUP(F$42,'Projection Effectifs'!$C$31:$M$38,3,FALSE)/'Hypothèses '!F50,0.5),0) -> 0 | G44: =IFERROR(CEILING(HLOOKUP(G$42,'Projection Effectifs'!$C$31:$M$38,3,FALSE)/'Hypothèses '!G50,0.5),0) -> 0 | H44: =IFERROR(CEILING(HLOOKUP(H$42,'Projection Effectifs'!$C$31:$M$38,3,FALSE)/'Hypothèses '!H50,0.5),0) -> 0 | I44: =IFERROR(CEILING(HLOOKUP(I$42,'Projection Effectifs'!$C$31:$M$38,3,FALSE)/'Hypothèses '!I50,0.5),0) -> 0 | J44: =IFERROR(CEILING(HLOOKUP(J$42,'Projection Effectifs'!$C$31:$M$38,3,FALSE)/'Hypothèses '!J50,0.5),0) -> 0 | K44: =IFERROR(CEILING(HLOOKUP(K$42,'Projection Effectifs'!$C$31:$M$38,3,FALSE)/'Hypothèses '!K50,0.5),0) -> 0
B45: Collège | D45: =IFERROR(ROUNDUP(HLOOKUP(D$42,'Projection Effectifs'!$C$31:$M$38,5,FALSE)/'Hypothèses '!D51,0),0) -> 1 | E45: =IFERROR(ROUNDUP(HLOOKUP(E$42,'Projection Effectifs'!$C$31:$M$38,5,FALSE)/'Hypothèses '!E51,0),0) -> 0 | F45: =IFERROR(ROUNDUP(HLOOKUP(F$42,'Projection Effectifs'!$C$31:$M$38,5,FALSE)/'Hypothèses '!F51,0),0) -> 0 | G45: =IFERROR(ROUNDUP(HLOOKUP(G$42,'Projection Effectifs'!$C$31:$M$38,5,FALSE)/'Hypothèses '!G51,0),0) -> 0 | H45: =IFERROR(ROUNDUP(HLOOKUP(H$42,'Projection Effectifs'!$C$31:$M$38,5,FALSE)/'Hypothèses '!H51,0),0) -> 0 | I45: =IFERROR(ROUNDUP(HLOOKUP(I$42,'Projection Effectifs'!$C$31:$M$38,5,FALSE)/'Hypothèses '!I51,0),0) -> 0 | J45: =IFERROR(ROUNDUP(HLOOKUP(J$42,'Projection Effectifs'!$C$31:$M$38,5,FALSE)/'Hypothèses '!J51,0),0) -> 0 | K45: =IFERROR(ROUNDUP(HLOOKUP(K$42,'Projection Effectifs'!$C$31:$M$38,5,FALSE)/'Hypothèses '!K51,0),0) -> 0 | M45: RESULTAT OPERATIONNEL SCOLAIRE
...

Sheet Calcul MS Personnels
C3: 2 | D3: 3 | E3: 4 | F3: 5 | G3: 6 | H3: 7 | I3: 8 | J3: 9 | K3: 10
C4: ='Hypothèses '!C12 -> 2023/2024 | D4: ='Hypothèses '!D12 -> 2024/2025 | E4: ='Hypothèses '!E12 -> 2025/2026 | F4: ='Hypothèses '!F12 -> 2026/2027 | G4: ='Hypothèses '!G12 -> 2027/2028 | H4: ='Hypothèses '!H12 -> 2028/2029 | I4: ='Hypothèses '!I12 -> 2029/2030 | J4: ='Hypothèses '!J12 -> 2030/2031 | K4: ='Hypothèses '!K12 -> 2031/2032 | M4: Référenciel | N4: Moyenne existant AEFE
A5: Report Hypothèses | B5: Personnels généraux communs | C5: =SUM(C6:C13) -> #N/A | D5: =SUM(D6:D13) -> #N/A | E5: =SUM(E6:E13) -> #N/A | F5: =SUM(F6:F13) -> #N/A | G5: =SUM(G6:G13) -> #N/A | H5: =SUM(H6:H13) -> #N/A | I5: =SUM(I6:I13) -> #N/A | J5: =SUM(J6:J13) -> #N/A | K5: =SUM(K6:K13) -> #N/A | M5: Personnels Primaire
A6: Ne pas modifier - voir onglet Hypothèses | B6: Chef d'Etablissement PDL | C6: =VLOOKUP($B6,'Hypothèses '!$B$56:$K$66,'Hypothèses '!C$56,FALSE) -> #N/A | D6: =VLOOKUP($B6,'Hypothèses '!$B$56:$K$66,'Hypothèses '!D$56,FALSE) -> #N/A | E6: =VLOOKUP($B6,'Hypothèses '!$B$56:$K$66,'Hypothèses '!E$56,FALSE) -> #N/A | F6: =VLOOKUP($B6,'Hypothèses '!$B$56:$K$66,'Hypothèses '!F$56,FALSE) -> #N/A | G6: =VLOOKUP($B6,'Hypothèses '!$B$56:$K$66,'Hypothèses '!G$56,FALSE) -> #N/A | H6: =VLOOKUP($B6,'Hypothèses '!$B$56:$K$66,'Hypothèses '!H$56,FALSE) -> #N/A | I6: =VLOOKUP($B6,'Hypothèses '!$B$56:$K$66,'Hypothèses '!I$56,FALSE) -> #N/A | J6: =VLOOKUP($B6,'Hypothèses '!$B$56:$K$66,'Hypothèses '!J$56,FALSE) -> #N/A | K6: =VLOOKUP($B6,'Hypothèses '!$B$56:$K$66,'Hypothèses '!K$56,FALSE) -> #N/A | M6: Nb elèves Primaire | N6: <100 | O6: 100 à 200 | P6: 200 à 500 | Q6: 500 à 1000 | R6: 1000 à 1500
B7: DAF PDL | C7: =VLOOKUP($B7,'Hypothèses '!$B$56:$K$66,'Hypothèses '!C$56,FALSE) -> #N/A | D7: =VLOOKUP($B7,'Hypothèses '!$B$56:$K$66,'Hypothèses '!D$56,FALSE) -> #N/A | E7: =VLOOKUP($B7,'Hypothèses '!$B$56:$K$66,'Hypothèses '!E$56,FALSE) -> #N/A | F7: =VLOOKUP($B7,'Hypothèses '!$B$56:$K$66,'Hypothèses '!F$56,FALSE) -> #N/A | G7: =VLOOKUP($B7,'Hypothèses '!$B$56:$K$66,'Hypothèses '!G$56,FALSE) -> #N/A | H7: =VLOOKUP($B7,'Hypothèses '!$B$56:$K$66,'Hypothèses '!H$56,FALSE) -> #N/A | I7: =VLOOKUP($B7,'Hypothèses '!$B$56:$K$66,'Hypothèses '!I$56,FALSE) -> #N/A | J7: =VLOOKUP($B7,'Hypothèses '!$B$56:$K$66,'Hypothèses '!J$56,FALSE) -> #N/A | K7: =VLOOKUP($B7,'Hypothèses '!$B$56:$K$66,'Hypothèses '!K$56,FALSE) -> #N/A | M7: Directrice ou directeur | N7: 1 | O7: 1 | P7: 1 | Q7: 1 | R7: 1
B8: DRH | C8: =VLOOKUP($B8,'Hypothèses '!$B$56:$K$66,'Hypothèses '!C$56,FALSE) -> 0 | D8: =VLOOKUP($B8,'Hypothèses '!$B$56:$K$66,'Hypothèses '!D$56,FALSE) -> 2 | E8: =VLOOKUP($B8,'Hypothèses '!$B$56:$K$66,'Hypothèses '!E$56,FALSE) -> 0 | F8: =VLOOKUP($B8,'Hypothèses '!$B$56:$K$66,'Hypothèses '!F$56,FALSE) -> 0 | G8: =VLOOKUP($B8,'Hypothèses '!$B$56:$K$66,'Hypothèses '!G$56,FALSE) -> 0 | H8: =VLOOKUP($B8,'Hypothèses '!$B$56:$K$66,'Hypothèses '!H$56,FALSE) -> 0 | I8: =VLOOKUP($B8,'Hypothèses '!$B$56:$K$66,'Hypothèses '!I$56,FALSE) -> 0 | J8: =VLOOKUP($B8,'Hypothèses '!$B$56:$K$66,'Hypothèses '!J$56,FALSE) -> 0 | K8: =VLOOKUP($B8,'Hypothèses '!$B$56:$K$66,'Hypothèses '!K$56,FALSE) -> 0 | M8: direction adjoint | N8: 0 | O8: 0 | P8: 0 | Q8: 1 | R8: 1
B9: Autre Administratif | C9: =VLOOKUP($B9,'Hypothèses '!$B$56:$K$66,'Hypothèses '!C$56,FALSE) -> 0 | D9: =VLOOKUP($B9,'Hypothèses '!$B$56:$K$66,'Hypothèses '!D$56,FALSE) -> 0 | E9: =VLOOKUP($B9,'Hypothèses '!$B$56:$K$66,'Hypothèses '!E$56,FALSE) -> 0 | F9: =VLOOKUP($B9,'Hypothèses '!$B$56:$K$66,'Hypothèses '!F$56,FALSE) -> 0 | G9: =VLOOKUP($B9,'Hypothèses '!$B$56:$K$66,'Hypothèses '!G$56,FALSE) -> 0 | H9: =VLOOKUP($B9,'Hypothèses '!$B$56:$K$66,'Hypothèses '!H$56,FALSE) -> 0 | I9: =VLOOKUP($B9,'Hypothèses '!$B$56:$K$66,'Hypothèses '!I$56,FALSE) -> 0 | J9: =VLOOKUP($B9,'Hypothèses '!$B$56:$K$66,'Hypothèses '!J$56,FALSE) -> 0 | K9: =VLOOKUP($B9,'Hypothèses '!$B$56:$K$66,'Hypothèses '!K$56,FALSE) -> 0 | M9: Vie scolaire - CPE /Educateurs | N9: 0 | O9: 0.5 | P9: 1 | Q9: 2 | R9: 3
B10: Technique - Informatique - Maintenance | C10: =VLOOKUP($B10,'Hypothèses '!$B$56:$K$66,'Hypothèses '!C$56,FALSE) -> #N/A | D10: =VLOOKUP($B10,'Hypothèses '!$B$56:$K$66,'Hypothèses '!D$56,FALSE) -> #N/A | E10: =VLOOKUP($B10,'Hypothèses '!$B$56:$K$66,'Hypothèses '!E$56,FALSE) -> #N/A | F10: =VLOOKUP($B10,'Hypothèses '!$B$56:$K$66,'Hypothèses '!F$56,FALSE) -> #N/A | G10: =VLOOKUP($B10,'Hypothèses '!$B$56:$K$66,'Hypothèses '!G$56,FALSE) -> #N/A | H10: =VLOOKUP($B10,'Hypothèses '!$B$56:$K$66,'Hypothèses '!H$56,FALSE) -> #N/A | I10: =VLOOKUP($B10,'Hypothèses '!$B$56:$K$66,'Hypothèses '!I$56,FALSE) -> #N/A | J10: =VLOOKUP($B10,'Hypothèses '!$B$56:$K$66,'Hypothèses '!J$56,FALSE) -> #N/A | K10: =VLOOKUP($B10,'Hypothèses '!$B$56:$K$66,'Hypothèses '!K$56,FALSE) -> #N/A | M10: Documentation | N10: 0 | O10: 0.5 | P10: 1 | Q10: 1.5 | R10: 2
B11: Entretien / Sécurité | C11: =VLOOKUP($B11,'Hypothèses '!$B$56:$K$66,'Hypothèses '!C$56,FALSE) -> 0 | D11: =VLOOKUP($B11,'Hypothèses '!$B$56:$K$66,'Hypothèses '!D$56,FALSE) -> 1 | E11: =VLOOKUP($B11,'Hypothèses '!$B$56:$K$66,'Hypothèses '!E$56,FALSE) -> 0 | F11: =VLOOKUP($B11,'Hypothèses '!$B$56:$K$66,'Hypothèses '!F$56,FALSE) -> 0 | G11: =VLOOKUP($B11,'Hypothèses '!$B$56:$K$66,'Hypothèses '!G$56,FALSE) -> 0 | H11: =VLOOKUP($B11,'Hypothèses '!$B$56:$K$66,'Hypothèses '!H$56,FALSE) -> 0 | I11: =VLOOKUP($B11,'Hypothèses '!$B$56:$K$66,'Hypothèses '!I$56,FALSE) -> 0 | J11: =VLOOKUP($B11,'Hypothèses '!$B$56:$K$66,'Hypothèses '!J$56,FALSE) -> 0 | K11: =VLOOKUP($B11,'Hypothèses '!$B$56:$K$66,'Hypothèses '!K$56,FALSE) -> 0 | M11: Infirmière | N11: 0.5 | O11: 1 | P11: 1.5 | Q11: 2 | R11: 2.5
B12: Documentation | C12: =VLOOKUP($B12,'Hypothèses '!$B$56:$K$66,'Hypothèses '!C$56,FALSE) -> 0 | D12: =VLOOKUP($B12,'Hypothèses '!$B$56:$K$66,'Hypothèses '!D$56,FALSE) -> 2 | E12: =VLOOKUP($B12,'Hypothèses '!$B$56:$K$66,'Hypothèses '!E$56,FALSE) -> 0 | F12: =VLOOKUP($B12,'Hypothèses '!$B$56:$K$66,'Hypothèses '!F$56,FALSE) -> 0 | G12: =VLOOKUP($B12,'Hypothèses '!$B$56:$K$66,'Hypothèses '!G$56,FALSE) -> 0 | H12: =VLOOKUP($B12,'Hypothèses '!$B$56:$K$66,'Hypothèses '!H$56,FALSE) -> 0 | I12: =VLOOKUP($B12,'Hypothèses '!$B$56:$K$66,'Hypothèses '!I$56,FALSE) -> 0 | J12: =VLOOKUP($B12,'Hypothèses '!$B$56:$K$66,'Hypothèses '!J$56,FALSE) -> 0 | K12: =VLOOKUP($B12,'Hypothèses '!$B$56:$K$66,'Hypothèses '!K$56,FALSE) -> 0
B13: Autre commun | C13: 0 | D13: =VLOOKUP($B13,'Hypothèses '!$B$56:$K$66,'Hypothèses '!D$56,FALSE) -> 0 | E13: =VLOOKUP($B13,'Hypothèses '!$B$56:$K$66,'Hypothèses '!E$56,FALSE) -> 0 | F13: =VLOOKUP($B13,'Hypothèses '!$B$56:$K$66,'Hypothèses '!F$56,FALSE) -> 0 | G13: =VLOOKUP($B13,'Hypothèses '!$B$56:$K$66,'Hypothèses '!G$56,FALSE) -> 0 | H13: =VLOOKUP($B13,'Hypothèses '!$B$56:$K$66,'Hypothèses '!H$56,FALSE) -> 0 | I13: =VLOOKUP($B13,'Hypothèses '!$B$56:$K$66,'Hypothèses '!I$56,FALSE) -> 0 | J13: =VLOOKUP($B13,'Hypothèses '!$B$56:$K$66,'Hypothèses '!J$56,FALSE) -> 0 | K13: =VLOOKUP($B13,'Hypothèses '!$B$56:$K$66,'Hypothèses '!K$56,FALSE) -> 0
A14: Report Hypothèses
A15: Ne pas modifier - voir onglet Hypothèses | B15: Personnels Primaire Commun | C15: =SUM(C16:C22) -> #N/A | D15: =SUM(D16:D22) -> #N/A | E15: =SUM(E16:E22) -> #N/A | F15: =SUM(F16:F22) -> #N/A | G15: =SUM(G16:G22) -> #N/A | H15: =SUM(H16:H22) -> #N/A | I15: =SUM(I16:I22) -> #N/A | J15: =SUM(J16:J22) -> #N/A | K15: =SUM(K16:K22) -> #N/A
B16: Direction PDL | C16: =VLOOKUP($B16,'Hypothèses '!$B$68:$K$74,'Hypothèses '!C$56,FALSE) -> #N/A | D16: =VLOOKUP($B16,'Hypothèses '!$B$68:$K$74,'Hypothèses '!D$56,FALSE) -> #N/A | E16: =VLOOKUP($B16,'Hypothèses '!$B$68:$K$74,'Hypothèses '!E$56,FALSE) -> #N/A | F16: =VLOOKUP($B16,'Hypothèses '!$B$68:$K$74,'Hypothèses '!F$56,FALSE) -> #N/A | G16: =VLOOKUP($B16,'Hypothèses '!$B$68:$K$74,'Hypothèses '!G$56,FALSE) -> #N/A | H16: =VLOOKUP($B16,'Hypothèses '!$B$68:$K$74,'Hypothèses '!H$56,FALSE) -> #N/A | I16: =VLOOKUP($B16,'Hypothèses '!$B$68:$K$74,'Hypothèses '!I$56,FALSE) -> #N/A | J16: =VLOOKUP($B16,'Hypothèses '!$B$68:$K$74,'Hypothèses '!J$56,FALSE) -> #N/A | K16: =VLOOKUP($B16,'Hypothèses '!$B$68:$K$74,'Hypothèses '!K$56,FALSE) -> #N/A
B17: Direction adjointe | C17: =VLOOKUP($B17,'Hypothèses '!$B$68:$K$74,'Hypothèses '!C$56,FALSE) -> 0 | D17: =VLOOKUP($B17,'Hypothèses '!$B$68:$K$74,'Hypothèses '!D$56,FALSE) -> 0 | E17: =VLOOKUP($B17,'Hypothèses '!$B$68:$K$74,'Hypothèses '!E$56,FALSE) -> 0 | F17: =VLOOKUP($B17,'Hypothèses '!$B$68:$K$74,'Hypothèses '!F$56,FALSE) -> 0 | G17: =VLOOKUP($B17,'Hypothèses '!$B$68:$K$74,'Hypothèses '!G$56,FALSE) -> 0 | H17: =VLOOKUP($B17,'Hypothèses '!$B$68:$K$74,'Hypothèses '!H$56,FALSE) -> 0 | I17: =VLOOKUP($B17,'Hypothèses '!$B$68:$K$74,'Hypothèses '!I$56,FALSE) -> 0 | J17: =VLOOKUP($B17,'Hypothèses '!$B$68:$K$74,'Hypothèses '!J$56,FALSE) -> 0 | K17: =VLOOKUP($B17,'Hypothèses '!$B$68:$K$74,'Hypothèses '!K$56,FALSE) -> 0
B18: Conseiller pédagogique | C18: =VLOOKUP($B18,'Hypothèses '!$B$68:$K$74,'Hypothèses '!C$56,FALSE) -> 0 | D18: =VLOOKUP($B18,'Hypothèses '!$B$68:$K$74,'Hypothèses '!D$56,FALSE) -> 0 | E18: =VLOOKUP($B18,'Hypothèses '!$B$68:$K$74,'Hypothèses '!E$56,FALSE) -> 0 | F18: =VLOOKUP($B18,'Hypothèses '!$B$68:$K$74,'Hypothèses '!F$56,FALSE) -> 0 | G18: =VLOOKUP($B18,'Hypothèses '!$B$68:$K$74,'Hypothèses '!G$56,FALSE) -> 0 | H18: =VLOOKUP($B18,'Hypothèses '!$B$68:$K$74,'Hypothèses '!H$56,FALSE) -> 0 | I18: =VLOOKUP($B18,'Hypothèses '!$B$68:$K$74,'Hypothèses '!I$56,FALSE) -> 0 | J18: =VLOOKUP($B18,'Hypothèses '!$B$68:$K$74,'Hypothèses '!J$56,FALSE) -> 0 | K18: =VLOOKUP($B18,'Hypothèses '!$B$68:$K$74,'Hypothèses '!K$56,FALSE) -> 0
B19: Vie scolaire - Educateurs | C19: =VLOOKUP($B19,'Hypothèses '!$B$68:$K$74,'Hypothèses '!C$56,FALSE) -> 0 | D19: =VLOOKUP($B19,'Hypothèses '!$B$68:$K$74,'Hypothèses '!D$56,FALSE) -> 1 | E19: =VLOOKUP($B19,'Hypothèses '!$B$68:$K$74,'Hypothèses '!E$56,FALSE) -> 0 | F19: =VLOOKUP($B19,'Hypothèses '!$B$68:$K$74,'Hypothèses '!F$56,FALSE) -> 0 | G19: =VLOOKUP($B19,'Hypothèses '!$B$68:$K$74,'Hypothèses '!G$56,FALSE) -> 0 | H19: =VLOOKUP($B19,'Hypothèses '!$B$68:$K$74,'Hypothèses '!H$56,FALSE) -> 0 | I19: =VLOOKUP($B19,'Hypothèses '!$B$68:$K$74,'Hypothèses '!I$56,FALSE) -> 0 | J19: =VLOOKUP($B19,'Hypothèses '!$B$68:$K$74,'Hypothèses '!J$56,FALSE) -> 0 | K19: =VLOOKUP($B19,'Hypothèses '!$B$68:$K$74,'Hypothèses '!K$56,FALSE) -> 0
B20: Documentation | C20: =VLOOKUP($B20,'Hypothèses '!$B$68:$K$74,'Hypothèses '!C$56,FALSE) -> 0 | D20: =VLOOKUP($B20,'Hypothèses '!$B$68:$K$74,'Hypothèses '!D$56,FALSE) -> 1 | E20: =VLOOKUP($B20,'Hypothèses '!$B$68:$K$74,'Hypothèses '!E$56,FALSE) -> 0 | F20: =VLOOKUP($B20,'Hypothèses '!$B$68:$K$74,'Hypothèses '!F$56,FALSE) -> 0 | G20: =VLOOKUP($B20,'Hypothèses '!$B$68:$K$74,'Hypothèses '!G$56,FALSE) -> 0 | H20: =VLOOKUP($B20,'Hypothèses '!$B$68:$K$74,'Hypothèses '!H$56,FALSE) -> 0 | I20: =VLOOKUP($B20,'Hypothèses '!$B$68:$K$74,'Hypothèses '!I$56,FALSE) -> 0 | J20: =VLOOKUP($B20,'Hypothèses '!$B$68:$K$74,'Hypothèses '!J$56,FALSE) -> 0 | K20: =VLOOKUP($B20,'Hypothèses '!$B$68:$K$74,'Hypothèses '!K$56,FALSE) -> 0
B21: Infirmière | C21: =VLOOKUP($B21,'Hypothèses '!$B$68:$K$74,'Hypothèses '!C$56,FALSE) -> 0 | D21: =VLOOKUP($B21,'Hypothèses '!$B$68:$K$74,'Hypothèses '!D$56,FALSE) -> 0 | E21: =VLOOKUP($B21,'Hypothèses '!$B$68:$K$74,'Hypothèses '!E$56,FALSE) -> 0 | F21: =VLOOKUP($B21,'Hypothèses '!$B$68:$K$74,'Hypothèses '!F$56,FALSE) -> 0 | G21: =VLOOKUP($B21,'Hypothèses '!$B$68:$K$74,'Hypothèses '!G$56,FALSE) -> 0 | H21: =VLOOKUP($B21,'Hypothèses '!$B$68:$K$74,'Hypothèses '!H$56,FALSE) -> 0 | I21: =VLOOKUP($B21,'Hypothèses '!$B$68:$K$74,'Hypothèses '!I$56,FALSE) -> 0 | J21: =VLOOKUP($B21,'Hypothèses '!$B$68:$K$74,'Hypothèses '!J$56,FALSE) -> 0 | K21: =VLOOKUP($B21,'Hypothèses '!$B$68:$K$74,'Hypothèses '!K$56,FALSE) -> 0
A22: Report Hypothèses | B22: Autre primaire commun | C22: =VLOOKUP($B22,'Hypothèses '!$B$68:$K$74,'Hypothèses '!C$56,FALSE) -> 0 | D22: =VLOOKUP($B22,'Hypothèses '!$B$68:$K$74,'Hypothèses '!D$56,FALSE) -> 2 | E22: =VLOOKUP($B22,'Hypothèses '!$B$68:$K$74,'Hypothèses '!E$56,FALSE) -> 0 | F22: =VLOOKUP($B22,'Hypothèses '!$B$68:$K$74,'Hypothèses '!F$56,FALSE) -> 0 | G22: =VLOOKUP($B22,'Hypothèses '!$B$68:$K$74,'Hypothèses '!G$56,FALSE) -> 0 | H22: =VLOOKUP($B22,'Hypothèses '!$B$68:$K$74,'Hypothèses '!H$56,FALSE) -> 0 | I22: =VLOOKUP($B22,'Hypothèses '!$B$68:$K$74,'Hypothèses '!I$56,FALSE) -> 0 | J22: =VLOOKUP($B22,'Hypothèses '!$B$68:$K$74,'Hypothèses '!J$56,FALSE) -> 0 | K22: =VLOOKUP($B22,'Hypothèses '!$B$68:$K$74,'Hypothèses '!K$56,FALSE) -> 0
A23: Ne pas modifier - voir onglet Hypothèses
B24: Personnels secondaire commun | C24: =SUM(C25:C32) -> #N/A | D24: =SUM(D25:D32) -> #N/A | E24: =SUM(E25:E32) -> #N/A | F24: =SUM(F25:F32) -> #N/A | G24: =SUM(G25:G32) -> #N/A | H24: =SUM(H25:H32) -> #N/A | I24: =SUM(I25:I32) -> #N/A | J24: =SUM(J25:J32) -> #N/A | K24: =SUM(K25:K32) -> #N/A
B25: Proviseur adjoint PDL | C25: =VLOOKUP($B25,'Hypothèses '!$B$76:$K$83,'Hypothèses '!C$56,FALSE) -> #N/A | D25: =VLOOKUP($B25,'Hypothèses '!$B$76:$K$83,'Hypothèses '!D$56,FALSE) -> #N/A | E25: =VLOOKUP($B25,'Hypothèses '!$B$76:$K$83,'Hypothèses '!E$56,FALSE) -> #N/A | F25: =VLOOKUP($B25,'Hypothèses '!$B$76:$K$83,'Hypothèses '!F$56,FALSE) -> #N/A | G25: =VLOOKUP($B25,'Hypothèses '!$B$76:$K$83,'Hypothèses '!G$56,FALSE) -> #N/A | H25: =VLOOKUP($B25,'Hypothèses '!$B$76:$K$83,'Hypothèses '!H$56,FALSE) -> #N/A | I25: =VLOOKUP($B25,'Hypothèses '!$B$76:$K$83,'Hypothèses '!I$56,FALSE) -> #N/A | J25: =VLOOKUP($B25,'Hypothèses '!$B$76:$K$83,'Hypothèses '!J$56,FALSE) -> #N/A | K25: =VLOOKUP($B25,'Hypothèses '!$B$76:$K$83,'Hypothèses '!K$56,FALSE) -> #N/A
B26: CPE (Conseiller Principal d'Education) PDL | C26: =VLOOKUP($B26,'Hypothèses '!$B$76:$K$83,'Hypothèses '!C$56,FALSE) -> 1 | D26: =VLOOKUP($B26,'Hypothèses '!$B$76:$K$83,'Hypothèses '!D$56,FALSE) -> 1 | E26: =VLOOKUP($B26,'Hypothèses '!$B$76:$K$83,'Hypothèses '!E$56,FALSE) -> 1 | F26: =VLOOKUP($B26,'Hypothèses '!$B$76:$K$83,'Hypothèses '!F$56,FALSE) -> 1 | G26: =VLOOKUP($B26,'Hypothèses '!$B$76:$K$83,'Hypothèses '!G$56,FALSE) -> 1 | H26: =VLOOKUP($B26,'Hypothèses '!$B$76:$K$83,'Hypothèses '!H$56,FALSE) -> 1 | I26: =VLOOKUP($B26,'Hypothèses '!$B$76:$K$83,'Hypothèses '!I$56,FALSE) -> 1 | J26: =VLOOKUP($B26,'Hypothèses '!$B$76:$K$83,'Hypothèses '!J$56,FALSE) -> 1 | K26: =VLOOKUP($B26,'Hypothèses '!$B$76:$K$83,'Hypothèses '!K$56,FALSE) -> 1
B27: Vie scolaire - Educateurs | C27: =VLOOKUP($B27,'Hypothèses '!$B$76:$K$83,'Hypothèses '!C$56,FALSE) -> 11 | D27: =VLOOKUP($B27,'Hypothèses '!$B$76:$K$83,'Hypothèses '!D$56,FALSE) -> 14 | E27: =VLOOKUP($B27,'Hypothèses '!$B$76:$K$83,'Hypothèses '!E$56,FALSE) -> 14 | F27: =VLOOKUP($B27,'Hypothèses '!$B$76:$K$83,'Hypothèses '!F$56,FALSE) -> 14 | G27: =VLOOKUP($B27,'Hypothèses '!$B$76:$K$83,'Hypothèses '!G$56,FALSE) -> 14 | H27: =VLOOKUP($B27,'Hypothèses '!$B$76:$K$83,'Hypothèses '!H$56,FALSE) -> 14 | I27: =VLOOKUP($B27,'Hypothèses '!$B$76:$K$83,'Hypothèses '!I$56,FALSE) -> 14 | J27: =VLOOKUP($B27,'Hypothèses '!$B$76:$K$83,'Hypothèses '!J$56,FALSE) -> 14 | K27: =VLOOKUP($B27,'Hypothèses '!$B$76:$K$83,'Hypothèses '!K$56,FALSE) -> 14
B28: Documentation | C28: =VLOOKUP($B28,'Hypothèses '!$B$76:$K$83,'Hypothèses '!C$56,FALSE) -> 1 | D28: =VLOOKUP($B28,'Hypothèses '!$B$76:$K$83,'Hypothèses '!D$56,FALSE) -> 2 | E28: =VLOOKUP($B28,'Hypothèses '!$B$76:$K$83,'Hypothèses '!E$56,FALSE) -> 2 | F28: =VLOOKUP($B28,'Hypothèses '!$B$76:$K$83,'Hypothèses '!F$56,FALSE) -> 2 | G28: =VLOOKUP($B28,'Hypothèses '!$B$76:$K$83,'Hypothèses '!G$56,FALSE) -> 2 | H28: =VLOOKUP($B28,'Hypothèses '!$B$76:$K$83,'Hypothèses '!H$56,FALSE) -> 2 | I28: =VLOOKUP($B28,'Hypothèses '!$B$76:$K$83,'Hypothèses '!I$56,FALSE) -> 2 | J28: =VLOOKUP($B28,'Hypothèses '!$B$76:$K$83,'Hypothèses '!J$56,FALSE) -> 2 | K28: =VLOOKUP($B28,'Hypothèses '!$B$76:$K$83,'Hypothèses '!K$56,FALSE) -> 2
B29: Infirmière | C29: =VLOOKUP($B29,'Hypothèses '!$B$76:$K$83,'Hypothèses '!C$56,FALSE) -> 1 | D29: =VLOOKUP($B29,'Hypothèses '!$B$76:$K$83,'Hypothèses '!D$56,FALSE) -> 2 | E29: =VLOOKUP($B29,'Hypothèses '!$B$76:$K$83,'Hypothèses '!E$56,FALSE) -> 2 | F29: =VLOOKUP($B29,'Hypothèses '!$B$76:$K$83,'Hypothèses '!F$56,FALSE) -> 2 | G29: =VLOOKUP($B29,'Hypothèses '!$B$76:$K$83,'Hypothèses '!G$56,FALSE) -> 2 | H29: =VLOOKUP($B29,'Hypothèses '!$B$76:$K$83,'Hypothèses '!H$56,FALSE) -> 2 | I29: =VLOOKUP($B29,'Hypothèses '!$B$76:$K$83,'Hypothèses '!I$56,FALSE) -> 2 | J29: =VLOOKUP($B29,'Hypothèses '!$B$76:$K$83,'Hypothèses '!J$56,FALSE) -> 2 | K29: =VLOOKUP($B29,'Hypothèses '!$B$76:$K$83,'Hypothèses '!K$56,FALSE) -> 2
B30: Laboratoire | C30: =VLOOKUP($B30,'Hypothèses '!$B$76:$K$83,'Hypothèses '!C$56,FALSE) -> 2 | D30: =VLOOKUP($B30,'Hypothèses '!$B$76:$K$83,'Hypothèses '!D$56,FALSE) -> 1 | E30: =VLOOKUP($B30,'Hypothèses '!$B$76:$K$83,'Hypothèses '!E$56,FALSE) -> 1 | F30: =VLOOKUP($B30,'Hypothèses '!$B$76:$K$83,'Hypothèses '!F$56,FALSE) -> 1 | G30: =VLOOKUP($B30,'Hypothèses '!$B$76:$K$83,'Hypothèses '!G$56,FALSE) -> 1 | H30: =VLOOKUP($B30,'Hypothèses '!$B$76:$K$83,'Hypothèses '!H$56,FALSE) -> 1 | I30: =VLOOKUP($B30,'Hypothèses '!$B$76:$K$83,'Hypothèses '!I$56,FALSE) -> 1 | J30: =VLOOKUP($B30,'Hypothèses '!$B$76:$K$83,'Hypothèses '!J$56,FALSE) -> 1 | K30: =VLOOKUP($B30,'Hypothèses '!$B$76:$K$83,'Hypothèses '!K$56,FALSE) -> 1
B31: Orientation | C31: =VLOOKUP($B31,'Hypothèses '!$B$76:$K$83,'Hypothèses '!C$56,FALSE) -> 1 | D31: =VLOOKUP($B31,'Hypothèses '!$B$76:$K$83,'Hypothèses '!D$56,FALSE) -> 0 | E31: =VLOOKUP($B31,'Hypothèses '!$B$76:$K$83,'Hypothèses '!E$56,FALSE) -> 0 | F31: =VLOOKUP($B31,'Hypothèses '!$B$76:$K$83,'Hypothèses '!F$56,FALSE) -> 0 | G31: =VLOOKUP($B31,'Hypothèses '!$B$76:$K$83,'Hypothèses '!G$56,FALSE) -> 0 | H31: =VLOOKUP($B31,'Hypothèses '!$B$76:$K$83,'Hypothèses '!H$56,FALSE) -> 0 | I31: =VLOOKUP($B31,'Hypothèses '!$B$76:$K$83,'Hypothèses '!I$56,FALSE) -> 0 | J31: =VLOOKUP($B31,'Hypothèses '!$B$76:$K$83,'Hypothèses '!J$56,FALSE) -> 0 | K31: =VLOOKUP($B31,'Hypothèses '!$B$76:$K$83,'Hypothèses '!K$56,FALSE) -> 0
B32: Autre secondaire commun | C32: =VLOOKUP($B32,'Hypothèses '!$B$76:$K$83,'Hypothèses '!C$56,FALSE) -> 2 | D32: =VLOOKUP($B32,'Hypothèses '!$B$76:$K$83,'Hypothèses '!D$56,FALSE) -> 0 | E32: =VLOOKUP($B32,'Hypothèses '!$B$76:$K$83,'Hypothèses '!E$56,FALSE) -> 0 | F32: =VLOOKUP($B32,'Hypothèses '!$B$76:$K$83,'Hypothèses '!F$56,FALSE) -> 0 | G32: =VLOOKUP($B32,'Hypothèses '!$B$76:$K$83,'Hypothèses '!G$56,FALSE) -> 0 | H32: =VLOOKUP($B32,'Hypothèses '!$B$76:$K$83,'Hypothèses '!H$56,FALSE) -> 0 | I32: =VLOOKUP($B32,'Hypothèses '!$B$76:$K$83,'Hypothèses '!I$56,FALSE) -> 0 | J32: =VLOOKUP($B32,'Hypothèses '!$B$76:$K$83,'Hypothèses '!J$56,FALSE) -> 0 | K32: =VLOOKUP($B32,'Hypothèses '!$B$76:$K$83,'Hypothèses '!K$56,FALSE) -> 0
A34: CALCULS MASSE SALARIALE | D34: ='Hypothèses '!C9 -> 2024 | E34: =D34+1 -> 2025 | F34: =E34+1 -> 2026 | G34: =F34+1 -> 2027 | H34: =G34+1 -> 2028 | I34: =H34+1 -> 2029 | J34: =I34+1 -> 2030 | K34: =J34+1 -> 2031
B35: augmentation salariale | D35: =HLOOKUP(D$34,'Hypothèses '!$C$34:$K$35,2,FALSE) -> 0 | E35: =HLOOKUP(E$34,'Hypothèses '!$C$34:$K$35,2,FALSE) -> 0 | F35: =HLOOKUP(F$34,'Hypothèses '!$C$34:$K$35,2,FALSE) -> 0 | G35: =HLOOKUP(G$34,'Hypothèses '!$C$34:$K$35,2,FALSE) -> 0 | H35: =HLOOKUP(H$34,'Hypothèses '!$C$34:$K$35,2,FALSE) -> 0 | I35: =HLOOKUP(I$34,'Hypothèses '!$C$34:$K$35,2,FALSE) -> 0 | J35: =HLOOKUP(J$34,'Hypothèses '!$C$34:$K$35,2,FALSE) -> 0 | K35: =HLOOKUP(K$34,'Hypothèses '!$C$34:$K$35,2,FALSE) -> 0
B36: taux PRRD | D36: =HLOOKUP(D$34,'Hypothèses '!$C$34:$K$40,7,FALSE) -> 0 | E36: =HLOOKUP(E$34,'Hypothèses '!$C$34:$K$40,7,FALSE) -> 0 | F36: =HLOOKUP(F$34,'Hypothèses '!$C$34:$K$40,7,FALSE) -> 0 | G36: =HLOOKUP(G$34,'Hypothèses '!$C$34:$K$40,7,FALSE) -> 0 | H36: =HLOOKUP(H$34,'Hypothèses '!$C$34:$K$40,7,FALSE) -> 0 | I36: =HLOOKUP(I$34,'Hypothèses '!$C$34:$K$40,7,FALSE) -> 0 | J36: =HLOOKUP(J$34,'Hypothèses '!$C$34:$K$40,7,FALSE) -> 0 | K36: =HLOOKUP(K$34,'Hypothèses '!$C$34:$K$40,7,FALSE) -> 0
B37: Taux change | D37: =HLOOKUP(D$34,'Hypothèses '!$C$34:$K$40,5,FALSE) -> 0.25 | E37: =HLOOKUP(E$34,'Hypothèses '!$C$34:$K$40,5,FALSE) -> 0.25 | F37: =HLOOKUP(F$34,'Hypothèses '!$C$34:$K$40,5,FALSE) -> 0.25 | G37: =HLOOKUP(G$34,'Hypothèses '!$C$34:$K$40,5,FALSE) -> 0.25 | H37: =HLOOKUP(H$34,'Hypothèses '!$C$34:$K$40,5,FALSE) -> 0.25 | I37: =HLOOKUP(I$34,'Hypothèses '!$C$34:$K$40,5,FALSE) -> 0.25 | J37: =HLOOKUP(J$34,'Hypothèses '!$C$34:$K$40,5,FALSE) -> 0.25 | K37: =HLOOKUP(K$34,'Hypothèses '!$C$34:$K$40,5,FALSE) -> 0.25
A38: MATERNELLE | C38: =C$4 -> 2023/2024 | D38: =D$4 -> 2024/2025 | E38: =E$4 -> 2025/2026 | F38: =F$4 -> 2026/2027 | G38: =G$4 -> 2027/2028 | H38: =H$4 -> 2028/2029 | I38: =I$4 -> 2029/2030 | J38: =J$4 -> 2030/2031 | K38: =K$4 -> 2031/2032
A39: Personnel total | C39: =C40+C60 -> #N/A | D39: =D40+D60 -> #N/A | E39: =E40+E60 -> #N/A | F39: =F40+F60 -> #N/A | G39: =G40+G60 -> #N/A | H39: =H40+H60 -> #N/A | I39: =I40+I60 -> #N/A | J39: =J40+J60 -> #N/A | K39: =K40+K60 -> #N/A
A40: Personnels non enseignants - Proratisation par niveau | C40: =SUM(C42:C49)+SUM(C52:C58)+C65 -> #N/A | D40: =SUM(D42:D49)+SUM(D52:D58)+D65 -> #N/A | E40: =SUM(E42:E49)+SUM(E52:E58)+E65 -> #N/A | F40: =SUM(F42:F49)+SUM(F52:F58)+F65 -> #N/A | G40: =SUM(G42:G49)+SUM(G52:G58)+G65 -> #N/A | H40: =SUM(H42:H49)+SUM(H52:H58)+H65 -> #N/A | I40: =SUM(I42:I49)+SUM(I52:I58)+I65 -> #N/A | J40: =SUM(J42:J49)+SUM(J52:J58)+J65 -> #N/A | K40: =SUM(K42:K49)+SUM(K52:K58)+K65 -> #N/A
A41: Communs | B41: Clé répartition | C41: =HLOOKUP(C38,'Projection Effectifs'!$S$31:$AC$35,2,FALSE) -> 0 | D41: =HLOOKUP(D38,'Projection Effectifs'!$S$31:$AC$35,2,FALSE) -> 0.16314031 | E41: =HLOOKUP(E38,'Projection Effectifs'!$S$31:$AC$35,2,FALSE) -> 0.1490411 | F41: =HLOOKUP(F38,'Projection Effectifs'!$S$31:$AC$35,2,FALSE) -> 0.11380282 | G41: =HLOOKUP(G38,'Projection Effectifs'!$S$31:$AC$35,2,FALSE) -> 0.11117613 | H41: =HLOOKUP(H38,'Projection Effectifs'!$S$31:$AC$35,2,FALSE) -> 0.14125956 | I41: =HLOOKUP(I38,'Projection Effectifs'!$S$31:$AC$35,2,FALSE) -> 0.17584994 | J41: =HLOOKUP(J38,'Projection Effectifs'!$S$31:$AC$35,2,FALSE) -> 0.21176471 | K41: =HLOOKUP(K38,'Projection Effectifs'!$S$31:$AC$35,2,FALSE) -> 0.21466905
B42: =$B$6 -> Chef d'Etablissement PDL | C42: =VLOOKUP($B42,$B$6:$K$13,C$3,FALSE)*C$41 -> #N/A | D42: =VLOOKUP($B42,$B$6:$K$13,D$3,FALSE)*D$41 -> #N/A | E42: =VLOOKUP($B42,$B$6:$K$13,E$3,FALSE)*E$41 -> #N/A | F42: =VLOOKUP($B42,$B$6:$K$13,F$3,FALSE)*F$41 -> #N/A | G42: =VLOOKUP($B42,$B$6:$K$13,G$3,FALSE)*G$41 -> #N/A | H42: =VLOOKUP($B42,$B$6:$K$13,H$3,FALSE)*H$41 -> #N/A | I42: =VLOOKUP($B42,$B$6:$K$13,I$3,FALSE)*I$41 -> #N/A | J42: =VLOOKUP($B42,$B$6:$K$13,J$3,FALSE)*J$41 -> #N/A | K42: =VLOOKUP($B42,$B$6:$K$13,K$3,FALSE)*K$41 -> #N/A
B43: =$B$7 -> DAF PDL | C43: =VLOOKUP($B43,$B$6:$K$13,C$3,FALSE)*C$41 -> #N/A | D43: =VLOOKUP($B43,$B$6:$K$13,D$3,FALSE)*D$41 -> #N/A | E43: =VLOOKUP($B43,$B$6:$K$13,E$3,FALSE)*E$41 -> #N/A | F43: =VLOOKUP($B43,$B$6:$K$13,F$3,FALSE)*F$41 -> #N/A | G43: =VLOOKUP($B43,$B$6:$K$13,G$3,FALSE)*G$41 -> #N/A | H43: =VLOOKUP($B43,$B$6:$K$13,H$3,FALSE)*H$41 -> #N/A | I43: =VLOOKUP($B43,$B$6:$K$13,I$3,FALSE)*I$41 -> #N/A | J43: =VLOOKUP($B43,$B$6:$K$13,J$3,FALSE)*J$41 -> #N/A | K43: =VLOOKUP($B43,$B$6:$K$13,K$3,FALSE)*K$41 -> #N/A
...

Sheet Compte Résultat ML
A2: COMPTE DE RESULTAT PREVISIONNEL
A3: Monnaie Locale
C4: ='Hypothèses '!$C$9 -> 2024 | D4: =C4+1 -> 2025 | E4: =D4+1 -> 2026 | F4: =E4+1 -> 2027 | G4: =F4+1 -> 2028 | H4: =G4+1 -> 2029 | I4: =H4+1 -> 2030 | J4: =I4+1 -> 2031
A5: RESULTAT OPERATIONNEL
A6: GLOBAL | C6: =C15-C60 -> #N/A | D6: =D15-D60 -> #N/A | E6: =E15-E60 -> #N/A | F6: =F15-F60 -> #N/A | G6: =G15-G60 -> #N/A | H6: =H15-H60 -> #N/A | I6: =I15-I60 -> #N/A | J6: =J15-J60 -> #N/A
A7: MATERNELLE | C7: =C24-C84 -> #N/A | D7: =D24-D84 -> #N/A | E7: =E24-E84 -> #N/A | F7: =F24-F84 -> #N/A | G7: =G24-G84 -> #N/A | H7: =H24-H84 -> #N/A | I7: =I24-I84 -> #N/A | J7: =J24-J84 -> #N/A
A8: ELEMENTAIRE | C8: =C32-C110 -> #N/A | D8: =D32-D110 -> #N/A | E8: =E32-E110 -> #N/A | F8: =F32-F110 -> #N/A | G8: =G32-G110 -> #N/A | H8: =H32-H110 -> #N/A | I8: =I32-I110 -> #N/A | J8: =J32-J110 -> #N/A
