Workbook

Sheet Number of class 2025-26
A1: École Française Internationale de Riyad (EFIR) - Classes by Level
A3: Cycle | B3: Level | C3: Number of students | D3: Number of Classes
A4: Maternelle | B4: Petite Section (PS) | C4: 65 | D4: 3
A5: Maternelle | B5: Moyenne Section (MS) | C5: 77 | D5: 3
A6: Maternelle | B6: Grande Section (GS) | C6: 124 | D6: 5
A7: Élémentaire | B7: CP (Cours Préparatoire) | C7: 126 | D7: 6
A8: Élémentaire | B8: CE1 | C8: 118 | D8: 5
A9: Élémentaire | B9: CE2 | C9: 132 | D9: 6
A10: Élémentaire | B10: CM1 | C10: 121 | D10: 5
A11: Élémentaire | B11: CM2 | C11: 121 | D11: 5
A12: Collège | B12: 6ème | C12: 151 | D12: 6
A13: Collège | B13: 5ème | C13: 139 | D13: 6
A14: Collège | B14: 4ème | C14: 120 | D14: 5
A15: Collège | B15: 3ème | C15: 103 | D15: 4
... A18: Lycée | B18: Terminale | C18: 111 | D18: 4
A20: SUMMARY BY CYCLE
A21: Maternelle (Kindergarten) | C21: =SUM(C4:C6) -> 266 | D21: =SUM(D4:D6) -> 11
A22: Élémentaire (Elementary) | C22: =SUM(C7:C11) -> 618 | D22: =SUM(D7:D11) -> 27
A23: Collège (Middle School) | C23: =SUM(C12:C15) -> 513 | D23: =SUM(D12:D15) -> 21
A24: Lycée (High School) | C24: =SUM(C16:C18) -> 356 | D24: =SUM(D16:D18) -> 14
A26: TOTAL CLASSES | C26: =SUM(C21:C24) -> 1753 | D26: =SUM(D21:D24) -> 73
A27: Source: EFIR Structure Pédagogique — https://www.efiriyad.com/structure-pedagogique/

Sheet Teacher Requirements
A1: EFIR — Teacher Staffing Requirements Matrix 2025-26
A2: Purpose: Calculate FTE requirements per teacher profile. Blue cells = editable assumptions.
A4: PARAMETERS
A5: Statutory Hours / Week | C5: Certifié | D5: 18 | E5: h/week | G5: HSA (Supp. Hrs) | H5: 0 | I5: h/week
C6: Prof. des Écoles (PE) | D6: 24 | E6: h/week | G6: Effective Certifié | H6: =$D$5+$H$5 -> 18 | I6: h/week
A7: LV2/LVB Student Split | C7: % Arabic | D7: 0.5 | E7: % German | F7: 0.1 | G7: % Spanish | H7: 0.4 | I7: =IF(D7+F7+H7=1,"✓","≠100%!") -> ✓
G8: MATERNELLE | J8: ÉLÉMENTAIRE | O8: COLLÈGE | S8: LYCÉE | V8: COMPUTATION
A9: Category | B9: Type | C9: Subject / Matière | D9: Teacher Profile | E9: Groups / Class | G9: PS | H9: MS | I9: GS | J9: CP | K9: CE1 | L9: CE2 | M9: CM1 | N9: CM2 | O9: 6ème | P9: 5ème | Q9: 4ème | R9: 3ème | S9: 2nde | T9: 1ère | U9: Tle | V9: Total Hrs/Wk | W9: Statutory | X9: FTE Req. | Y9: Headcount
C10: Number of Classes | G10: 3 | H10: 3 | I10: 5 | J10: 6 | K10: 5 | L10: 6 | M10: 5 | N10: 5 | O10: 6 | P10: 6 | Q10: 5 | R10: 4 | S10: 5 | T10: 5 | U10: 4
A11: BLOCK 1 — MATERNELLE / PRIMAIRE
A12: HOMEROOM
A13: Homeroom | C13: Homeroom Maternelle | D13: Professeur des écoles (PE) | E13: 1 | G13: 24 | H13: 24 | I13: 24 | V13: {=SUMPRODUCT(IF(ISNUMBER(G13:U13),G13:U13,0),$G$10:$U$10)*E13} -> 264 | W13: =IF(ISNUMBER(SEARCH("PE",D13)),$D$6,$D$5) -> 24 | X13: =SUM($G$10:$I$10) -> 11 | Y13: =X13 -> 11
A14: Homeroom | B14: Homeroom | C14: ASEM Maternelle | D14: ASEM | E14: 1 | G14: 24 | H14: 24 | I14: 24 | V14: {=SUMPRODUCT(IF(ISNUMBER(G14:U14),G14:U14,0),$G$10:$U$10)*E14} -> 264 | W14: =$D$6 -> 24 | X14: =SUM($G$10:$I$10) -> 11 | Y14: =X14 -> 11
B15: Homeroom | C15: ⬛ Subtotal Maternelle | V15: =V13+V14 -> 528 | W15: =$D$6 -> 24 | X15: =X13 -> 11 | Y15: =X15 -> 11
A16: Homeroom | C16: Homeroom Élémentaire | D16: Professeur des écoles (PE) | E16: 1 | J16: 24 | K16: 24 | L16: 24 | M16: 24 | N16: 24 | V16: {=SUMPRODUCT(IF(ISNUMBER(G16:U16),G16:U16,0),$G$10:$U$10)*E16} -> 648 | W16: =IF(ISNUMBER(SEARCH("PE",D16)),$D$6,$D$5) -> 24 | X16: =SUM($J$10:$N$10) -> 27 | Y16: =X16 -> 27
B17: Homeroom | C17: ⬛ Subtotal Élémentaire | V17: =V16 -> 648 | W17: =$D$6 -> 24 | X17: =X16 -> 27 | Y17: =X16 -> 27
A18: ARABIC LANGUAGE
A19: ▸ Primaire | C19: Arabe (Arabophone group) | D19: Enseignant Arabe | E19: 1 | G19: 2 | H19: 2 | I19: 2.67 | J19: 2 | K19: 2 | L19: 2 | M19: 2 | N19: 2 | V19: {=SUMPRODUCT(IF(ISNUMBER(G19:U19),G19:U19,0),$G$10:$U$10)*E19} -> 79.35 | W19: =IF(ISNUMBER(SEARCH("PE",D19)),$D$6,$D$5) -> 18 | X19: =IF(V19=0,"",V19/$H$6) -> 4.4083333 | Y19: =IF(X19="","",ROUNDUP(X19,0)) -> 5
A20: ▸ Primaire | B20: Core | C20: Arabe (Non-Arabophone group) | D20: Enseignant Arabe | E20: 1 | I20: 2.67 | J20: 2 | K20: 2 | L20: 2 | M20: 2 | N20: 2 | V20: {=SUMPRODUCT(IF(ISNUMBER(G20:U20),G20:U20,0),$G$10:$U$10)*E20} -> 67.35 | W20: =IF(ISNUMBER(SEARCH("PE",D20)),$D$6,$D$5) -> 18 | X20: =IF(V20=0,"",V20/$H$6) -> 3.7416667 | Y20: =IF(X20="","",ROUNDUP(X20,0)) -> 4
B21: Core | C21: ⬛ Subtotal Primaire (shared pool) | V21: =V19+V20 -> 146.7 | W21: =$D$5 -> 18 | X21: =IF(V21=0,"",V21/$H$6) -> 8.15 | Y21: =IF(X21="","",ROUNDUP(X21,0)) -> 9
A22: ENGLISH LANGUAGE
A23: ▸ Primaire | C23: Anglais (Primaire) | D23: Enseignant Anglais Primaire | E23: 1 | I23: 0.67 | J23: 1.5 | K23: 1.5 | L23: 1.5 | M23: 1.5 | N23: 1.5 | V23: {=SUMPRODUCT(IF(ISNUMBER(G23:U23),G23:U23,0),$G$10:$U$10)*E23} -> 43.85 | W23: =IF(ISNUMBER(SEARCH("PE",D23)),$D$6,$D$5) -> 18 | X23: =IF(V23=0,"",V23/$H$6) -> 2.4361111 | Y23: =IF(X23="","",ROUNDUP(X23,0)) -> 3
B24: Core | C24: ⬛ Subtotal Primaire (shared pool) | V24: =V23 -> 43.85 | W24: =$D$5 -> 18 | X24: =IF(V24=0,"",V24/$H$6) -> 2.4361111 | Y24: =IF(X24="","",ROUNDUP(X24,0)) -> 3
A26: BLOCK 2 — COLLÈGE / LYCÉE
A27: CORE SUBJECTS — TRONC COMMUN
A28: FRENCH LANGUAGE
A29: Français | B29: Core | C29: Français | D29: Certifié Lettres | E29: 1 | O29: {=IFERROR(INDEX(Curriculum_Detail!H:H,MATCH(1,(Curriculum_Detail!D:D="6e")*(Curriculum_Detail!F:F="Français")*(Curriculum_Detail!E:E="Core"),0)),"")} -> 4.5 | P29: {=IFERROR(INDEX(Curriculum_Detail!H:H,MATCH(1,(Curriculum_Detail!D:D="5e")*(Curriculum_Detail!F:F="Français")*(Curriculum_Detail!E:E="Core"),0)),"")} -> 4.5 | Q29: {=IFERROR(INDEX(Curriculum_Detail!H:H,MATCH(1,(Curriculum_Detail!D:D="4e")*(Curriculum_Detail!F:F="Français")*(Curriculum_Detail!E:E="Core"),0)),"")} -> 4.5 | R29: {=IFERROR(INDEX(Curriculum_Detail!H:H,MATCH(1,(Curriculum_Detail!D:D="3e")*(Curriculum_Detail!F:F="Français")*(Curriculum_Detail!E:E="Core"),0)),"")} -> 4 | S29: {=IFERROR(INDEX(Curriculum_Detail!H:H,MATCH(1,(Curriculum_Detail!D:D="Seconde")*(Curriculum_Detail!F:F="Français")*(Curriculum_Detail!E:E="Core"),0)),"")} -> 4 | T29: {=IFERROR(INDEX(Curriculum_Detail!H:H,MATCH(1,(Curriculum_Detail!D:D="Première")*(Curriculum_Detail!F:F="Français")*(Curriculum_Detail!E:E="Core"),0)),"")} -> 4 | V29: {=SUMPRODUCT(IF(ISNUMBER(G29:U29),G29:U29,0),$G$10:$U$10)*E29} -> 132.5 | W29: =IF(ISNUMBER(SEARCH("PE",D29)),$D$6,$D$5) -> 18 | X29: =IF(V29=0,"",V29/$H$6) -> 7.3611111 | Y29: =IF(X29="","",ROUNDUP(X29,0)) -> 8
A30: Français | B30: Core | C30: Philosophie | D30: Certifié Philosophie | E30: 1 | U30: {=IFERROR(INDEX(Curriculum_Detail!H:H,MATCH(1,(Curriculum_Detail!D:D="Terminale")*(Curriculum_Detail!F:F="Philosophie")*(Curriculum_Detail!E:E="Core"),0)),"")} -> 4 | V30: {=SUMPRODUCT(IF(ISNUMBER(G30:U30),G30:U30,0),$G$10:$U$10)*E30} -> 16 | W30: =IF(ISNUMBER(SEARCH("PE",D30)),$D$6,$D$5) -> 18 | X30: =IF(V30=0,"",V30/$H$6) -> 0.88888889 | Y30: =IF(X30="","",ROUNDUP(X30,0)) -> 1
A31: Français | B31: Specialty | C31: Spé. HLP (1ère) | D31: Certifié Lettres | E31: 1 | T31: {=IFERROR(INDEX(Curriculum_Detail!H:H,MATCH(1,(Curriculum_Detail!D:D="Première")*(Curriculum_Detail!F:F="Humanités, littérature et philosophie")*(Curriculum_Detail!E:E="Specialty"),0)),0)} -> 4 | V31: =T31*E31 -> 4 | W31: =$D$5 -> 18 | X31: =IF(V31=0,"",V31/$H$6) -> 0.22222222 | Y31: =IF(X31="","",ROUNDUP(X31,0)) -> 1
A32: Français | B32: Specialty | C32: Spé. HLP (Tle) | D32: Certifié Philosophie | F32: 1 | U32: {=IFERROR(INDEX(Curriculum_Detail!H:H,MATCH(1,(Curriculum_Detail!D:D="Terminale")*(Curriculum_Detail!F:F="Humanités, littérature et philosophie")*(Curriculum_Detail!E:E="Specialty"),0)),0)} -> 6 | V32: =U32*F32 -> 6 | W32: =$D$5 -> 18 | X32: =IF(V32=0,"",V32/$H$6) -> 0.33333333 | Y32: =IF(X32="","",ROUNDUP(X32,0)) -> 1
A33: MATHEMATICS
A34: Maths | B34: Core | C34: Mathématiques | D34: Certifié Maths | E34: 1 | O34: {=IFERROR(INDEX(Curriculum_Detail!H:H,MATCH(1,(Curriculum_Detail!D:D="6e")*(Curriculum_Detail!F:F="Mathématiques")*(Curriculum_Detail!E:E="Core"),0)),"")} -> 4.5 | P34: {=IFERROR(INDEX(Curriculum_Detail!H:H,MATCH(1,(Curriculum_Detail!D:D="5e")*(Curriculum_Detail!F:F="Mathématiques")*(Curriculum_Detail!E:E="Core"),0)),"")} -> 3.5 | Q34: {=IFERROR(INDEX(Curriculum_Detail!H:H,MATCH(1,(Curriculum_Detail!D:D="4e")*(Curriculum_Detail!F:F="Mathématiques")*(Curriculum_Detail!E:E="Core"),0)),"")} -> 3.5 | R34: {=IFERROR(INDEX(Curriculum_Detail!H:H,MATCH(1,(Curriculum_Detail!D:D="3e")*(Curriculum_Detail!F:F="Mathématiques")*(Curriculum_Detail!E:E="Core"),0)),"")} -> 3.5 | S34: {=IFERROR(INDEX(Curriculum_Detail!H:H,MATCH(1,(Curriculum_Detail!D:D="Seconde")*(Curriculum_Detail!F:F="Mathématiques")*(Curriculum_Detail!E:E="Core"),0)),"")} -> 4 | V34: {=SUMPRODUCT(IF(ISNUMBER(G34:U34),G34:U34,0),$G$10:$U$10)*E34} -> 99.5 | W34: =IF(ISNUMBER(SEARCH("PE",D34)),$D$6,$D$5) -> 18 | X34: =IF(V34=0,"",V34/$H$6) -> 5.5277778 | Y34: =IF(X34="","",ROUNDUP(X34,0)) -> 6
A35: Maths | B35: Core | C35: Soutien / approfondissement | D35: Certifié Maths | E35: 1 | O35: {=IFERROR(INDEX(Curriculum_Detail!H:H,MATCH(1,(Curriculum_Detail!D:D="6e")*(Curriculum_Detail!F:F="Soutien / approfondissement en français ou mathématiques")*(Curriculum_Detail!E:E="Core"),0)),"")} -> 1 | V35: {=SUMPRODUCT(IF(ISNUMBER(G35:U35),G35:U35,0),$G$10:$U$10)*E35} -> 6 | W35: =IF(ISNUMBER(SEARCH("PE",D35)),$D$6,$D$5) -> 18 | X35: =IF(V35=0,"",V35/$H$6) -> 0.33333333 | Y35: =IF(X35="","",ROUNDUP(X35,0)) -> 1
A36: Maths | B36: Specialty | C36: Spé. Mathématiques | D36: Certifié Maths | E36: 2 | F36: 2 | T36: {=IFERROR(INDEX(Curriculum_Detail!H:H,MATCH(1,(Curriculum_Detail!D:D="Première")*(Curriculum_Detail!F:F="Mathématiques")*(Curriculum_Detail!E:E="Specialty"),0)),0)} -> 4 | U36: {=IFERROR(INDEX(Curriculum_Detail!H:H,MATCH(1,(Curriculum_Detail!D:D="Terminale")*(Curriculum_Detail!F:F="Mathématiques")*(Curriculum_Detail!E:E="Specialty"),0)),0)} -> 6 | V36: =T36*E36+U36*F36 -> 20 | W36: =$D$5 -> 18 | X36: =IF(V36=0,"",V36/$H$6) -> 1.1111111 | Y36: =IF(X36="","",ROUNDUP(X36,0)) -> 2
A37: Maths | B37: Option | C37: Maths Complémentaires (opt.) | D37: Certifié Maths | E37: 0 | F37: 4 | T37: 0 | U37: 3 | V37: =T37*E37+U37*F37 -> 12 | W37: =$D$5 -> 18 | X37: =IF(V37=0,"",V37/$H$6) -> 0.66666667 | Y37: =IF(X37="","",ROUNDUP(X37,0)) -> 1
A38: Maths | B38: Option | C38: Maths Expertes (opt.) | D38: Certifié Maths | E38: 0 | F38: 2 | T38: 0 | U38: 3 | V38: =T38*E38+U38*F38 -> 6 | W38: =$D$5 -> 18 | X38: =IF(V38=0,"",V38/$H$6) -> 0.33333333 | Y38: =IF(X38="","",ROUNDUP(X38,0)) -> 1
A39: HISTORY, GEOGRAPHY & CIVICS
A40: HG-EMC | B40: Core | C40: Histoire-Géographie | D40: Certifié Hist-Géo | E40: 1 | O40: {=IFERROR(INDEX(Curriculum_Detail!H:H,MATCH(1,(Curriculum_Detail!D:D="6e")*(Curriculum_Detail!F:F="Histoire-géographie")*(Curriculum_Detail!E:E="Core"),0)),"")} -> 2.5 | P40: {=IFERROR(INDEX(Curriculum_Detail!H:H,MATCH(1,(Curriculum_Detail!D:D="5e")*(Curriculum_Detail!F:F="Histoire-géographie")*(Curriculum_Detail!E:E="Core"),0)),"")} -> 2.5 | Q40: {=IFERROR(INDEX(Curriculum_Detail!H:H,MATCH(1,(Curriculum_Detail!D:D="4e")*(Curriculum_Detail!F:F="Histoire-géographie")*(Curriculum_Detail!E:E="Core"),0)),"")} -> 2.5 | R40: {=IFERROR(INDEX(Curriculum_Detail!H:H,MATCH(1,(Curriculum_Detail!D:D="3e")*(Curriculum_Detail!F:F="Histoire-géographie")*(Curriculum_Detail!E:E="Core"),0)),"")} -> 3 | S40: {=IFERROR(INDEX(Curriculum_Detail!H:H,MATCH(1,(Curriculum_Detail!D:D="Seconde")*(Curriculum_Detail!F:F="Histoire-géographie")*(Curriculum_Detail!E:E="Core"),0)),"")} -> 3 | T40: {=IFERROR(INDEX(Curriculum_Detail!H:H,MATCH(1,(Curriculum_Detail!D:D="Première")*(Curriculum_Detail!F:F="Histoire-géographie")*(Curriculum_Detail!E:E="Core"),0)),"")} -> 3 | U40: {=IFERROR(INDEX(Curriculum_Detail!H:H,MATCH(1,(Curriculum_Detail!D:D="Terminale")*(Curriculum_Detail!F:F="Histoire-géographie")*(Curriculum_Detail!E:E="Core"),0)),"")} -> 3 | V40: {=SUMPRODUCT(IF(ISNUMBER(G40:U40),G40:U40,0),$G$10:$U$10)*E40} -> 96.5 | W40: =IF(ISNUMBER(SEARCH("PE",D40)),$D$6,$D$5) -> 18 | X40: =IF(V40=0,"",V40/$H$6) -> 5.3611111 | Y40: =IF(X40="","",ROUNDUP(X40,0)) -> 6
A41: HG-EMC | B41: Core | C41: Enseignement moral et civique | D41: Certifié EMC | E41: 1 | O41: {=IFERROR(INDEX(Curriculum_Detail!H:H,MATCH(1,(Curriculum_Detail!D:D="6e")*(Curriculum_Detail!F:F="Enseignement moral et civique")*(Curriculum_Detail!E:E="Core"),0)),"")} -> 0.5 | P41: {=IFERROR(INDEX(Curriculum_Detail!H:H,MATCH(1,(Curriculum_Detail!D:D="5e")*(Curriculum_Detail!F:F="Enseignement moral et civique")*(Curriculum_Detail!E:E="Core"),0)),"")} -> 0.5 | Q41: {=IFERROR(INDEX(Curriculum_Detail!H:H,MATCH(1,(Curriculum_Detail!D:D="4e")*(Curriculum_Detail!F:F="Enseignement moral et civique")*(Curriculum_Detail!E:E="Core"),0)),"")} -> 0.5 | R41: {=IFERROR(INDEX(Curriculum_Detail!H:H,MATCH(1,(Curriculum_Detail!D:D="3e")*(Curriculum_Detail!F:F="Enseignement moral et civique")*(Curriculum_Detail!E:E="Core"),0)),"")} -> 0.5 | S41: {=IFERROR(INDEX(Curriculum_Detail!H:H,MATCH(1,(Curriculum_Detail!D:D="Seconde")*(Curriculum_Detail!F:F="Enseignement moral et civique")*(Curriculum_Detail!E:E="Core"),0)),"")} -> 0.5 | T41: {=IFERROR(INDEX(Curriculum_Detail!H:H,MATCH(1,(Curriculum_Detail!D:D="Première")*(Curriculum_Detail!F:F="Enseignement moral et civique")*(Curriculum_Detail!E:E="Core"),0)),"")} -> 0.5 | U41: {=IFERROR(INDEX(Curriculum_Detail!H:H,MATCH(1,(Curriculum_Detail!D:D="Terminale")*(Curriculum_Detail!F:F="Enseignement moral et civique")*(Curriculum_Detail!E:E="Core"),0)),"")} -> 0.5 | V41: {=SUMPRODUCT(IF(ISNUMBER(G41:U41),G41:U41,0),$G$10:$U$10)*E41} -> 17.5 | W41: =IF(ISNUMBER(SEARCH("PE",D41)),$D$6,$D$5) -> 18 | X41: =IF(V41=0,"",V41/$H$6) -> 0.97222222 | Y41: =IF(X41="","",ROUNDUP(X41,0)) -> 1
A42: HG-EMC | B42: Specialty | C42: Spé. HGGSP | D42: Certifié Hist-Géo | E42: 2 | F42: 1 | T42: {=IFERROR(INDEX(Curriculum_Detail!H:H,MATCH(1,(Curriculum_Detail!D:D="Première")*(Curriculum_Detail!F:F="Histoire-géographie, géopolitique et sciences politiques")*(Curriculum_Detail!E:E="Specialty"),0)),0)} -> 4 | U42: {=IFERROR(INDEX(Curriculum_Detail!H:H,MATCH(1,(Curriculum_Detail!D:D="Terminale")*(Curriculum_Detail!F:F="Histoire-géographie, géopolitique et sciences politiques")*(Curriculum_Detail!E:E="Specialty"),0)),0)} -> 6 | V42: =T42*E42+U42*F42 -> 14 | W42: =$D$5 -> 18 | X42: =IF(V42=0,"",V42/$H$6) -> 0.77777778 | Y42: =IF(X42="","",ROUNDUP(X42,0)) -> 1
...

Sheet Curriculum_Detail
A1: Sort Order | B1: Cycle | C1: Stage | D1: Level | E1: Track | F1: Subject | G1: Hour Status | H1: Weekly Hours | I1: Annual Hours | J1: Planning Groups | K1: Delivered Hours/Wk | L1: Teacher Load Hrs/Wk | M1: Required FTE | N1: Avg Cost per FTE | O1: Est Annual Cost | P1: Source URL | Q1: Notes
A2: 300 | B2: Cycle 3 | C2: Collège | D2: 6e | E2: Core | F2: Français | G2: Official | H2: 4.5 | I2: 162 | J2: 6 | K2: 27 | L2: 18 | M2: 1.5 | N2: 0 | O2: 0 | P2: https://www.education.gouv.fr/les-horaires-par-cycle-au-college-9884
A3: 301 | B3: Cycle 3 | C3: Collège | D3: 6e | E3: Core | F3: Mathématiques | G3: Official | H3: 4.5 | I3: 162 | J3: 6 | K3: 27 | L3: 18 | M3: 1.5 | N3: 0 | O3: 0 | P3: https://www.education.gouv.fr/les-horaires-par-cycle-au-college-9884
A4: 302 | B4: Cycle 3 | C4: Collège | D4: 6e | E4: Core | F4: Histoire-géographie | G4: Derived from official grouped block | H4: 2.5 | I4: 90 | J4: 6 | K4: 15 | L4: 18 | M4: 0.83333333 | N4: 0 | O4: 0 | P4: https://www.education.gouv.fr/les-horaires-par-cycle-au-college-9884 | Q4: Derived from official 3 h grouped block 'Histoire-géographie + EMC', of which EMC is 30 minutes.
A5: 303 | B5: Cycle 3 | C5: Collège | D5: 6e | E5: Core | F5: Enseignement moral et civique | G5: Derived from official grouped block | H5: 0.5 | I5: 18 | J5: 6 | K5: 3 | L5: 18 | M5: 0.16666667 | N5: 0 | O5: 0 | P5: https://www.education.gouv.fr/les-horaires-par-cycle-au-college-9884 | Q5: Derived from official 3 h grouped block 'Histoire-géographie + EMC', of which EMC is 30 minutes.
A6: 304 | B6: Cycle 3 | C6: Collège | D6: 6e | E6: Core | F6: Langue vivante 1 | G6: Official | H6: 4 | I6: 144 | J6: 6 | K6: 24 | L6: 18 | M6: 1.3333333 | N6: 0 | O6: 0 | P6: https://www.education.gouv.fr/les-horaires-par-cycle-au-college-9884
A7: 305 | B7: Cycle 3 | C7: Collège | D7: 6e | E7: Core | F7: Sciences de la vie et de la Terre + Physique-chimie | G7: Official grouped sciences block | H7: 3 | I7: 108 | J7: 6 | K7: 18 | L7: 18 | M7: 1 | N7: 0 | O7: 0 | P7: https://www.education.gouv.fr/les-horaires-par-cycle-au-college-9884 | Q7: Current official 6e timetable groups the sciences block at 3 h/week.
A8: 306 | B8: Cycle 3 | C8: Collège | D8: 6e | E8: Core | F8: Éducation physique et sportive | G8: Official | H8: 4 | I8: 144 | J8: 6 | K8: 24 | L8: 18 | M8: 1.3333333 | N8: 0 | O8: 0 | P8: https://www.education.gouv.fr/les-horaires-par-cycle-au-college-9884
A9: 307 | B9: Cycle 3 | C9: Collège | D9: 6e | E9: Core | F9: Arts plastiques | G9: Official | H9: 1 | I9: 36 | J9: 6 | K9: 6 | L9: 18 | M9: 0.33333333 | N9: 0 | O9: 0 | P9: https://www.education.gouv.fr/les-horaires-par-cycle-au-college-9884
A10: 308 | B10: Cycle 3 | C10: Collège | D10: 6e | E10: Core | F10: Éducation musicale | G10: Official | H10: 1 | I10: 36 | J10: 6 | K10: 6 | L10: 18 | M10: 0.33333333 | N10: 0 | O10: 0 | P10: https://www.education.gouv.fr/les-horaires-par-cycle-au-college-9884
A11: 309 | B11: Cycle 3 | C11: Collège | D11: 6e | E11: Core | F11: Soutien / approfondissement en français ou mathématiques | G11: Official | H11: 1 | I11: 36 | J11: 6 | K11: 6 | L11: 18 | M11: 0.33333333 | N11: 0 | O11: 0 | P11: https://www.education.gouv.fr/les-horaires-par-cycle-au-college-9884
A12: 400 | B12: Cycle 4 | C12: Collège | D12: 5e | E12: Core | F12: Français | G12: Official | H12: 4.5 | I12: 162 | J12: 6 | K12: 27 | L12: 18 | M12: 1.5 | N12: 0 | O12: 0 | P12: https://www.education.gouv.fr/les-horaires-par-cycle-au-college-9884
A13: 401 | B13: Cycle 4 | C13: Collège | D13: 5e | E13: Core | F13: Mathématiques | G13: Official | H13: 3.5 | I13: 126 | J13: 6 | K13: 21 | L13: 18 | M13: 1.1666667 | N13: 0 | O13: 0 | P13: https://www.education.gouv.fr/les-horaires-par-cycle-au-college-9884
A14: 402 | B14: Cycle 4 | C14: Collège | D14: 5e | E14: Core | F14: Histoire-géographie | G14: Derived from official grouped block | H14: 2.5 | I14: 90 | J14: 6 | K14: 15 | L14: 18 | M14: 0.83333333 | N14: 0 | O14: 0 | P14: https://www.education.gouv.fr/les-horaires-par-cycle-au-college-9884 | Q14: Derived from official grouped block 'Histoire-géographie + EMC' with EMC = 30 minutes.
A15: 403 | B15: Cycle 4 | C15: Collège | D15: 5e | E15: Core | F15: Enseignement moral et civique | G15: Derived from official grouped block | H15: 0.5 | I15: 18 | J15: 6 | K15: 3 | L15: 18 | M15: 0.16666667 | N15: 0 | O15: 0 | P15: https://www.education.gouv.fr/les-horaires-par-cycle-au-college-9884 | Q15: Derived from official grouped block 'Histoire-géographie + EMC' with EMC = 30 minutes.
A16: 404 | B16: Cycle 4 | C16: Collège | D16: 5e | E16: Core | F16: Langue vivante 1 | G16: Official | H16: 3 | I16: 108 | J16: 6 | K16: 18 | L16: 18 | M16: 1 | N16: 0 | O16: 0 | P16: https://www.education.gouv.fr/les-horaires-par-cycle-au-college-9884
A17: 405 | B17: Cycle 4 | C17: Collège | D17: 5e | E17: Core | F17: Langue vivante 2 | G17: Official | H17: 2.5 | I17: 90 | J17: 6 | K17: 15 | L17: 18 | M17: 0.83333333 | N17: 0 | O17: 0 | P17: https://www.education.gouv.fr/les-horaires-par-cycle-au-college-9884
A18: 406 | B18: Cycle 4 | C18: Collège | D18: 5e | E18: Core | F18: Sciences de la vie et de la Terre | G18: Official | H18: 1.5 | I18: 54 | J18: 6 | K18: 9 | L18: 18 | M18: 0.5 | N18: 0 | O18: 0 | P18: https://www.education.gouv.fr/les-horaires-par-cycle-au-college-9884
A19: 407 | B19: Cycle 4 | C19: Collège | D19: 5e | E19: Core | F19: Physique-chimie | G19: Official | H19: 1.5 | I19: 54 | J19: 6 | K19: 9 | L19: 18 | M19: 0.5 | N19: 0 | O19: 0 | P19: https://www.education.gouv.fr/les-horaires-par-cycle-au-college-9884
A20: 408 | B20: Cycle 4 | C20: Collège | D20: 5e | E20: Core | F20: Technologie | G20: Official | H20: 1.5 | I20: 54 | J20: 6 | K20: 9 | L20: 18 | M20: 0.5 | N20: 0 | O20: 0 | P20: https://www.education.gouv.fr/les-horaires-par-cycle-au-college-9884
A21: 409 | B21: Cycle 4 | C21: Collège | D21: 5e | E21: Core | F21: Éducation physique et sportive | G21: Official | H21: 3 | I21: 108 | J21: 6 | K21: 18 | L21: 18 | M21: 1 | N21: 0 | O21: 0 | P21: https://www.education.gouv.fr/les-horaires-par-cycle-au-college-9884
A22: 410 | B22: Cycle 4 | C22: Collège | D22: 5e | E22: Core | F22: Arts plastiques | G22: Official | H22: 1 | I22: 36 | J22: 6 | K22: 6 | L22: 18 | M22: 0.33333333 | N22: 0 | O22: 0 | P22: https://www.education.gouv.fr/les-horaires-par-cycle-au-college-9884
A23: 411 | B23: Cycle 4 | C23: Collège | D23: 5e | E23: Core | F23: Éducation musicale | G23: Official | H23: 1 | I23: 36 | J23: 6 | K23: 6 | L23: 18 | M23: 0.33333333 | N23: 0 | O23: 0 | P23: https://www.education.gouv.fr/les-horaires-par-cycle-au-college-9884
A24: 412 | B24: Cycle 4 | C24: Collège | D24: 4e | E24: Core | F24: Français | G24: Official | H24: 4.5 | I24: 162 | J24: 5 | K24: 22.5 | L24: 18 | M24: 1.25 | N24: 0 | O24: 0 | P24: https://www.education.gouv.fr/les-horaires-par-cycle-au-college-9884
A25: 413 | B25: Cycle 4 | C25: Collège | D25: 4e | E25: Core | F25: Mathématiques | G25: Official | H25: 3.5 | I25: 126 | J25: 5 | K25: 17.5 | L25: 18 | M25: 0.97222222 | N25: 0 | O25: 0 | P25: https://www.education.gouv.fr/les-horaires-par-cycle-au-college-9884
A26: 414 | B26: Cycle 4 | C26: Collège | D26: 4e | E26: Core | F26: Histoire-géographie | G26: Derived from official grouped block | H26: 2.5 | I26: 90 | J26: 5 | K26: 12.5 | L26: 18 | M26: 0.69444444 | N26: 0 | O26: 0 | P26: https://www.education.gouv.fr/les-horaires-par-cycle-au-college-9884 | Q26: Derived from official grouped block 'Histoire-géographie + EMC' with EMC = 30 minutes.
A27: 415 | B27: Cycle 4 | C27: Collège | D27: 4e | E27: Core | F27: Enseignement moral et civique | G27: Derived from official grouped block | H27: 0.5 | I27: 18 | J27: 5 | K27: 2.5 | L27: 18 | M27: 0.13888889 | N27: 0 | O27: 0 | P27: https://www.education.gouv.fr/les-horaires-par-cycle-au-college-9884 | Q27: Derived from official grouped block 'Histoire-géographie + EMC' with EMC = 30 minutes.
A28: 416 | B28: Cycle 4 | C28: Collège | D28: 4e | E28: Core | F28: Langue vivante 1 | G28: Official | H28: 3 | I28: 108 | J28: 5 | K28: 15 | L28: 18 | M28: 0.83333333 | N28: 0 | O28: 0 | P28: https://www.education.gouv.fr/les-horaires-par-cycle-au-college-9884
A29: 417 | B29: Cycle 4 | C29: Collège | D29: 4e | E29: Core | F29: Langue vivante 2 | G29: Official | H29: 2.5 | I29: 90 | J29: 5 | K29: 12.5 | L29: 18 | M29: 0.69444444 | N29: 0 | O29: 0 | P29: https://www.education.gouv.fr/les-horaires-par-cycle-au-college-9884
A30: 418 | B30: Cycle 4 | C30: Collège | D30: 4e | E30: Core | F30: Sciences de la vie et de la Terre | G30: Official | H30: 1.5 | I30: 54 | J30: 5 | K30: 7.5 | L30: 18 | M30: 0.41666667 | N30: 0 | O30: 0 | P30: https://www.education.gouv.fr/les-horaires-par-cycle-au-college-9884
A31: 419 | B31: Cycle 4 | C31: Collège | D31: 4e | E31: Core | F31: Physique-chimie | G31: Official | H31: 1.5 | I31: 54 | J31: 5 | K31: 7.5 | L31: 18 | M31: 0.41666667 | N31: 0 | O31: 0 | P31: https://www.education.gouv.fr/les-horaires-par-cycle-au-college-9884
A32: 420 | B32: Cycle 4 | C32: Collège | D32: 4e | E32: Core | F32: Technologie | G32: Official | H32: 1.5 | I32: 54 | J32: 5 | K32: 7.5 | L32: 18 | M32: 0.41666667 | N32: 0 | O32: 0 | P32: https://www.education.gouv.fr/les-horaires-par-cycle-au-college-9884
A33: 421 | B33: Cycle 4 | C33: Collège | D33: 4e | E33: Core | F33: Éducation physique et sportive | G33: Official | H33: 3 | I33: 108 | J33: 5 | K33: 15 | L33: 18 | M33: 0.83333333 | N33: 0 | O33: 0 | P33: https://www.education.gouv.fr/les-horaires-par-cycle-au-college-9884
A34: 422 | B34: Cycle 4 | C34: Collège | D34: 4e | E34: Core | F34: Arts plastiques | G34: Official | H34: 1 | I34: 36 | J34: 5 | K34: 5 | L34: 18 | M34: 0.27777778 | N34: 0 | O34: 0 | P34: https://www.education.gouv.fr/les-horaires-par-cycle-au-college-9884
A35: 423 | B35: Cycle 4 | C35: Collège | D35: 4e | E35: Core | F35: Éducation musicale | G35: Official | H35: 1 | I35: 36 | J35: 5 | K35: 5 | L35: 18 | M35: 0.27777778 | N35: 0 | O35: 0 | P35: https://www.education.gouv.fr/les-horaires-par-cycle-au-college-9884
A36: 424 | B36: Cycle 4 | C36: Collège | D36: 3e | E36: Core | F36: Français | G36: Official | H36: 4 | I36: 144 | J36: 4 | K36: 16 | L36: 18 | M36: 0.88888889 | N36: 0 | O36: 0 | P36: https://www.education.gouv.fr/les-horaires-par-cycle-au-college-9884
A37: 425 | B37: Cycle 4 | C37: Collège | D37: 3e | E37: Core | F37: Mathématiques | G37: Official | H37: 3.5 | I37: 126 | J37: 4 | K37: 14 | L37: 18 | M37: 0.77777778 | N37: 0 | O37: 0 | P37: https://www.education.gouv.fr/les-horaires-par-cycle-au-college-9884
A38: 426 | B38: Cycle 4 | C38: Collège | D38: 3e | E38: Core | F38: Histoire-géographie | G38: Derived from official grouped block | H38: 3 | I38: 108 | J38: 4 | K38: 12 | L38: 18 | M38: 0.66666667 | N38: 0 | O38: 0 | P38: https://www.education.gouv.fr/les-horaires-par-cycle-au-college-9884 | Q38: Derived from official grouped block 'Histoire-géographie + EMC' with EMC = 30 minutes.
A39: 427 | B39: Cycle 4 | C39: Collège | D39: 3e | E39: Core | F39: Enseignement moral et civique | G39: Derived from official grouped block | H39: 0.5 | I39: 18 | J39: 4 | K39: 2 | L39: 18 | M39: 0.11111111 | N39: 0 | O39: 0 | P39: https://www.education.gouv.fr/les-horaires-par-cycle-au-college-9884 | Q39: Derived from official grouped block 'Histoire-géographie + EMC' with EMC = 30 minutes.
A40: 428 | B40: Cycle 4 | C40: Collège | D40: 3e | E40: Core | F40: Langue vivante 1 | G40: Official | H40: 3 | I40: 108 | J40: 4 | K40: 12 | L40: 18 | M40: 0.66666667 | N40: 0 | O40: 0 | P40: https://www.education.gouv.fr/les-horaires-par-cycle-au-college-9884
...

Sheet Master Data
A1: EFIR — Staff Master Data FY2025-2026
A2: Active: 185 (159 Local + 26 AEFE) | Departed: 1 | Total rows: 186 | Currency: SAR | QA Validated: 2026-03-21
A4: # | B4: Last Name | C4: First Name | D4: Contract Type | E4: Function / Role | F4: Department | G4: Subject / Discipline | H4: Teacher / Non-Teacher | I4: Teacher Profile | J4: Allocation (Band) | K4: Level | L4: Status | M4: Joining Date | N4: YoS | O4: Base Salary (SAR) | P4: Housing (IL) | Q4: Transport (IT) | R4: Resp. Premium | S4: HSA (10m) | T4: Monthly Gross (SAR) | U4: Hourly % | V4: Payment Method | W4: Aug. 2026-27 | X4: Notes (QA)
A5: 1 | B5: ABED | C5: Ghina | D5: Contrat Local | E5: Assistant(e) d'éducation | F5: Vie Scolaire & Support | G5: Vie scolaire | H5: Non-Teacher | J5: Secondaire | K5: Vie Scolaire & Support | L5: Existing | M5: 45170 | N5: 3.3 | O5: 7400 | P5: 2500 | Q5: 500 | T5: 10400 | U5: 1 | V5: Liquide | W5: 200 | X5: ✓ Verified: All salary fields match payroll file.
A6: 2 | B6: ABID | C6: Hamdi | D6: Contrat Local | E6: Assistant(e) d'éducation | F6: Vie Scolaire & Support | G6: Vie scolaire | H6: Non-Teacher | J6: Secondaire | K6: Vie Scolaire & Support | L6: Existing | M6: 42614 | N6: 10.3 | O6: 9000 | P6: 2500 | Q6: 500 | T6: 12000 | U6: 1 | V6: Virement | W6: 400 | X6: ✓ Verified: All salary fields match payroll file.
A7: 3 | B7: ABOU RJEILI | C7: Christina | D7: Contrat Local | E7: Assistant(e) d'éducation | F7: Vie Scolaire & Support | G7: Vie scolaire | H7: Non-Teacher | J7: Secondaire | K7: Vie Scolaire & Support | L7: Existing | M7: 45536 | N7: 2.3 | O7: 7200 | P7: 2500 | Q7: 500 | T7: 10200 | U7: 1 | V7: Virement | W7: 200 | X7: ✓ Verified: All salary fields match payroll file.
A8: 4 | B8: ABOUTALEB | C8: Hasnae | D8: Contrat Local | E8: Professeur(e) des écoles | F8: Élémentaire | G8: Generaliste | H8: Teacher | I8: Professeur des écoles (PE) | J8: PSB | K8: Maternelle | L8: Existing | M8: 44440 | N8: 5.3 | O8: 9000 | P8: 2500 | Q8: 500 | T8: 12000 | U8: 1 | V8: Virement | W8: 250 | X8: ✓ Verified: All salary fields match payroll file.
A9: 5 | B9: ABSIL | C9: Marie-Savine | D9: Contrat Local | E9: Professeur(e) des écoles | F9: Élémentaire | G9: Generaliste | H9: Teacher | I9: Professeur des écoles (PE) | J9: Élémentaire (TBD) | K9: Élémentaire | L9: Existing | M9: 45901 | N9: 1.3 | O9: 10500 | P9: 2500 | Q9: 500 | T9: 13500 | U9: 1 | V9: Liquide | W9: Nouveau Contrat | X9: ✓ Verified: All salary fields match payroll file.
A10: 6 | B10: ACHATOU | C10: Nadia | D10: Contrat Local | E10: Responsable RH | F10: Administration | G10: Ressources humaines | H10: Non-Teacher | J10: Administration | K10: Administration | L10: Existing | M10: 42614 | N10: 10.3 | O10: 12250 | P10: 2500 | Q10: 500 | R10: 1000 | T10: 16250 | U10: 1 | V10: Mudad | W10: 250 | X10: ✓ Verified: All salary fields match payroll file.
A11: 7 | B11: ADJTOUTAH | C11: Anissa | D11: Contrat Local | E11: Professeur(e) des écoles | F11: Élémentaire | G11: Generaliste | H11: Teacher | I11: Professeur des écoles (PE) | J11: Élémentaire (TBD) | K11: Élémentaire | L11: Existing | M11: 45901 | N11: 1.3 | O11: 8250 | P11: 2500 | Q11: 500 | T11: 11250 | U11: 1 | V11: Liquide | W11: Nouveau Contrat | X11: ✓ Verified: All salary fields match payroll file.
A12: 8 | B12: AHYOUD | C12: Hanan | D12: Contrat Local | E12: Professeur(e) des écoles | F12: Élémentaire | G12: Generaliste | H12: Teacher | I12: Professeur des écoles (PE) | J12: GSD | K12: Maternelle | L12: Existing | M12: 42614 | N12: 10.3 | O12: 10250 | P12: 2500 | Q12: 500 | T12: 13250 | U12: 1 | V12: Virement | W12: 250 | X12: ✓ Verified: All salary fields match payroll file.
A13: 9 | B13: AL JUNDI | C13: Tamara | D13: Contrat Local | E13: Enseignant de langue étrangère | F13: Élémentaire | G13: Arabe | H13: Teacher | I13: Enseignant Arabe | J13: PS-CM2 (Primaire) | K13: Primaire | L13: Existing | M13: 35309 | N13: 30.3 | O13: 9750 | P13: 2500 | Q13: 500 | S13: 1140 | T13: 13890 | U13: 1 | V13: Virement | W13: 250 | X13: ✓ Verified: All salary fields match payroll file.
A14: 10 | B14: AL NAHED | C14: Saliha | D14: Contrat Local | E14: Professeur(e) des écoles | F14: Élémentaire | G14: Generaliste | H14: Teacher | I14: Professeur des écoles (PE) | J14: CE2 D | K14: Élémentaire | L14: Existing | M14: 45536 | N14: 2.3 | O14: 8750 | P14: 2500 | Q14: 500 | T14: 11750 | U14: 1 | V14: Virement | W14: 250 | X14: ✓ Verified: All salary fields match payroll file.
A15: 11 | B15: AL OSSAIMI AL OTAIBI | C15: BADR | D15: Contrat Local | E15: Démarcheur | F15: Administration | G15: Relations publiques | H15: Non-Teacher | J15: Administration | K15: Administration | L15: Existing | O15: 2000 | P15: 2500 | Q15: 500 | T15: 5000 | U15: 1 | V15: Virement | W15: Nouveau Contrat | X15: ✓ Verified: All salary fields match payroll file. | MISSING: Joining Date is blank. Needs HR input. | MISSING: YoS is blank. Needs HR input.
A16: 12 | B16: AL SHAKHAA | C16: Nada | D16: Contrat Local | E16: Chargé(e) du programme noor | F16: Administration | G16: Programme Noor | H16: Non-Teacher | J16: Administration | K16: Administration | L16: Existing | M16: 42283 | N16: 11.2 | O16: 9500 | P16: 2500 | Q16: 500 | T16: 12500 | U16: 1 | V16: Mudad | W16: 250 | X16: ✓ Verified: All salary fields match payroll file.
A17: 13 | B17: ALAMRI | C17: Shalan | D17: Contrat Local | E17: Chargé(e) des relations publiques | F17: Administration | G17: Relations publiques | H17: Non-Teacher | J17: Administration | K17: Administration | L17: Existing | M17: 44867 | N17: 4.2 | O17: 12250 | P17: 2500 | Q17: 500 | R17: 1000 | T17: 16250 | U17: 1 | V17: Mudad | W17: 250 | X17: ✓ Verified: All salary fields match payroll file.
A18: 14 | B18: ALNACHAR | C18: Farah | D18: Contrat Local | E18: Assistant(e) d'éducation | F18: Vie Scolaire & Support | G18: Vie scolaire | H18: Non-Teacher | J18: Primaire | K18: Vie Scolaire & Support | L18: Existing | M18: 45901 | N18: 1.3 | O18: 7000 | P18: 2500 | Q18: 500 | T18: 10000 | U18: 1 | V18: Virement | W18: Nouveau Contrat | X18: ✓ Verified: All salary fields match payroll file.
A19: 15 | B19: AMANAT | C19: Aisha | D19: Contrat Local | E19: Professeur(e) des écoles | F19: Élémentaire | G19: Generaliste | H19: Teacher | I19: Professeur des écoles (PE) | J19: MSB | K19: Maternelle | L19: Existing | M19: 45536 | N19: 2.3 | O19: 8250 | P19: 2500 | Q19: 500 | T19: 11250 | U19: 1 | V19: Liquide | W19: 250 | X19: ✓ Verified: All salary fields match payroll file.
A20: 16 | B20: AMRI | C20: Kehena | D20: Contrat Local | E20: Enseignant second degré | F20: Collège / Lycée | G20: Francais | H20: Teacher | I20: Certifié Lettres | J20: PP 6eme B | K20: Secondaire | L20: Existing | M20: 40787 | N20: 15.3 | O20: 12000 | P20: 2500 | Q20: 500 | S20: 900 | T20: 15900 | U20: 1 | V20: Virement | W20: 250 | X20: ✓ Verified: All salary fields match payroll file.
A21: 17 | B21: ASSEKOUR | C21: Soufiane | D21: Contrat Local | E21: Enseignant second degré | F21: Collège / Lycée | G21: EPS | H21: Teacher | I21: Certifié EPS | J21: Collège & Lycée | K21: Secondaire | L21: Existing | M21: 45901 | N21: 1.3 | O21: 8750 | P21: 2500 | Q21: 500 | S21: 700 | T21: 12450 | U21: 1 | V21: Liquide | W21: Nouveau Contrat | X21: ✓ Verified: All salary fields match payroll file.
A22: 18 | B22: AYACHI | C22: Amen | D22: Contrat Local | E22: Professeur(e) des écoles | F22: Élémentaire | G22: Generaliste | H22: Teacher | I22: Professeur des écoles (PE) | J22: MSE | K22: Maternelle | L22: Existing | M22: 45536 | N22: 2.3 | O22: 9000 | P22: 2500 | Q22: 500 | T22: 12000 | U22: 1 | V22: Virement | W22: 250 | X22: ✓ Verified: All salary fields match payroll file.
A23: 19 | B23: BACHOUR | C23: Reem | D23: Contrat Local | E23: Enseignant de langue étrangère | F23: Élémentaire | G23: Arabe | H23: Teacher | I23: Enseignant Arabe | J23: PS-CM2 (Primaire) | K23: Primaire | L23: Existing | M23: 36404 | N23: 27.3 | O23: 13250 | P23: 2500 | Q23: 500 | S23: 1140 | T23: 17390 | U23: 1 | V23: Virement | W23: 250 | X23: ✓ Verified: All salary fields match payroll file.
A24: 20 | B24: BADR | C24: Chantal | D24: Contrat Local | E24: Enseignant de langue étrangère | F24: Élémentaire | G24: Arabe | H24: Teacher | I24: Enseignant Arabe | J24: PS-CM2 (Primaire) | K24: Primaire | L24: Existing | M24: 40787 | N24: 15.3 | O24: 10250 | P24: 2500 | Q24: 500 | S24: 70 | T24: 13320 | U24: 1 | V24: Virement | W24: 250 | X24: ✓ Verified: All salary fields match payroll file.
A25: 21 | B25: BALLAN | C25: Christiane | D25: Contrat Local | E25: Enseignant de langue étrangère second degré | F25: Collège / Lycée | G25: Arabe | H25: Teacher | I25: Certifié Arabe | J25: Collège & Lycée | K25: Secondaire | L25: Existing | M25: 44805 | N25: 4.3 | O25: 8750 | P25: 2500 | Q25: 500 | S25: 1300 | T25: 13050 | U25: 1 | V25: Virement | W25: 250 | X25: ✓ Verified: All salary fields match payroll file.
A26: 22 | B26: BASBOUS | C26: Carla | D26: Contrat Local | E26: Enseignant de langue étrangère second degré | F26: Collège / Lycée | G26: Arabe (coordinatrice) | H26: Teacher | I26: Certifié Arabe | J26: Collège & Lycée | K26: Secondaire | L26: Existing | M26: 36770 | N26: 26.3 | O26: 9500 | P26: 2500 | Q26: 500 | S26: 400 | T26: 12900 | U26: 1 | V26: Liquide | W26: -3250 (nouveau contrat retraite) | X26: ✓ Verified: All salary fields match payroll file.
A27: 23 | B27: BAYDOUN | C27: Fayza | D27: Contrat Local | E27: Assistante de direction | F27: Administration | G27: Secretariat | H27: Non-Teacher | J27: Administration | K27: Administration | L27: Existing | M27: 45902 | N27: 1.3 | O27: 7400 | P27: 2500 | Q27: 500 | T27: 10400 | U27: 1 | V27: Virement | W27: Nouveau Contrat | X27: ✓ Verified: All salary fields match payroll file.
A28: 24 | B28: BELLILA LAOUATI | C28: Ilham | D28: Contrat Local | E28: Enseignant second degré | F28: Collège / Lycée | G28: SVT | H28: Teacher | I28: Certifié SVT | J28: PP 5eme E | K28: Secondaire | L28: Existing | M28: 45170 | N28: 3.3 | O28: 9500 | P28: 2500 | Q28: 500 | S28: 880 | T28: 13380 | U28: 1 | V28: Liquide | W28: 250 | X28: ✓ Verified: All salary fields match payroll file.
A29: 25 | B29: BEN ABDESSALEM | C29: Yousra | D29: Contrat Local | E29: Professeur(e) des écoles | F29: Élémentaire | G29: Generaliste | H29: Teacher | I29: Professeur des écoles (PE) | J29: CM2 F | K29: Élémentaire | L29: Existing | M29: 45536 | N29: 2.3 | O29: 9000 | P29: 2500 | Q29: 500 | T29: 12000 | U29: 1 | V29: Liquide | W29: 250 | X29: ✓ Verified: All salary fields match payroll file.
A30: 26 | B30: BEN AMAR | C30: Amira | D30: Contrat Local | E30: Professeur(e) des écoles | F30: Élémentaire | G30: Generaliste | H30: Teacher | I30: Professeur des écoles (PE) | J30: CE2 A | K30: Élémentaire | L30: Existing | M30: 45170 | N30: 3.3 | O30: 11000 | P30: 2500 | Q30: 500 | T30: 14000 | U30: 1 | V30: Virement | W30: 250 | X30: ✓ Verified: All salary fields match payroll file.
A31: 27 | B31: BEN FGUIRA | C31: Fares | D31: Contrat Local | E31: Professeur(e) d'EPS | F31: Collège / Lycée | G31: EPS | H31: Teacher | I31: Certifié EPS | J31: Collège & Lycée | K31: Secondaire | L31: Existing | M31: 44805 | N31: 4.3 | O31: 8750 | P31: 2500 | Q31: 500 | S31: 500 | T31: 12250 | U31: 1 | V31: Liquide | W31: 250 | X31: ✓ Verified: All salary fields match payroll file.
A32: 28 | B32: BEN HIBA | C32: Nesrine | D32: Contrat Local | E32: Enseignant second degré | F32: Collège / Lycée | G32: EMC | H32: Teacher | I32: Certifié EMC | J32: Secondaire (TBD) | K32: Secondaire | L32: Existing | M32: 45901 | N32: 1.3 | O32: 7200 | P32: 2250 | Q32: 450 | T32: 9900 | U32: 0.9 | V32: Liquide | W32: Nouveau Contrat | X32: ✓ Verified: All salary fields match payroll file.
A33: 29 | B33: BEN KIRAN | C33: Ambre | D33: Contrat Local | E33: Responsable APS | F33: Vie Scolaire & Support | G33: Activites periscolaires | H33: Non-Teacher | J33: Primaire & Secondaire | K33: Vie Scolaire & Support | L33: Existing | M33: 45908 | N33: 1.3 | O33: 13000 | P33: 2500 | Q33: 500 | T33: 16000 | U33: 1 | V33: Liquide | W33: Nouveau Contrat | X33: ✓ Verified: All salary fields match payroll file.
A34: 30 | B34: BEN OTHMAN | C34: Noelle | D34: Contrat Local | E34: Enseignant second degré | F34: Collège / Lycée | G34: Sciences economiques (SES) | H34: Teacher | I34: Certifié SES | J34: Collège & Lycée | K34: Secondaire | L34: Existing | M34: 44075 | N34: 6.3 | O34: 9250 | P34: 2500 | Q34: 500 | T34: 12250 | U34: 1 | V34: Virement | W34: 250 | X34: ✓ Verified: All salary fields match payroll file.
A35: 31 | B35: BEN SMIDA ÉP BEN IDRIS | C35: Khadija | D35: Contrat Local | E35: Enseignant second degré | F35: Collège / Lycée | G35: Mathematiques | H35: Teacher | I35: Certifié Maths | J35: PP 2nde A | K35: Secondaire | L35: Existing | M35: 44440 | N35: 5.3 | O35: 9000 | P35: 2500 | Q35: 500 | S35: 1080 | T35: 13080 | U35: 1 | V35: Liquide | W35: 250 | X35: ✓ Verified: All salary fields match payroll file.
A36: 32 | B36: BENBERNOU | C36: Rabia | D36: Contrat Local | E36: Assistante maternelle | F36: Maternelle | G36: ASEM | H36: Non-Teacher | J36: MSA | K36: Maternelle | L36: Existing | M36: 42979 | N36: 9.3 | O36: 7200 | P36: 2500 | Q36: 500 | T36: 10200 | U36: 1 | V36: Virement | W36: 200 | X36: ✓ Verified: All salary fields match payroll file.
A37: 33 | B37: BOUGATFA | C37: Rim | D37: Contrat Local | E37: Enseignant second degré | F37: Collège / Lycée | G37: TBD | H37: Teacher | I37: TBD | J37: Secondaire (TBD) | K37: Secondaire | L37: Existing | M37: 45901 | N37: 1.3 | O37: 8250 | P37: 2500 | Q37: 500 | T37: 11250 | U37: 1 | V37: Virement | W37: Nouveau Contrat | X37: ✓ Verified: All salary fields match payroll file.
A38: 34 | B38: BOUHJAR | C38: Fahmi | D38: Contrat Local | E38: Enseignant second degré | F38: Collège / Lycée | G38: Sciences physiques | H38: Teacher | I38: Certifié Physique-Chimie | J38: Collège & Lycée | K38: Secondaire | L38: Existing | M38: 43344 | N38: 8.3 | O38: 10000 | P38: 2500 | Q38: 500 | S38: 1300 | T38: 14300 | U38: 1 | V38: Virement | W38: 250 | X38: ✓ Verified: All salary fields match payroll file.
A39: 35 | B39: BOULMANE | C39: Lala-Malika | D39: Contrat Local | E39: Coordinatrice inclusion | F39: Vie Scolaire & Support | G39: Inclusion | H39: Non-Teacher | J39: Primaire & Secondaire | K39: Vie Scolaire & Support | L39: Existing | M39: 44805 | N39: 4.3 | O39: 11750 | P39: 2500 | Q39: 500 | T39: 14750 | U39: 1 | V39: Virement | W39: 250 | X39: ✓ Verified: All salary fields match payroll file.
A40: 36 | B40: BOURAOUI | C40: Nasri | D40: Contrat Local | E40: Assistant(e) d'éducation | F40: Vie Scolaire & Support | G40: Vie scolaire | H40: Non-Teacher | J40: Secondaire | K40: Vie Scolaire & Support | L40: Existing | M40: 45536 | N40: 2.3 | O40: 7600 | P40: 2500 | Q40: 500 | T40: 10600 | U40: 1 | V40: Virement | W40: 200 | X40: ✓ Verified: All salary fields match payroll file.
A41: 37 | B41: BOURSAULT | C41: Géraldine | D41: Contrat Local | E41: Enseignant second degré | F41: Collège / Lycée | G41: Mathematiques | H41: Teacher | I41: Certifié Maths | J41: Collège & Lycée | K41: Secondaire | L41: Existing | M41: 45536 | N41: 2.3 | O41: 10000 | P41: 2500 | Q41: 500 | S41: 900 | T41: 13900 | U41: 1 | V41: Virement | W41: 250 | X41: ✓ Verified: All salary fields match payroll file.
...
